Workbook

Sheet data
A1: Title prefix:
A2: Entry order | B2: Player Name | C2: Player Dojo | D2: Display Name | E2: Player Number | F2: Metadata
A3: 1 | B3: Cersei Lannister | C3: Team Gamma | D3: LANNISTER | E3: K1
A4: 5 | B4: Gandalf The Grey | C4: Team Eta | D4: GANDALF | E4: K2
A5: 6 | B5: Hermione Granger | C5: Team Theta | D5: GRANGER | E5: K3
A6: 7 | B6: Inigo Montoya | C6: Team Iota | D6: MONTOYA | E6: K4
A7: 8 | B7: Jon Snow | C7: Team Kappa | D7: SNOW | E7: K5
A8: 9 | B8: Katniss Everdeen | C8: Team Lambda | D8: EVERDEEN | E8: K6
A9: 15 | B9: Petyr Baelish | C9: Team Pi | D9: BAELISH | E9: K7
A10: 11 | B10: Legolas Greenleaf | C10: Team Mu | D10: GREENLEAF | E10: K8
A11: 4 | B11: Frodo Baggins | C11: Team Zeta | D11: BAGGINS | E11: K9
A12: 12 | B12: Moby Dick | C12: Team Nu | D12: DICK | E12: K10
A13: 13 | B13: Neville Longbottom | C13: Team Xi | D13: LONGBOTTOM | E13: K11
A14: 14 | B14: Othello | C14: Team Omicron | D14: OTHELLO | E14: K12
... A26: 3 | B26: Eddard Stark | C26: Team Epsilon | D26: STARK | E26: K24

Sheet Time Estimator
A1: Number of pools | B1: Team size | C1: Matches per pool | D1: Time per match | E1: Total time for matches | F1: Padding time for rotation | G1: Time for breaks | H1: Total Time
A2: 0 | B2: 1 | C2: 0 | D2: 0.0020833333 | E2: =(A2*B2*C2*D2) | F2: 0.00034722222 | G2: 0.020833333 | H2: =C2*I2+J2
A3: 0 | B3: 0 | C3: 0 | D3: 0.0020833333 | E3: =(A3*B3*C3*D3) | F3: 0.00034722222 | G3: 0.020833333 | H3: =E3+(A3*C3*F3)+G3
A7: Number of Elimination Matches | B7: Team size | D7: Time per match | E7: Total time for matches | F7: Padding time for rotation | G7: Time for breaks | H7: Total Time
A8: 23 | B8: 1 | D8: 0.0027777778 | E8: =(A8*B8*D8) | F8: 0.00034722222 | G8: 0.020833333 | H8: =E8+(A8*F8)+G8
E13: Tournament Summary
A14: 2 | E14: Total Pool Time | H14: =H2
E15: Total Elimination Time | H15: =H8
E16: Grand Total (Sequential) | H16: =H14+H15
E17: Grand Total (Parallel across Courts) | H17: =H16/A14
E18: Start Time: | H18: 0.375
E19: Estimated Finish Time | H19: =H18+H17

Sheet Elimination Matches
A1: Shiaijo A | I1: Shiaijo B
A2: Round 1 - Match 1 | I2: Round 1 - Match 5
A3: White | D3: vs | G3: Red | I3: White | L3: vs | O3: Red
A4: ='data'!$B$5 | G4: ='data'!$B$4 | I4: ='data'!$B$17 | O4: ='data'!$B$16
F6: 1. | N6: 1.
F7: 2. | N7: 2.
A10: Round 1 - Match 2 | I10: Round 1 - Match 6
A11: White | D11: vs | G11: Red | I11: White | L11: vs | O11: Red
A12: ='data'!$B$15 | G12: ='data'!$B$7 | I12: ='data'!$B$20 | O12: ='data'!$B$19
F14: 1. | N14: 1.
F15: 2. | N15: 2.
A18: Round 1 - Match 3 | I18: Round 1 - Match 7
A19: White | D19: vs | G19: Red | I19: White | L19: vs | O19: Red
A20: ='data'!$B$11 | G20: ='data'!$B$10 | I20: ='data'!$B$23 | O20: ='data'!$B$22
F22: 1. | N22: 1.
F23: 2. | N23: 2.
A26: Round 1 - Match 4 | I26: Round 1 - Match 8
A27: White | D27: vs | G27: Red | I27: White | L27: vs | O27: Red
A28: ='data'!$B$14 | G28: ='data'!$B$13 | I28: ='data'!$B$26 | O28: ='data'!$B$25
F30: 1. | N30: 1.
F31: 2. | N31: 2.
A39: Round 2 - Match 9 | I39: Round 2 - Match 13
A40: White | D40: vs | G40: Red | I40: White | L40: vs | O40: Red
A41: =CONCATENATE("M 1 ",G6) | G41: ='data'!$B$20 | I41: =CONCATENATE("M 5 ",O6) | O41: ='data'!$B$15
F43: 1. | N43: 1.
F44: 2. | N44: 2.
A47: Round 2 - Match 10 | I47: Round 2 - Match 14
A48: White | D48: vs | G48: Red | I48: White | L48: vs | O48: Red
A49: =CONCATENATE("M 2 ",G14) | G49: ='data'!$B$6 | I49: =CONCATENATE("M 6 ",O14) | O49: ='data'!$B$18
F51: 1. | N51: 1.
F52: 2. | N52: 2.
A55: Round 2 - Match 11 | I55: Round 2 - Match 15
A56: White | D56: vs | G56: Red | I56: White | L56: vs | O56: Red
A57: =CONCATENATE("M 3 ",G22) | G57: ='data'!$B$9 | I57: =CONCATENATE("M 7 ",O22) | O57: ='data'!$B$21
F59: 1. | N59: 1.
F60: 2. | N60: 2.
A63: Round 2 - Match 12 | I63: Round 2 - Match 16
A64: White | D64: vs | G64: Red | I64: White | L64: vs | O64: Red
A65: =CONCATENATE("M 4 ",G30) | G65: ='data'!$B$12 | I65: =CONCATENATE("M 8 ",O30) | O65: ='data'!$B$24
F67: 1. | N67: 1.
...

Sheet Tree 1
A1: =IF(data!$B$1="","Shiaijo A",data!$B$1&" - Shiaijo A")
E6: LANNISTER
G8: 9
C9: GANDALF
E10: 1
C11: GRANGER
I12: 17
E14: MONTOYA
G16: 10
C17: SNOW
E18: 2
C19: EVERDEEN
K20: 21
E22: BAELISH
G24: 11
C25: GREENLEAF
E26: 3
C27: BAGGINS
I28: 18
E30: DICK
G32: 12
C33: LONGBOTTOM
E34: 4
C35: OTHELLO

Sheet Tree 2
A1: =IF(data!$B$1="","Shiaijo B",data!$B$1&" - Shiaijo B")
E6: EVERDEEN
G8: 13
C9: QUIRRELL
E10: 5
C11: WEASLEY
I12: 19
E14: GAMGEE
G16: 14
C17: TARGARYEN
E18: 6
C19: LANNISTER
K20: 22
E22: ULYSSES
G24: 15
C25: VOLDEMORT
E26: 7
C27: WONKA
I28: 20
E30: DAXOS
G32: 16
C33: YGRITTE
E34: 8
C35: STARK

Sheet Names to Print A
A1: ='data'!$E$3 | B1: ='data'!D3
A2: ='data'!$E$4 | B2: ='data'!D4
A3: ='data'!$E$5 | B3: ='data'!D5
A4: ='data'!$E$6 | B4: ='data'!D6
A5: ='data'!$E$7 | B5: ='data'!D7
A6: ='data'!$E$8 | B6: ='data'!D8
A7: ='data'!$E$9 | B7: ='data'!D9
A8: ='data'!$E$10 | B8: ='data'!D10
A9: ='data'!$E$11 | B9: ='data'!D11
A10: ='data'!$E$12 | B10: ='data'!D12
A11: ='data'!$E$13 | B11: ='data'!D13
A12: ='data'!$E$14 | B12: ='data'!D14

Sheet Names to Print B
A1: ='data'!$E$15 | B1: ='data'!D15
A2: ='data'!$E$16 | B2: ='data'!D16
A3: ='data'!$E$17 | B3: ='data'!D17
A4: ='data'!$E$18 | B4: ='data'!D18
A5: ='data'!$E$19 | B5: ='data'!D19
A6: ='data'!$E$20 | B6: ='data'!D20
A7: ='data'!$E$21 | B7: ='data'!D21
A8: ='data'!$E$22 | B8: ='data'!D22
A9: ='data'!$E$23 | B9: ='data'!D23
A10: ='data'!$E$24 | B10: ='data'!D24
A11: ='data'!$E$25 | B11: ='data'!D25
A12: ='data'!$E$26 | B12: ='data'!D26
