Workbook

Sheet data
A1: Title prefix:
A2: Entry order | B2: Player Name | C2: Player Dojo | D2: Display Name | E2: Player Number | F2: Metadata
A3: 27 | B3: Kaden Martin | C3: Team Alpha | D3: MARTIN | E3: K1
A4: 24 | B4: Hudson Jackson | C4: Team Theta | D4: JACKSON | E4: K2
A5: 25 | B5: Isaac White | C5: Team Iota | D5: WHITE | E5: K3
A6: 26 | B6: Jackson Harris | C6: Team Kappa | D6: HARRIS | E6: K4
A7: 83 | B7: Quirinus Quirrell | C7: Team Rho | D7: QUIRRELL | E7: K5
A8: 77 | B8: Katniss Everdeen | C8: Team Lambda | D8: EVERDEEN | E8: K6
A9: 7 | B9: Quentin Allen | C9: Team Beta | D9: ALLEN | E9: K7
A10: 8 | B10: Robert Young | C10: Team Gamma | D10: YOUNG | E10: K8
A11: 9 | B11: Steven Hernandez | C11: Team Delta | D11: HERNANDEZ | E11: K9
A12: 10 | B12: Thomas King | C12: Team Epsilon | D12: KING | E12: K10
A13: 11 | B13: Uriel Wright | C13: Team Alpha | D13: WRIGHT | E13: K11
A14: 59 | B14: Ray Bradbury | C14: Team Sigma | D14: BRADBURY | E14: K12
... A93: 91 | B93: Ygritte | C93: Team Alpha | D93: YGRITTE | E93: K91

Sheet Time Estimator
A1: Number of pools | B1: Team size | C1: Matches per pool | D1: Time per match | E1: Total time for matches | F1: Padding time for rotation | G1: Time for breaks | H1: Total Time
A2: 0 | B2: 1 | C2: 0 | D2: 0.0020833333 | E2: =(A2*B2*C2*D2) | F2: 0.00034722222 | G2: 0.020833333 | H2: =C2*I2+J2
A3: 0 | B3: 0 | C3: 0 | D3: 0.0020833333 | E3: =(A3*B3*C3*D3) | F3: 0.00034722222 | G3: 0.020833333 | H3: =E3+(A3*C3*F3)+G3
A7: Number of Elimination Matches | B7: Team size | D7: Time per match | E7: Total time for matches | F7: Padding time for rotation | G7: Time for breaks | H7: Total Time
A8: 90 | B8: 1 | D8: 0.0027777778 | E8: =(A8*B8*D8) | F8: 0.00034722222 | G8: 0.020833333 | H8: =E8+(A8*F8)+G8
E13: Tournament Summary
A14: 2 | E14: Total Pool Time | H14: =H2
E15: Total Elimination Time | H15: =H8
E16: Grand Total (Sequential) | H16: =H14+H15
E17: Grand Total (Parallel across Courts) | H17: =H16/A14
E18: Start Time: | H18: 0.375
E19: Estimated Finish Time | H19: =H18+H17

Sheet Elimination Matches
A1: Shiaijo A | I1: Shiaijo B
A2: Round 1 - Match 1 | I2: Round 1 - Match 17
A3: White | D3: vs | G3: Red | I3: White | L3: vs | O3: Red
A4: ='data'!$B$4 | G4: ='data'!$B$3 | I4: ='data'!$B$49 | O4: ='data'!$B$55
F6: 1. | N6: 1.
F7: 2. | N7: 2.
A10: Round 1 - Match 2 | I10: Round 1 - Match 18
A11: White | D11: vs | G11: Red | I11: White | L11: vs | O11: Red
A12: ='data'!$B$7 | G12: ='data'!$B$6 | I12: ='data'!$B$52 | O12: ='data'!$B$51
F14: 1. | N14: 1.
F15: 2. | N15: 2.
A18: Round 1 - Match 3 | I18: Round 1 - Match 19
A19: White | D19: vs | G19: Red | I19: White | L19: vs | O19: Red
A20: ='data'!$B$38 | G20: ='data'!$B$37 | I20: ='data'!$B$55 | O20: ='data'!$B$54
F22: 1. | N22: 1.
F23: 2. | N23: 2.
A26: Round 1 - Match 4 | I26: Round 1 - Match 20
A27: White | D27: vs | G27: Red | I27: White | L27: vs | O27: Red
A28: ='data'!$B$91 | G28: ='data'!$B$90 | I28: ='data'!$B$58 | O28: ='data'!$B$57
F30: 1. | N30: 1.
F31: 2. | N31: 2.
A34: Round 1 - Match 5 | I34: Round 1 - Match 21
A35: White | D35: vs | G35: Red | I35: White | L35: vs | O35: Red
A36: ='data'!$B$15 | G36: ='data'!$B$14 | I36: ='data'!$B$61 | O36: ='data'!$B$60
F38: 1. | N38: 1.
F39: 2. | N39: 2.
A42: Round 1 - Match 6 | I42: Round 1 - Match 22
A43: White | D43: vs | G43: Red | I43: White | L43: vs | O43: Red
A44: ='data'!$B$85 | G44: ='data'!$B$17 | I44: ='data'!$B$64 | O44: ='data'!$B$63
F46: 1. | N46: 1.
F47: 2. | N47: 2.
A50: Round 1 - Match 7 | I50: Round 1 - Match 23
A51: White | D51: vs | G51: Red | I51: White | L51: vs | O51: Red
A52: ='data'!$B$21 | G52: ='data'!$B$20 | I52: ='data'!$B$67 | O52: ='data'!$B$66
F54: 1. | N54: 1.
F55: 2. | N55: 2.
A58: Round 1 - Match 8 | I58: Round 1 - Match 24
A59: White | D59: vs | G59: Red | I59: White | L59: vs | O59: Red
A60: ='data'!$B$24 | G60: ='data'!$B$23 | I60: ='data'!$B$82 | O60: ='data'!$B$69
F62: 1. | N62: 1.
...

Sheet Tree 1
A1: =IF(data!$B$1="","Shiaijo A",data!$B$1&" - Shiaijo A")
C5: MARTIN
E6: 1
C7: JACKSON
I12: 60
E14: WHITE
G16: 33
C17: HARRIS
E18: 2
C19: QUIRRELL
K20: 76
E22: EVERDEEN
G24: 34
C25: ALLEN
E26: 3
C27: YOUNG
I28: 61
E30: HERNANDEZ
G32: 35
C33: KING
E34: 4
C35: WRIGHT

Sheet Tree 2
A1: =IF(data!$B$1="","Shiaijo A",data!$B$1&" - Shiaijo A")
C5: BRADBURY
E6: 5
C7: PLATH
I12: 62
E14: LANNISTER
G16: 36
C17: LE GUIN
E18: 6
C19: WALKER
K20: 77
E22: THOMPSON
G24: 37
C25: EVANS
E26: 7
C27: WILSON
I28: 63
E30: MOORE
G32: 38
C33: TAYLOR
E34: 8
C35: ANDERSON

Sheet Tree 3
A1: =IF(data!$B$1="","Shiaijo A",data!$B$1&" - Shiaijo A")
C5: THOMAS
E6: 9
C7: LONGBOTTOM
I12: 64
E14: WILDE
G16: 39
C17: DICK
E18: 10
C19: SHELLEY
K20: 78
E22: THOMPSON
G24: 40
C25: MARTINEZ
E26: 11
C27: CLARK
I28: 65
E30: RODRIGUEZ
G32: 41
C33: LEWIS
E34: 12
C35: ADAMS

Sheet Tree 4
A1: =IF(data!$B$1="","Shiaijo A",data!$B$1&" - Shiaijo A")
E6: HALL
G8: 42
C9: ALLEN
E10: 13
C11: YOUNG
I12: 66
E14: HERNANDEZ
G16: 43
C17: VOLDEMORT
E18: 14
C19: WONKA
K20: 79
E22: CARROLL
G24: 44
C25: HILL
E26: 15
C27: CONAN
I28: 67
E30: STOKER
G32: 45
C33: DICKENS
E34: 16
C35: DEFOE

Sheet Tree 5
A1: =IF(data!$B$1="","Shiaijo B",data!$B$1&" - Shiaijo B")
C5: LOPEZ
E6: 17
C7: GREEN
I12: 68
E14: ORWELL
G16: 46
C17: MELVILLE
E18: 18
C19: ASIMOV
K20: 80
E22: AUSTEN
G24: 47
C25: VONNEGUT
E26: 19
C27: LOPEZ
I28: 69
E30: CLARK
G32: 48
C33: HAWTHORNE
E34: 20
C35: LEWIS

Sheet Tree 6
A1: =IF(data!$B$1="","Shiaijo B",data!$B$1&" - Shiaijo B")
E6: LEE
G8: 49
C9: BLAKE
E10: 21
C11: MARTEL
I12: 70
E14: HILL
G16: 50
C17: HARDY
E18: 22
C19: DOSTOEVSKY
K20: 81
E22: WOOLF
G24: 51
C25: SHAKESPEARE
E26: 23
C27: HERBERT
I28: 71
E30: BRONTE
G32: 52
C33: DUMBLEDORE
E34: 24
C35: BAGGINS

Sheet Tree 7
A1: =IF(data!$B$1="","Shiaijo B",data!$B$1&" - Shiaijo B")
C5: LANNISTER
E6: 25
C7: TARGARYEN
I12: 72
E14: STARK
G16: 53
C17: RODRIGUEZ
E18: 26
C19: GANDALF
K20: 82
E22: GRANGER
G24: 54
C25: MONTOYA
E26: 27
C27: SNOW
I28: 73
E30: HALL
G32: 55
C33: GREENLEAF
E34: 28
C35: DICK

Sheet Tree 8
A1: =IF(data!$B$1="","Shiaijo B",data!$B$1&" - Shiaijo B")
E6: BAGGINS
G8: 56
C9: OTHELLO
E10: 29
C11: BAELISH
I12: 74
E14: WALKER
G16: 57
C17: WEASLEY
E18: 30
C19: GAMGEE
K20: 83
E22: SCOTT
G24: 58
C25: ULYSSES
E26: 31
C27: KING
I28: 75
E30: WRIGHT
G32: 59
C33: DAXOS
E34: 32
C35: YGRITTE

Sheet Names to Print A
A1: ='data'!$E$3 | B1: ='data'!D3
A2: ='data'!$E$4 | B2: ='data'!D4
A3: ='data'!$E$5 | B3: ='data'!D5
A4: ='data'!$E$6 | B4: ='data'!D6
A5: ='data'!$E$7 | B5: ='data'!D7
A6: ='data'!$E$8 | B6: ='data'!D8
A7: ='data'!$E$9 | B7: ='data'!D9
A8: ='data'!$E$10 | B8: ='data'!D10
A9: ='data'!$E$11 | B9: ='data'!D11
A10: ='data'!$E$12 | B10: ='data'!D12
A11: ='data'!$E$13 | B11: ='data'!D13
A12: ='data'!$E$14 | B12: ='data'!D14
A13: ='data'!$E$15 | B13: ='data'!D15
A14: ='data'!$E$16 | B14: ='data'!D16
A15: ='data'!$E$17 | B15: ='data'!D17
A16: ='data'!$E$18 | B16: ='data'!D18
A17: ='data'!$E$19 | B17: ='data'!D19
A18: ='data'!$E$20 | B18: ='data'!D20
A19: ='data'!$E$21 | B19: ='data'!D21
A20: ='data'!$E$22 | B20: ='data'!D22
A21: ='data'!$E$23 | B21: ='data'!D23
A22: ='data'!$E$24 | B22: ='data'!D24
A23: ='data'!$E$25 | B23: ='data'!D25
A24: ='data'!$E$26 | B24: ='data'!D26
A25: ='data'!$E$27 | B25: ='data'!D27
A26: ='data'!$E$28 | B26: ='data'!D28
A27: ='data'!$E$29 | B27: ='data'!D29
A28: ='data'!$E$30 | B28: ='data'!D30
A29: ='data'!$E$31 | B29: ='data'!D31
A30: ='data'!$E$32 | B30: ='data'!D32
A31: ='data'!$E$33 | B31: ='data'!D33
A32: ='data'!$E$34 | B32: ='data'!D34
A33: ='data'!$E$35 | B33: ='data'!D35
A34: ='data'!$E$36 | B34: ='data'!D36
A35: ='data'!$E$37 | B35: ='data'!D37
A36: ='data'!$E$38 | B36: ='data'!D38
A37: ='data'!$E$39 | B37: ='data'!D39
A38: ='data'!$E$40 | B38: ='data'!D40
A39: ='data'!$E$41 | B39: ='data'!D41
A40: ='data'!$E$42 | B40: ='data'!D42
...

Sheet Names to Print B
A1: ='data'!$E$49 | B1: ='data'!D49
A2: ='data'!$E$50 | B2: ='data'!D50
A3: ='data'!$E$51 | B3: ='data'!D51
A4: ='data'!$E$52 | B4: ='data'!D52
A5: ='data'!$E$53 | B5: ='data'!D53
A6: ='data'!$E$54 | B6: ='data'!D54
A7: ='data'!$E$55 | B7: ='data'!D55
A8: ='data'!$E$56 | B8: ='data'!D56
A9: ='data'!$E$57 | B9: ='data'!D57
A10: ='data'!$E$58 | B10: ='data'!D58
A11: ='data'!$E$59 | B11: ='data'!D59
A12: ='data'!$E$60 | B12: ='data'!D60
A13: ='data'!$E$61 | B13: ='data'!D61
A14: ='data'!$E$62 | B14: ='data'!D62
A15: ='data'!$E$63 | B15: ='data'!D63
A16: ='data'!$E$64 | B16: ='data'!D64
A17: ='data'!$E$65 | B17: ='data'!D65
A18: ='data'!$E$66 | B18: ='data'!D66
A19: ='data'!$E$67 | B19: ='data'!D67
A20: ='data'!$E$68 | B20: ='data'!D68
A21: ='data'!$E$69 | B21: ='data'!D69
A22: ='data'!$E$70 | B22: ='data'!D70
A23: ='data'!$E$71 | B23: ='data'!D71
A24: ='data'!$E$72 | B24: ='data'!D72
A25: ='data'!$E$73 | B25: ='data'!D73
A26: ='data'!$E$74 | B26: ='data'!D74
A27: ='data'!$E$75 | B27: ='data'!D75
A28: ='data'!$E$76 | B28: ='data'!D76
A29: ='data'!$E$77 | B29: ='data'!D77
A30: ='data'!$E$78 | B30: ='data'!D78
A31: ='data'!$E$79 | B31: ='data'!D79
A32: ='data'!$E$80 | B32: ='data'!D80
A33: ='data'!$E$81 | B33: ='data'!D81
A34: ='data'!$E$82 | B34: ='data'!D82
A35: ='data'!$E$83 | B35: ='data'!D83
A36: ='data'!$E$84 | B36: ='data'!D84
A37: ='data'!$E$85 | B37: ='data'!D85
A38: ='data'!$E$86 | B38: ='data'!D86
A39: ='data'!$E$87 | B39: ='data'!D87
A40: ='data'!$E$88 | B40: ='data'!D88
...
