Workbook

Sheet data
A1: Title prefix:
A2: Number | B2: Player Name | C2: Player Dojo | E2: Metadata
A3: 0 | B3: Kevin Clark | C3: Team Alpha
A4: 1 | B4: Luke Rodriguez | C4: Team Beta
A5: 2 | B5: Michael Lewis | C5: Team Gamma
A6: 3 | B6: Nathan Lee | C6: Team Delta
A7: 4 | B7: Oliver Walker | C7: Team Epsilon
A8: 5 | B8: Paul Hall | C8: Team Alpha
A9: 6 | B9: Quentin Allen | C9: Team Beta
A10: 7 | B10: Robert Young | C10: Team Gamma
A11: 8 | B11: Steven Hernandez | C11: Team Delta
A12: 9 | B12: Thomas King | C12: Team Epsilon

Sheet Time Estimator
A1: Number of pools | B1: Team size | C1: Matches per pool | D1: Time per match | E1: Total time for matches | F1: Padding time for rotation | G1: Time for breaks | H1: Total Time
A2: 0 | B2: 5 | C2: 0 | D2: 0.0020833333 | E2: =(A2*B2*C2*D2) | F2: 0.00034722222 | G2: 0.020833333 | H2: =C2*I2+J2
A3: 0 | B3: 0 | C3: 0 | D3: 0.0020833333 | E3: =(A3*B3*C3*D3) | F3: 0.00034722222 | G3: 0.020833333 | H3: =E3+(A3*C3*F3)+G3
A7: Number of Elimination Matches | B7: Team size | D7: Time per match | E7: Total time for matches | F7: Padding time for rotation | G7: Time for breaks | H7: Total Time
A8: 9 | B8: 5 | D8: 0.0027777778 | E8: =(A8*B8*D8) | F8: 0.00034722222 | G8: 0.020833333 | H8: =E8+(A8*F8)+G8
E13: Tournament Summary
A14: 1 | E14: Total Pool Time | H14: =H2
E15: Total Elimination Time | H15: =H8
E16: Grand Total (Sequential) | H16: =H14+H15
E17: Grand Total (Parallel across Courts) | H17: =H16/A14
E18: Start Time: | H18: 0.375
E19: Estimated Finish Time | H19: =H18+H17

Sheet Elimination Matches
A1: Shiaijo A
A2: Round 1 - Match 1
A3: White | D3: vs | G3: Red
A4: ='data'!$B$4 | G4: ='data'!$B$3
A5: 1 | G5: 1
A6: 2 | G6: 2
A7: 3 | G7: 3
A8: 4 | G8: 4
A9: 5 | G9: 5
A11: ='data'!$B$4 | B11: IV | C11: PW | E11: PW | F11: IV | G11: ='data'!$B$3
A12: Victories / Points | B12: =IF(UPPER(D5)="X",0,IF((LEN(SUBSTITUTE(SUBSTITUTE(SUBSTITUTE(B5," ",""),"0",""),"-",""))+LEN(SUBSTITUTE(SUBSTITUTE(SUBSTITUTE(C5," ",""),"0",""),"-","")))>(LEN(SUBSTITUTE(SUBSTITUTE(SUBSTITUTE(E5," ",""),"0",""),"-",""))+LEN(SUBSTITUTE(SUBSTITUTE(SUBSTITUTE(F5," ",""),"0",""),"-",""))),1,0))+IF(UPPER(D6)="X",0,IF((LEN(SUBSTITUTE(SUBSTITUTE(SUBSTITUTE(B6," ",""),"0",""),"-",""))+LEN(SUBSTITUTE(SUBSTITUTE(SUBSTITUTE(C6," ",""),"0",""),"-","")))>(LEN(SUBSTITUTE(SUBSTITUTE(SUBSTITUTE(E6," ",""),"0",""),"-",""))+LEN(SUBSTITUTE(SUBSTITUTE(SUBSTITUTE(F6," ",""),"0",""),"-",""))),1,0))+IF(UPPER(D7)="X",0,IF((LEN(SUBSTITUTE(SUBSTITUTE(SUBSTITUTE(B7," ",""),"0",""),"-",""))+LEN(SUBSTITUTE(SUBSTITUTE(SUBSTITUTE(C7," ",""),"0",""),"-","")))>(LEN(SUBSTITUTE(SUBSTITUTE(SUBSTITUTE(E7," ",""),"0",""),"-",""))+LEN(SUBSTITUTE(SUBSTITUTE(SUBSTITUTE(F7," ",""),"0",""),"-",""))),1,0))+IF(UPPER(D8)="X",0,IF((LEN(SUBSTITUTE(SUBSTITUTE(SUBSTITUTE(B8," ",""),"0",""),"-",""))+LEN(SUBSTITUTE(SUBSTITUTE(SUBSTITUTE(C8," ",""),"0",""),"-","")))>(LEN(SUBSTITUTE(SUBSTITUTE(SUBSTITUTE(E8," ",""),"0",""),"-",""))+LEN(SUBSTITUTE(SUBSTITUTE(SUBSTITUTE(F8," ",""),"0",""),"-",""))),1,0))+IF(UPPER(D9)="X",0,IF((LEN(SUBSTITUTE(SUBSTITUTE(SUBSTITUTE(B9," ",""),"0",""),"-",""))+LEN(SUBSTITUTE(SUBSTITUTE(SUBSTITUTE(C9," ",""),"0",""),"-","")))>(LEN(SUBSTITUTE(SUBSTITUTE(SUBSTITUTE(E9," ",""),"0",""),"-",""))+LEN(SUBSTITUTE(SUBSTITUTE(SUBSTITUTE(F9," ",""),"0",""),"-",""))),1,0)) | C12: =LEN(SUBSTITUTE(SUBSTITUTE(SUBSTITUTE(B5," ",""),"0",""),"-",""))+LEN(SUBSTITUTE(SUBSTITUTE(SUBSTITUTE(C5," ",""),"0",""),"-",""))+LEN(SUBSTITUTE(SUBSTITUTE(SUBSTITUTE(B6," ",""),"0",""),"-",""))+LEN(SUBSTITUTE(SUBSTITUTE(SUBSTITUTE(C6," ",""),"0",""),"-",""))+LEN(SUBSTITUTE(SUBSTITUTE(SUBSTITUTE(B7," ",""),"0",""),"-",""))+LEN(SUBSTITUTE(SUBSTITUTE(SUBSTITUTE(C7," ",""),"0",""),"-",""))+LEN(SUBSTITUTE(SUBSTITUTE(SUBSTITUTE(B8," ",""),"0",""),"-",""))+LEN(SUBSTITUTE(SUBSTITUTE(SUBSTITUTE(C8," ",""),"0",""),"-",""))+LEN(SUBSTITUTE(SUBSTITUTE(SUBSTITUTE(B9," ",""),"0",""),"-",""))+LEN(SUBSTITUTE(SUBSTITUTE(SUBSTITUTE(C9," ",""),"0",""),"-","")) | E12: =LEN(SUBSTITUTE(SUBSTITUTE(SUBSTITUTE(E5," ",""),"0",""),"-",""))+LEN(SUBSTITUTE(SUBSTITUTE(SUBSTITUTE(F5," ",""),"0",""),"-",""))+LEN(SUBSTITUTE(SUBSTITUTE(SUBSTITUTE(E6," ",""),"0",""),"-",""))+LEN(SUBSTITUTE(SUBSTITUTE(SUBSTITUTE(F6," ",""),"0",""),"-",""))+LEN(SUBSTITUTE(SUBSTITUTE(SUBSTITUTE(E7," ",""),"0",""),"-",""))+LEN(SUBSTITUTE(SUBSTITUTE(SUBSTITUTE(F7," ",""),"0",""),"-",""))+LEN(SUBSTITUTE(SUBSTITUTE(SUBSTITUTE(E8," ",""),"0",""),"-",""))+LEN(SUBSTITUTE(SUBSTITUTE(SUBSTITUTE(F8," ",""),"0",""),"-",""))+LEN(SUBSTITUTE(SUBSTITUTE(SUBSTITUTE(E9," ",""),"0",""),"-",""))+LEN(SUBSTITUTE(SUBSTITUTE(SUBSTITUTE(F9," ",""),"0",""),"-","")) | F12: =IF(UPPER(D5)="X",0,IF((LEN(SUBSTITUTE(SUBSTITUTE(SUBSTITUTE(E5," ",""),"0",""),"-",""))+LEN(SUBSTITUTE(SUBSTITUTE(SUBSTITUTE(F5," ",""),"0",""),"-","")))>(LEN(SUBSTITUTE(SUBSTITUTE(SUBSTITUTE(B5," ",""),"0",""),"-",""))+LEN(SUBSTITUTE(SUBSTITUTE(SUBSTITUTE(C5," ",""),"0",""),"-",""))),1,0))+IF(UPPER(D6)="X",0,IF((LEN(SUBSTITUTE(SUBSTITUTE(SUBSTITUTE(E6," ",""),"0",""),"-",""))+LEN(SUBSTITUTE(SUBSTITUTE(SUBSTITUTE(F6," ",""),"0",""),"-","")))>(LEN(SUBSTITUTE(SUBSTITUTE(SUBSTITUTE(B6," ",""),"0",""),"-",""))+LEN(SUBSTITUTE(SUBSTITUTE(SUBSTITUTE(C6," ",""),"0",""),"-",""))),1,0))+IF(UPPER(D7)="X",0,IF((LEN(SUBSTITUTE(SUBSTITUTE(SUBSTITUTE(E7," ",""),"0",""),"-",""))+LEN(SUBSTITUTE(SUBSTITUTE(SUBSTITUTE(F7," ",""),"0",""),"-","")))>(LEN(SUBSTITUTE(SUBSTITUTE(SUBSTITUTE(B7," ",""),"0",""),"-",""))+LEN(SUBSTITUTE(SUBSTITUTE(SUBSTITUTE(C7," ",""),"0",""),"-",""))),1,0))+IF(UPPER(D8)="X",0,IF((LEN(SUBSTITUTE(SUBSTITUTE(SUBSTITUTE(E8," ",""),"0",""),"-",""))+LEN(SUBSTITUTE(SUBSTITUTE(SUBSTITUTE(F8," ",""),"0",""),"-","")))>(LEN(SUBSTITUTE(SUBSTITUTE(SUBSTITUTE(B8," ",""),"0",""),"-",""))+LEN(SUBSTITUTE(SUBSTITUTE(SUBSTITUTE(C8," ",""),"0",""),"-",""))),1,0))+IF(UPPER(D9)="X",0,IF((LEN(SUBSTITUTE(SUBSTITUTE(SUBSTITUTE(E9," ",""),"0",""),"-",""))+LEN(SUBSTITUTE(SUBSTITUTE(SUBSTITUTE(F9," ",""),"0",""),"-","")))>(LEN(SUBSTITUTE(SUBSTITUTE(SUBSTITUTE(B9," ",""),"0",""),"-",""))+LEN(SUBSTITUTE(SUBSTITUTE(SUBSTITUTE(C9," ",""),"0",""),"-",""))),1,0)) | G12: Victories / Points
F15: 1.
F16: 2.
A18: Round 1 - Match 2
A19: White | D19: vs | G19: Red
A20: ='data'!$B$7 | G20: ='data'!$B$6
A21: 1 | G21: 1
A22: 2 | G22: 2
A23: 3 | G23: 3
A24: 4 | G24: 4
A25: 5 | G25: 5
A27: ='data'!$B$7 | B27: IV | C27: PW | E27: PW | F27: IV | G27: ='data'!$B$6
A28: Victories / Points | B28: =IF(UPPER(D21)="X",0,IF((LEN(SUBSTITUTE(SUBSTITUTE(SUBSTITUTE(B21," ",""),"0",""),"-",""))+LEN(SUBSTITUTE(SUBSTITUTE(SUBSTITUTE(C21," ",""),"0",""),"-","")))>(LEN(SUBSTITUTE(SUBSTITUTE(SUBSTITUTE(E21," ",""),"0",""),"-",""))+LEN(SUBSTITUTE(SUBSTITUTE(SUBSTITUTE(F21," ",""),"0",""),"-",""))),1,0))+IF(UPPER(D22)="X",0,IF((LEN(SUBSTITUTE(SUBSTITUTE(SUBSTITUTE(B22," ",""),"0",""),"-",""))+LEN(SUBSTITUTE(SUBSTITUTE(SUBSTITUTE(C22," ",""),"0",""),"-","")))>(LEN(SUBSTITUTE(SUBSTITUTE(SUBSTITUTE(E22," ",""),"0",""),"-",""))+LEN(SUBSTITUTE(SUBSTITUTE(SUBSTITUTE(F22," ",""),"0",""),"-",""))),1,0))+IF(UPPER(D23)="X",0,IF((LEN(SUBSTITUTE(SUBSTITUTE(SUBSTITUTE(B23," ",""),"0",""),"-",""))+LEN(SUBSTITUTE(SUBSTITUTE(SUBSTITUTE(C23," ",""),"0",""),"-","")))>(LEN(SUBSTITUTE(SUBSTITUTE(SUBSTITUTE(E23," ",""),"0",""),"-",""))+LEN(SUBSTITUTE(SUBSTITUTE(SUBSTITUTE(F23," ",""),"0",""),"-",""))),1,0))+IF(UPPER(D24)="X",0,IF((LEN(SUBSTITUTE(SUBSTITUTE(SUBSTITUTE(B24," ",""),"0",""),"-",""))+LEN(SUBSTITUTE(SUBSTITUTE(SUBSTITUTE(C24," ",""),"0",""),"-","")))>(LEN(SUBSTITUTE(SUBSTITUTE(SUBSTITUTE(E24," ",""),"0",""),"-",""))+LEN(SUBSTITUTE(SUBSTITUTE(SUBSTITUTE(F24," ",""),"0",""),"-",""))),1,0))+IF(UPPER(D25)="X",0,IF((LEN(SUBSTITUTE(SUBSTITUTE(SUBSTITUTE(B25," ",""),"0",""),"-",""))+LEN(SUBSTITUTE(SUBSTITUTE(SUBSTITUTE(C25," ",""),"0",""),"-","")))>(LEN(SUBSTITUTE(SUBSTITUTE(SUBSTITUTE(E25," ",""),"0",""),"-",""))+LEN(SUBSTITUTE(SUBSTITUTE(SUBSTITUTE(F25," ",""),"0",""),"-",""))),1,0)) | C28: =LEN(SUBSTITUTE(SUBSTITUTE(SUBSTITUTE(B21," ",""),"0",""),"-",""))+LEN(SUBSTITUTE(SUBSTITUTE(SUBSTITUTE(C21," ",""),"0",""),"-",""))+LEN(SUBSTITUTE(SUBSTITUTE(SUBSTITUTE(B22," ",""),"0",""),"-",""))+LEN(SUBSTITUTE(SUBSTITUTE(SUBSTITUTE(C22," ",""),"0",""),"-",""))+LEN(SUBSTITUTE(SUBSTITUTE(SUBSTITUTE(B23," ",""),"0",""),"-",""))+LEN(SUBSTITUTE(SUBSTITUTE(SUBSTITUTE(C23," ",""),"0",""),"-",""))+LEN(SUBSTITUTE(SUBSTITUTE(SUBSTITUTE(B24," ",""),"0",""),"-",""))+LEN(SUBSTITUTE(SUBSTITUTE(SUBSTITUTE(C24," ",""),"0",""),"-",""))+LEN(SUBSTITUTE(SUBSTITUTE(SUBSTITUTE(B25," ",""),"0",""),"-",""))+LEN(SUBSTITUTE(SUBSTITUTE(SUBSTITUTE(C25," ",""),"0",""),"-","")) | E28: =LEN(SUBSTITUTE(SUBSTITUTE(SUBSTITUTE(E21," ",""),"0",""),"-",""))+LEN(SUBSTITUTE(SUBSTITUTE(SUBSTITUTE(F21," ",""),"0",""),"-",""))+LEN(SUBSTITUTE(SUBSTITUTE(SUBSTITUTE(E22," ",""),"0",""),"-",""))+LEN(SUBSTITUTE(SUBSTITUTE(SUBSTITUTE(F22," ",""),"0",""),"-",""))+LEN(SUBSTITUTE(SUBSTITUTE(SUBSTITUTE(E23," ",""),"0",""),"-",""))+LEN(SUBSTITUTE(SUBSTITUTE(SUBSTITUTE(F23," ",""),"0",""),"-",""))+LEN(SUBSTITUTE(SUBSTITUTE(SUBSTITUTE(E24," ",""),"0",""),"-",""))+LEN(SUBSTITUTE(SUBSTITUTE(SUBSTITUTE(F24," ",""),"0",""),"-",""))+LEN(SUBSTITUTE(SUBSTITUTE(SUBSTITUTE(E25," ",""),"0",""),"-",""))+LEN(SUBSTITUTE(SUBSTITUTE(SUBSTITUTE(F25," ",""),"0",""),"-","")) | F28: =IF(UPPER(D21)="X",0,IF((LEN(SUBSTITUTE(SUBSTITUTE(SUBSTITUTE(E21," ",""),"0",""),"-",""))+LEN(SUBSTITUTE(SUBSTITUTE(SUBSTITUTE(F21," ",""),"0",""),"-","")))>(LEN(SUBSTITUTE(SUBSTITUTE(SUBSTITUTE(B21," ",""),"0",""),"-",""))+LEN(SUBSTITUTE(SUBSTITUTE(SUBSTITUTE(C21," ",""),"0",""),"-",""))),1,0))+IF(UPPER(D22)="X",0,IF((LEN(SUBSTITUTE(SUBSTITUTE(SUBSTITUTE(E22," ",""),"0",""),"-",""))+LEN(SUBSTITUTE(SUBSTITUTE(SUBSTITUTE(F22," ",""),"0",""),"-","")))>(LEN(SUBSTITUTE(SUBSTITUTE(SUBSTITUTE(B22," ",""),"0",""),"-",""))+LEN(SUBSTITUTE(SUBSTITUTE(SUBSTITUTE(C22," ",""),"0",""),"-",""))),1,0))+IF(UPPER(D23)="X",0,IF((LEN(SUBSTITUTE(SUBSTITUTE(SUBSTITUTE(E23," ",""),"0",""),"-",""))+LEN(SUBSTITUTE(SUBSTITUTE(SUBSTITUTE(F23," ",""),"0",""),"-","")))>(LEN(SUBSTITUTE(SUBSTITUTE(SUBSTITUTE(B23," ",""),"0",""),"-",""))+LEN(SUBSTITUTE(SUBSTITUTE(SUBSTITUTE(C23," ",""),"0",""),"-",""))),1,0))+IF(UPPER(D24)="X",0,IF((LEN(SUBSTITUTE(SUBSTITUTE(SUBSTITUTE(E24," ",""),"0",""),"-",""))+LEN(SUBSTITUTE(SUBSTITUTE(SUBSTITUTE(F24," ",""),"0",""),"-","")))>(LEN(SUBSTITUTE(SUBSTITUTE(SUBSTITUTE(B24," ",""),"0",""),"-",""))+LEN(SUBSTITUTE(SUBSTITUTE(SUBSTITUTE(C24," ",""),"0",""),"-",""))),1,0))+IF(UPPER(D25)="X",0,IF((LEN(SUBSTITUTE(SUBSTITUTE(SUBSTITUTE(E25," ",""),"0",""),"-",""))+LEN(SUBSTITUTE(SUBSTITUTE(SUBSTITUTE(F25," ",""),"0",""),"-","")))>(LEN(SUBSTITUTE(SUBSTITUTE(SUBSTITUTE(B25," ",""),"0",""),"-",""))+LEN(SUBSTITUTE(SUBSTITUTE(SUBSTITUTE(C25," ",""),"0",""),"-",""))),1,0)) | G28: Victories / Points
F31: 1.
F32: 2.
A34: Round 1 - Match 3
A35: White | D35: vs | G35: Red
A36: ='data'!$B$9 | G36: ='data'!$B$8
A37: 1 | G37: 1
A38: 2 | G38: 2
A39: 3 | G39: 3
A40: 4 | G40: 4
A41: 5 | G41: 5
A43: ='data'!$B$9 | B43: IV | C43: PW | E43: PW | F43: IV | G43: ='data'!$B$8
A44: Victories / Points | B44: =IF(UPPER(D37)="X",0,IF((LEN(SUBSTITUTE(SUBSTITUTE(SUBSTITUTE(B37," ",""),"0",""),"-",""))+LEN(SUBSTITUTE(SUBSTITUTE(SUBSTITUTE(C37," ",""),"0",""),"-","")))>(LEN(SUBSTITUTE(SUBSTITUTE(SUBSTITUTE(E37," ",""),"0",""),"-",""))+LEN(SUBSTITUTE(SUBSTITUTE(SUBSTITUTE(F37," ",""),"0",""),"-",""))),1,0))+IF(UPPER(D38)="X",0,IF((LEN(SUBSTITUTE(SUBSTITUTE(SUBSTITUTE(B38," ",""),"0",""),"-",""))+LEN(SUBSTITUTE(SUBSTITUTE(SUBSTITUTE(C38," ",""),"0",""),"-","")))>(LEN(SUBSTITUTE(SUBSTITUTE(SUBSTITUTE(E38," ",""),"0",""),"-",""))+LEN(SUBSTITUTE(SUBSTITUTE(SUBSTITUTE(F38," ",""),"0",""),"-",""))),1,0))+IF(UPPER(D39)="X",0,IF((LEN(SUBSTITUTE(SUBSTITUTE(SUBSTITUTE(B39," ",""),"0",""),"-",""))+LEN(SUBSTITUTE(SUBSTITUTE(SUBSTITUTE(C39," ",""),"0",""),"-","")))>(LEN(SUBSTITUTE(SUBSTITUTE(SUBSTITUTE(E39," ",""),"0",""),"-",""))+LEN(SUBSTITUTE(SUBSTITUTE(SUBSTITUTE(F39," ",""),"0",""),"-",""))),1,0))+IF(UPPER(D40)="X",0,IF((LEN(SUBSTITUTE(SUBSTITUTE(SUBSTITUTE(B40," ",""),"0",""),"-",""))+LEN(SUBSTITUTE(SUBSTITUTE(SUBSTITUTE(C40," ",""),"0",""),"-","")))>(LEN(SUBSTITUTE(SUBSTITUTE(SUBSTITUTE(E40," ",""),"0",""),"-",""))+LEN(SUBSTITUTE(SUBSTITUTE(SUBSTITUTE(F40," ",""),"0",""),"-",""))),1,0))+IF(UPPER(D41)="X",0,IF((LEN(SUBSTITUTE(SUBSTITUTE(SUBSTITUTE(B41," ",""),"0",""),"-",""))+LEN(SUBSTITUTE(SUBSTITUTE(SUBSTITUTE(C41," ",""),"0",""),"-","")))>(LEN(SUBSTITUTE(SUBSTITUTE(SUBSTITUTE(E41," ",""),"0",""),"-",""))+LEN(SUBSTITUTE(SUBSTITUTE(SUBSTITUTE(F41," ",""),"0",""),"-",""))),1,0)) | C44: =LEN(SUBSTITUTE(SUBSTITUTE(SUBSTITUTE(B37," ",""),"0",""),"-",""))+LEN(SUBSTITUTE(SUBSTITUTE(SUBSTITUTE(C37," ",""),"0",""),"-",""))+LEN(SUBSTITUTE(SUBSTITUTE(SUBSTITUTE(B38," ",""),"0",""),"-",""))+LEN(SUBSTITUTE(SUBSTITUTE(SUBSTITUTE(C38," ",""),"0",""),"-",""))+LEN(SUBSTITUTE(SUBSTITUTE(SUBSTITUTE(B39," ",""),"0",""),"-",""))+LEN(SUBSTITUTE(SUBSTITUTE(SUBSTITUTE(C39," ",""),"0",""),"-",""))+LEN(SUBSTITUTE(SUBSTITUTE(SUBSTITUTE(B40," ",""),"0",""),"-",""))+LEN(SUBSTITUTE(SUBSTITUTE(SUBSTITUTE(C40," ",""),"0",""),"-",""))+LEN(SUBSTITUTE(SUBSTITUTE(SUBSTITUTE(B41," ",""),"0",""),"-",""))+LEN(SUBSTITUTE(SUBSTITUTE(SUBSTITUTE(C41," ",""),"0",""),"-","")) | E44: =LEN(SUBSTITUTE(SUBSTITUTE(SUBSTITUTE(E37," ",""),"0",""),"-",""))+LEN(SUBSTITUTE(SUBSTITUTE(SUBSTITUTE(F37," ",""),"0",""),"-",""))+LEN(SUBSTITUTE(SUBSTITUTE(SUBSTITUTE(E38," ",""),"0",""),"-",""))+LEN(SUBSTITUTE(SUBSTITUTE(SUBSTITUTE(F38," ",""),"0",""),"-",""))+LEN(SUBSTITUTE(SUBSTITUTE(SUBSTITUTE(E39," ",""),"0",""),"-",""))+LEN(SUBSTITUTE(SUBSTITUTE(SUBSTITUTE(F39," ",""),"0",""),"-",""))+LEN(SUBSTITUTE(SUBSTITUTE(SUBSTITUTE(E40," ",""),"0",""),"-",""))+LEN(SUBSTITUTE(SUBSTITUTE(SUBSTITUTE(F40," ",""),"0",""),"-",""))+LEN(SUBSTITUTE(SUBSTITUTE(SUBSTITUTE(E41," ",""),"0",""),"-",""))+LEN(SUBSTITUTE(SUBSTITUTE(SUBSTITUTE(F41," ",""),"0",""),"-","")) | F44: =IF(UPPER(D37)="X",0,IF((LEN(SUBSTITUTE(SUBSTITUTE(SUBSTITUTE(E37," ",""),"0",""),"-",""))+LEN(SUBSTITUTE(SUBSTITUTE(SUBSTITUTE(F37," ",""),"0",""),"-","")))>(LEN(SUBSTITUTE(SUBSTITUTE(SUBSTITUTE(B37," ",""),"0",""),"-",""))+LEN(SUBSTITUTE(SUBSTITUTE(SUBSTITUTE(C37," ",""),"0",""),"-",""))),1,0))+IF(UPPER(D38)="X",0,IF((LEN(SUBSTITUTE(SUBSTITUTE(SUBSTITUTE(E38," ",""),"0",""),"-",""))+LEN(SUBSTITUTE(SUBSTITUTE(SUBSTITUTE(F38," ",""),"0",""),"-","")))>(LEN(SUBSTITUTE(SUBSTITUTE(SUBSTITUTE(B38," ",""),"0",""),"-",""))+LEN(SUBSTITUTE(SUBSTITUTE(SUBSTITUTE(C38," ",""),"0",""),"-",""))),1,0))+IF(UPPER(D39)="X",0,IF((LEN(SUBSTITUTE(SUBSTITUTE(SUBSTITUTE(E39," ",""),"0",""),"-",""))+LEN(SUBSTITUTE(SUBSTITUTE(SUBSTITUTE(F39," ",""),"0",""),"-","")))>(LEN(SUBSTITUTE(SUBSTITUTE(SUBSTITUTE(B39," ",""),"0",""),"-",""))+LEN(SUBSTITUTE(SUBSTITUTE(SUBSTITUTE(C39," ",""),"0",""),"-",""))),1,0))+IF(UPPER(D40)="X",0,IF((LEN(SUBSTITUTE(SUBSTITUTE(SUBSTITUTE(E40," ",""),"0",""),"-",""))+LEN(SUBSTITUTE(SUBSTITUTE(SUBSTITUTE(F40," ",""),"0",""),"-","")))>(LEN(SUBSTITUTE(SUBSTITUTE(SUBSTITUTE(B40," ",""),"0",""),"-",""))+LEN(SUBSTITUTE(SUBSTITUTE(SUBSTITUTE(C40," ",""),"0",""),"-",""))),1,0))+IF(UPPER(D41)="X",0,IF((LEN(SUBSTITUTE(SUBSTITUTE(SUBSTITUTE(E41," ",""),"0",""),"-",""))+LEN(SUBSTITUTE(SUBSTITUTE(SUBSTITUTE(F41," ",""),"0",""),"-","")))>(LEN(SUBSTITUTE(SUBSTITUTE(SUBSTITUTE(B41," ",""),"0",""),"-",""))+LEN(SUBSTITUTE(SUBSTITUTE(SUBSTITUTE(C41," ",""),"0",""),"-",""))),1,0)) | G44: Victories / Points
F47: 1.
F48: 2.
A50: Round 1 - Match 4
A51: White | D51: vs | G51: Red
A52: ='data'!$B$12 | G52: ='data'!$B$11
...

Sheet Tree 1
A1: =IF(data!$B$1="","Shiaijo A",data!$B$1&" - Shiaijo A")
C5: Kevin Clark
E6: 1
C7: Luke Rodriguez
I12: 7
E14: Michael Lewis
G16: 5
C17: Nathan Lee
E18: 2
C19: Oliver Walker
K20: 9
C21: Paul Hall
E22: 3
C23: Quentin Allen
I28: 8
E30: Robert Young
G32: 6
C33: Steven Hernandez
E34: 4
C35: Thomas King

Sheet Names to Print A
A1: 0 | B1: ='data'!$B$3
A2: 1 | B2: ='data'!$B$4
A3: 2 | B3: ='data'!$B$5
A4: 3 | B4: ='data'!$B$6
A5: 4 | B5: ='data'!$B$7
A6: 5 | B6: ='data'!$B$8
A7: 6 | B7: ='data'!$B$9
A8: 7 | B8: ='data'!$B$10
A9: 8 | B9: ='data'!$B$11
A10: 9 | B10: ='data'!$B$12
