Workbook

Sheet data
A1: Title prefix:
A2: Pool | B2: Player Name | C2: Player Dojo | D2: Player Number | E2: Metadata
A3: Pool A | B3: Kevin Clark | C3: Team Alpha | D3: K1
A4: Pool A | B4: Luke Rodriguez | C4: Team Beta | D4: K2
A5: Pool A | B5: Michael Lewis | C5: Team Gamma | D5: K3
A6: Pool A | B6: Nathan Lee | C6: Team Delta | D6: K4
A7: Pool A | B7: Oliver Walker | C7: Team Epsilon | D7: K5
A8: Pool A | B8: Paul Hall | C8: Team Zeta | D8: K6
A9: Pool A | B9: Quentin Allen | C9: Team Eta | D9: K7
A10: Pool A | B10: Robert Young | C10: Team Theta | D10: K8

Sheet Time Estimator
A1: Number of pools | B1: Team size | C1: Matches per pool | D1: Time per match | E1: Total time for matches | F1: Padding time for rotation | G1: Time for breaks | H1: Total Time
A2: 1 | B2: 1 | C2: 28 | D2: 0.0020833333 | E2: =(A2*B2*C2*D2) | F2: 0.00034722222 | G2: 0.020833333 | H2: =C2*I2+J2
A3: 0 | B3: 0 | C3: 0 | D3: 0.0020833333 | E3: =(A3*B3*C3*D3) | F3: 0.00034722222 | G3: 0.020833333 | H3: =E3+(A3*C3*F3)+G3
A7: Number of Elimination Matches | B7: Team size | D7: Time per match | E7: Total time for matches | F7: Padding time for rotation | G7: Time for breaks | H7: Total Time
A8: 1 | B8: 1 | D8: 0.0027777778 | E8: =(A8*B8*D8) | F8: 0.00034722222 | G8: 0.020833333 | H8: =E8+(A8*F8)+G8
E13: Tournament Summary
A14: 1 | E14: Total Pool Time | H14: =H2
E15: Total Elimination Time | H15: =H8
E16: Grand Total (Sequential) | H16: =H14+H15
E17: Grand Total (Parallel across Courts) | H17: =H16/A14
E18: Start Time: | H18: 0.375
E19: Estimated Finish Time | H19: =H18+H17

Sheet Pool Draw
B2: =IF(data!$B$1="","Tournament Pools",data!$B$1&" - Tournament Pools")
B5: ='data'!$A$10
B6: =data!$D$3&" "&data!$B$3
B7: =data!$D$4&" "&data!$B$4
B8: =data!$D$5&" "&data!$B$5
B9: =data!$D$6&" "&data!$B$6
B10: =data!$D$7&" "&data!$B$7
B11: =data!$D$8&" "&data!$B$8
B12: =data!$D$9&" "&data!$B$9
B13: =data!$D$10&" "&data!$B$10

Sheet Pool Matches
A1: Shiaijo A
A2: ='data'!$A$10
A3: White | D3: vs | G3: Red
A4: =data!$D$4&" "&data!$B$4 | G4: =data!$D$3&" "&data!$B$3
A5: =data!$D$4&" "&data!$B$4 | G5: =data!$D$5&" "&data!$B$5
A6: =data!$D$6&" "&data!$B$6 | G6: =data!$D$5&" "&data!$B$5
A7: =data!$D$6&" "&data!$B$6 | G7: =data!$D$7&" "&data!$B$7
A8: =data!$D$8&" "&data!$B$8 | G8: =data!$D$7&" "&data!$B$7
A9: =data!$D$8&" "&data!$B$8 | G9: =data!$D$9&" "&data!$B$9
A10: =data!$D$10&" "&data!$B$10 | G10: =data!$D$9&" "&data!$B$9
A11: =data!$D$5&" "&data!$B$5 | G11: =data!$D$3&" "&data!$B$3
A12: =data!$D$6&" "&data!$B$6 | G12: =data!$D$4&" "&data!$B$4
A13: =data!$D$7&" "&data!$B$7 | G13: =data!$D$5&" "&data!$B$5
A14: =data!$D$8&" "&data!$B$8 | G14: =data!$D$6&" "&data!$B$6
A15: =data!$D$9&" "&data!$B$9 | G15: =data!$D$7&" "&data!$B$7
A16: =data!$D$10&" "&data!$B$10 | G16: =data!$D$8&" "&data!$B$8
A17: =data!$D$6&" "&data!$B$6 | G17: =data!$D$3&" "&data!$B$3
A18: =data!$D$7&" "&data!$B$7 | G18: =data!$D$4&" "&data!$B$4
A19: =data!$D$8&" "&data!$B$8 | G19: =data!$D$5&" "&data!$B$5
A20: =data!$D$9&" "&data!$B$9 | G20: =data!$D$6&" "&data!$B$6
A21: =data!$D$10&" "&data!$B$10 | G21: =data!$D$7&" "&data!$B$7
A22: =data!$D$3&" "&data!$B$3 | G22: =data!$D$7&" "&data!$B$7
A23: =data!$D$8&" "&data!$B$8 | G23: =data!$D$4&" "&data!$B$4
A24: =data!$D$9&" "&data!$B$9 | G24: =data!$D$5&" "&data!$B$5
A25: =data!$D$10&" "&data!$B$10 | G25: =data!$D$6&" "&data!$B$6
A26: =data!$D$8&" "&data!$B$8 | G26: =data!$D$3&" "&data!$B$3
A27: =data!$D$9&" "&data!$B$9 | G27: =data!$D$4&" "&data!$B$4
A28: =data!$D$10&" "&data!$B$10 | G28: =data!$D$5&" "&data!$B$5
A29: =data!$D$9&" "&data!$B$9 | G29: =data!$D$3&" "&data!$B$3
A30: =data!$D$10&" "&data!$B$10 | G30: =data!$D$4&" "&data!$B$4
A31: =data!$D$10&" "&data!$B$10 | G31: =data!$D$3&" "&data!$B$3
A33: Results | B33: W | C33: L | D33: T | E33: PW | F33: PL | G33: Rank
A34: =data!$D$3&" "&data!$B$3 | B34: =IF(OR(COUNTA(B4,C4,E4,F4)>0,OR(D4="X",D4="x")),IF(OR(D4="X",D4="x",AND(OR(COUNTA(B4,C4,E4,F4)>0,OR(D4="X",D4="x")),(LEN(SUBSTITUTE(SUBSTITUTE(SUBSTITUTE(B4," ",""),"0",""),"-",""))+LEN(SUBSTITUTE(SUBSTITUTE(SUBSTITUTE(C4," ",""),"0",""),"-","")))=(LEN(SUBSTITUTE(SUBSTITUTE(SUBSTITUTE(E4," ",""),"0",""),"-",""))+LEN(SUBSTITUTE(SUBSTITUTE(SUBSTITUTE(F4," ",""),"0",""),"-",""))))),0,(LEN(SUBSTITUTE(SUBSTITUTE(SUBSTITUTE(E4," ",""),"0",""),"-",""))+LEN(SUBSTITUTE(SUBSTITUTE(SUBSTITUTE(F4," ",""),"0",""),"-",""))>LEN(SUBSTITUTE(SUBSTITUTE(SUBSTITUTE(B4," ",""),"0",""),"-",""))+LEN(SUBSTITUTE(SUBSTITUTE(SUBSTITUTE(C4," ",""),"0",""),"-","")))*1),0)+IF(OR(COUNTA(B11,C11,E11,F11)>0,OR(D11="X",D11="x")),IF(OR(D11="X",D11="x",AND(OR(COUNTA(B11,C11,E11,F11)>0,OR(D11="X",D11="x")),(LEN(SUBSTITUTE(SUBSTITUTE(SUBSTITUTE(B11," ",""),"0",""),"-",""))+LEN(SUBSTITUTE(SUBSTITUTE(SUBSTITUTE(C11," ",""),"0",""),"-","")))=(LEN(SUBSTITUTE(SUBSTITUTE(SUBSTITUTE(E11," ",""),"0",""),"-",""))+LEN(SUBSTITUTE(SUBSTITUTE(SUBSTITUTE(F11," ",""),"0",""),"-",""))))),0,(LEN(SUBSTITUTE(SUBSTITUTE(SUBSTITUTE(E11," ",""),"0",""),"-",""))+LEN(SUBSTITUTE(SUBSTITUTE(SUBSTITUTE(F11," ",""),"0",""),"-",""))>LEN(SUBSTITUTE(SUBSTITUTE(SUBSTITUTE(B11," ",""),"0",""),"-",""))+LEN(SUBSTITUTE(SUBSTITUTE(SUBSTITUTE(C11," ",""),"0",""),"-","")))*1),0)+IF(OR(COUNTA(B17,C17,E17,F17)>0,OR(D17="X",D17="x")),IF(OR(D17="X",D17="x",AND(OR(COUNTA(B17,C17,E17,F17)>0,OR(D17="X",D17="x")),(LEN(SUBSTITUTE(SUBSTITUTE(SUBSTITUTE(B17," ",""),"0",""),"-",""))+LEN(SUBSTITUTE(SUBSTITUTE(SUBSTITUTE(C17," ",""),"0",""),"-","")))=(LEN(SUBSTITUTE(SUBSTITUTE(SUBSTITUTE(E17," ",""),"0",""),"-",""))+LEN(SUBSTITUTE(SUBSTITUTE(SUBSTITUTE(F17," ",""),"0",""),"-",""))))),0,(LEN(SUBSTITUTE(SUBSTITUTE(SUBSTITUTE(E17," ",""),"0",""),"-",""))+LEN(SUBSTITUTE(SUBSTITUTE(SUBSTITUTE(F17," ",""),"0",""),"-",""))>LEN(SUBSTITUTE(SUBSTITUTE(SUBSTITUTE(B17," ",""),"0",""),"-",""))+LEN(SUBSTITUTE(SUBSTITUTE(SUBSTITUTE(C17," ",""),"0",""),"-","")))*1),0)+IF(OR(COUNTA(B22,C22,E22,F22)>0,OR(D22="X",D22="x")),IF(OR(D22="X",D22="x",AND(OR(COUNTA(B22,C22,E22,F22)>0,OR(D22="X",D22="x")),(LEN(SUBSTITUTE(SUBSTITUTE(SUBSTITUTE(B22," ",""),"0",""),"-",""))+LEN(SUBSTITUTE(SUBSTITUTE(SUBSTITUTE(C22," ",""),"0",""),"-","")))=(LEN(SUBSTITUTE(SUBSTITUTE(SUBSTITUTE(E22," ",""),"0",""),"-",""))+LEN(SUBSTITUTE(SUBSTITUTE(SUBSTITUTE(F22," ",""),"0",""),"-",""))))),0,(LEN(SUBSTITUTE(SUBSTITUTE(SUBSTITUTE(B22," ",""),"0",""),"-",""))+LEN(SUBSTITUTE(SUBSTITUTE(SUBSTITUTE(C22," ",""),"0",""),"-",""))>LEN(SUBSTITUTE(SUBSTITUTE(SUBSTITUTE(E22," ",""),"0",""),"-",""))+LEN(SUBSTITUTE(SUBSTITUTE(SUBSTITUTE(F22," ",""),"0",""),"-","")))*1),0)+IF(OR(COUNTA(B26,C26,E26,F26)>0,OR(D26="X",D26="x")),IF(OR(D26="X",D26="x",AND(OR(COUNTA(B26,C26,E26,F26)>0,OR(D26="X",D26="x")),(LEN(SUBSTITUTE(SUBSTITUTE(SUBSTITUTE(B26," ",""),"0",""),"-",""))+LEN(SUBSTITUTE(SUBSTITUTE(SUBSTITUTE(C26," ",""),"0",""),"-","")))=(LEN(SUBSTITUTE(SUBSTITUTE(SUBSTITUTE(E26," ",""),"0",""),"-",""))+LEN(SUBSTITUTE(SUBSTITUTE(SUBSTITUTE(F26," ",""),"0",""),"-",""))))),0,(LEN(SUBSTITUTE(SUBSTITUTE(SUBSTITUTE(E26," ",""),"0",""),"-",""))+LEN(SUBSTITUTE(SUBSTITUTE(SUBSTITUTE(F26," ",""),"0",""),"-",""))>LEN(SUBSTITUTE(SUBSTITUTE(SUBSTITUTE(B26," ",""),"0",""),"-",""))+LEN(SUBSTITUTE(SUBSTITUTE(SUBSTITUTE(C26," ",""),"0",""),"-","")))*1),0)+IF(OR(COUNTA(B29,C29,E29,F29)>0,OR(D29="X",D29="x")),IF(OR(D29="X",D29="x",AND(OR(COUNTA(B29,C29,E29,F29)>0,OR(D29="X",D29="x")),(LEN(SUBSTITUTE(SUBSTITUTE(SUBSTITUTE(B29," ",""),"0",""),"-",""))+LEN(SUBSTITUTE(SUBSTITUTE(SUBSTITUTE(C29," ",""),"0",""),"-","")))=(LEN(SUBSTITUTE(SUBSTITUTE(SUBSTITUTE(E29," ",""),"0",""),"-",""))+LEN(SUBSTITUTE(SUBSTITUTE(SUBSTITUTE(F29," ",""),"0",""),"-",""))))),0,(LEN(SUBSTITUTE(SUBSTITUTE(SUBSTITUTE(E29," ",""),"0",""),"-",""))+LEN(SUBSTITUTE(SUBSTITUTE(SUBSTITUTE(F29," ",""),"0",""),"-",""))>LEN(SUBSTITUTE(SUBSTITUTE(SUBSTITUTE(B29," ",""),"0",""),"-",""))+LEN(SUBSTITUTE(SUBSTITUTE(SUBSTITUTE(C29," ",""),"0",""),"-","")))*1),0)+IF(OR(COUNTA(B31,C31,E31,F31)>0,OR(D31="X",D31="x")),IF(OR(D31="X",D31="x",AND(OR(COUNTA(B31,C31,E31,F31)>0,OR(D31="X",D31="x")),(LEN(SUBSTITUTE(SUBSTITUTE(SUBSTITUTE(B31," ",""),"0",""),"-",""))+LEN(SUBSTITUTE(SUBSTITUTE(SUBSTITUTE(C31," ",""),"0",""),"-","")))=(LEN(SUBSTITUTE(SUBSTITUTE(SUBSTITUTE(E31," ",""),"0",""),"-",""))+LEN(SUBSTITUTE(SUBSTITUTE(SUBSTITUTE(F31," ",""),"0",""),"-",""))))),0,(LEN(SUBSTITUTE(SUBSTITUTE(SUBSTITUTE(E31," ",""),"0",""),"-",""))+LEN(SUBSTITUTE(SUBSTITUTE(SUBSTITUTE(F31," ",""),"0",""),"-",""))>LEN(SUBSTITUTE(SUBSTITUTE(SUBSTITUTE(B31," ",""),"0",""),"-",""))+LEN(SUBSTITUTE(SUBSTITUTE(SUBSTITUTE(C31," ",""),"0",""),"-","")))*1),0) | C34: =IF(OR(COUNTA(B4,C4,E4,F4)>0,OR(D4="X",D4="x")),IF(OR(D4="X",D4="x",AND(OR(COUNTA(B4,C4,E4,F4)>0,OR(D4="X",D4="x")),(LEN(SUBSTITUTE(SUBSTITUTE(SUBSTITUTE(B4," ",""),"0",""),"-",""))+LEN(SUBSTITUTE(SUBSTITUTE(SUBSTITUTE(C4," ",""),"0",""),"-","")))=(LEN(SUBSTITUTE(SUBSTITUTE(SUBSTITUTE(E4," ",""),"0",""),"-",""))+LEN(SUBSTITUTE(SUBSTITUTE(SUBSTITUTE(F4," ",""),"0",""),"-",""))))),0,(LEN(SUBSTITUTE(SUBSTITUTE(SUBSTITUTE(E4," ",""),"0",""),"-",""))+LEN(SUBSTITUTE(SUBSTITUTE(SUBSTITUTE(F4," ",""),"0",""),"-",""))<LEN(SUBSTITUTE(SUBSTITUTE(SUBSTITUTE(B4," ",""),"0",""),"-",""))+LEN(SUBSTITUTE(SUBSTITUTE(SUBSTITUTE(C4," ",""),"0",""),"-","")))*1),0)+IF(OR(COUNTA(B11,C11,E11,F11)>0,OR(D11="X",D11="x")),IF(OR(D11="X",D11="x",AND(OR(COUNTA(B11,C11,E11,F11)>0,OR(D11="X",D11="x")),(LEN(SUBSTITUTE(SUBSTITUTE(SUBSTITUTE(B11," ",""),"0",""),"-",""))+LEN(SUBSTITUTE(SUBSTITUTE(SUBSTITUTE(C11," ",""),"0",""),"-","")))=(LEN(SUBSTITUTE(SUBSTITUTE(SUBSTITUTE(E11," ",""),"0",""),"-",""))+LEN(SUBSTITUTE(SUBSTITUTE(SUBSTITUTE(F11," ",""),"0",""),"-",""))))),0,(LEN(SUBSTITUTE(SUBSTITUTE(SUBSTITUTE(E11," ",""),"0",""),"-",""))+LEN(SUBSTITUTE(SUBSTITUTE(SUBSTITUTE(F11," ",""),"0",""),"-",""))<LEN(SUBSTITUTE(SUBSTITUTE(SUBSTITUTE(B11," ",""),"0",""),"-",""))+LEN(SUBSTITUTE(SUBSTITUTE(SUBSTITUTE(C11," ",""),"0",""),"-","")))*1),0)+IF(OR(COUNTA(B17,C17,E17,F17)>0,OR(D17="X",D17="x")),IF(OR(D17="X",D17="x",AND(OR(COUNTA(B17,C17,E17,F17)>0,OR(D17="X",D17="x")),(LEN(SUBSTITUTE(SUBSTITUTE(SUBSTITUTE(B17," ",""),"0",""),"-",""))+LEN(SUBSTITUTE(SUBSTITUTE(SUBSTITUTE(C17," ",""),"0",""),"-","")))=(LEN(SUBSTITUTE(SUBSTITUTE(SUBSTITUTE(E17," ",""),"0",""),"-",""))+LEN(SUBSTITUTE(SUBSTITUTE(SUBSTITUTE(F17," ",""),"0",""),"-",""))))),0,(LEN(SUBSTITUTE(SUBSTITUTE(SUBSTITUTE(E17," ",""),"0",""),"-",""))+LEN(SUBSTITUTE(SUBSTITUTE(SUBSTITUTE(F17," ",""),"0",""),"-",""))<LEN(SUBSTITUTE(SUBSTITUTE(SUBSTITUTE(B17," ",""),"0",""),"-",""))+LEN(SUBSTITUTE(SUBSTITUTE(SUBSTITUTE(C17," ",""),"0",""),"-","")))*1),0)+IF(OR(COUNTA(B22,C22,E22,F22)>0,OR(D22="X",D22="x")),IF(OR(D22="X",D22="x",AND(OR(COUNTA(B22,C22,E22,F22)>0,OR(D22="X",D22="x")),(LEN(SUBSTITUTE(SUBSTITUTE(SUBSTITUTE(B22," ",""),"0",""),"-",""))+LEN(SUBSTITUTE(SUBSTITUTE(SUBSTITUTE(C22," ",""),"0",""),"-","")))=(LEN(SUBSTITUTE(SUBSTITUTE(SUBSTITUTE(E22," ",""),"0",""),"-",""))+LEN(SUBSTITUTE(SUBSTITUTE(SUBSTITUTE(F22," ",""),"0",""),"-",""))))),0,(LEN(SUBSTITUTE(SUBSTITUTE(SUBSTITUTE(B22," ",""),"0",""),"-",""))+LEN(SUBSTITUTE(SUBSTITUTE(SUBSTITUTE(C22," ",""),"0",""),"-",""))<LEN(SUBSTITUTE(SUBSTITUTE(SUBSTITUTE(E22," ",""),"0",""),"-",""))+LEN(SUBSTITUTE(SUBSTITUTE(SUBSTITUTE(F22," ",""),"0",""),"-","")))*1),0)+IF(OR(COUNTA(B26,C26,E26,F26)>0,OR(D26="X",D26="x")),IF(OR(D26="X",D26="x",AND(OR(COUNTA(B26,C26,E26,F26)>0,OR(D26="X",D26="x")),(LEN(SUBSTITUTE(SUBSTITUTE(SUBSTITUTE(B26," ",""),"0",""),"-",""))+LEN(SUBSTITUTE(SUBSTITUTE(SUBSTITUTE(C26," ",""),"0",""),"-","")))=(LEN(SUBSTITUTE(SUBSTITUTE(SUBSTITUTE(E26," ",""),"0",""),"-",""))+LEN(SUBSTITUTE(SUBSTITUTE(SUBSTITUTE(F26," ",""),"0",""),"-",""))))),0,(LEN(SUBSTITUTE(SUBSTITUTE(SUBSTITUTE(E26," ",""),"0",""),"-",""))+LEN(SUBSTITUTE(SUBSTITUTE(SUBSTITUTE(F26," ",""),"0",""),"-",""))<LEN(SUBSTITUTE(SUBSTITUTE(SUBSTITUTE(B26," ",""),"0",""),"-",""))+LEN(SUBSTITUTE(SUBSTITUTE(SUBSTITUTE(C26," ",""),"0",""),"-","")))*1),0)+IF(OR(COUNTA(B29,C29,E29,F29)>0,OR(D29="X",D29="x")),IF(OR(D29="X",D29="x",AND(OR(COUNTA(B29,C29,E29,F29)>0,OR(D29="X",D29="x")),(LEN(SUBSTITUTE(SUBSTITUTE(SUBSTITUTE(B29," ",""),"0",""),"-",""))+LEN(SUBSTITUTE(SUBSTITUTE(SUBSTITUTE(C29," ",""),"0",""),"-","")))=(LEN(SUBSTITUTE(SUBSTITUTE(SUBSTITUTE(E29," ",""),"0",""),"-",""))+LEN(SUBSTITUTE(SUBSTITUTE(SUBSTITUTE(F29," ",""),"0",""),"-",""))))),0,(LEN(SUBSTITUTE(SUBSTITUTE(SUBSTITUTE(E29," ",""),"0",""),"-",""))+LEN(SUBSTITUTE(SUBSTITUTE(SUBSTITUTE(F29," ",""),"0",""),"-",""))<LEN(SUBSTITUTE(SUBSTITUTE(SUBSTITUTE(B29," ",""),"0",""),"-",""))+LEN(SUBSTITUTE(SUBSTITUTE(SUBSTITUTE(C29," ",""),"0",""),"-","")))*1),0)+IF(OR(COUNTA(B31,C31,E31,F31)>0,OR(D31="X",D31="x")),IF(OR(D31="X",D31="x",AND(OR(COUNTA(B31,C31,E31,F31)>0,OR(D31="X",D31="x")),(LEN(SUBSTITUTE(SUBSTITUTE(SUBSTITUTE(B31," ",""),"0",""),"-",""))+LEN(SUBSTITUTE(SUBSTITUTE(SUBSTITUTE(C31," ",""),"0",""),"-","")))=(LEN(SUBSTITUTE(SUBSTITUTE(SUBSTITUTE(E31," ",""),"0",""),"-",""))+LEN(SUBSTITUTE(SUBSTITUTE(SUBSTITUTE(F31," ",""),"0",""),"-",""))))),0,(LEN(SUBSTITUTE(SUBSTITUTE(SUBSTITUTE(E31," ",""),"0",""),"-",""))+LEN(SUBSTITUTE(SUBSTITUTE(SUBSTITUTE(F31," ",""),"0",""),"-",""))<LEN(SUBSTITUTE(SUBSTITUTE(SUBSTITUTE(B31," ",""),"0",""),"-",""))+LEN(SUBSTITUTE(SUBSTITUTE(SUBSTITUTE(C31," ",""),"0",""),"-","")))*1),0) | D34: =IF(OR(COUNTA(B4,C4,E4,F4)>0,OR(D4="X",D4="x")),IF(OR(D4="X",D4="x",AND(OR(COUNTA(B4,C4,E4,F4)>0,OR(D4="X",D4="x")),(LEN(SUBSTITUTE(SUBSTITUTE(SUBSTITUTE(B4," ",""),"0",""),"-",""))+LEN(SUBSTITUTE(SUBSTITUTE(SUBSTITUTE(C4," ",""),"0",""),"-","")))=(LEN(SUBSTITUTE(SUBSTITUTE(SUBSTITUTE(E4," ",""),"0",""),"-",""))+LEN(SUBSTITUTE(SUBSTITUTE(SUBSTITUTE(F4," ",""),"0",""),"-",""))))),1,0),0)+IF(OR(COUNTA(B11,C11,E11,F11)>0,OR(D11="X",D11="x")),IF(OR(D11="X",D11="x",AND(OR(COUNTA(B11,C11,E11,F11)>0,OR(D11="X",D11="x")),(LEN(SUBSTITUTE(SUBSTITUTE(SUBSTITUTE(B11," ",""),"0",""),"-",""))+LEN(SUBSTITUTE(SUBSTITUTE(SUBSTITUTE(C11," ",""),"0",""),"-","")))=(LEN(SUBSTITUTE(SUBSTITUTE(SUBSTITUTE(E11," ",""),"0",""),"-",""))+LEN(SUBSTITUTE(SUBSTITUTE(SUBSTITUTE(F11," ",""),"0",""),"-",""))))),1,0),0)+IF(OR(COUNTA(B17,C17,E17,F17)>0,OR(D17="X",D17="x")),IF(OR(D17="X",D17="x",AND(OR(COUNTA(B17,C17,E17,F17)>0,OR(D17="X",D17="x")),(LEN(SUBSTITUTE(SUBSTITUTE(SUBSTITUTE(B17," ",""),"0",""),"-",""))+LEN(SUBSTITUTE(SUBSTITUTE(SUBSTITUTE(C17," ",""),"0",""),"-","")))=(LEN(SUBSTITUTE(SUBSTITUTE(SUBSTITUTE(E17," ",""),"0",""),"-",""))+LEN(SUBSTITUTE(SUBSTITUTE(SUBSTITUTE(F17," ",""),"0",""),"-",""))))),1,0),0)+IF(OR(COUNTA(B22,C22,E22,F22)>0,OR(D22="X",D22="x")),IF(OR(D22="X",D22="x",AND(OR(COUNTA(B22,C22,E22,F22)>0,OR(D22="X",D22="x")),(LEN(SUBSTITUTE(SUBSTITUTE(SUBSTITUTE(B22," ",""),"0",""),"-",""))+LEN(SUBSTITUTE(SUBSTITUTE(SUBSTITUTE(C22," ",""),"0",""),"-","")))=(LEN(SUBSTITUTE(SUBSTITUTE(SUBSTITUTE(E22," ",""),"0",""),"-",""))+LEN(SUBSTITUTE(SUBSTITUTE(SUBSTITUTE(F22," ",""),"0",""),"-",""))))),1,0),0)+IF(OR(COUNTA(B26,C26,E26,F26)>0,OR(D26="X",D26="x")),IF(OR(D26="X",D26="x",AND(OR(COUNTA(B26,C26,E26,F26)>0,OR(D26="X",D26="x")),(LEN(SUBSTITUTE(SUBSTITUTE(SUBSTITUTE(B26," ",""),"0",""),"-",""))+LEN(SUBSTITUTE(SUBSTITUTE(SUBSTITUTE(C26," ",""),"0",""),"-","")))=(LEN(SUBSTITUTE(SUBSTITUTE(SUBSTITUTE(E26," ",""),"0",""),"-",""))+LEN(SUBSTITUTE(SUBSTITUTE(SUBSTITUTE(F26," ",""),"0",""),"-",""))))),1,0),0)+IF(OR(COUNTA(B29,C29,E29,F29)>0,OR(D29="X",D29="x")),IF(OR(D29="X",D29="x",AND(OR(COUNTA(B29,C29,E29,F29)>0,OR(D29="X",D29="x")),(LEN(SUBSTITUTE(SUBSTITUTE(SUBSTITUTE(B29," ",""),"0",""),"-",""))+LEN(SUBSTITUTE(SUBSTITUTE(SUBSTITUTE(C29," ",""),"0",""),"-","")))=(LEN(SUBSTITUTE(SUBSTITUTE(SUBSTITUTE(E29," ",""),"0",""),"-",""))+LEN(SUBSTITUTE(SUBSTITUTE(SUBSTITUTE(F29," ",""),"0",""),"-",""))))),1,0),0)+IF(OR(COUNTA(B31,C31,E31,F31)>0,OR(D31="X",D31="x")),IF(OR(D31="X",D31="x",AND(OR(COUNTA(B31,C31,E31,F31)>0,OR(D31="X",D31="x")),(LEN(SUBSTITUTE(SUBSTITUTE(SUBSTITUTE(B31," ",""),"0",""),"-",""))+LEN(SUBSTITUTE(SUBSTITUTE(SUBSTITUTE(C31," ",""),"0",""),"-","")))=(LEN(SUBSTITUTE(SUBSTITUTE(SUBSTITUTE(E31," ",""),"0",""),"-",""))+LEN(SUBSTITUTE(SUBSTITUTE(SUBSTITUTE(F31," ",""),"0",""),"-",""))))),1,0),0) | E34: =LEN(SUBSTITUTE(SUBSTITUTE(SUBSTITUTE(E4," ",""),"0",""),"-",""))+LEN(SUBSTITUTE(SUBSTITUTE(SUBSTITUTE(F4," ",""),"0",""),"-",""))+LEN(SUBSTITUTE(SUBSTITUTE(SUBSTITUTE(E11," ",""),"0",""),"-",""))+LEN(SUBSTITUTE(SUBSTITUTE(SUBSTITUTE(F11," ",""),"0",""),"-",""))+LEN(SUBSTITUTE(SUBSTITUTE(SUBSTITUTE(E17," ",""),"0",""),"-",""))+LEN(SUBSTITUTE(SUBSTITUTE(SUBSTITUTE(F17," ",""),"0",""),"-",""))+LEN(SUBSTITUTE(SUBSTITUTE(SUBSTITUTE(B22," ",""),"0",""),"-",""))+LEN(SUBSTITUTE(SUBSTITUTE(SUBSTITUTE(C22," ",""),"0",""),"-",""))+LEN(SUBSTITUTE(SUBSTITUTE(SUBSTITUTE(E26," ",""),"0",""),"-",""))+LEN(SUBSTITUTE(SUBSTITUTE(SUBSTITUTE(F26," ",""),"0",""),"-",""))+LEN(SUBSTITUTE(SUBSTITUTE(SUBSTITUTE(E29," ",""),"0",""),"-",""))+LEN(SUBSTITUTE(SUBSTITUTE(SUBSTITUTE(F29," ",""),"0",""),"-",""))+LEN(SUBSTITUTE(SUBSTITUTE(SUBSTITUTE(E31," ",""),"0",""),"-",""))+LEN(SUBSTITUTE(SUBSTITUTE(SUBSTITUTE(F31," ",""),"0",""),"-","")) | F34: =LEN(SUBSTITUTE(SUBSTITUTE(SUBSTITUTE(B4," ",""),"0",""),"-",""))+LEN(SUBSTITUTE(SUBSTITUTE(SUBSTITUTE(C4," ",""),"0",""),"-",""))+LEN(SUBSTITUTE(SUBSTITUTE(SUBSTITUTE(B11," ",""),"0",""),"-",""))+LEN(SUBSTITUTE(SUBSTITUTE(SUBSTITUTE(C11," ",""),"0",""),"-",""))+LEN(SUBSTITUTE(SUBSTITUTE(SUBSTITUTE(B17," ",""),"0",""),"-",""))+LEN(SUBSTITUTE(SUBSTITUTE(SUBSTITUTE(C17," ",""),"0",""),"-",""))+LEN(SUBSTITUTE(SUBSTITUTE(SUBSTITUTE(E22," ",""),"0",""),"-",""))+LEN(SUBSTITUTE(SUBSTITUTE(SUBSTITUTE(F22," ",""),"0",""),"-",""))+LEN(SUBSTITUTE(SUBSTITUTE(SUBSTITUTE(B26," ",""),"0",""),"-",""))+LEN(SUBSTITUTE(SUBSTITUTE(SUBSTITUTE(C26," ",""),"0",""),"-",""))+LEN(SUBSTITUTE(SUBSTITUTE(SUBSTITUTE(B29," ",""),"0",""),"-",""))+LEN(SUBSTITUTE(SUBSTITUTE(SUBSTITUTE(C29," ",""),"0",""),"-",""))+LEN(SUBSTITUTE(SUBSTITUTE(SUBSTITUTE(B31," ",""),"0",""),"-",""))+LEN(SUBSTITUTE(SUBSTITUTE(SUBSTITUTE(C31," ",""),"0",""),"-","")) | G34: =RANK(U34,$U$34:$U$41)+COUNTIF($U$33:U33,U34) | U34: =(B34*1000000)-(C34*10000)+(D34*100)+(E34*1)-(F34*0.01)
A35: =data!$D$4&" "&data!$B$4 | B35: =IF(OR(COUNTA(B4,C4,E4,F4)>0,OR(D4="X",D4="x")),IF(OR(D4="X",D4="x",AND(OR(COUNTA(B4,C4,E4,F4)>0,OR(D4="X",D4="x")),(LEN(SUBSTITUTE(SUBSTITUTE(SUBSTITUTE(B4," ",""),"0",""),"-",""))+LEN(SUBSTITUTE(SUBSTITUTE(SUBSTITUTE(C4," ",""),"0",""),"-","")))=(LEN(SUBSTITUTE(SUBSTITUTE(SUBSTITUTE(E4," ",""),"0",""),"-",""))+LEN(SUBSTITUTE(SUBSTITUTE(SUBSTITUTE(F4," ",""),"0",""),"-",""))))),0,(LEN(SUBSTITUTE(SUBSTITUTE(SUBSTITUTE(B4," ",""),"0",""),"-",""))+LEN(SUBSTITUTE(SUBSTITUTE(SUBSTITUTE(C4," ",""),"0",""),"-",""))>LEN(SUBSTITUTE(SUBSTITUTE(SUBSTITUTE(E4," ",""),"0",""),"-",""))+LEN(SUBSTITUTE(SUBSTITUTE(SUBSTITUTE(F4," ",""),"0",""),"-","")))*1),0)+IF(OR(COUNTA(B5,C5,E5,F5)>0,OR(D5="X",D5="x")),IF(OR(D5="X",D5="x",AND(OR(COUNTA(B5,C5,E5,F5)>0,OR(D5="X",D5="x")),(LEN(SUBSTITUTE(SUBSTITUTE(SUBSTITUTE(B5," ",""),"0",""),"-",""))+LEN(SUBSTITUTE(SUBSTITUTE(SUBSTITUTE(C5," ",""),"0",""),"-","")))=(LEN(SUBSTITUTE(SUBSTITUTE(SUBSTITUTE(E5," ",""),"0",""),"-",""))+LEN(SUBSTITUTE(SUBSTITUTE(SUBSTITUTE(F5," ",""),"0",""),"-",""))))),0,(LEN(SUBSTITUTE(SUBSTITUTE(SUBSTITUTE(B5," ",""),"0",""),"-",""))+LEN(SUBSTITUTE(SUBSTITUTE(SUBSTITUTE(C5," ",""),"0",""),"-",""))>LEN(SUBSTITUTE(SUBSTITUTE(SUBSTITUTE(E5," ",""),"0",""),"-",""))+LEN(SUBSTITUTE(SUBSTITUTE(SUBSTITUTE(F5," ",""),"0",""),"-","")))*1),0)+IF(OR(COUNTA(B12,C12,E12,F12)>0,OR(D12="X",D12="x")),IF(OR(D12="X",D12="x",AND(OR(COUNTA(B12,C12,E12,F12)>0,OR(D12="X",D12="x")),(LEN(SUBSTITUTE(SUBSTITUTE(SUBSTITUTE(B12," ",""),"0",""),"-",""))+LEN(SUBSTITUTE(SUBSTITUTE(SUBSTITUTE(C12," ",""),"0",""),"-","")))=(LEN(SUBSTITUTE(SUBSTITUTE(SUBSTITUTE(E12," ",""),"0",""),"-",""))+LEN(SUBSTITUTE(SUBSTITUTE(SUBSTITUTE(F12," ",""),"0",""),"-",""))))),0,(LEN(SUBSTITUTE(SUBSTITUTE(SUBSTITUTE(E12," ",""),"0",""),"-",""))+LEN(SUBSTITUTE(SUBSTITUTE(SUBSTITUTE(F12," ",""),"0",""),"-",""))>LEN(SUBSTITUTE(SUBSTITUTE(SUBSTITUTE(B12," ",""),"0",""),"-",""))+LEN(SUBSTITUTE(SUBSTITUTE(SUBSTITUTE(C12," ",""),"0",""),"-","")))*1),0)+IF(OR(COUNTA(B18,C18,E18,F18)>0,OR(D18="X",D18="x")),IF(OR(D18="X",D18="x",AND(OR(COUNTA(B18,C18,E18,F18)>0,OR(D18="X",D18="x")),(LEN(SUBSTITUTE(SUBSTITUTE(SUBSTITUTE(B18," ",""),"0",""),"-",""))+LEN(SUBSTITUTE(SUBSTITUTE(SUBSTITUTE(C18," ",""),"0",""),"-","")))=(LEN(SUBSTITUTE(SUBSTITUTE(SUBSTITUTE(E18," ",""),"0",""),"-",""))+LEN(SUBSTITUTE(SUBSTITUTE(SUBSTITUTE(F18," ",""),"0",""),"-",""))))),0,(LEN(SUBSTITUTE(SUBSTITUTE(SUBSTITUTE(E18," ",""),"0",""),"-",""))+LEN(SUBSTITUTE(SUBSTITUTE(SUBSTITUTE(F18," ",""),"0",""),"-",""))>LEN(SUBSTITUTE(SUBSTITUTE(SUBSTITUTE(B18," ",""),"0",""),"-",""))+LEN(SUBSTITUTE(SUBSTITUTE(SUBSTITUTE(C18," ",""),"0",""),"-","")))*1),0)+IF(OR(COUNTA(B23,C23,E23,F23)>0,OR(D23="X",D23="x")),IF(OR(D23="X",D23="x",AND(OR(COUNTA(B23,C23,E23,F23)>0,OR(D23="X",D23="x")),(LEN(SUBSTITUTE(SUBSTITUTE(SUBSTITUTE(B23," ",""),"0",""),"-",""))+LEN(SUBSTITUTE(SUBSTITUTE(SUBSTITUTE(C23," ",""),"0",""),"-","")))=(LEN(SUBSTITUTE(SUBSTITUTE(SUBSTITUTE(E23," ",""),"0",""),"-",""))+LEN(SUBSTITUTE(SUBSTITUTE(SUBSTITUTE(F23," ",""),"0",""),"-",""))))),0,(LEN(SUBSTITUTE(SUBSTITUTE(SUBSTITUTE(E23," ",""),"0",""),"-",""))+LEN(SUBSTITUTE(SUBSTITUTE(SUBSTITUTE(F23," ",""),"0",""),"-",""))>LEN(SUBSTITUTE(SUBSTITUTE(SUBSTITUTE(B23," ",""),"0",""),"-",""))+LEN(SUBSTITUTE(SUBSTITUTE(SUBSTITUTE(C23," ",""),"0",""),"-","")))*1),0)+IF(OR(COUNTA(B27,C27,E27,F27)>0,OR(D27="X",D27="x")),IF(OR(D27="X",D27="x",AND(OR(COUNTA(B27,C27,E27,F27)>0,OR(D27="X",D27="x")),(LEN(SUBSTITUTE(SUBSTITUTE(SUBSTITUTE(B27," ",""),"0",""),"-",""))+LEN(SUBSTITUTE(SUBSTITUTE(SUBSTITUTE(C27," ",""),"0",""),"-","")))=(LEN(SUBSTITUTE(SUBSTITUTE(SUBSTITUTE(E27," ",""),"0",""),"-",""))+LEN(SUBSTITUTE(SUBSTITUTE(SUBSTITUTE(F27," ",""),"0",""),"-",""))))),0,(LEN(SUBSTITUTE(SUBSTITUTE(SUBSTITUTE(E27," ",""),"0",""),"-",""))+LEN(SUBSTITUTE(SUBSTITUTE(SUBSTITUTE(F27," ",""),"0",""),"-",""))>LEN(SUBSTITUTE(SUBSTITUTE(SUBSTITUTE(B27," ",""),"0",""),"-",""))+LEN(SUBSTITUTE(SUBSTITUTE(SUBSTITUTE(C27," ",""),"0",""),"-","")))*1),0)+IF(OR(COUNTA(B30,C30,E30,F30)>0,OR(D30="X",D30="x")),IF(OR(D30="X",D30="x",AND(OR(COUNTA(B30,C30,E30,F30)>0,OR(D30="X",D30="x")),(LEN(SUBSTITUTE(SUBSTITUTE(SUBSTITUTE(B30," ",""),"0",""),"-",""))+LEN(SUBSTITUTE(SUBSTITUTE(SUBSTITUTE(C30," ",""),"0",""),"-","")))=(LEN(SUBSTITUTE(SUBSTITUTE(SUBSTITUTE(E30," ",""),"0",""),"-",""))+LEN(SUBSTITUTE(SUBSTITUTE(SUBSTITUTE(F30," ",""),"0",""),"-",""))))),0,(LEN(SUBSTITUTE(SUBSTITUTE(SUBSTITUTE(E30," ",""),"0",""),"-",""))+LEN(SUBSTITUTE(SUBSTITUTE(SUBSTITUTE(F30," ",""),"0",""),"-",""))>LEN(SUBSTITUTE(SUBSTITUTE(SUBSTITUTE(B30," ",""),"0",""),"-",""))+LEN(SUBSTITUTE(SUBSTITUTE(SUBSTITUTE(C30," ",""),"0",""),"-","")))*1),0) | C35: =IF(OR(COUNTA(B4,C4,E4,F4)>0,OR(D4="X",D4="x")),IF(OR(D4="X",D4="x",AND(OR(COUNTA(B4,C4,E4,F4)>0,OR(D4="X",D4="x")),(LEN(SUBSTITUTE(SUBSTITUTE(SUBSTITUTE(B4," ",""),"0",""),"-",""))+LEN(SUBSTITUTE(SUBSTITUTE(SUBSTITUTE(C4," ",""),"0",""),"-","")))=(LEN(SUBSTITUTE(SUBSTITUTE(SUBSTITUTE(E4," ",""),"0",""),"-",""))+LEN(SUBSTITUTE(SUBSTITUTE(SUBSTITUTE(F4," ",""),"0",""),"-",""))))),0,(LEN(SUBSTITUTE(SUBSTITUTE(SUBSTITUTE(B4," ",""),"0",""),"-",""))+LEN(SUBSTITUTE(SUBSTITUTE(SUBSTITUTE(C4," ",""),"0",""),"-",""))<LEN(SUBSTITUTE(SUBSTITUTE(SUBSTITUTE(E4," ",""),"0",""),"-",""))+LEN(SUBSTITUTE(SUBSTITUTE(SUBSTITUTE(F4," ",""),"0",""),"-","")))*1),0)+IF(OR(COUNTA(B5,C5,E5,F5)>0,OR(D5="X",D5="x")),IF(OR(D5="X",D5="x",AND(OR(COUNTA(B5,C5,E5,F5)>0,OR(D5="X",D5="x")),(LEN(SUBSTITUTE(SUBSTITUTE(SUBSTITUTE(B5," ",""),"0",""),"-",""))+LEN(SUBSTITUTE(SUBSTITUTE(SUBSTITUTE(C5," ",""),"0",""),"-","")))=(LEN(SUBSTITUTE(SUBSTITUTE(SUBSTITUTE(E5," ",""),"0",""),"-",""))+LEN(SUBSTITUTE(SUBSTITUTE(SUBSTITUTE(F5," ",""),"0",""),"-",""))))),0,(LEN(SUBSTITUTE(SUBSTITUTE(SUBSTITUTE(B5," ",""),"0",""),"-",""))+LEN(SUBSTITUTE(SUBSTITUTE(SUBSTITUTE(C5," ",""),"0",""),"-",""))<LEN(SUBSTITUTE(SUBSTITUTE(SUBSTITUTE(E5," ",""),"0",""),"-",""))+LEN(SUBSTITUTE(SUBSTITUTE(SUBSTITUTE(F5," ",""),"0",""),"-","")))*1),0)+IF(OR(COUNTA(B12,C12,E12,F12)>0,OR(D12="X",D12="x")),IF(OR(D12="X",D12="x",AND(OR(COUNTA(B12,C12,E12,F12)>0,OR(D12="X",D12="x")),(LEN(SUBSTITUTE(SUBSTITUTE(SUBSTITUTE(B12," ",""),"0",""),"-",""))+LEN(SUBSTITUTE(SUBSTITUTE(SUBSTITUTE(C12," ",""),"0",""),"-","")))=(LEN(SUBSTITUTE(SUBSTITUTE(SUBSTITUTE(E12," ",""),"0",""),"-",""))+LEN(SUBSTITUTE(SUBSTITUTE(SUBSTITUTE(F12," ",""),"0",""),"-",""))))),0,(LEN(SUBSTITUTE(SUBSTITUTE(SUBSTITUTE(E12," ",""),"0",""),"-",""))+LEN(SUBSTITUTE(SUBSTITUTE(SUBSTITUTE(F12," ",""),"0",""),"-",""))<LEN(SUBSTITUTE(SUBSTITUTE(SUBSTITUTE(B12," ",""),"0",""),"-",""))+LEN(SUBSTITUTE(SUBSTITUTE(SUBSTITUTE(C12," ",""),"0",""),"-","")))*1),0)+IF(OR(COUNTA(B18,C18,E18,F18)>0,OR(D18="X",D18="x")),IF(OR(D18="X",D18="x",AND(OR(COUNTA(B18,C18,E18,F18)>0,OR(D18="X",D18="x")),(LEN(SUBSTITUTE(SUBSTITUTE(SUBSTITUTE(B18," ",""),"0",""),"-",""))+LEN(SUBSTITUTE(SUBSTITUTE(SUBSTITUTE(C18," ",""),"0",""),"-","")))=(LEN(SUBSTITUTE(SUBSTITUTE(SUBSTITUTE(E18," ",""),"0",""),"-",""))+LEN(SUBSTITUTE(SUBSTITUTE(SUBSTITUTE(F18," ",""),"0",""),"-",""))))),0,(LEN(SUBSTITUTE(SUBSTITUTE(SUBSTITUTE(E18," ",""),"0",""),"-",""))+LEN(SUBSTITUTE(SUBSTITUTE(SUBSTITUTE(F18," ",""),"0",""),"-",""))<LEN(SUBSTITUTE(SUBSTITUTE(SUBSTITUTE(B18," ",""),"0",""),"-",""))+LEN(SUBSTITUTE(SUBSTITUTE(SUBSTITUTE(C18," ",""),"0",""),"-","")))*1),0)+IF(OR(COUNTA(B23,C23,E23,F23)>0,OR(D23="X",D23="x")),IF(OR(D23="X",D23="x",AND(OR(COUNTA(B23,C23,E23,F23)>0,OR(D23="X",D23="x")),(LEN(SUBSTITUTE(SUBSTITUTE(SUBSTITUTE(B23," ",""),"0",""),"-",""))+LEN(SUBSTITUTE(SUBSTITUTE(SUBSTITUTE(C23," ",""),"0",""),"-","")))=(LEN(SUBSTITUTE(SUBSTITUTE(SUBSTITUTE(E23," ",""),"0",""),"-",""))+LEN(SUBSTITUTE(SUBSTITUTE(SUBSTITUTE(F23," ",""),"0",""),"-",""))))),0,(LEN(SUBSTITUTE(SUBSTITUTE(SUBSTITUTE(E23," ",""),"0",""),"-",""))+LEN(SUBSTITUTE(SUBSTITUTE(SUBSTITUTE(F23," ",""),"0",""),"-",""))<LEN(SUBSTITUTE(SUBSTITUTE(SUBSTITUTE(B23," ",""),"0",""),"-",""))+LEN(SUBSTITUTE(SUBSTITUTE(SUBSTITUTE(C23," ",""),"0",""),"-","")))*1),0)+IF(OR(COUNTA(B27,C27,E27,F27)>0,OR(D27="X",D27="x")),IF(OR(D27="X",D27="x",AND(OR(COUNTA(B27,C27,E27,F27)>0,OR(D27="X",D27="x")),(LEN(SUBSTITUTE(SUBSTITUTE(SUBSTITUTE(B27," ",""),"0",""),"-",""))+LEN(SUBSTITUTE(SUBSTITUTE(SUBSTITUTE(C27," ",""),"0",""),"-","")))=(LEN(SUBSTITUTE(SUBSTITUTE(SUBSTITUTE(E27," ",""),"0",""),"-",""))+LEN(SUBSTITUTE(SUBSTITUTE(SUBSTITUTE(F27," ",""),"0",""),"-",""))))),0,(LEN(SUBSTITUTE(SUBSTITUTE(SUBSTITUTE(E27," ",""),"0",""),"-",""))+LEN(SUBSTITUTE(SUBSTITUTE(SUBSTITUTE(F27," ",""),"0",""),"-",""))<LEN(SUBSTITUTE(SUBSTITUTE(SUBSTITUTE(B27," ",""),"0",""),"-",""))+LEN(SUBSTITUTE(SUBSTITUTE(SUBSTITUTE(C27," ",""),"0",""),"-","")))*1),0)+IF(OR(COUNTA(B30,C30,E30,F30)>0,OR(D30="X",D30="x")),IF(OR(D30="X",D30="x",AND(OR(COUNTA(B30,C30,E30,F30)>0,OR(D30="X",D30="x")),(LEN(SUBSTITUTE(SUBSTITUTE(SUBSTITUTE(B30," ",""),"0",""),"-",""))+LEN(SUBSTITUTE(SUBSTITUTE(SUBSTITUTE(C30," ",""),"0",""),"-","")))=(LEN(SUBSTITUTE(SUBSTITUTE(SUBSTITUTE(E30," ",""),"0",""),"-",""))+LEN(SUBSTITUTE(SUBSTITUTE(SUBSTITUTE(F30," ",""),"0",""),"-",""))))),0,(LEN(SUBSTITUTE(SUBSTITUTE(SUBSTITUTE(E30," ",""),"0",""),"-",""))+LEN(SUBSTITUTE(SUBSTITUTE(SUBSTITUTE(F30," ",""),"0",""),"-",""))<LEN(SUBSTITUTE(SUBSTITUTE(SUBSTITUTE(B30," ",""),"0",""),"-",""))+LEN(SUBSTITUTE(SUBSTITUTE(SUBSTITUTE(C30," ",""),"0",""),"-","")))*1),0) | D35: =IF(OR(COUNTA(B4,C4,E4,F4)>0,OR(D4="X",D4="x")),IF(OR(D4="X",D4="x",AND(OR(COUNTA(B4,C4,E4,F4)>0,OR(D4="X",D4="x")),(LEN(SUBSTITUTE(SUBSTITUTE(SUBSTITUTE(B4," ",""),"0",""),"-",""))+LEN(SUBSTITUTE(SUBSTITUTE(SUBSTITUTE(C4," ",""),"0",""),"-","")))=(LEN(SUBSTITUTE(SUBSTITUTE(SUBSTITUTE(E4," ",""),"0",""),"-",""))+LEN(SUBSTITUTE(SUBSTITUTE(SUBSTITUTE(F4," ",""),"0",""),"-",""))))),1,0),0)+IF(OR(COUNTA(B5,C5,E5,F5)>0,OR(D5="X",D5="x")),IF(OR(D5="X",D5="x",AND(OR(COUNTA(B5,C5,E5,F5)>0,OR(D5="X",D5="x")),(LEN(SUBSTITUTE(SUBSTITUTE(SUBSTITUTE(B5," ",""),"0",""),"-",""))+LEN(SUBSTITUTE(SUBSTITUTE(SUBSTITUTE(C5," ",""),"0",""),"-","")))=(LEN(SUBSTITUTE(SUBSTITUTE(SUBSTITUTE(E5," ",""),"0",""),"-",""))+LEN(SUBSTITUTE(SUBSTITUTE(SUBSTITUTE(F5," ",""),"0",""),"-",""))))),1,0),0)+IF(OR(COUNTA(B12,C12,E12,F12)>0,OR(D12="X",D12="x")),IF(OR(D12="X",D12="x",AND(OR(COUNTA(B12,C12,E12,F12)>0,OR(D12="X",D12="x")),(LEN(SUBSTITUTE(SUBSTITUTE(SUBSTITUTE(B12," ",""),"0",""),"-",""))+LEN(SUBSTITUTE(SUBSTITUTE(SUBSTITUTE(C12," ",""),"0",""),"-","")))=(LEN(SUBSTITUTE(SUBSTITUTE(SUBSTITUTE(E12," ",""),"0",""),"-",""))+LEN(SUBSTITUTE(SUBSTITUTE(SUBSTITUTE(F12," ",""),"0",""),"-",""))))),1,0),0)+IF(OR(COUNTA(B18,C18,E18,F18)>0,OR(D18="X",D18="x")),IF(OR(D18="X",D18="x",AND(OR(COUNTA(B18,C18,E18,F18)>0,OR(D18="X",D18="x")),(LEN(SUBSTITUTE(SUBSTITUTE(SUBSTITUTE(B18," ",""),"0",""),"-",""))+LEN(SUBSTITUTE(SUBSTITUTE(SUBSTITUTE(C18," ",""),"0",""),"-","")))=(LEN(SUBSTITUTE(SUBSTITUTE(SUBSTITUTE(E18," ",""),"0",""),"-",""))+LEN(SUBSTITUTE(SUBSTITUTE(SUBSTITUTE(F18," ",""),"0",""),"-",""))))),1,0),0)+IF(OR(COUNTA(B23,C23,E23,F23)>0,OR(D23="X",D23="x")),IF(OR(D23="X",D23="x",AND(OR(COUNTA(B23,C23,E23,F23)>0,OR(D23="X",D23="x")),(LEN(SUBSTITUTE(SUBSTITUTE(SUBSTITUTE(B23," ",""),"0",""),"-",""))+LEN(SUBSTITUTE(SUBSTITUTE(SUBSTITUTE(C23," ",""),"0",""),"-","")))=(LEN(SUBSTITUTE(SUBSTITUTE(SUBSTITUTE(E23," ",""),"0",""),"-",""))+LEN(SUBSTITUTE(SUBSTITUTE(SUBSTITUTE(F23," ",""),"0",""),"-",""))))),1,0),0)+IF(OR(COUNTA(B27,C27,E27,F27)>0,OR(D27="X",D27="x")),IF(OR(D27="X",D27="x",AND(OR(COUNTA(B27,C27,E27,F27)>0,OR(D27="X",D27="x")),(LEN(SUBSTITUTE(SUBSTITUTE(SUBSTITUTE(B27," ",""),"0",""),"-",""))+LEN(SUBSTITUTE(SUBSTITUTE(SUBSTITUTE(C27," ",""),"0",""),"-","")))=(LEN(SUBSTITUTE(SUBSTITUTE(SUBSTITUTE(E27," ",""),"0",""),"-",""))+LEN(SUBSTITUTE(SUBSTITUTE(SUBSTITUTE(F27," ",""),"0",""),"-",""))))),1,0),0)+IF(OR(COUNTA(B30,C30,E30,F30)>0,OR(D30="X",D30="x")),IF(OR(D30="X",D30="x",AND(OR(COUNTA(B30,C30,E30,F30)>0,OR(D30="X",D30="x")),(LEN(SUBSTITUTE(SUBSTITUTE(SUBSTITUTE(B30," ",""),"0",""),"-",""))+LEN(SUBSTITUTE(SUBSTITUTE(SUBSTITUTE(C30," ",""),"0",""),"-","")))=(LEN(SUBSTITUTE(SUBSTITUTE(SUBSTITUTE(E30," ",""),"0",""),"-",""))+LEN(SUBSTITUTE(SUBSTITUTE(SUBSTITUTE(F30," ",""),"0",""),"-",""))))),1,0),0) | E35: =LEN(SUBSTITUTE(SUBSTITUTE(SUBSTITUTE(B4," ",""),"0",""),"-",""))+LEN(SUBSTITUTE(SUBSTITUTE(SUBSTITUTE(C4," ",""),"0",""),"-",""))+LEN(SUBSTITUTE(SUBSTITUTE(SUBSTITUTE(B5," ",""),"0",""),"-",""))+LEN(SUBSTITUTE(SUBSTITUTE(SUBSTITUTE(C5," ",""),"0",""),"-",""))+LEN(SUBSTITUTE(SUBSTITUTE(SUBSTITUTE(E12," ",""),"0",""),"-",""))+LEN(SUBSTITUTE(SUBSTITUTE(SUBSTITUTE(F12," ",""),"0",""),"-",""))+LEN(SUBSTITUTE(SUBSTITUTE(SUBSTITUTE(E18," ",""),"0",""),"-",""))+LEN(SUBSTITUTE(SUBSTITUTE(SUBSTITUTE(F18," ",""),"0",""),"-",""))+LEN(SUBSTITUTE(SUBSTITUTE(SUBSTITUTE(E23," ",""),"0",""),"-",""))+LEN(SUBSTITUTE(SUBSTITUTE(SUBSTITUTE(F23," ",""),"0",""),"-",""))+LEN(SUBSTITUTE(SUBSTITUTE(SUBSTITUTE(E27," ",""),"0",""),"-",""))+LEN(SUBSTITUTE(SUBSTITUTE(SUBSTITUTE(F27," ",""),"0",""),"-",""))+LEN(SUBSTITUTE(SUBSTITUTE(SUBSTITUTE(E30," ",""),"0",""),"-",""))+LEN(SUBSTITUTE(SUBSTITUTE(SUBSTITUTE(F30," ",""),"0",""),"-","")) | F35: =LEN(SUBSTITUTE(SUBSTITUTE(SUBSTITUTE(E4," ",""),"0",""),"-",""))+LEN(SUBSTITUTE(SUBSTITUTE(SUBSTITUTE(F4," ",""),"0",""),"-",""))+LEN(SUBSTITUTE(SUBSTITUTE(SUBSTITUTE(E5," ",""),"0",""),"-",""))+LEN(SUBSTITUTE(SUBSTITUTE(SUBSTITUTE(F5," ",""),"0",""),"-",""))+LEN(SUBSTITUTE(SUBSTITUTE(SUBSTITUTE(B12," ",""),"0",""),"-",""))+LEN(SUBSTITUTE(SUBSTITUTE(SUBSTITUTE(C12," ",""),"0",""),"-",""))+LEN(SUBSTITUTE(SUBSTITUTE(SUBSTITUTE(B18," ",""),"0",""),"-",""))+LEN(SUBSTITUTE(SUBSTITUTE(SUBSTITUTE(C18," ",""),"0",""),"-",""))+LEN(SUBSTITUTE(SUBSTITUTE(SUBSTITUTE(B23," ",""),"0",""),"-",""))+LEN(SUBSTITUTE(SUBSTITUTE(SUBSTITUTE(C23," ",""),"0",""),"-",""))+LEN(SUBSTITUTE(SUBSTITUTE(SUBSTITUTE(B27," ",""),"0",""),"-",""))+LEN(SUBSTITUTE(SUBSTITUTE(SUBSTITUTE(C27," ",""),"0",""),"-",""))+LEN(SUBSTITUTE(SUBSTITUTE(SUBSTITUTE(B30," ",""),"0",""),"-",""))+LEN(SUBSTITUTE(SUBSTITUTE(SUBSTITUTE(C30," ",""),"0",""),"-","")) | G35: =RANK(U35,$U$34:$U$41)+COUNTIF($U$33:U34,U35) | U35: =(B35*1000000)-(C35*10000)+(D35*100)+(E35*1)-(F35*0.01)
A36: =data!$D$5&" "&data!$B$5 | B36: =IF(OR(COUNTA(B5,C5,E5,F5)>0,OR(D5="X",D5="x")),IF(OR(D5="X",D5="x",AND(OR(COUNTA(B5,C5,E5,F5)>0,OR(D5="X",D5="x")),(LEN(SUBSTITUTE(SUBSTITUTE(SUBSTITUTE(B5," ",""),"0",""),"-",""))+LEN(SUBSTITUTE(SUBSTITUTE(SUBSTITUTE(C5," ",""),"0",""),"-","")))=(LEN(SUBSTITUTE(SUBSTITUTE(SUBSTITUTE(E5," ",""),"0",""),"-",""))+LEN(SUBSTITUTE(SUBSTITUTE(SUBSTITUTE(F5," ",""),"0",""),"-",""))))),0,(LEN(SUBSTITUTE(SUBSTITUTE(SUBSTITUTE(E5," ",""),"0",""),"-",""))+LEN(SUBSTITUTE(SUBSTITUTE(SUBSTITUTE(F5," ",""),"0",""),"-",""))>LEN(SUBSTITUTE(SUBSTITUTE(SUBSTITUTE(B5," ",""),"0",""),"-",""))+LEN(SUBSTITUTE(SUBSTITUTE(SUBSTITUTE(C5," ",""),"0",""),"-","")))*1),0)+IF(OR(COUNTA(B6,C6,E6,F6)>0,OR(D6="X",D6="x")),IF(OR(D6="X",D6="x",AND(OR(COUNTA(B6,C6,E6,F6)>0,OR(D6="X",D6="x")),(LEN(SUBSTITUTE(SUBSTITUTE(SUBSTITUTE(B6," ",""),"0",""),"-",""))+LEN(SUBSTITUTE(SUBSTITUTE(SUBSTITUTE(C6," ",""),"0",""),"-","")))=(LEN(SUBSTITUTE(SUBSTITUTE(SUBSTITUTE(E6," ",""),"0",""),"-",""))+LEN(SUBSTITUTE(SUBSTITUTE(SUBSTITUTE(F6," ",""),"0",""),"-",""))))),0,(LEN(SUBSTITUTE(SUBSTITUTE(SUBSTITUTE(E6," ",""),"0",""),"-",""))+LEN(SUBSTITUTE(SUBSTITUTE(SUBSTITUTE(F6," ",""),"0",""),"-",""))>LEN(SUBSTITUTE(SUBSTITUTE(SUBSTITUTE(B6," ",""),"0",""),"-",""))+LEN(SUBSTITUTE(SUBSTITUTE(SUBSTITUTE(C6," ",""),"0",""),"-","")))*1),0)+IF(OR(COUNTA(B11,C11,E11,F11)>0,OR(D11="X",D11="x")),IF(OR(D11="X",D11="x",AND(OR(COUNTA(B11,C11,E11,F11)>0,OR(D11="X",D11="x")),(LEN(SUBSTITUTE(SUBSTITUTE(SUBSTITUTE(B11," ",""),"0",""),"-",""))+LEN(SUBSTITUTE(SUBSTITUTE(SUBSTITUTE(C11," ",""),"0",""),"-","")))=(LEN(SUBSTITUTE(SUBSTITUTE(SUBSTITUTE(E11," ",""),"0",""),"-",""))+LEN(SUBSTITUTE(SUBSTITUTE(SUBSTITUTE(F11," ",""),"0",""),"-",""))))),0,(LEN(SUBSTITUTE(SUBSTITUTE(SUBSTITUTE(B11," ",""),"0",""),"-",""))+LEN(SUBSTITUTE(SUBSTITUTE(SUBSTITUTE(C11," ",""),"0",""),"-",""))>LEN(SUBSTITUTE(SUBSTITUTE(SUBSTITUTE(E11," ",""),"0",""),"-",""))+LEN(SUBSTITUTE(SUBSTITUTE(SUBSTITUTE(F11," ",""),"0",""),"-","")))*1),0)+IF(OR(COUNTA(B13,C13,E13,F13)>0,OR(D13="X",D13="x")),IF(OR(D13="X",D13="x",AND(OR(COUNTA(B13,C13,E13,F13)>0,OR(D13="X",D13="x")),(LEN(SUBSTITUTE(SUBSTITUTE(SUBSTITUTE(B13," ",""),"0",""),"-",""))+LEN(SUBSTITUTE(SUBSTITUTE(SUBSTITUTE(C13," ",""),"0",""),"-","")))=(LEN(SUBSTITUTE(SUBSTITUTE(SUBSTITUTE(E13," ",""),"0",""),"-",""))+LEN(SUBSTITUTE(SUBSTITUTE(SUBSTITUTE(F13," ",""),"0",""),"-",""))))),0,(LEN(SUBSTITUTE(SUBSTITUTE(SUBSTITUTE(E13," ",""),"0",""),"-",""))+LEN(SUBSTITUTE(SUBSTITUTE(SUBSTITUTE(F13," ",""),"0",""),"-",""))>LEN(SUBSTITUTE(SUBSTITUTE(SUBSTITUTE(B13," ",""),"0",""),"-",""))+LEN(SUBSTITUTE(SUBSTITUTE(SUBSTITUTE(C13," ",""),"0",""),"-","")))*1),0)+IF(OR(COUNTA(B19,C19,E19,F19)>0,OR(D19="X",D19="x")),IF(OR(D19="X",D19="x",AND(OR(COUNTA(B19,C19,E19,F19)>0,OR(D19="X",D19="x")),(LEN(SUBSTITUTE(SUBSTITUTE(SUBSTITUTE(B19," ",""),"0",""),"-",""))+LEN(SUBSTITUTE(SUBSTITUTE(SUBSTITUTE(C19," ",""),"0",""),"-","")))=(LEN(SUBSTITUTE(SUBSTITUTE(SUBSTITUTE(E19," ",""),"0",""),"-",""))+LEN(SUBSTITUTE(SUBSTITUTE(SUBSTITUTE(F19," ",""),"0",""),"-",""))))),0,(LEN(SUBSTITUTE(SUBSTITUTE(SUBSTITUTE(E19," ",""),"0",""),"-",""))+LEN(SUBSTITUTE(SUBSTITUTE(SUBSTITUTE(F19," ",""),"0",""),"-",""))>LEN(SUBSTITUTE(SUBSTITUTE(SUBSTITUTE(B19," ",""),"0",""),"-",""))+LEN(SUBSTITUTE(SUBSTITUTE(SUBSTITUTE(C19," ",""),"0",""),"-","")))*1),0)+IF(OR(COUNTA(B24,C24,E24,F24)>0,OR(D24="X",D24="x")),IF(OR(D24="X",D24="x",AND(OR(COUNTA(B24,C24,E24,F24)>0,OR(D24="X",D24="x")),(LEN(SUBSTITUTE(SUBSTITUTE(SUBSTITUTE(B24," ",""),"0",""),"-",""))+LEN(SUBSTITUTE(SUBSTITUTE(SUBSTITUTE(C24," ",""),"0",""),"-","")))=(LEN(SUBSTITUTE(SUBSTITUTE(SUBSTITUTE(E24," ",""),"0",""),"-",""))+LEN(SUBSTITUTE(SUBSTITUTE(SUBSTITUTE(F24," ",""),"0",""),"-",""))))),0,(LEN(SUBSTITUTE(SUBSTITUTE(SUBSTITUTE(E24," ",""),"0",""),"-",""))+LEN(SUBSTITUTE(SUBSTITUTE(SUBSTITUTE(F24," ",""),"0",""),"-",""))>LEN(SUBSTITUTE(SUBSTITUTE(SUBSTITUTE(B24," ",""),"0",""),"-",""))+LEN(SUBSTITUTE(SUBSTITUTE(SUBSTITUTE(C24," ",""),"0",""),"-","")))*1),0)+IF(OR(COUNTA(B28,C28,E28,F28)>0,OR(D28="X",D28="x")),IF(OR(D28="X",D28="x",AND(OR(COUNTA(B28,C28,E28,F28)>0,OR(D28="X",D28="x")),(LEN(SUBSTITUTE(SUBSTITUTE(SUBSTITUTE(B28," ",""),"0",""),"-",""))+LEN(SUBSTITUTE(SUBSTITUTE(SUBSTITUTE(C28," ",""),"0",""),"-","")))=(LEN(SUBSTITUTE(SUBSTITUTE(SUBSTITUTE(E28," ",""),"0",""),"-",""))+LEN(SUBSTITUTE(SUBSTITUTE(SUBSTITUTE(F28," ",""),"0",""),"-",""))))),0,(LEN(SUBSTITUTE(SUBSTITUTE(SUBSTITUTE(E28," ",""),"0",""),"-",""))+LEN(SUBSTITUTE(SUBSTITUTE(SUBSTITUTE(F28," ",""),"0",""),"-",""))>LEN(SUBSTITUTE(SUBSTITUTE(SUBSTITUTE(B28," ",""),"0",""),"-",""))+LEN(SUBSTITUTE(SUBSTITUTE(SUBSTITUTE(C28," ",""),"0",""),"-","")))*1),0) | C36: =IF(OR(COUNTA(B5,C5,E5,F5)>0,OR(D5="X",D5="x")),IF(OR(D5="X",D5="x",AND(OR(COUNTA(B5,C5,E5,F5)>0,OR(D5="X",D5="x")),(LEN(SUBSTITUTE(SUBSTITUTE(SUBSTITUTE(B5," ",""),"0",""),"-",""))+LEN(SUBSTITUTE(SUBSTITUTE(SUBSTITUTE(C5," ",""),"0",""),"-","")))=(LEN(SUBSTITUTE(SUBSTITUTE(SUBSTITUTE(E5," ",""),"0",""),"-",""))+LEN(SUBSTITUTE(SUBSTITUTE(SUBSTITUTE(F5," ",""),"0",""),"-",""))))),0,(LEN(SUBSTITUTE(SUBSTITUTE(SUBSTITUTE(E5," ",""),"0",""),"-",""))+LEN(SUBSTITUTE(SUBSTITUTE(SUBSTITUTE(F5," ",""),"0",""),"-",""))<LEN(SUBSTITUTE(SUBSTITUTE(SUBSTITUTE(B5," ",""),"0",""),"-",""))+LEN(SUBSTITUTE(SUBSTITUTE(SUBSTITUTE(C5," ",""),"0",""),"-","")))*1),0)+IF(OR(COUNTA(B6,C6,E6,F6)>0,OR(D6="X",D6="x")),IF(OR(D6="X",D6="x",AND(OR(COUNTA(B6,C6,E6,F6)>0,OR(D6="X",D6="x")),(LEN(SUBSTITUTE(SUBSTITUTE(SUBSTITUTE(B6," ",""),"0",""),"-",""))+LEN(SUBSTITUTE(SUBSTITUTE(SUBSTITUTE(C6," ",""),"0",""),"-","")))=(LEN(SUBSTITUTE(SUBSTITUTE(SUBSTITUTE(E6," ",""),"0",""),"-",""))+LEN(SUBSTITUTE(SUBSTITUTE(SUBSTITUTE(F6," ",""),"0",""),"-",""))))),0,(LEN(SUBSTITUTE(SUBSTITUTE(SUBSTITUTE(E6," ",""),"0",""),"-",""))+LEN(SUBSTITUTE(SUBSTITUTE(SUBSTITUTE(F6," ",""),"0",""),"-",""))<LEN(SUBSTITUTE(SUBSTITUTE(SUBSTITUTE(B6," ",""),"0",""),"-",""))+LEN(SUBSTITUTE(SUBSTITUTE(SUBSTITUTE(C6," ",""),"0",""),"-","")))*1),0)+IF(OR(COUNTA(B11,C11,E11,F11)>0,OR(D11="X",D11="x")),IF(OR(D11="X",D11="x",AND(OR(COUNTA(B11,C11,E11,F11)>0,OR(D11="X",D11="x")),(LEN(SUBSTITUTE(SUBSTITUTE(SUBSTITUTE(B11," ",""),"0",""),"-",""))+LEN(SUBSTITUTE(SUBSTITUTE(SUBSTITUTE(C11," ",""),"0",""),"-","")))=(LEN(SUBSTITUTE(SUBSTITUTE(SUBSTITUTE(E11," ",""),"0",""),"-",""))+LEN(SUBSTITUTE(SUBSTITUTE(SUBSTITUTE(F11," ",""),"0",""),"-",""))))),0,(LEN(SUBSTITUTE(SUBSTITUTE(SUBSTITUTE(B11," ",""),"0",""),"-",""))+LEN(SUBSTITUTE(SUBSTITUTE(SUBSTITUTE(C11," ",""),"0",""),"-",""))<LEN(SUBSTITUTE(SUBSTITUTE(SUBSTITUTE(E11," ",""),"0",""),"-",""))+LEN(SUBSTITUTE(SUBSTITUTE(SUBSTITUTE(F11," ",""),"0",""),"-","")))*1),0)+IF(OR(COUNTA(B13,C13,E13,F13)>0,OR(D13="X",D13="x")),IF(OR(D13="X",D13="x",AND(OR(COUNTA(B13,C13,E13,F13)>0,OR(D13="X",D13="x")),(LEN(SUBSTITUTE(SUBSTITUTE(SUBSTITUTE(B13," ",""),"0",""),"-",""))+LEN(SUBSTITUTE(SUBSTITUTE(SUBSTITUTE(C13," ",""),"0",""),"-","")))=(LEN(SUBSTITUTE(SUBSTITUTE(SUBSTITUTE(E13," ",""),"0",""),"-",""))+LEN(SUBSTITUTE(SUBSTITUTE(SUBSTITUTE(F13," ",""),"0",""),"-",""))))),0,(LEN(SUBSTITUTE(SUBSTITUTE(SUBSTITUTE(E13," ",""),"0",""),"-",""))+LEN(SUBSTITUTE(SUBSTITUTE(SUBSTITUTE(F13," ",""),"0",""),"-",""))<LEN(SUBSTITUTE(SUBSTITUTE(SUBSTITUTE(B13," ",""),"0",""),"-",""))+LEN(SUBSTITUTE(SUBSTITUTE(SUBSTITUTE(C13," ",""),"0",""),"-","")))*1),0)+IF(OR(COUNTA(B19,C19,E19,F19)>0,OR(D19="X",D19="x")),IF(OR(D19="X",D19="x",AND(OR(COUNTA(B19,C19,E19,F19)>0,OR(D19="X",D19="x")),(LEN(SUBSTITUTE(SUBSTITUTE(SUBSTITUTE(B19," ",""),"0",""),"-",""))+LEN(SUBSTITUTE(SUBSTITUTE(SUBSTITUTE(C19," ",""),"0",""),"-","")))=(LEN(SUBSTITUTE(SUBSTITUTE(SUBSTITUTE(E19," ",""),"0",""),"-",""))+LEN(SUBSTITUTE(SUBSTITUTE(SUBSTITUTE(F19," ",""),"0",""),"-",""))))),0,(LEN(SUBSTITUTE(SUBSTITUTE(SUBSTITUTE(E19," ",""),"0",""),"-",""))+LEN(SUBSTITUTE(SUBSTITUTE(SUBSTITUTE(F19," ",""),"0",""),"-",""))<LEN(SUBSTITUTE(SUBSTITUTE(SUBSTITUTE(B19," ",""),"0",""),"-",""))+LEN(SUBSTITUTE(SUBSTITUTE(SUBSTITUTE(C19," ",""),"0",""),"-","")))*1),0)+IF(OR(COUNTA(B24,C24,E24,F24)>0,OR(D24="X",D24="x")),IF(OR(D24="X",D24="x",AND(OR(COUNTA(B24,C24,E24,F24)>0,OR(D24="X",D24="x")),(LEN(SUBSTITUTE(SUBSTITUTE(SUBSTITUTE(B24," ",""),"0",""),"-",""))+LEN(SUBSTITUTE(SUBSTITUTE(SUBSTITUTE(C24," ",""),"0",""),"-","")))=(LEN(SUBSTITUTE(SUBSTITUTE(SUBSTITUTE(E24," ",""),"0",""),"-",""))+LEN(SUBSTITUTE(SUBSTITUTE(SUBSTITUTE(F24," ",""),"0",""),"-",""))))),0,(LEN(SUBSTITUTE(SUBSTITUTE(SUBSTITUTE(E24," ",""),"0",""),"-",""))+LEN(SUBSTITUTE(SUBSTITUTE(SUBSTITUTE(F24," ",""),"0",""),"-",""))<LEN(SUBSTITUTE(SUBSTITUTE(SUBSTITUTE(B24," ",""),"0",""),"-",""))+LEN(SUBSTITUTE(SUBSTITUTE(SUBSTITUTE(C24," ",""),"0",""),"-","")))*1),0)+IF(OR(COUNTA(B28,C28,E28,F28)>0,OR(D28="X",D28="x")),IF(OR(D28="X",D28="x",AND(OR(COUNTA(B28,C28,E28,F28)>0,OR(D28="X",D28="x")),(LEN(SUBSTITUTE(SUBSTITUTE(SUBSTITUTE(B28," ",""),"0",""),"-",""))+LEN(SUBSTITUTE(SUBSTITUTE(SUBSTITUTE(C28," ",""),"0",""),"-","")))=(LEN(SUBSTITUTE(SUBSTITUTE(SUBSTITUTE(E28," ",""),"0",""),"-",""))+LEN(SUBSTITUTE(SUBSTITUTE(SUBSTITUTE(F28," ",""),"0",""),"-",""))))),0,(LEN(SUBSTITUTE(SUBSTITUTE(SUBSTITUTE(E28," ",""),"0",""),"-",""))+LEN(SUBSTITUTE(SUBSTITUTE(SUBSTITUTE(F28," ",""),"0",""),"-",""))<LEN(SUBSTITUTE(SUBSTITUTE(SUBSTITUTE(B28," ",""),"0",""),"-",""))+LEN(SUBSTITUTE(SUBSTITUTE(SUBSTITUTE(C28," ",""),"0",""),"-","")))*1),0) | D36: =IF(OR(COUNTA(B5,C5,E5,F5)>0,OR(D5="X",D5="x")),IF(OR(D5="X",D5="x",AND(OR(COUNTA(B5,C5,E5,F5)>0,OR(D5="X",D5="x")),(LEN(SUBSTITUTE(SUBSTITUTE(SUBSTITUTE(B5," ",""),"0",""),"-",""))+LEN(SUBSTITUTE(SUBSTITUTE(SUBSTITUTE(C5," ",""),"0",""),"-","")))=(LEN(SUBSTITUTE(SUBSTITUTE(SUBSTITUTE(E5," ",""),"0",""),"-",""))+LEN(SUBSTITUTE(SUBSTITUTE(SUBSTITUTE(F5," ",""),"0",""),"-",""))))),1,0),0)+IF(OR(COUNTA(B6,C6,E6,F6)>0,OR(D6="X",D6="x")),IF(OR(D6="X",D6="x",AND(OR(COUNTA(B6,C6,E6,F6)>0,OR(D6="X",D6="x")),(LEN(SUBSTITUTE(SUBSTITUTE(SUBSTITUTE(B6," ",""),"0",""),"-",""))+LEN(SUBSTITUTE(SUBSTITUTE(SUBSTITUTE(C6," ",""),"0",""),"-","")))=(LEN(SUBSTITUTE(SUBSTITUTE(SUBSTITUTE(E6," ",""),"0",""),"-",""))+LEN(SUBSTITUTE(SUBSTITUTE(SUBSTITUTE(F6," ",""),"0",""),"-",""))))),1,0),0)+IF(OR(COUNTA(B11,C11,E11,F11)>0,OR(D11="X",D11="x")),IF(OR(D11="X",D11="x",AND(OR(COUNTA(B11,C11,E11,F11)>0,OR(D11="X",D11="x")),(LEN(SUBSTITUTE(SUBSTITUTE(SUBSTITUTE(B11," ",""),"0",""),"-",""))+LEN(SUBSTITUTE(SUBSTITUTE(SUBSTITUTE(C11," ",""),"0",""),"-","")))=(LEN(SUBSTITUTE(SUBSTITUTE(SUBSTITUTE(E11," ",""),"0",""),"-",""))+LEN(SUBSTITUTE(SUBSTITUTE(SUBSTITUTE(F11," ",""),"0",""),"-",""))))),1,0),0)+IF(OR(COUNTA(B13,C13,E13,F13)>0,OR(D13="X",D13="x")),IF(OR(D13="X",D13="x",AND(OR(COUNTA(B13,C13,E13,F13)>0,OR(D13="X",D13="x")),(LEN(SUBSTITUTE(SUBSTITUTE(SUBSTITUTE(B13," ",""),"0",""),"-",""))+LEN(SUBSTITUTE(SUBSTITUTE(SUBSTITUTE(C13," ",""),"0",""),"-","")))=(LEN(SUBSTITUTE(SUBSTITUTE(SUBSTITUTE(E13," ",""),"0",""),"-",""))+LEN(SUBSTITUTE(SUBSTITUTE(SUBSTITUTE(F13," ",""),"0",""),"-",""))))),1,0),0)+IF(OR(COUNTA(B19,C19,E19,F19)>0,OR(D19="X",D19="x")),IF(OR(D19="X",D19="x",AND(OR(COUNTA(B19,C19,E19,F19)>0,OR(D19="X",D19="x")),(LEN(SUBSTITUTE(SUBSTITUTE(SUBSTITUTE(B19," ",""),"0",""),"-",""))+LEN(SUBSTITUTE(SUBSTITUTE(SUBSTITUTE(C19," ",""),"0",""),"-","")))=(LEN(SUBSTITUTE(SUBSTITUTE(SUBSTITUTE(E19," ",""),"0",""),"-",""))+LEN(SUBSTITUTE(SUBSTITUTE(SUBSTITUTE(F19," ",""),"0",""),"-",""))))),1,0),0)+IF(OR(COUNTA(B24,C24,E24,F24)>0,OR(D24="X",D24="x")),IF(OR(D24="X",D24="x",AND(OR(COUNTA(B24,C24,E24,F24)>0,OR(D24="X",D24="x")),(LEN(SUBSTITUTE(SUBSTITUTE(SUBSTITUTE(B24," ",""),"0",""),"-",""))+LEN(SUBSTITUTE(SUBSTITUTE(SUBSTITUTE(C24," ",""),"0",""),"-","")))=(LEN(SUBSTITUTE(SUBSTITUTE(SUBSTITUTE(E24," ",""),"0",""),"-",""))+LEN(SUBSTITUTE(SUBSTITUTE(SUBSTITUTE(F24," ",""),"0",""),"-",""))))),1,0),0)+IF(OR(COUNTA(B28,C28,E28,F28)>0,OR(D28="X",D28="x")),IF(OR(D28="X",D28="x",AND(OR(COUNTA(B28,C28,E28,F28)>0,OR(D28="X",D28="x")),(LEN(SUBSTITUTE(SUBSTITUTE(SUBSTITUTE(B28," ",""),"0",""),"-",""))+LEN(SUBSTITUTE(SUBSTITUTE(SUBSTITUTE(C28," ",""),"0",""),"-","")))=(LEN(SUBSTITUTE(SUBSTITUTE(SUBSTITUTE(E28," ",""),"0",""),"-",""))+LEN(SUBSTITUTE(SUBSTITUTE(SUBSTITUTE(F28," ",""),"0",""),"-",""))))),1,0),0) | E36: =LEN(SUBSTITUTE(SUBSTITUTE(SUBSTITUTE(E5," ",""),"0",""),"-",""))+LEN(SUBSTITUTE(SUBSTITUTE(SUBSTITUTE(F5," ",""),"0",""),"-",""))+LEN(SUBSTITUTE(SUBSTITUTE(SUBSTITUTE(E6," ",""),"0",""),"-",""))+LEN(SUBSTITUTE(SUBSTITUTE(SUBSTITUTE(F6," ",""),"0",""),"-",""))+LEN(SUBSTITUTE(SUBSTITUTE(SUBSTITUTE(B11," ",""),"0",""),"-",""))+LEN(SUBSTITUTE(SUBSTITUTE(SUBSTITUTE(C11," ",""),"0",""),"-",""))+LEN(SUBSTITUTE(SUBSTITUTE(SUBSTITUTE(E13," ",""),"0",""),"-",""))+LEN(SUBSTITUTE(SUBSTITUTE(SUBSTITUTE(F13," ",""),"0",""),"-",""))+LEN(SUBSTITUTE(SUBSTITUTE(SUBSTITUTE(E19," ",""),"0",""),"-",""))+LEN(SUBSTITUTE(SUBSTITUTE(SUBSTITUTE(F19," ",""),"0",""),"-",""))+LEN(SUBSTITUTE(SUBSTITUTE(SUBSTITUTE(E24," ",""),"0",""),"-",""))+LEN(SUBSTITUTE(SUBSTITUTE(SUBSTITUTE(F24," ",""),"0",""),"-",""))+LEN(SUBSTITUTE(SUBSTITUTE(SUBSTITUTE(E28," ",""),"0",""),"-",""))+LEN(SUBSTITUTE(SUBSTITUTE(SUBSTITUTE(F28," ",""),"0",""),"-","")) | F36: =LEN(SUBSTITUTE(SUBSTITUTE(SUBSTITUTE(B5," ",""),"0",""),"-",""))+LEN(SUBSTITUTE(SUBSTITUTE(SUBSTITUTE(C5," ",""),"0",""),"-",""))+LEN(SUBSTITUTE(SUBSTITUTE(SUBSTITUTE(B6," ",""),"0",""),"-",""))+LEN(SUBSTITUTE(SUBSTITUTE(SUBSTITUTE(C6," ",""),"0",""),"-",""))+LEN(SUBSTITUTE(SUBSTITUTE(SUBSTITUTE(E11," ",""),"0",""),"-",""))+LEN(SUBSTITUTE(SUBSTITUTE(SUBSTITUTE(F11," ",""),"0",""),"-",""))+LEN(SUBSTITUTE(SUBSTITUTE(SUBSTITUTE(B13," ",""),"0",""),"-",""))+LEN(SUBSTITUTE(SUBSTITUTE(SUBSTITUTE(C13," ",""),"0",""),"-",""))+LEN(SUBSTITUTE(SUBSTITUTE(SUBSTITUTE(B19," ",""),"0",""),"-",""))+LEN(SUBSTITUTE(SUBSTITUTE(SUBSTITUTE(C19," ",""),"0",""),"-",""))+LEN(SUBSTITUTE(SUBSTITUTE(SUBSTITUTE(B24," ",""),"0",""),"-",""))+LEN(SUBSTITUTE(SUBSTITUTE(SUBSTITUTE(C24," ",""),"0",""),"-",""))+LEN(SUBSTITUTE(SUBSTITUTE(SUBSTITUTE(B28," ",""),"0",""),"-",""))+LEN(SUBSTITUTE(SUBSTITUTE(SUBSTITUTE(C28," ",""),"0",""),"-","")) | G36: =RANK(U36,$U$34:$U$41)+COUNTIF($U$33:U35,U36) | U36: =(B36*1000000)-(C36*10000)+(D36*100)+(E36*1)-(F36*0.01)
