Workbook

Sheet data
A1: Title prefix:
A2: Pool | B2: Player Name | C2: Player Dojo | D2: Display Name | E2: Player Number | F2: Metadata
A3: Pool A | B3: Cersei Lannister | C3: Team Gamma | D3: LANNISTER | E3: K1
A4: Pool A | B4: Hermione Granger | C4: Team Theta | D4: GRANGER | E4: K2
A5: Pool A | B5: Moby Dick | C5: Team Nu | D5: DICK | E5: K3
A6: Pool A | B6: Quirinus Quirrell | C6: Team Rho | D6: QUIRRELL | E6: K4
A7: Pool A | B7: Voldemort | C7: Team Chi | D7: VOLDEMORT | E7: K5
A8: Pool B | B8: Gandalf The Grey | C8: Team Eta | D8: GANDALF | E8: K6
A9: Pool B | B9: Jon Snow | C9: Team Kappa | D9: SNOW | E9: K7
A10: Pool B | B10: Neville Longbottom | C10: Team Xi | D10: LONGBOTTOM | E10: K8
A11: Pool B | B11: Samwise Gamgee | C11: Team Tau | D11: GAMGEE | E11: K9
A12: Pool B | B12: Xaro Xhoan Daxos | C12: Team Omega | D12: DAXOS | E12: K10
A13: Pool C | B13: Eddard Stark | C13: Team Epsilon | D13: STARK | E13: K11
A14: Pool C | B14: Katniss Everdeen | C14: Team Mu | D14: EVERDEEN | E14: K12
... A26: Pool E | B26: Ygritte | C26: Team Alpha | D26: YGRITTE | E26: K24

Sheet Time Estimator
A1: Number of pools | B1: Team size | C1: Matches per pool | D1: Time per match | E1: Total time for matches | F1: Padding time for rotation | G1: Time for breaks | H1: Total Time
A2: 5 | B2: 1 | C2: 24 | D2: 0.0020833333 | E2: =(A2*B2*C2*D2) | F2: 0.00034722222 | G2: 0.020833333 | H2: =C2*I2+J2
A3: 0 | B3: 0 | C3: 0 | D3: 0.0020833333 | E3: =(A3*B3*C3*D3) | F3: 0.00034722222 | G3: 0.020833333 | H3: =E3+(A3*C3*F3)+G3
A7: Number of Elimination Matches | B7: Team size | D7: Time per match | E7: Total time for matches | F7: Padding time for rotation | G7: Time for breaks | H7: Total Time
A8: 4 | B8: 1 | D8: 0.0027777778 | E8: =(A8*B8*D8) | F8: 0.00034722222 | G8: 0.020833333 | H8: =E8+(A8*F8)+G8
E13: Tournament Summary
A14: 2 | E14: Total Pool Time | H14: =H2
E15: Total Elimination Time | H15: =H8
E16: Grand Total (Sequential) | H16: =H14+H15
E17: Grand Total (Parallel across Courts) | H17: =H16/A14
E18: Start Time: | H18: 0.375
E19: Estimated Finish Time | H19: =H18+H17

Sheet Pool Draw
B2: =IF(data!$B$1="","Tournament Pools",data!$B$1&" - Tournament Pools")
B5: ='data'!$A$7 | D5: ='data'!$A$16 | F5: ='data'!$A$26
B6: =data!$E$3&" "&data!$B$3 | D6: =data!$E$13&" "&data!$B$13 | F6: =data!$E$22&" "&data!$B$22
B7: =data!$E$4&" "&data!$B$4 | D7: =data!$E$14&" "&data!$B$14 | F7: =data!$E$23&" "&data!$B$23
B8: =data!$E$5&" "&data!$B$5 | D8: =data!$E$15&" "&data!$B$15 | F8: =data!$E$24&" "&data!$B$24
B9: =data!$E$6&" "&data!$B$6 | D9: =data!$E$16&" "&data!$B$16 | F9: =data!$E$25&" "&data!$B$25
B10: =data!$E$7&" "&data!$B$7 | F10: =data!$E$26&" "&data!$B$26
D12: ='data'!$A$21
B13: ='data'!$A$12 | D13: =data!$E$17&" "&data!$B$17
B14: =data!$E$8&" "&data!$B$8 | D14: =data!$E$18&" "&data!$B$18
B15: =data!$E$9&" "&data!$B$9 | D15: =data!$E$19&" "&data!$B$19
B16: =data!$E$10&" "&data!$B$10 | D16: =data!$E$20&" "&data!$B$20
B17: =data!$E$11&" "&data!$B$11 | D17: =data!$E$21&" "&data!$B$21
B18: =data!$E$12&" "&data!$B$12

Sheet Pool Matches
A1: Shiaijo A | I1: Shiaijo B
A2: ='data'!$A$7 | I2: ='data'!$A$21
A3: White | D3: vs | G3: Red | I3: White | L3: vs | O3: Red
A4: =data!$E$4&" "&data!$B$4 | G4: =data!$E$3&" "&data!$B$3 | I4: =data!$E$18&" "&data!$B$18 | O4: =data!$E$17&" "&data!$B$17
A5: =data!$E$4&" "&data!$B$4 | G5: =data!$E$5&" "&data!$B$5 | I5: =data!$E$18&" "&data!$B$18 | O5: =data!$E$19&" "&data!$B$19
A6: =data!$E$6&" "&data!$B$6 | G6: =data!$E$5&" "&data!$B$5 | I6: =data!$E$20&" "&data!$B$20 | O6: =data!$E$19&" "&data!$B$19
A7: =data!$E$6&" "&data!$B$6 | G7: =data!$E$7&" "&data!$B$7 | I7: =data!$E$20&" "&data!$B$20 | O7: =data!$E$21&" "&data!$B$21
A8: =data!$E$3&" "&data!$B$3 | G8: =data!$E$7&" "&data!$B$7 | I8: =data!$E$17&" "&data!$B$17 | O8: =data!$E$21&" "&data!$B$21
A10: Results | B10: W | C10: L | D10: T | E10: PW | F10: PL | G10: Rank | I10: Results | J10: W | K10: L | L10: T | M10: PW | N10: PL | O10: Rank
A11: =data!$E$3&" "&data!$B$3 | B11: =IF(OR(COUNTA(B4,C4,E4,F4)>0,OR(D4="X",D4="x")),IF(OR(D4="X",D4="x",AND(OR(COUNTA(B4,C4,E4,F4)>0,OR(D4="X",D4="x")),(LEN(SUBSTITUTE(SUBSTITUTE(SUBSTITUTE(B4," ",""),"0",""),"-",""))+LEN(SUBSTITUTE(SUBSTITUTE(SUBSTITUTE(C4," ",""),"0",""),"-","")))=(LEN(SUBSTITUTE(SUBSTITUTE(SUBSTITUTE(E4," ",""),"0",""),"-",""))+LEN(SUBSTITUTE(SUBSTITUTE(SUBSTITUTE(F4," ",""),"0",""),"-",""))))),0,(LEN(SUBSTITUTE(SUBSTITUTE(SUBSTITUTE(E4," ",""),"0",""),"-",""))+LEN(SUBSTITUTE(SUBSTITUTE(SUBSTITUTE(F4," ",""),"0",""),"-",""))>LEN(SUBSTITUTE(SUBSTITUTE(SUBSTITUTE(B4," ",""),"0",""),"-",""))+LEN(SUBSTITUTE(SUBSTITUTE(SUBSTITUTE(C4," ",""),"0",""),"-","")))*1),0)+IF(OR(COUNTA(B8,C8,E8,F8)>0,OR(D8="X",D8="x")),IF(OR(D8="X",D8="x",AND(OR(COUNTA(B8,C8,E8,F8)>0,OR(D8="X",D8="x")),(LEN(SUBSTITUTE(SUBSTITUTE(SUBSTITUTE(B8," ",""),"0",""),"-",""))+LEN(SUBSTITUTE(SUBSTITUTE(SUBSTITUTE(C8," ",""),"0",""),"-","")))=(LEN(SUBSTITUTE(SUBSTITUTE(SUBSTITUTE(E8," ",""),"0",""),"-",""))+LEN(SUBSTITUTE(SUBSTITUTE(SUBSTITUTE(F8," ",""),"0",""),"-",""))))),0,(LEN(SUBSTITUTE(SUBSTITUTE(SUBSTITUTE(B8," ",""),"0",""),"-",""))+LEN(SUBSTITUTE(SUBSTITUTE(SUBSTITUTE(C8," ",""),"0",""),"-",""))>LEN(SUBSTITUTE(SUBSTITUTE(SUBSTITUTE(E8," ",""),"0",""),"-",""))+LEN(SUBSTITUTE(SUBSTITUTE(SUBSTITUTE(F8," ",""),"0",""),"-","")))*1),0) | C11: =IF(OR(COUNTA(B4,C4,E4,F4)>0,OR(D4="X",D4="x")),IF(OR(D4="X",D4="x",AND(OR(COUNTA(B4,C4,E4,F4)>0,OR(D4="X",D4="x")),(LEN(SUBSTITUTE(SUBSTITUTE(SUBSTITUTE(B4," ",""),"0",""),"-",""))+LEN(SUBSTITUTE(SUBSTITUTE(SUBSTITUTE(C4," ",""),"0",""),"-","")))=(LEN(SUBSTITUTE(SUBSTITUTE(SUBSTITUTE(E4," ",""),"0",""),"-",""))+LEN(SUBSTITUTE(SUBSTITUTE(SUBSTITUTE(F4," ",""),"0",""),"-",""))))),0,(LEN(SUBSTITUTE(SUBSTITUTE(SUBSTITUTE(E4," ",""),"0",""),"-",""))+LEN(SUBSTITUTE(SUBSTITUTE(SUBSTITUTE(F4," ",""),"0",""),"-",""))<LEN(SUBSTITUTE(SUBSTITUTE(SUBSTITUTE(B4," ",""),"0",""),"-",""))+LEN(SUBSTITUTE(SUBSTITUTE(SUBSTITUTE(C4," ",""),"0",""),"-","")))*1),0)+IF(OR(COUNTA(B8,C8,E8,F8)>0,OR(D8="X",D8="x")),IF(OR(D8="X",D8="x",AND(OR(COUNTA(B8,C8,E8,F8)>0,OR(D8="X",D8="x")),(LEN(SUBSTITUTE(SUBSTITUTE(SUBSTITUTE(B8," ",""),"0",""),"-",""))+LEN(SUBSTITUTE(SUBSTITUTE(SUBSTITUTE(C8," ",""),"0",""),"-","")))=(LEN(SUBSTITUTE(SUBSTITUTE(SUBSTITUTE(E8," ",""),"0",""),"-",""))+LEN(SUBSTITUTE(SUBSTITUTE(SUBSTITUTE(F8," ",""),"0",""),"-",""))))),0,(LEN(SUBSTITUTE(SUBSTITUTE(SUBSTITUTE(B8," ",""),"0",""),"-",""))+LEN(SUBSTITUTE(SUBSTITUTE(SUBSTITUTE(C8," ",""),"0",""),"-",""))<LEN(SUBSTITUTE(SUBSTITUTE(SUBSTITUTE(E8," ",""),"0",""),"-",""))+LEN(SUBSTITUTE(SUBSTITUTE(SUBSTITUTE(F8," ",""),"0",""),"-","")))*1),0) | D11: =IF(OR(COUNTA(B4,C4,E4,F4)>0,OR(D4="X",D4="x")),IF(OR(D4="X",D4="x",AND(OR(COUNTA(B4,C4,E4,F4)>0,OR(D4="X",D4="x")),(LEN(SUBSTITUTE(SUBSTITUTE(SUBSTITUTE(B4," ",""),"0",""),"-",""))+LEN(SUBSTITUTE(SUBSTITUTE(SUBSTITUTE(C4," ",""),"0",""),"-","")))=(LEN(SUBSTITUTE(SUBSTITUTE(SUBSTITUTE(E4," ",""),"0",""),"-",""))+LEN(SUBSTITUTE(SUBSTITUTE(SUBSTITUTE(F4," ",""),"0",""),"-",""))))),1,0),0)+IF(OR(COUNTA(B8,C8,E8,F8)>0,OR(D8="X",D8="x")),IF(OR(D8="X",D8="x",AND(OR(COUNTA(B8,C8,E8,F8)>0,OR(D8="X",D8="x")),(LEN(SUBSTITUTE(SUBSTITUTE(SUBSTITUTE(B8," ",""),"0",""),"-",""))+LEN(SUBSTITUTE(SUBSTITUTE(SUBSTITUTE(C8," ",""),"0",""),"-","")))=(LEN(SUBSTITUTE(SUBSTITUTE(SUBSTITUTE(E8," ",""),"0",""),"-",""))+LEN(SUBSTITUTE(SUBSTITUTE(SUBSTITUTE(F8," ",""),"0",""),"-",""))))),1,0),0) | E11: =LEN(SUBSTITUTE(SUBSTITUTE(SUBSTITUTE(E4," ",""),"0",""),"-",""))+LEN(SUBSTITUTE(SUBSTITUTE(SUBSTITUTE(F4," ",""),"0",""),"-",""))+LEN(SUBSTITUTE(SUBSTITUTE(SUBSTITUTE(B8," ",""),"0",""),"-",""))+LEN(SUBSTITUTE(SUBSTITUTE(SUBSTITUTE(C8," ",""),"0",""),"-","")) | F11: =LEN(SUBSTITUTE(SUBSTITUTE(SUBSTITUTE(B4," ",""),"0",""),"-",""))+LEN(SUBSTITUTE(SUBSTITUTE(SUBSTITUTE(C4," ",""),"0",""),"-",""))+LEN(SUBSTITUTE(SUBSTITUTE(SUBSTITUTE(E8," ",""),"0",""),"-",""))+LEN(SUBSTITUTE(SUBSTITUTE(SUBSTITUTE(F8," ",""),"0",""),"-","")) | G11: =RANK(U11,$U$11:$U$15)+COUNTIF($U$10:U10,U11) | I11: =data!$E$17&" "&data!$B$17 | J11: =IF(OR(COUNTA(J4,K4,M4,N4)>0,OR(L4="X",L4="x")),IF(OR(L4="X",L4="x",AND(OR(COUNTA(J4,K4,M4,N4)>0,OR(L4="X",L4="x")),(LEN(SUBSTITUTE(SUBSTITUTE(SUBSTITUTE(J4," ",""),"0",""),"-",""))+LEN(SUBSTITUTE(SUBSTITUTE(SUBSTITUTE(K4," ",""),"0",""),"-","")))=(LEN(SUBSTITUTE(SUBSTITUTE(SUBSTITUTE(M4," ",""),"0",""),"-",""))+LEN(SUBSTITUTE(SUBSTITUTE(SUBSTITUTE(N4," ",""),"0",""),"-",""))))),0,(LEN(SUBSTITUTE(SUBSTITUTE(SUBSTITUTE(M4," ",""),"0",""),"-",""))+LEN(SUBSTITUTE(SUBSTITUTE(SUBSTITUTE(N4," ",""),"0",""),"-",""))>LEN(SUBSTITUTE(SUBSTITUTE(SUBSTITUTE(J4," ",""),"0",""),"-",""))+LEN(SUBSTITUTE(SUBSTITUTE(SUBSTITUTE(K4," ",""),"0",""),"-","")))*1),0)+IF(OR(COUNTA(J8,K8,M8,N8)>0,OR(L8="X",L8="x")),IF(OR(L8="X",L8="x",AND(OR(COUNTA(J8,K8,M8,N8)>0,OR(L8="X",L8="x")),(LEN(SUBSTITUTE(SUBSTITUTE(SUBSTITUTE(J8," ",""),"0",""),"-",""))+LEN(SUBSTITUTE(SUBSTITUTE(SUBSTITUTE(K8," ",""),"0",""),"-","")))=(LEN(SUBSTITUTE(SUBSTITUTE(SUBSTITUTE(M8," ",""),"0",""),"-",""))+LEN(SUBSTITUTE(SUBSTITUTE(SUBSTITUTE(N8," ",""),"0",""),"-",""))))),0,(LEN(SUBSTITUTE(SUBSTITUTE(SUBSTITUTE(J8," ",""),"0",""),"-",""))+LEN(SUBSTITUTE(SUBSTITUTE(SUBSTITUTE(K8," ",""),"0",""),"-",""))>LEN(SUBSTITUTE(SUBSTITUTE(SUBSTITUTE(M8," ",""),"0",""),"-",""))+LEN(SUBSTITUTE(SUBSTITUTE(SUBSTITUTE(N8," ",""),"0",""),"-","")))*1),0) | K11: =IF(OR(COUNTA(J4,K4,M4,N4)>0,OR(L4="X",L4="x")),IF(OR(L4="X",L4="x",AND(OR(COUNTA(J4,K4,M4,N4)>0,OR(L4="X",L4="x")),(LEN(SUBSTITUTE(SUBSTITUTE(SUBSTITUTE(J4," ",""),"0",""),"-",""))+LEN(SUBSTITUTE(SUBSTITUTE(SUBSTITUTE(K4," ",""),"0",""),"-","")))=(LEN(SUBSTITUTE(SUBSTITUTE(SUBSTITUTE(M4," ",""),"0",""),"-",""))+LEN(SUBSTITUTE(SUBSTITUTE(SUBSTITUTE(N4," ",""),"0",""),"-",""))))),0,(LEN(SUBSTITUTE(SUBSTITUTE(SUBSTITUTE(M4," ",""),"0",""),"-",""))+LEN(SUBSTITUTE(SUBSTITUTE(SUBSTITUTE(N4," ",""),"0",""),"-",""))<LEN(SUBSTITUTE(SUBSTITUTE(SUBSTITUTE(J4," ",""),"0",""),"-",""))+LEN(SUBSTITUTE(SUBSTITUTE(SUBSTITUTE(K4," ",""),"0",""),"-","")))*1),0)+IF(OR(COUNTA(J8,K8,M8,N8)>0,OR(L8="X",L8="x")),IF(OR(L8="X",L8="x",AND(OR(COUNTA(J8,K8,M8,N8)>0,OR(L8="X",L8="x")),(LEN(SUBSTITUTE(SUBSTITUTE(SUBSTITUTE(J8," ",""),"0",""),"-",""))+LEN(SUBSTITUTE(SUBSTITUTE(SUBSTITUTE(K8," ",""),"0",""),"-","")))=(LEN(SUBSTITUTE(SUBSTITUTE(SUBSTITUTE(M8," ",""),"0",""),"-",""))+LEN(SUBSTITUTE(SUBSTITUTE(SUBSTITUTE(N8," ",""),"0",""),"-",""))))),0,(LEN(SUBSTITUTE(SUBSTITUTE(SUBSTITUTE(J8," ",""),"0",""),"-",""))+LEN(SUBSTITUTE(SUBSTITUTE(SUBSTITUTE(K8," ",""),"0",""),"-",""))<LEN(SUBSTITUTE(SUBSTITUTE(SUBSTITUTE(M8," ",""),"0",""),"-",""))+LEN(SUBSTITUTE(SUBSTITUTE(SUBSTITUTE(N8," ",""),"0",""),"-","")))*1),0) | L11: =IF(OR(COUNTA(J4,K4,M4,N4)>0,OR(L4="X",L4="x")),IF(OR(L4="X",L4="x",AND(OR(COUNTA(J4,K4,M4,N4)>0,OR(L4="X",L4="x")),(LEN(SUBSTITUTE(SUBSTITUTE(SUBSTITUTE(J4," ",""),"0",""),"-",""))+LEN(SUBSTITUTE(SUBSTITUTE(SUBSTITUTE(K4," ",""),"0",""),"-","")))=(LEN(SUBSTITUTE(SUBSTITUTE(SUBSTITUTE(M4," ",""),"0",""),"-",""))+LEN(SUBSTITUTE(SUBSTITUTE(SUBSTITUTE(N4," ",""),"0",""),"-",""))))),1,0),0)+IF(OR(COUNTA(J8,K8,M8,N8)>0,OR(L8="X",L8="x")),IF(OR(L8="X",L8="x",AND(OR(COUNTA(J8,K8,M8,N8)>0,OR(L8="X",L8="x")),(LEN(SUBSTITUTE(SUBSTITUTE(SUBSTITUTE(J8," ",""),"0",""),"-",""))+LEN(SUBSTITUTE(SUBSTITUTE(SUBSTITUTE(K8," ",""),"0",""),"-","")))=(LEN(SUBSTITUTE(SUBSTITUTE(SUBSTITUTE(M8," ",""),"0",""),"-",""))+LEN(SUBSTITUTE(SUBSTITUTE(SUBSTITUTE(N8," ",""),"0",""),"-",""))))),1,0),0) | M11: =LEN(SUBSTITUTE(SUBSTITUTE(SUBSTITUTE(M4," ",""),"0",""),"-",""))+LEN(SUBSTITUTE(SUBSTITUTE(SUBSTITUTE(N4," ",""),"0",""),"-",""))+LEN(SUBSTITUTE(SUBSTITUTE(SUBSTITUTE(J8," ",""),"0",""),"-",""))+LEN(SUBSTITUTE(SUBSTITUTE(SUBSTITUTE(K8," ",""),"0",""),"-","")) | N11: =LEN(SUBSTITUTE(SUBSTITUTE(SUBSTITUTE(J4," ",""),"0",""),"-",""))+LEN(SUBSTITUTE(SUBSTITUTE(SUBSTITUTE(K4," ",""),"0",""),"-",""))+LEN(SUBSTITUTE(SUBSTITUTE(SUBSTITUTE(M8," ",""),"0",""),"-",""))+LEN(SUBSTITUTE(SUBSTITUTE(SUBSTITUTE(N8," ",""),"0",""),"-","")) | O11: =RANK(AC11,$AC$11:$AC$15)+COUNTIF($AC$10:AC10,AC11) | U11: =(B11*1000000)-(C11*10000)+(D11*100)+(E11*1)-(F11*0.01) | AC11: =(J11*1000000)-(K11*10000)+(L11*100)+(M11*1)-(N11*0.01)
A12: =data!$E$4&" "&data!$B$4 | B12: =IF(OR(COUNTA(B4,C4,E4,F4)>0,OR(D4="X",D4="x")),IF(OR(D4="X",D4="x",AND(OR(COUNTA(B4,C4,E4,F4)>0,OR(D4="X",D4="x")),(LEN(SUBSTITUTE(SUBSTITUTE(SUBSTITUTE(B4," ",""),"0",""),"-",""))+LEN(SUBSTITUTE(SUBSTITUTE(SUBSTITUTE(C4," ",""),"0",""),"-","")))=(LEN(SUBSTITUTE(SUBSTITUTE(SUBSTITUTE(E4," ",""),"0",""),"-",""))+LEN(SUBSTITUTE(SUBSTITUTE(SUBSTITUTE(F4," ",""),"0",""),"-",""))))),0,(LEN(SUBSTITUTE(SUBSTITUTE(SUBSTITUTE(B4," ",""),"0",""),"-",""))+LEN(SUBSTITUTE(SUBSTITUTE(SUBSTITUTE(C4," ",""),"0",""),"-",""))>LEN(SUBSTITUTE(SUBSTITUTE(SUBSTITUTE(E4," ",""),"0",""),"-",""))+LEN(SUBSTITUTE(SUBSTITUTE(SUBSTITUTE(F4," ",""),"0",""),"-","")))*1),0)+IF(OR(COUNTA(B5,C5,E5,F5)>0,OR(D5="X",D5="x")),IF(OR(D5="X",D5="x",AND(OR(COUNTA(B5,C5,E5,F5)>0,OR(D5="X",D5="x")),(LEN(SUBSTITUTE(SUBSTITUTE(SUBSTITUTE(B5," ",""),"0",""),"-",""))+LEN(SUBSTITUTE(SUBSTITUTE(SUBSTITUTE(C5," ",""),"0",""),"-","")))=(LEN(SUBSTITUTE(SUBSTITUTE(SUBSTITUTE(E5," ",""),"0",""),"-",""))+LEN(SUBSTITUTE(SUBSTITUTE(SUBSTITUTE(F5," ",""),"0",""),"-",""))))),0,(LEN(SUBSTITUTE(SUBSTITUTE(SUBSTITUTE(B5," ",""),"0",""),"-",""))+LEN(SUBSTITUTE(SUBSTITUTE(SUBSTITUTE(C5," ",""),"0",""),"-",""))>LEN(SUBSTITUTE(SUBSTITUTE(SUBSTITUTE(E5," ",""),"0",""),"-",""))+LEN(SUBSTITUTE(SUBSTITUTE(SUBSTITUTE(F5," ",""),"0",""),"-","")))*1),0) | C12: =IF(OR(COUNTA(B4,C4,E4,F4)>0,OR(D4="X",D4="x")),IF(OR(D4="X",D4="x",AND(OR(COUNTA(B4,C4,E4,F4)>0,OR(D4="X",D4="x")),(LEN(SUBSTITUTE(SUBSTITUTE(SUBSTITUTE(B4," ",""),"0",""),"-",""))+LEN(SUBSTITUTE(SUBSTITUTE(SUBSTITUTE(C4," ",""),"0",""),"-","")))=(LEN(SUBSTITUTE(SUBSTITUTE(SUBSTITUTE(E4," ",""),"0",""),"-",""))+LEN(SUBSTITUTE(SUBSTITUTE(SUBSTITUTE(F4," ",""),"0",""),"-",""))))),0,(LEN(SUBSTITUTE(SUBSTITUTE(SUBSTITUTE(B4," ",""),"0",""),"-",""))+LEN(SUBSTITUTE(SUBSTITUTE(SUBSTITUTE(C4," ",""),"0",""),"-",""))<LEN(SUBSTITUTE(SUBSTITUTE(SUBSTITUTE(E4," ",""),"0",""),"-",""))+LEN(SUBSTITUTE(SUBSTITUTE(SUBSTITUTE(F4," ",""),"0",""),"-","")))*1),0)+IF(OR(COUNTA(B5,C5,E5,F5)>0,OR(D5="X",D5="x")),IF(OR(D5="X",D5="x",AND(OR(COUNTA(B5,C5,E5,F5)>0,OR(D5="X",D5="x")),(LEN(SUBSTITUTE(SUBSTITUTE(SUBSTITUTE(B5," ",""),"0",""),"-",""))+LEN(SUBSTITUTE(SUBSTITUTE(SUBSTITUTE(C5," ",""),"0",""),"-","")))=(LEN(SUBSTITUTE(SUBSTITUTE(SUBSTITUTE(E5," ",""),"0",""),"-",""))+LEN(SUBSTITUTE(SUBSTITUTE(SUBSTITUTE(F5," ",""),"0",""),"-",""))))),0,(LEN(SUBSTITUTE(SUBSTITUTE(SUBSTITUTE(B5," ",""),"0",""),"-",""))+LEN(SUBSTITUTE(SUBSTITUTE(SUBSTITUTE(C5," ",""),"0",""),"-",""))<LEN(SUBSTITUTE(SUBSTITUTE(SUBSTITUTE(E5," ",""),"0",""),"-",""))+LEN(SUBSTITUTE(SUBSTITUTE(SUBSTITUTE(F5," ",""),"0",""),"-","")))*1),0) | D12: =IF(OR(COUNTA(B4,C4,E4,F4)>0,OR(D4="X",D4="x")),IF(OR(D4="X",D4="x",AND(OR(COUNTA(B4,C4,E4,F4)>0,OR(D4="X",D4="x")),(LEN(SUBSTITUTE(SUBSTITUTE(SUBSTITUTE(B4," ",""),"0",""),"-",""))+LEN(SUBSTITUTE(SUBSTITUTE(SUBSTITUTE(C4," ",""),"0",""),"-","")))=(LEN(SUBSTITUTE(SUBSTITUTE(SUBSTITUTE(E4," ",""),"0",""),"-",""))+LEN(SUBSTITUTE(SUBSTITUTE(SUBSTITUTE(F4," ",""),"0",""),"-",""))))),1,0),0)+IF(OR(COUNTA(B5,C5,E5,F5)>0,OR(D5="X",D5="x")),IF(OR(D5="X",D5="x",AND(OR(COUNTA(B5,C5,E5,F5)>0,OR(D5="X",D5="x")),(LEN(SUBSTITUTE(SUBSTITUTE(SUBSTITUTE(B5," ",""),"0",""),"-",""))+LEN(SUBSTITUTE(SUBSTITUTE(SUBSTITUTE(C5," ",""),"0",""),"-","")))=(LEN(SUBSTITUTE(SUBSTITUTE(SUBSTITUTE(E5," ",""),"0",""),"-",""))+LEN(SUBSTITUTE(SUBSTITUTE(SUBSTITUTE(F5," ",""),"0",""),"-",""))))),1,0),0) | E12: =LEN(SUBSTITUTE(SUBSTITUTE(SUBSTITUTE(B4," ",""),"0",""),"-",""))+LEN(SUBSTITUTE(SUBSTITUTE(SUBSTITUTE(C4," ",""),"0",""),"-",""))+LEN(SUBSTITUTE(SUBSTITUTE(SUBSTITUTE(B5," ",""),"0",""),"-",""))+LEN(SUBSTITUTE(SUBSTITUTE(SUBSTITUTE(C5," ",""),"0",""),"-","")) | F12: =LEN(SUBSTITUTE(SUBSTITUTE(SUBSTITUTE(E4," ",""),"0",""),"-",""))+LEN(SUBSTITUTE(SUBSTITUTE(SUBSTITUTE(F4," ",""),"0",""),"-",""))+LEN(SUBSTITUTE(SUBSTITUTE(SUBSTITUTE(E5," ",""),"0",""),"-",""))+LEN(SUBSTITUTE(SUBSTITUTE(SUBSTITUTE(F5," ",""),"0",""),"-","")) | G12: =RANK(U12,$U$11:$U$15)+COUNTIF($U$10:U11,U12) | I12: =data!$E$18&" "&data!$B$18 | J12: =IF(OR(COUNTA(J4,K4,M4,N4)>0,OR(L4="X",L4="x")),IF(OR(L4="X",L4="x",AND(OR(COUNTA(J4,K4,M4,N4)>0,OR(L4="X",L4="x")),(LEN(SUBSTITUTE(SUBSTITUTE(SUBSTITUTE(J4," ",""),"0",""),"-",""))+LEN(SUBSTITUTE(SUBSTITUTE(SUBSTITUTE(K4," ",""),"0",""),"-","")))=(LEN(SUBSTITUTE(SUBSTITUTE(SUBSTITUTE(M4," ",""),"0",""),"-",""))+LEN(SUBSTITUTE(SUBSTITUTE(SUBSTITUTE(N4," ",""),"0",""),"-",""))))),0,(LEN(SUBSTITUTE(SUBSTITUTE(SUBSTITUTE(J4," ",""),"0",""),"-",""))+LEN(SUBSTITUTE(SUBSTITUTE(SUBSTITUTE(K4," ",""),"0",""),"-",""))>LEN(SUBSTITUTE(SUBSTITUTE(SUBSTITUTE(M4," ",""),"0",""),"-",""))+LEN(SUBSTITUTE(SUBSTITUTE(SUBSTITUTE(N4," ",""),"0",""),"-","")))*1),0)+IF(OR(COUNTA(J5,K5,M5,N5)>0,OR(L5="X",L5="x")),IF(OR(L5="X",L5="x",AND(OR(COUNTA(J5,K5,M5,N5)>0,OR(L5="X",L5="x")),(LEN(SUBSTITUTE(SUBSTITUTE(SUBSTITUTE(J5," ",""),"0",""),"-",""))+LEN(SUBSTITUTE(SUBSTITUTE(SUBSTITUTE(K5," ",""),"0",""),"-","")))=(LEN(SUBSTITUTE(SUBSTITUTE(SUBSTITUTE(M5," ",""),"0",""),"-",""))+LEN(SUBSTITUTE(SUBSTITUTE(SUBSTITUTE(N5," ",""),"0",""),"-",""))))),0,(LEN(SUBSTITUTE(SUBSTITUTE(SUBSTITUTE(J5," ",""),"0",""),"-",""))+LEN(SUBSTITUTE(SUBSTITUTE(SUBSTITUTE(K5," ",""),"0",""),"-",""))>LEN(SUBSTITUTE(SUBSTITUTE(SUBSTITUTE(M5," ",""),"0",""),"-",""))+LEN(SUBSTITUTE(SUBSTITUTE(SUBSTITUTE(N5," ",""),"0",""),"-","")))*1),0) | K12: =IF(OR(COUNTA(J4,K4,M4,N4)>0,OR(L4="X",L4="x")),IF(OR(L4="X",L4="x",AND(OR(COUNTA(J4,K4,M4,N4)>0,OR(L4="X",L4="x")),(LEN(SUBSTITUTE(SUBSTITUTE(SUBSTITUTE(J4," ",""),"0",""),"-",""))+LEN(SUBSTITUTE(SUBSTITUTE(SUBSTITUTE(K4," ",""),"0",""),"-","")))=(LEN(SUBSTITUTE(SUBSTITUTE(SUBSTITUTE(M4," ",""),"0",""),"-",""))+LEN(SUBSTITUTE(SUBSTITUTE(SUBSTITUTE(N4," ",""),"0",""),"-",""))))),0,(LEN(SUBSTITUTE(SUBSTITUTE(SUBSTITUTE(J4," ",""),"0",""),"-",""))+LEN(SUBSTITUTE(SUBSTITUTE(SUBSTITUTE(K4," ",""),"0",""),"-",""))<LEN(SUBSTITUTE(SUBSTITUTE(SUBSTITUTE(M4," ",""),"0",""),"-",""))+LEN(SUBSTITUTE(SUBSTITUTE(SUBSTITUTE(N4," ",""),"0",""),"-","")))*1),0)+IF(OR(COUNTA(J5,K5,M5,N5)>0,OR(L5="X",L5="x")),IF(OR(L5="X",L5="x",AND(OR(COUNTA(J5,K5,M5,N5)>0,OR(L5="X",L5="x")),(LEN(SUBSTITUTE(SUBSTITUTE(SUBSTITUTE(J5," ",""),"0",""),"-",""))+LEN(SUBSTITUTE(SUBSTITUTE(SUBSTITUTE(K5," ",""),"0",""),"-","")))=(LEN(SUBSTITUTE(SUBSTITUTE(SUBSTITUTE(M5," ",""),"0",""),"-",""))+LEN(SUBSTITUTE(SUBSTITUTE(SUBSTITUTE(N5," ",""),"0",""),"-",""))))),0,(LEN(SUBSTITUTE(SUBSTITUTE(SUBSTITUTE(J5," ",""),"0",""),"-",""))+LEN(SUBSTITUTE(SUBSTITUTE(SUBSTITUTE(K5," ",""),"0",""),"-",""))<LEN(SUBSTITUTE(SUBSTITUTE(SUBSTITUTE(M5," ",""),"0",""),"-",""))+LEN(SUBSTITUTE(SUBSTITUTE(SUBSTITUTE(N5," ",""),"0",""),"-","")))*1),0) | L12: =IF(OR(COUNTA(J4,K4,M4,N4)>0,OR(L4="X",L4="x")),IF(OR(L4="X",L4="x",AND(OR(COUNTA(J4,K4,M4,N4)>0,OR(L4="X",L4="x")),(LEN(SUBSTITUTE(SUBSTITUTE(SUBSTITUTE(J4," ",""),"0",""),"-",""))+LEN(SUBSTITUTE(SUBSTITUTE(SUBSTITUTE(K4," ",""),"0",""),"-","")))=(LEN(SUBSTITUTE(SUBSTITUTE(SUBSTITUTE(M4," ",""),"0",""),"-",""))+LEN(SUBSTITUTE(SUBSTITUTE(SUBSTITUTE(N4," ",""),"0",""),"-",""))))),1,0),0)+IF(OR(COUNTA(J5,K5,M5,N5)>0,OR(L5="X",L5="x")),IF(OR(L5="X",L5="x",AND(OR(COUNTA(J5,K5,M5,N5)>0,OR(L5="X",L5="x")),(LEN(SUBSTITUTE(SUBSTITUTE(SUBSTITUTE(J5," ",""),"0",""),"-",""))+LEN(SUBSTITUTE(SUBSTITUTE(SUBSTITUTE(K5," ",""),"0",""),"-","")))=(LEN(SUBSTITUTE(SUBSTITUTE(SUBSTITUTE(M5," ",""),"0",""),"-",""))+LEN(SUBSTITUTE(SUBSTITUTE(SUBSTITUTE(N5," ",""),"0",""),"-",""))))),1,0),0) | M12: =LEN(SUBSTITUTE(SUBSTITUTE(SUBSTITUTE(J4," ",""),"0",""),"-",""))+LEN(SUBSTITUTE(SUBSTITUTE(SUBSTITUTE(K4," ",""),"0",""),"-",""))+LEN(SUBSTITUTE(SUBSTITUTE(SUBSTITUTE(J5," ",""),"0",""),"-",""))+LEN(SUBSTITUTE(SUBSTITUTE(SUBSTITUTE(K5," ",""),"0",""),"-","")) | N12: =LEN(SUBSTITUTE(SUBSTITUTE(SUBSTITUTE(M4," ",""),"0",""),"-",""))+LEN(SUBSTITUTE(SUBSTITUTE(SUBSTITUTE(N4," ",""),"0",""),"-",""))+LEN(SUBSTITUTE(SUBSTITUTE(SUBSTITUTE(M5," ",""),"0",""),"-",""))+LEN(SUBSTITUTE(SUBSTITUTE(SUBSTITUTE(N5," ",""),"0",""),"-","")) | O12: =RANK(AC12,$AC$11:$AC$15)+COUNTIF($AC$10:AC11,AC12) | U12: =(B12*1000000)-(C12*10000)+(D12*100)+(E12*1)-(F12*0.01) | AC12: =(J12*1000000)-(K12*10000)+(L12*100)+(M12*1)-(N12*0.01)
A13: =data!$E$5&" "&data!$B$5 | B13: =IF(OR(COUNTA(B5,C5,E5,F5)>0,OR(D5="X",D5="x")),IF(OR(D5="X",D5="x",AND(OR(COUNTA(B5,C5,E5,F5)>0,OR(D5="X",D5="x")),(LEN(SUBSTITUTE(SUBSTITUTE(SUBSTITUTE(B5," ",""),"0",""),"-",""))+LEN(SUBSTITUTE(SUBSTITUTE(SUBSTITUTE(C5," ",""),"0",""),"-","")))=(LEN(SUBSTITUTE(SUBSTITUTE(SUBSTITUTE(E5," ",""),"0",""),"-",""))+LEN(SUBSTITUTE(SUBSTITUTE(SUBSTITUTE(F5," ",""),"0",""),"-",""))))),0,(LEN(SUBSTITUTE(SUBSTITUTE(SUBSTITUTE(E5," ",""),"0",""),"-",""))+LEN(SUBSTITUTE(SUBSTITUTE(SUBSTITUTE(F5," ",""),"0",""),"-",""))>LEN(SUBSTITUTE(SUBSTITUTE(SUBSTITUTE(B5," ",""),"0",""),"-",""))+LEN(SUBSTITUTE(SUBSTITUTE(SUBSTITUTE(C5," ",""),"0",""),"-","")))*1),0)+IF(OR(COUNTA(B6,C6,E6,F6)>0,OR(D6="X",D6="x")),IF(OR(D6="X",D6="x",AND(OR(COUNTA(B6,C6,E6,F6)>0,OR(D6="X",D6="x")),(LEN(SUBSTITUTE(SUBSTITUTE(SUBSTITUTE(B6," ",""),"0",""),"-",""))+LEN(SUBSTITUTE(SUBSTITUTE(SUBSTITUTE(C6," ",""),"0",""),"-","")))=(LEN(SUBSTITUTE(SUBSTITUTE(SUBSTITUTE(E6," ",""),"0",""),"-",""))+LEN(SUBSTITUTE(SUBSTITUTE(SUBSTITUTE(F6," ",""),"0",""),"-",""))))),0,(LEN(SUBSTITUTE(SUBSTITUTE(SUBSTITUTE(E6," ",""),"0",""),"-",""))+LEN(SUBSTITUTE(SUBSTITUTE(SUBSTITUTE(F6," ",""),"0",""),"-",""))>LEN(SUBSTITUTE(SUBSTITUTE(SUBSTITUTE(B6," ",""),"0",""),"-",""))+LEN(SUBSTITUTE(SUBSTITUTE(SUBSTITUTE(C6," ",""),"0",""),"-","")))*1),0) | C13: =IF(OR(COUNTA(B5,C5,E5,F5)>0,OR(D5="X",D5="x")),IF(OR(D5="X",D5="x",AND(OR(COUNTA(B5,C5,E5,F5)>0,OR(D5="X",D5="x")),(LEN(SUBSTITUTE(SUBSTITUTE(SUBSTITUTE(B5," ",""),"0",""),"-",""))+LEN(SUBSTITUTE(SUBSTITUTE(SUBSTITUTE(C5," ",""),"0",""),"-","")))=(LEN(SUBSTITUTE(SUBSTITUTE(SUBSTITUTE(E5," ",""),"0",""),"-",""))+LEN(SUBSTITUTE(SUBSTITUTE(SUBSTITUTE(F5," ",""),"0",""),"-",""))))),0,(LEN(SUBSTITUTE(SUBSTITUTE(SUBSTITUTE(E5," ",""),"0",""),"-",""))+LEN(SUBSTITUTE(SUBSTITUTE(SUBSTITUTE(F5," ",""),"0",""),"-",""))<LEN(SUBSTITUTE(SUBSTITUTE(SUBSTITUTE(B5," ",""),"0",""),"-",""))+LEN(SUBSTITUTE(SUBSTITUTE(SUBSTITUTE(C5," ",""),"0",""),"-","")))*1),0)+IF(OR(COUNTA(B6,C6,E6,F6)>0,OR(D6="X",D6="x")),IF(OR(D6="X",D6="x",AND(OR(COUNTA(B6,C6,E6,F6)>0,OR(D6="X",D6="x")),(LEN(SUBSTITUTE(SUBSTITUTE(SUBSTITUTE(B6," ",""),"0",""),"-",""))+LEN(SUBSTITUTE(SUBSTITUTE(SUBSTITUTE(C6," ",""),"0",""),"-","")))=(LEN(SUBSTITUTE(SUBSTITUTE(SUBSTITUTE(E6," ",""),"0",""),"-",""))+LEN(SUBSTITUTE(SUBSTITUTE(SUBSTITUTE(F6," ",""),"0",""),"-",""))))),0,(LEN(SUBSTITUTE(SUBSTITUTE(SUBSTITUTE(E6," ",""),"0",""),"-",""))+LEN(SUBSTITUTE(SUBSTITUTE(SUBSTITUTE(F6," ",""),"0",""),"-",""))<LEN(SUBSTITUTE(SUBSTITUTE(SUBSTITUTE(B6," ",""),"0",""),"-",""))+LEN(SUBSTITUTE(SUBSTITUTE(SUBSTITUTE(C6," ",""),"0",""),"-","")))*1),0) | D13: =IF(OR(COUNTA(B5,C5,E5,F5)>0,OR(D5="X",D5="x")),IF(OR(D5="X",D5="x",AND(OR(COUNTA(B5,C5,E5,F5)>0,OR(D5="X",D5="x")),(LEN(SUBSTITUTE(SUBSTITUTE(SUBSTITUTE(B5," ",""),"0",""),"-",""))+LEN(SUBSTITUTE(SUBSTITUTE(SUBSTITUTE(C5," ",""),"0",""),"-","")))=(LEN(SUBSTITUTE(SUBSTITUTE(SUBSTITUTE(E5," ",""),"0",""),"-",""))+LEN(SUBSTITUTE(SUBSTITUTE(SUBSTITUTE(F5," ",""),"0",""),"-",""))))),1,0),0)+IF(OR(COUNTA(B6,C6,E6,F6)>0,OR(D6="X",D6="x")),IF(OR(D6="X",D6="x",AND(OR(COUNTA(B6,C6,E6,F6)>0,OR(D6="X",D6="x")),(LEN(SUBSTITUTE(SUBSTITUTE(SUBSTITUTE(B6," ",""),"0",""),"-",""))+LEN(SUBSTITUTE(SUBSTITUTE(SUBSTITUTE(C6," ",""),"0",""),"-","")))=(LEN(SUBSTITUTE(SUBSTITUTE(SUBSTITUTE(E6," ",""),"0",""),"-",""))+LEN(SUBSTITUTE(SUBSTITUTE(SUBSTITUTE(F6," ",""),"0",""),"-",""))))),1,0),0) | E13: =LEN(SUBSTITUTE(SUBSTITUTE(SUBSTITUTE(E5," ",""),"0",""),"-",""))+LEN(SUBSTITUTE(SUBSTITUTE(SUBSTITUTE(F5," ",""),"0",""),"-",""))+LEN(SUBSTITUTE(SUBSTITUTE(SUBSTITUTE(E6," ",""),"0",""),"-",""))+LEN(SUBSTITUTE(SUBSTITUTE(SUBSTITUTE(F6," ",""),"0",""),"-","")) | F13: =LEN(SUBSTITUTE(SUBSTITUTE(SUBSTITUTE(B5," ",""),"0",""),"-",""))+LEN(SUBSTITUTE(SUBSTITUTE(SUBSTITUTE(C5," ",""),"0",""),"-",""))+LEN(SUBSTITUTE(SUBSTITUTE(SUBSTITUTE(B6," ",""),"0",""),"-",""))+LEN(SUBSTITUTE(SUBSTITUTE(SUBSTITUTE(C6," ",""),"0",""),"-","")) | G13: =RANK(U13,$U$11:$U$15)+COUNTIF($U$10:U12,U13) | I13: =data!$E$19&" "&data!$B$19 | J13: =IF(OR(COUNTA(J5,K5,M5,N5)>0,OR(L5="X",L5="x")),IF(OR(L5="X",L5="x",AND(OR(COUNTA(J5,K5,M5,N5)>0,OR(L5="X",L5="x")),(LEN(SUBSTITUTE(SUBSTITUTE(SUBSTITUTE(J5," ",""),"0",""),"-",""))+LEN(SUBSTITUTE(SUBSTITUTE(SUBSTITUTE(K5," ",""),"0",""),"-","")))=(LEN(SUBSTITUTE(SUBSTITUTE(SUBSTITUTE(M5," ",""),"0",""),"-",""))+LEN(SUBSTITUTE(SUBSTITUTE(SUBSTITUTE(N5," ",""),"0",""),"-",""))))),0,(LEN(SUBSTITUTE(SUBSTITUTE(SUBSTITUTE(M5," ",""),"0",""),"-",""))+LEN(SUBSTITUTE(SUBSTITUTE(SUBSTITUTE(N5," ",""),"0",""),"-",""))>LEN(SUBSTITUTE(SUBSTITUTE(SUBSTITUTE(J5," ",""),"0",""),"-",""))+LEN(SUBSTITUTE(SUBSTITUTE(SUBSTITUTE(K5," ",""),"0",""),"-","")))*1),0)+IF(OR(COUNTA(J6,K6,M6,N6)>0,OR(L6="X",L6="x")),IF(OR(L6="X",L6="x",AND(OR(COUNTA(J6,K6,M6,N6)>0,OR(L6="X",L6="x")),(LEN(SUBSTITUTE(SUBSTITUTE(SUBSTITUTE(J6," ",""),"0",""),"-",""))+LEN(SUBSTITUTE(SUBSTITUTE(SUBSTITUTE(K6," ",""),"0",""),"-","")))=(LEN(SUBSTITUTE(SUBSTITUTE(SUBSTITUTE(M6," ",""),"0",""),"-",""))+LEN(SUBSTITUTE(SUBSTITUTE(SUBSTITUTE(N6," ",""),"0",""),"-",""))))),0,(LEN(SUBSTITUTE(SUBSTITUTE(SUBSTITUTE(M6," ",""),"0",""),"-",""))+LEN(SUBSTITUTE(SUBSTITUTE(SUBSTITUTE(N6," ",""),"0",""),"-",""))>LEN(SUBSTITUTE(SUBSTITUTE(SUBSTITUTE(J6," ",""),"0",""),"-",""))+LEN(SUBSTITUTE(SUBSTITUTE(SUBSTITUTE(K6," ",""),"0",""),"-","")))*1),0) | K13: =IF(OR(COUNTA(J5,K5,M5,N5)>0,OR(L5="X",L5="x")),IF(OR(L5="X",L5="x",AND(OR(COUNTA(J5,K5,M5,N5)>0,OR(L5="X",L5="x")),(LEN(SUBSTITUTE(SUBSTITUTE(SUBSTITUTE(J5," ",""),"0",""),"-",""))+LEN(SUBSTITUTE(SUBSTITUTE(SUBSTITUTE(K5," ",""),"0",""),"-","")))=(LEN(SUBSTITUTE(SUBSTITUTE(SUBSTITUTE(M5," ",""),"0",""),"-",""))+LEN(SUBSTITUTE(SUBSTITUTE(SUBSTITUTE(N5," ",""),"0",""),"-",""))))),0,(LEN(SUBSTITUTE(SUBSTITUTE(SUBSTITUTE(M5," ",""),"0",""),"-",""))+LEN(SUBSTITUTE(SUBSTITUTE(SUBSTITUTE(N5," ",""),"0",""),"-",""))<LEN(SUBSTITUTE(SUBSTITUTE(SUBSTITUTE(J5," ",""),"0",""),"-",""))+LEN(SUBSTITUTE(SUBSTITUTE(SUBSTITUTE(K5," ",""),"0",""),"-","")))*1),0)+IF(OR(COUNTA(J6,K6,M6,N6)>0,OR(L6="X",L6="x")),IF(OR(L6="X",L6="x",AND(OR(COUNTA(J6,K6,M6,N6)>0,OR(L6="X",L6="x")),(LEN(SUBSTITUTE(SUBSTITUTE(SUBSTITUTE(J6," ",""),"0",""),"-",""))+LEN(SUBSTITUTE(SUBSTITUTE(SUBSTITUTE(K6," ",""),"0",""),"-","")))=(LEN(SUBSTITUTE(SUBSTITUTE(SUBSTITUTE(M6," ",""),"0",""),"-",""))+LEN(SUBSTITUTE(SUBSTITUTE(SUBSTITUTE(N6," ",""),"0",""),"-",""))))),0,(LEN(SUBSTITUTE(SUBSTITUTE(SUBSTITUTE(M6," ",""),"0",""),"-",""))+LEN(SUBSTITUTE(SUBSTITUTE(SUBSTITUTE(N6," ",""),"0",""),"-",""))<LEN(SUBSTITUTE(SUBSTITUTE(SUBSTITUTE(J6," ",""),"0",""),"-",""))+LEN(SUBSTITUTE(SUBSTITUTE(SUBSTITUTE(K6," ",""),"0",""),"-","")))*1),0) | L13: =IF(OR(COUNTA(J5,K5,M5,N5)>0,OR(L5="X",L5="x")),IF(OR(L5="X",L5="x",AND(OR(COUNTA(J5,K5,M5,N5)>0,OR(L5="X",L5="x")),(LEN(SUBSTITUTE(SUBSTITUTE(SUBSTITUTE(J5," ",""),"0",""),"-",""))+LEN(SUBSTITUTE(SUBSTITUTE(SUBSTITUTE(K5," ",""),"0",""),"-","")))=(LEN(SUBSTITUTE(SUBSTITUTE(SUBSTITUTE(M5," ",""),"0",""),"-",""))+LEN(SUBSTITUTE(SUBSTITUTE(SUBSTITUTE(N5," ",""),"0",""),"-",""))))),1,0),0)+IF(OR(COUNTA(J6,K6,M6,N6)>0,OR(L6="X",L6="x")),IF(OR(L6="X",L6="x",AND(OR(COUNTA(J6,K6,M6,N6)>0,OR(L6="X",L6="x")),(LEN(SUBSTITUTE(SUBSTITUTE(SUBSTITUTE(J6," ",""),"0",""),"-",""))+LEN(SUBSTITUTE(SUBSTITUTE(SUBSTITUTE(K6," ",""),"0",""),"-","")))=(LEN(SUBSTITUTE(SUBSTITUTE(SUBSTITUTE(M6," ",""),"0",""),"-",""))+LEN(SUBSTITUTE(SUBSTITUTE(SUBSTITUTE(N6," ",""),"0",""),"-",""))))),1,0),0) | M13: =LEN(SUBSTITUTE(SUBSTITUTE(SUBSTITUTE(M5," ",""),"0",""),"-",""))+LEN(SUBSTITUTE(SUBSTITUTE(SUBSTITUTE(N5," ",""),"0",""),"-",""))+LEN(SUBSTITUTE(SUBSTITUTE(SUBSTITUTE(M6," ",""),"0",""),"-",""))+LEN(SUBSTITUTE(SUBSTITUTE(SUBSTITUTE(N6," ",""),"0",""),"-","")) | N13: =LEN(SUBSTITUTE(SUBSTITUTE(SUBSTITUTE(J5," ",""),"0",""),"-",""))+LEN(SUBSTITUTE(SUBSTITUTE(SUBSTITUTE(K5," ",""),"0",""),"-",""))+LEN(SUBSTITUTE(SUBSTITUTE(SUBSTITUTE(J6," ",""),"0",""),"-",""))+LEN(SUBSTITUTE(SUBSTITUTE(SUBSTITUTE(K6," ",""),"0",""),"-","")) | O13: =RANK(AC13,$AC$11:$AC$15)+COUNTIF($AC$10:AC12,AC13) | U13: =(B13*1000000)-(C13*10000)+(D13*100)+(E13*1)-(F13*0.01) | AC13: =(J13*1000000)-(K13*10000)+(L13*100)+(M13*1)-(N13*0.01)
A14: =data!$E$6&" "&data!$B$6 | B14: =IF(OR(COUNTA(B6,C6,E6,F6)>0,OR(D6="X",D6="x")),IF(OR(D6="X",D6="x",AND(OR(COUNTA(B6,C6,E6,F6)>0,OR(D6="X",D6="x")),(LEN(SUBSTITUTE(SUBSTITUTE(SUBSTITUTE(B6," ",""),"0",""),"-",""))+LEN(SUBSTITUTE(SUBSTITUTE(SUBSTITUTE(C6," ",""),"0",""),"-","")))=(LEN(SUBSTITUTE(SUBSTITUTE(SUBSTITUTE(E6," ",""),"0",""),"-",""))+LEN(SUBSTITUTE(SUBSTITUTE(SUBSTITUTE(F6," ",""),"0",""),"-",""))))),0,(LEN(SUBSTITUTE(SUBSTITUTE(SUBSTITUTE(B6," ",""),"0",""),"-",""))+LEN(SUBSTITUTE(SUBSTITUTE(SUBSTITUTE(C6," ",""),"0",""),"-",""))>LEN(SUBSTITUTE(SUBSTITUTE(SUBSTITUTE(E6," ",""),"0",""),"-",""))+LEN(SUBSTITUTE(SUBSTITUTE(SUBSTITUTE(F6," ",""),"0",""),"-","")))*1),0)+IF(OR(COUNTA(B7,C7,E7,F7)>0,OR(D7="X",D7="x")),IF(OR(D7="X",D7="x",AND(OR(COUNTA(B7,C7,E7,F7)>0,OR(D7="X",D7="x")),(LEN(SUBSTITUTE(SUBSTITUTE(SUBSTITUTE(B7," ",""),"0",""),"-",""))+LEN(SUBSTITUTE(SUBSTITUTE(SUBSTITUTE(C7," ",""),"0",""),"-","")))=(LEN(SUBSTITUTE(SUBSTITUTE(SUBSTITUTE(E7," ",""),"0",""),"-",""))+LEN(SUBSTITUTE(SUBSTITUTE(SUBSTITUTE(F7," ",""),"0",""),"-",""))))),0,(LEN(SUBSTITUTE(SUBSTITUTE(SUBSTITUTE(B7," ",""),"0",""),"-",""))+LEN(SUBSTITUTE(SUBSTITUTE(SUBSTITUTE(C7," ",""),"0",""),"-",""))>LEN(SUBSTITUTE(SUBSTITUTE(SUBSTITUTE(E7," ",""),"0",""),"-",""))+LEN(SUBSTITUTE(SUBSTITUTE(SUBSTITUTE(F7," ",""),"0",""),"-","")))*1),0) | C14: =IF(OR(COUNTA(B6,C6,E6,F6)>0,OR(D6="X",D6="x")),IF(OR(D6="X",D6="x",AND(OR(COUNTA(B6,C6,E6,F6)>0,OR(D6="X",D6="x")),(LEN(SUBSTITUTE(SUBSTITUTE(SUBSTITUTE(B6," ",""),"0",""),"-",""))+LEN(SUBSTITUTE(SUBSTITUTE(SUBSTITUTE(C6," ",""),"0",""),"-","")))=(LEN(SUBSTITUTE(SUBSTITUTE(SUBSTITUTE(E6," ",""),"0",""),"-",""))+LEN(SUBSTITUTE(SUBSTITUTE(SUBSTITUTE(F6," ",""),"0",""),"-",""))))),0,(LEN(SUBSTITUTE(SUBSTITUTE(SUBSTITUTE(B6," ",""),"0",""),"-",""))+LEN(SUBSTITUTE(SUBSTITUTE(SUBSTITUTE(C6," ",""),"0",""),"-",""))<LEN(SUBSTITUTE(SUBSTITUTE(SUBSTITUTE(E6," ",""),"0",""),"-",""))+LEN(SUBSTITUTE(SUBSTITUTE(SUBSTITUTE(F6," ",""),"0",""),"-","")))*1),0)+IF(OR(COUNTA(B7,C7,E7,F7)>0,OR(D7="X",D7="x")),IF(OR(D7="X",D7="x",AND(OR(COUNTA(B7,C7,E7,F7)>0,OR(D7="X",D7="x")),(LEN(SUBSTITUTE(SUBSTITUTE(SUBSTITUTE(B7," ",""),"0",""),"-",""))+LEN(SUBSTITUTE(SUBSTITUTE(SUBSTITUTE(C7," ",""),"0",""),"-","")))=(LEN(SUBSTITUTE(SUBSTITUTE(SUBSTITUTE(E7," ",""),"0",""),"-",""))+LEN(SUBSTITUTE(SUBSTITUTE(SUBSTITUTE(F7," ",""),"0",""),"-",""))))),0,(LEN(SUBSTITUTE(SUBSTITUTE(SUBSTITUTE(B7," ",""),"0",""),"-",""))+LEN(SUBSTITUTE(SUBSTITUTE(SUBSTITUTE(C7," ",""),"0",""),"-",""))<LEN(SUBSTITUTE(SUBSTITUTE(SUBSTITUTE(E7," ",""),"0",""),"-",""))+LEN(SUBSTITUTE(SUBSTITUTE(SUBSTITUTE(F7," ",""),"0",""),"-","")))*1),0) | D14: =IF(OR(COUNTA(B6,C6,E6,F6)>0,OR(D6="X",D6="x")),IF(OR(D6="X",D6="x",AND(OR(COUNTA(B6,C6,E6,F6)>0,OR(D6="X",D6="x")),(LEN(SUBSTITUTE(SUBSTITUTE(SUBSTITUTE(B6," ",""),"0",""),"-",""))+LEN(SUBSTITUTE(SUBSTITUTE(SUBSTITUTE(C6," ",""),"0",""),"-","")))=(LEN(SUBSTITUTE(SUBSTITUTE(SUBSTITUTE(E6," ",""),"0",""),"-",""))+LEN(SUBSTITUTE(SUBSTITUTE(SUBSTITUTE(F6," ",""),"0",""),"-",""))))),1,0),0)+IF(OR(COUNTA(B7,C7,E7,F7)>0,OR(D7="X",D7="x")),IF(OR(D7="X",D7="x",AND(OR(COUNTA(B7,C7,E7,F7)>0,OR(D7="X",D7="x")),(LEN(SUBSTITUTE(SUBSTITUTE(SUBSTITUTE(B7," ",""),"0",""),"-",""))+LEN(SUBSTITUTE(SUBSTITUTE(SUBSTITUTE(C7," ",""),"0",""),"-","")))=(LEN(SUBSTITUTE(SUBSTITUTE(SUBSTITUTE(E7," ",""),"0",""),"-",""))+LEN(SUBSTITUTE(SUBSTITUTE(SUBSTITUTE(F7," ",""),"0",""),"-",""))))),1,0),0) | E14: =LEN(SUBSTITUTE(SUBSTITUTE(SUBSTITUTE(B6," ",""),"0",""),"-",""))+LEN(SUBSTITUTE(SUBSTITUTE(SUBSTITUTE(C6," ",""),"0",""),"-",""))+LEN(SUBSTITUTE(SUBSTITUTE(SUBSTITUTE(B7," ",""),"0",""),"-",""))+LEN(SUBSTITUTE(SUBSTITUTE(SUBSTITUTE(C7," ",""),"0",""),"-","")) | F14: =LEN(SUBSTITUTE(SUBSTITUTE(SUBSTITUTE(E6," ",""),"0",""),"-",""))+LEN(SUBSTITUTE(SUBSTITUTE(SUBSTITUTE(F6," ",""),"0",""),"-",""))+LEN(SUBSTITUTE(SUBSTITUTE(SUBSTITUTE(E7," ",""),"0",""),"-",""))+LEN(SUBSTITUTE(SUBSTITUTE(SUBSTITUTE(F7," ",""),"0",""),"-","")) | G14: =RANK(U14,$U$11:$U$15)+COUNTIF($U$10:U13,U14) | I14: =data!$E$20&" "&data!$B$20 | J14: =IF(OR(COUNTA(J6,K6,M6,N6)>0,OR(L6="X",L6="x")),IF(OR(L6="X",L6="x",AND(OR(COUNTA(J6,K6,M6,N6)>0,OR(L6="X",L6="x")),(LEN(SUBSTITUTE(SUBSTITUTE(SUBSTITUTE(J6," ",""),"0",""),"-",""))+LEN(SUBSTITUTE(SUBSTITUTE(SUBSTITUTE(K6," ",""),"0",""),"-","")))=(LEN(SUBSTITUTE(SUBSTITUTE(SUBSTITUTE(M6," ",""),"0",""),"-",""))+LEN(SUBSTITUTE(SUBSTITUTE(SUBSTITUTE(N6," ",""),"0",""),"-",""))))),0,(LEN(SUBSTITUTE(SUBSTITUTE(SUBSTITUTE(J6," ",""),"0",""),"-",""))+LEN(SUBSTITUTE(SUBSTITUTE(SUBSTITUTE(K6," ",""),"0",""),"-",""))>LEN(SUBSTITUTE(SUBSTITUTE(SUBSTITUTE(M6," ",""),"0",""),"-",""))+LEN(SUBSTITUTE(SUBSTITUTE(SUBSTITUTE(N6," ",""),"0",""),"-","")))*1),0)+IF(OR(COUNTA(J7,K7,M7,N7)>0,OR(L7="X",L7="x")),IF(OR(L7="X",L7="x",AND(OR(COUNTA(J7,K7,M7,N7)>0,OR(L7="X",L7="x")),(LEN(SUBSTITUTE(SUBSTITUTE(SUBSTITUTE(J7," ",""),"0",""),"-",""))+LEN(SUBSTITUTE(SUBSTITUTE(SUBSTITUTE(K7," ",""),"0",""),"-","")))=(LEN(SUBSTITUTE(SUBSTITUTE(SUBSTITUTE(M7," ",""),"0",""),"-",""))+LEN(SUBSTITUTE(SUBSTITUTE(SUBSTITUTE(N7," ",""),"0",""),"-",""))))),0,(LEN(SUBSTITUTE(SUBSTITUTE(SUBSTITUTE(J7," ",""),"0",""),"-",""))+LEN(SUBSTITUTE(SUBSTITUTE(SUBSTITUTE(K7," ",""),"0",""),"-",""))>LEN(SUBSTITUTE(SUBSTITUTE(SUBSTITUTE(M7," ",""),"0",""),"-",""))+LEN(SUBSTITUTE(SUBSTITUTE(SUBSTITUTE(N7," ",""),"0",""),"-","")))*1),0) | K14: =IF(OR(COUNTA(J6,K6,M6,N6)>0,OR(L6="X",L6="x")),IF(OR(L6="X",L6="x",AND(OR(COUNTA(J6,K6,M6,N6)>0,OR(L6="X",L6="x")),(LEN(SUBSTITUTE(SUBSTITUTE(SUBSTITUTE(J6," ",""),"0",""),"-",""))+LEN(SUBSTITUTE(SUBSTITUTE(SUBSTITUTE(K6," ",""),"0",""),"-","")))=(LEN(SUBSTITUTE(SUBSTITUTE(SUBSTITUTE(M6," ",""),"0",""),"-",""))+LEN(SUBSTITUTE(SUBSTITUTE(SUBSTITUTE(N6," ",""),"0",""),"-",""))))),0,(LEN(SUBSTITUTE(SUBSTITUTE(SUBSTITUTE(J6," ",""),"0",""),"-",""))+LEN(SUBSTITUTE(SUBSTITUTE(SUBSTITUTE(K6," ",""),"0",""),"-",""))<LEN(SUBSTITUTE(SUBSTITUTE(SUBSTITUTE(M6," ",""),"0",""),"-",""))+LEN(SUBSTITUTE(SUBSTITUTE(SUBSTITUTE(N6," ",""),"0",""),"-","")))*1),0)+IF(OR(COUNTA(J7,K7,M7,N7)>0,OR(L7="X",L7="x")),IF(OR(L7="X",L7="x",AND(OR(COUNTA(J7,K7,M7,N7)>0,OR(L7="X",L7="x")),(LEN(SUBSTITUTE(SUBSTITUTE(SUBSTITUTE(J7," ",""),"0",""),"-",""))+LEN(SUBSTITUTE(SUBSTITUTE(SUBSTITUTE(K7," ",""),"0",""),"-","")))=(LEN(SUBSTITUTE(SUBSTITUTE(SUBSTITUTE(M7," ",""),"0",""),"-",""))+LEN(SUBSTITUTE(SUBSTITUTE(SUBSTITUTE(N7," ",""),"0",""),"-",""))))),0,(LEN(SUBSTITUTE(SUBSTITUTE(SUBSTITUTE(J7," ",""),"0",""),"-",""))+LEN(SUBSTITUTE(SUBSTITUTE(SUBSTITUTE(K7," ",""),"0",""),"-",""))<LEN(SUBSTITUTE(SUBSTITUTE(SUBSTITUTE(M7," ",""),"0",""),"-",""))+LEN(SUBSTITUTE(SUBSTITUTE(SUBSTITUTE(N7," ",""),"0",""),"-","")))*1),0) | L14: =IF(OR(COUNTA(J6,K6,M6,N6)>0,OR(L6="X",L6="x")),IF(OR(L6="X",L6="x",AND(OR(COUNTA(J6,K6,M6,N6)>0,OR(L6="X",L6="x")),(LEN(SUBSTITUTE(SUBSTITUTE(SUBSTITUTE(J6," ",""),"0",""),"-",""))+LEN(SUBSTITUTE(SUBSTITUTE(SUBSTITUTE(K6," ",""),"0",""),"-","")))=(LEN(SUBSTITUTE(SUBSTITUTE(SUBSTITUTE(M6," ",""),"0",""),"-",""))+LEN(SUBSTITUTE(SUBSTITUTE(SUBSTITUTE(N6," ",""),"0",""),"-",""))))),1,0),0)+IF(OR(COUNTA(J7,K7,M7,N7)>0,OR(L7="X",L7="x")),IF(OR(L7="X",L7="x",AND(OR(COUNTA(J7,K7,M7,N7)>0,OR(L7="X",L7="x")),(LEN(SUBSTITUTE(SUBSTITUTE(SUBSTITUTE(J7," ",""),"0",""),"-",""))+LEN(SUBSTITUTE(SUBSTITUTE(SUBSTITUTE(K7," ",""),"0",""),"-","")))=(LEN(SUBSTITUTE(SUBSTITUTE(SUBSTITUTE(M7," ",""),"0",""),"-",""))+LEN(SUBSTITUTE(SUBSTITUTE(SUBSTITUTE(N7," ",""),"0",""),"-",""))))),1,0),0) | M14: =LEN(SUBSTITUTE(SUBSTITUTE(SUBSTITUTE(J6," ",""),"0",""),"-",""))+LEN(SUBSTITUTE(SUBSTITUTE(SUBSTITUTE(K6," ",""),"0",""),"-",""))+LEN(SUBSTITUTE(SUBSTITUTE(SUBSTITUTE(J7," ",""),"0",""),"-",""))+LEN(SUBSTITUTE(SUBSTITUTE(SUBSTITUTE(K7," ",""),"0",""),"-","")) | N14: =LEN(SUBSTITUTE(SUBSTITUTE(SUBSTITUTE(M6," ",""),"0",""),"-",""))+LEN(SUBSTITUTE(SUBSTITUTE(SUBSTITUTE(N6," ",""),"0",""),"-",""))+LEN(SUBSTITUTE(SUBSTITUTE(SUBSTITUTE(M7," ",""),"0",""),"-",""))+LEN(SUBSTITUTE(SUBSTITUTE(SUBSTITUTE(N7," ",""),"0",""),"-","")) | O14: =RANK(AC14,$AC$11:$AC$15)+COUNTIF($AC$10:AC13,AC14) | U14: =(B14*1000000)-(C14*10000)+(D14*100)+(E14*1)-(F14*0.01) | AC14: =(J14*1000000)-(K14*10000)+(L14*100)+(M14*1)-(N14*0.01)
A15: =data!$E$7&" "&data!$B$7 | B15: =IF(OR(COUNTA(B7,C7,E7,F7)>0,OR(D7="X",D7="x")),IF(OR(D7="X",D7="x",AND(OR(COUNTA(B7,C7,E7,F7)>0,OR(D7="X",D7="x")),(LEN(SUBSTITUTE(SUBSTITUTE(SUBSTITUTE(B7," ",""),"0",""),"-",""))+LEN(SUBSTITUTE(SUBSTITUTE(SUBSTITUTE(C7," ",""),"0",""),"-","")))=(LEN(SUBSTITUTE(SUBSTITUTE(SUBSTITUTE(E7," ",""),"0",""),"-",""))+LEN(SUBSTITUTE(SUBSTITUTE(SUBSTITUTE(F7," ",""),"0",""),"-",""))))),0,(LEN(SUBSTITUTE(SUBSTITUTE(SUBSTITUTE(E7," ",""),"0",""),"-",""))+LEN(SUBSTITUTE(SUBSTITUTE(SUBSTITUTE(F7," ",""),"0",""),"-",""))>LEN(SUBSTITUTE(SUBSTITUTE(SUBSTITUTE(B7," ",""),"0",""),"-",""))+LEN(SUBSTITUTE(SUBSTITUTE(SUBSTITUTE(C7," ",""),"0",""),"-","")))*1),0)+IF(OR(COUNTA(B8,C8,E8,F8)>0,OR(D8="X",D8="x")),IF(OR(D8="X",D8="x",AND(OR(COUNTA(B8,C8,E8,F8)>0,OR(D8="X",D8="x")),(LEN(SUBSTITUTE(SUBSTITUTE(SUBSTITUTE(B8," ",""),"0",""),"-",""))+LEN(SUBSTITUTE(SUBSTITUTE(SUBSTITUTE(C8," ",""),"0",""),"-","")))=(LEN(SUBSTITUTE(SUBSTITUTE(SUBSTITUTE(E8," ",""),"0",""),"-",""))+LEN(SUBSTITUTE(SUBSTITUTE(SUBSTITUTE(F8," ",""),"0",""),"-",""))))),0,(LEN(SUBSTITUTE(SUBSTITUTE(SUBSTITUTE(E8," ",""),"0",""),"-",""))+LEN(SUBSTITUTE(SUBSTITUTE(SUBSTITUTE(F8," ",""),"0",""),"-",""))>LEN(SUBSTITUTE(SUBSTITUTE(SUBSTITUTE(B8," ",""),"0",""),"-",""))+LEN(SUBSTITUTE(SUBSTITUTE(SUBSTITUTE(C8," ",""),"0",""),"-","")))*1),0) | C15: =IF(OR(COUNTA(B7,C7,E7,F7)>0,OR(D7="X",D7="x")),IF(OR(D7="X",D7="x",AND(OR(COUNTA(B7,C7,E7,F7)>0,OR(D7="X",D7="x")),(LEN(SUBSTITUTE(SUBSTITUTE(SUBSTITUTE(B7," ",""),"0",""),"-",""))+LEN(SUBSTITUTE(SUBSTITUTE(SUBSTITUTE(C7," ",""),"0",""),"-","")))=(LEN(SUBSTITUTE(SUBSTITUTE(SUBSTITUTE(E7," ",""),"0",""),"-",""))+LEN(SUBSTITUTE(SUBSTITUTE(SUBSTITUTE(F7," ",""),"0",""),"-",""))))),0,(LEN(SUBSTITUTE(SUBSTITUTE(SUBSTITUTE(E7," ",""),"0",""),"-",""))+LEN(SUBSTITUTE(SUBSTITUTE(SUBSTITUTE(F7," ",""),"0",""),"-",""))<LEN(SUBSTITUTE(SUBSTITUTE(SUBSTITUTE(B7," ",""),"0",""),"-",""))+LEN(SUBSTITUTE(SUBSTITUTE(SUBSTITUTE(C7," ",""),"0",""),"-","")))*1),0)+IF(OR(COUNTA(B8,C8,E8,F8)>0,OR(D8="X",D8="x")),IF(OR(D8="X",D8="x",AND(OR(COUNTA(B8,C8,E8,F8)>0,OR(D8="X",D8="x")),(LEN(SUBSTITUTE(SUBSTITUTE(SUBSTITUTE(B8," ",""),"0",""),"-",""))+LEN(SUBSTITUTE(SUBSTITUTE(SUBSTITUTE(C8," ",""),"0",""),"-","")))=(LEN(SUBSTITUTE(SUBSTITUTE(SUBSTITUTE(E8," ",""),"0",""),"-",""))+LEN(SUBSTITUTE(SUBSTITUTE(SUBSTITUTE(F8," ",""),"0",""),"-",""))))),0,(LEN(SUBSTITUTE(SUBSTITUTE(SUBSTITUTE(E8," ",""),"0",""),"-",""))+LEN(SUBSTITUTE(SUBSTITUTE(SUBSTITUTE(F8," ",""),"0",""),"-",""))<LEN(SUBSTITUTE(SUBSTITUTE(SUBSTITUTE(B8," ",""),"0",""),"-",""))+LEN(SUBSTITUTE(SUBSTITUTE(SUBSTITUTE(C8," ",""),"0",""),"-","")))*1),0) | D15: =IF(OR(COUNTA(B7,C7,E7,F7)>0,OR(D7="X",D7="x")),IF(OR(D7="X",D7="x",AND(OR(COUNTA(B7,C7,E7,F7)>0,OR(D7="X",D7="x")),(LEN(SUBSTITUTE(SUBSTITUTE(SUBSTITUTE(B7," ",""),"0",""),"-",""))+LEN(SUBSTITUTE(SUBSTITUTE(SUBSTITUTE(C7," ",""),"0",""),"-","")))=(LEN(SUBSTITUTE(SUBSTITUTE(SUBSTITUTE(E7," ",""),"0",""),"-",""))+LEN(SUBSTITUTE(SUBSTITUTE(SUBSTITUTE(F7," ",""),"0",""),"-",""))))),1,0),0)+IF(OR(COUNTA(B8,C8,E8,F8)>0,OR(D8="X",D8="x")),IF(OR(D8="X",D8="x",AND(OR(COUNTA(B8,C8,E8,F8)>0,OR(D8="X",D8="x")),(LEN(SUBSTITUTE(SUBSTITUTE(SUBSTITUTE(B8," ",""),"0",""),"-",""))+LEN(SUBSTITUTE(SUBSTITUTE(SUBSTITUTE(C8," ",""),"0",""),"-","")))=(LEN(SUBSTITUTE(SUBSTITUTE(SUBSTITUTE(E8," ",""),"0",""),"-",""))+LEN(SUBSTITUTE(SUBSTITUTE(SUBSTITUTE(F8," ",""),"0",""),"-",""))))),1,0),0) | E15: =LEN(SUBSTITUTE(SUBSTITUTE(SUBSTITUTE(E7," ",""),"0",""),"-",""))+LEN(SUBSTITUTE(SUBSTITUTE(SUBSTITUTE(F7," ",""),"0",""),"-",""))+LEN(SUBSTITUTE(SUBSTITUTE(SUBSTITUTE(E8," ",""),"0",""),"-",""))+LEN(SUBSTITUTE(SUBSTITUTE(SUBSTITUTE(F8," ",""),"0",""),"-","")) | F15: =LEN(SUBSTITUTE(SUBSTITUTE(SUBSTITUTE(B7," ",""),"0",""),"-",""))+LEN(SUBSTITUTE(SUBSTITUTE(SUBSTITUTE(C7," ",""),"0",""),"-",""))+LEN(SUBSTITUTE(SUBSTITUTE(SUBSTITUTE(B8," ",""),"0",""),"-",""))+LEN(SUBSTITUTE(SUBSTITUTE(SUBSTITUTE(C8," ",""),"0",""),"-","")) | G15: =RANK(U15,$U$11:$U$15)+COUNTIF($U$10:U14,U15) | I15: =data!$E$21&" "&data!$B$21 | J15: =IF(OR(COUNTA(J7,K7,M7,N7)>0,OR(L7="X",L7="x")),IF(OR(L7="X",L7="x",AND(OR(COUNTA(J7,K7,M7,N7)>0,OR(L7="X",L7="x")),(LEN(SUBSTITUTE(SUBSTITUTE(SUBSTITUTE(J7," ",""),"0",""),"-",""))+LEN(SUBSTITUTE(SUBSTITUTE(SUBSTITUTE(K7," ",""),"0",""),"-","")))=(LEN(SUBSTITUTE(SUBSTITUTE(SUBSTITUTE(M7," ",""),"0",""),"-",""))+LEN(SUBSTITUTE(SUBSTITUTE(SUBSTITUTE(N7," ",""),"0",""),"-",""))))),0,(LEN(SUBSTITUTE(SUBSTITUTE(SUBSTITUTE(M7," ",""),"0",""),"-",""))+LEN(SUBSTITUTE(SUBSTITUTE(SUBSTITUTE(N7," ",""),"0",""),"-",""))>LEN(SUBSTITUTE(SUBSTITUTE(SUBSTITUTE(J7," ",""),"0",""),"-",""))+LEN(SUBSTITUTE(SUBSTITUTE(SUBSTITUTE(K7," ",""),"0",""),"-","")))*1),0)+IF(OR(COUNTA(J8,K8,M8,N8)>0,OR(L8="X",L8="x")),IF(OR(L8="X",L8="x",AND(OR(COUNTA(J8,K8,M8,N8)>0,OR(L8="X",L8="x")),(LEN(SUBSTITUTE(SUBSTITUTE(SUBSTITUTE(J8," ",""),"0",""),"-",""))+LEN(SUBSTITUTE(SUBSTITUTE(SUBSTITUTE(K8," ",""),"0",""),"-","")))=(LEN(SUBSTITUTE(SUBSTITUTE(SUBSTITUTE(M8," ",""),"0",""),"-",""))+LEN(SUBSTITUTE(SUBSTITUTE(SUBSTITUTE(N8," ",""),"0",""),"-",""))))),0,(LEN(SUBSTITUTE(SUBSTITUTE(SUBSTITUTE(M8," ",""),"0",""),"-",""))+LEN(SUBSTITUTE(SUBSTITUTE(SUBSTITUTE(N8," ",""),"0",""),"-",""))>LEN(SUBSTITUTE(SUBSTITUTE(SUBSTITUTE(J8," ",""),"0",""),"-",""))+LEN(SUBSTITUTE(SUBSTITUTE(SUBSTITUTE(K8," ",""),"0",""),"-","")))*1),0) | K15: =IF(OR(COUNTA(J7,K7,M7,N7)>0,OR(L7="X",L7="x")),IF(OR(L7="X",L7="x",AND(OR(COUNTA(J7,K7,M7,N7)>0,OR(L7="X",L7="x")),(LEN(SUBSTITUTE(SUBSTITUTE(SUBSTITUTE(J7," ",""),"0",""),"-",""))+LEN(SUBSTITUTE(SUBSTITUTE(SUBSTITUTE(K7," ",""),"0",""),"-","")))=(LEN(SUBSTITUTE(SUBSTITUTE(SUBSTITUTE(M7," ",""),"0",""),"-",""))+LEN(SUBSTITUTE(SUBSTITUTE(SUBSTITUTE(N7," ",""),"0",""),"-",""))))),0,(LEN(SUBSTITUTE(SUBSTITUTE(SUBSTITUTE(M7," ",""),"0",""),"-",""))+LEN(SUBSTITUTE(SUBSTITUTE(SUBSTITUTE(N7," ",""),"0",""),"-",""))<LEN(SUBSTITUTE(SUBSTITUTE(SUBSTITUTE(J7," ",""),"0",""),"-",""))+LEN(SUBSTITUTE(SUBSTITUTE(SUBSTITUTE(K7," ",""),"0",""),"-","")))*1),0)+IF(OR(COUNTA(J8,K8,M8,N8)>0,OR(L8="X",L8="x")),IF(OR(L8="X",L8="x",AND(OR(COUNTA(J8,K8,M8,N8)>0,OR(L8="X",L8="x")),(LEN(SUBSTITUTE(SUBSTITUTE(SUBSTITUTE(J8," ",""),"0",""),"-",""))+LEN(SUBSTITUTE(SUBSTITUTE(SUBSTITUTE(K8," ",""),"0",""),"-","")))=(LEN(SUBSTITUTE(SUBSTITUTE(SUBSTITUTE(M8," ",""),"0",""),"-",""))+LEN(SUBSTITUTE(SUBSTITUTE(SUBSTITUTE(N8," ",""),"0",""),"-",""))))),0,(LEN(SUBSTITUTE(SUBSTITUTE(SUBSTITUTE(M8," ",""),"0",""),"-",""))+LEN(SUBSTITUTE(SUBSTITUTE(SUBSTITUTE(N8," ",""),"0",""),"-",""))<LEN(SUBSTITUTE(SUBSTITUTE(SUBSTITUTE(J8," ",""),"0",""),"-",""))+LEN(SUBSTITUTE(SUBSTITUTE(SUBSTITUTE(K8," ",""),"0",""),"-","")))*1),0) | L15: =IF(OR(COUNTA(J7,K7,M7,N7)>0,OR(L7="X",L7="x")),IF(OR(L7="X",L7="x",AND(OR(COUNTA(J7,K7,M7,N7)>0,OR(L7="X",L7="x")),(LEN(SUBSTITUTE(SUBSTITUTE(SUBSTITUTE(J7," ",""),"0",""),"-",""))+LEN(SUBSTITUTE(SUBSTITUTE(SUBSTITUTE(K7," ",""),"0",""),"-","")))=(LEN(SUBSTITUTE(SUBSTITUTE(SUBSTITUTE(M7," ",""),"0",""),"-",""))+LEN(SUBSTITUTE(SUBSTITUTE(SUBSTITUTE(N7," ",""),"0",""),"-",""))))),1,0),0)+IF(OR(COUNTA(J8,K8,M8,N8)>0,OR(L8="X",L8="x")),IF(OR(L8="X",L8="x",AND(OR(COUNTA(J8,K8,M8,N8)>0,OR(L8="X",L8="x")),(LEN(SUBSTITUTE(SUBSTITUTE(SUBSTITUTE(J8," ",""),"0",""),"-",""))+LEN(SUBSTITUTE(SUBSTITUTE(SUBSTITUTE(K8," ",""),"0",""),"-","")))=(LEN(SUBSTITUTE(SUBSTITUTE(SUBSTITUTE(M8," ",""),"0",""),"-",""))+LEN(SUBSTITUTE(SUBSTITUTE(SUBSTITUTE(N8," ",""),"0",""),"-",""))))),1,0),0) | M15: =LEN(SUBSTITUTE(SUBSTITUTE(SUBSTITUTE(M7," ",""),"0",""),"-",""))+LEN(SUBSTITUTE(SUBSTITUTE(SUBSTITUTE(N7," ",""),"0",""),"-",""))+LEN(SUBSTITUTE(SUBSTITUTE(SUBSTITUTE(M8," ",""),"0",""),"-",""))+LEN(SUBSTITUTE(SUBSTITUTE(SUBSTITUTE(N8," ",""),"0",""),"-","")) | N15: =LEN(SUBSTITUTE(SUBSTITUTE(SUBSTITUTE(J7," ",""),"0",""),"-",""))+LEN(SUBSTITUTE(SUBSTITUTE(SUBSTITUTE(K7," ",""),"0",""),"-",""))+LEN(SUBSTITUTE(SUBSTITUTE(SUBSTITUTE(J8," ",""),"0",""),"-",""))+LEN(SUBSTITUTE(SUBSTITUTE(SUBSTITUTE(K8," ",""),"0",""),"-","")) | O15: =RANK(AC15,$AC$11:$AC$15)+COUNTIF($AC$10:AC14,AC15) | U15: =(B15*1000000)-(C15*10000)+(D15*100)+(E15*1)-(F15*0.01) | AC15: =(J15*1000000)-(K15*10000)+(L15*100)+(M15*1)-(N15*0.01)
G18: Ranking | O18: Ranking
F19: 1. | G19: =IFERROR(INDEX($A$11:$A$15, MATCH(1, $G$11:$G$15, 0)), "-") | N19: 1. | O19: =IFERROR(INDEX($I$11:$I$15, MATCH(1, $O$11:$O$15, 0)), "-")
F20: 2. | G20: =IFERROR(INDEX($A$11:$A$15, MATCH(2, $G$11:$G$15, 0)), "-") | N20: 2. | O20: =IFERROR(INDEX($I$11:$I$15, MATCH(2, $O$11:$O$15, 0)), "-")
F21: 3. | G21: =IFERROR(INDEX($A$11:$A$15, MATCH(3, $G$11:$G$15, 0)), "-") | N21: 3. | O21: =IFERROR(INDEX($I$11:$I$15, MATCH(3, $O$11:$O$15, 0)), "-")
F22: 4. | G22: =IFERROR(INDEX($A$11:$A$15, MATCH(4, $G$11:$G$15, 0)), "-") | N22: 4. | O22: =IFERROR(INDEX($I$11:$I$15, MATCH(4, $O$11:$O$15, 0)), "-")
F23: 5. | G23: =IFERROR(INDEX($A$11:$A$15, MATCH(5, $G$11:$G$15, 0)), "-") | N23: 5. | O23: =IFERROR(INDEX($I$11:$I$15, MATCH(5, $O$11:$O$15, 0)), "-")
A25: ='data'!$A$12 | I25: ='data'!$A$26
A26: White | D26: vs | G26: Red | I26: White | L26: vs | O26: Red
A27: =data!$E$9&" "&data!$B$9 | G27: =data!$E$8&" "&data!$B$8 | I27: =data!$E$23&" "&data!$B$23 | O27: =data!$E$22&" "&data!$B$22
A28: =data!$E$9&" "&data!$B$9 | G28: =data!$E$10&" "&data!$B$10 | I28: =data!$E$23&" "&data!$B$23 | O28: =data!$E$24&" "&data!$B$24
A29: =data!$E$11&" "&data!$B$11 | G29: =data!$E$10&" "&data!$B$10 | I29: =data!$E$25&" "&data!$B$25 | O29: =data!$E$24&" "&data!$B$24
A30: =data!$E$11&" "&data!$B$11 | G30: =data!$E$12&" "&data!$B$12 | I30: =data!$E$25&" "&data!$B$25 | O30: =data!$E$26&" "&data!$B$26
A31: =data!$E$8&" "&data!$B$8 | G31: =data!$E$12&" "&data!$B$12 | I31: =data!$E$22&" "&data!$B$22 | O31: =data!$E$26&" "&data!$B$26
A33: Results | B33: W | C33: L | D33: T | E33: PW | F33: PL | G33: Rank | I33: Results | J33: W | K33: L | L33: T | M33: PW | N33: PL | O33: Rank
A34: =data!$E$8&" "&data!$B$8 | B34: =IF(OR(COUNTA(B27,C27,E27,F27)>0,OR(D27="X",D27="x")),IF(OR(D27="X",D27="x",AND(OR(COUNTA(B27,C27,E27,F27)>0,OR(D27="X",D27="x")),(LEN(SUBSTITUTE(SUBSTITUTE(SUBSTITUTE(B27," ",""),"0",""),"-",""))+LEN(SUBSTITUTE(SUBSTITUTE(SUBSTITUTE(C27," ",""),"0",""),"-","")))=(LEN(SUBSTITUTE(SUBSTITUTE(SUBSTITUTE(E27," ",""),"0",""),"-",""))+LEN(SUBSTITUTE(SUBSTITUTE(SUBSTITUTE(F27," ",""),"0",""),"-",""))))),0,(LEN(SUBSTITUTE(SUBSTITUTE(SUBSTITUTE(E27," ",""),"0",""),"-",""))+LEN(SUBSTITUTE(SUBSTITUTE(SUBSTITUTE(F27," ",""),"0",""),"-",""))>LEN(SUBSTITUTE(SUBSTITUTE(SUBSTITUTE(B27," ",""),"0",""),"-",""))+LEN(SUBSTITUTE(SUBSTITUTE(SUBSTITUTE(C27," ",""),"0",""),"-","")))*1),0)+IF(OR(COUNTA(B31,C31,E31,F31)>0,OR(D31="X",D31="x")),IF(OR(D31="X",D31="x",AND(OR(COUNTA(B31,C31,E31,F31)>0,OR(D31="X",D31="x")),(LEN(SUBSTITUTE(SUBSTITUTE(SUBSTITUTE(B31," ",""),"0",""),"-",""))+LEN(SUBSTITUTE(SUBSTITUTE(SUBSTITUTE(C31," ",""),"0",""),"-","")))=(LEN(SUBSTITUTE(SUBSTITUTE(SUBSTITUTE(E31," ",""),"0",""),"-",""))+LEN(SUBSTITUTE(SUBSTITUTE(SUBSTITUTE(F31," ",""),"0",""),"-",""))))),0,(LEN(SUBSTITUTE(SUBSTITUTE(SUBSTITUTE(B31," ",""),"0",""),"-",""))+LEN(SUBSTITUTE(SUBSTITUTE(SUBSTITUTE(C31," ",""),"0",""),"-",""))>LEN(SUBSTITUTE(SUBSTITUTE(SUBSTITUTE(E31," ",""),"0",""),"-",""))+LEN(SUBSTITUTE(SUBSTITUTE(SUBSTITUTE(F31," ",""),"0",""),"-","")))*1),0) | C34: =IF(OR(COUNTA(B27,C27,E27,F27)>0,OR(D27="X",D27="x")),IF(OR(D27="X",D27="x",AND(OR(COUNTA(B27,C27,E27,F27)>0,OR(D27="X",D27="x")),(LEN(SUBSTITUTE(SUBSTITUTE(SUBSTITUTE(B27," ",""),"0",""),"-",""))+LEN(SUBSTITUTE(SUBSTITUTE(SUBSTITUTE(C27," ",""),"0",""),"-","")))=(LEN(SUBSTITUTE(SUBSTITUTE(SUBSTITUTE(E27," ",""),"0",""),"-",""))+LEN(SUBSTITUTE(SUBSTITUTE(SUBSTITUTE(F27," ",""),"0",""),"-",""))))),0,(LEN(SUBSTITUTE(SUBSTITUTE(SUBSTITUTE(E27," ",""),"0",""),"-",""))+LEN(SUBSTITUTE(SUBSTITUTE(SUBSTITUTE(F27," ",""),"0",""),"-",""))<LEN(SUBSTITUTE(SUBSTITUTE(SUBSTITUTE(B27," ",""),"0",""),"-",""))+LEN(SUBSTITUTE(SUBSTITUTE(SUBSTITUTE(C27," ",""),"0",""),"-","")))*1),0)+IF(OR(COUNTA(B31,C31,E31,F31)>0,OR(D31="X",D31="x")),IF(OR(D31="X",D31="x",AND(OR(COUNTA(B31,C31,E31,F31)>0,OR(D31="X",D31="x")),(LEN(SUBSTITUTE(SUBSTITUTE(SUBSTITUTE(B31," ",""),"0",""),"-",""))+LEN(SUBSTITUTE(SUBSTITUTE(SUBSTITUTE(C31," ",""),"0",""),"-","")))=(LEN(SUBSTITUTE(SUBSTITUTE(SUBSTITUTE(E31," ",""),"0",""),"-",""))+LEN(SUBSTITUTE(SUBSTITUTE(SUBSTITUTE(F31," ",""),"0",""),"-",""))))),0,(LEN(SUBSTITUTE(SUBSTITUTE(SUBSTITUTE(B31," ",""),"0",""),"-",""))+LEN(SUBSTITUTE(SUBSTITUTE(SUBSTITUTE(C31," ",""),"0",""),"-",""))<LEN(SUBSTITUTE(SUBSTITUTE(SUBSTITUTE(E31," ",""),"0",""),"-",""))+LEN(SUBSTITUTE(SUBSTITUTE(SUBSTITUTE(F31," ",""),"0",""),"-","")))*1),0) | D34: =IF(OR(COUNTA(B27,C27,E27,F27)>0,OR(D27="X",D27="x")),IF(OR(D27="X",D27="x",AND(OR(COUNTA(B27,C27,E27,F27)>0,OR(D27="X",D27="x")),(LEN(SUBSTITUTE(SUBSTITUTE(SUBSTITUTE(B27," ",""),"0",""),"-",""))+LEN(SUBSTITUTE(SUBSTITUTE(SUBSTITUTE(C27," ",""),"0",""),"-","")))=(LEN(SUBSTITUTE(SUBSTITUTE(SUBSTITUTE(E27," ",""),"0",""),"-",""))+LEN(SUBSTITUTE(SUBSTITUTE(SUBSTITUTE(F27," ",""),"0",""),"-",""))))),1,0),0)+IF(OR(COUNTA(B31,C31,E31,F31)>0,OR(D31="X",D31="x")),IF(OR(D31="X",D31="x",AND(OR(COUNTA(B31,C31,E31,F31)>0,OR(D31="X",D31="x")),(LEN(SUBSTITUTE(SUBSTITUTE(SUBSTITUTE(B31," ",""),"0",""),"-",""))+LEN(SUBSTITUTE(SUBSTITUTE(SUBSTITUTE(C31," ",""),"0",""),"-","")))=(LEN(SUBSTITUTE(SUBSTITUTE(SUBSTITUTE(E31," ",""),"0",""),"-",""))+LEN(SUBSTITUTE(SUBSTITUTE(SUBSTITUTE(F31," ",""),"0",""),"-",""))))),1,0),0) | E34: =LEN(SUBSTITUTE(SUBSTITUTE(SUBSTITUTE(E27," ",""),"0",""),"-",""))+LEN(SUBSTITUTE(SUBSTITUTE(SUBSTITUTE(F27," ",""),"0",""),"-",""))+LEN(SUBSTITUTE(SUBSTITUTE(SUBSTITUTE(B31," ",""),"0",""),"-",""))+LEN(SUBSTITUTE(SUBSTITUTE(SUBSTITUTE(C31," ",""),"0",""),"-","")) | F34: =LEN(SUBSTITUTE(SUBSTITUTE(SUBSTITUTE(B27," ",""),"0",""),"-",""))+LEN(SUBSTITUTE(SUBSTITUTE(SUBSTITUTE(C27," ",""),"0",""),"-",""))+LEN(SUBSTITUTE(SUBSTITUTE(SUBSTITUTE(E31," ",""),"0",""),"-",""))+LEN(SUBSTITUTE(SUBSTITUTE(SUBSTITUTE(F31," ",""),"0",""),"-","")) | G34: =RANK(U34,$U$34:$U$38)+COUNTIF($U$33:U33,U34) | I34: =data!$E$22&" "&data!$B$22 | J34: =IF(OR(COUNTA(J27,K27,M27,N27)>0,OR(L27="X",L27="x")),IF(OR(L27="X",L27="x",AND(OR(COUNTA(J27,K27,M27,N27)>0,OR(L27="X",L27="x")),(LEN(SUBSTITUTE(SUBSTITUTE(SUBSTITUTE(J27," ",""),"0",""),"-",""))+LEN(SUBSTITUTE(SUBSTITUTE(SUBSTITUTE(K27," ",""),"0",""),"-","")))=(LEN(SUBSTITUTE(SUBSTITUTE(SUBSTITUTE(M27," ",""),"0",""),"-",""))+LEN(SUBSTITUTE(SUBSTITUTE(SUBSTITUTE(N27," ",""),"0",""),"-",""))))),0,(LEN(SUBSTITUTE(SUBSTITUTE(SUBSTITUTE(M27," ",""),"0",""),"-",""))+LEN(SUBSTITUTE(SUBSTITUTE(SUBSTITUTE(N27," ",""),"0",""),"-",""))>LEN(SUBSTITUTE(SUBSTITUTE(SUBSTITUTE(J27," ",""),"0",""),"-",""))+LEN(SUBSTITUTE(SUBSTITUTE(SUBSTITUTE(K27," ",""),"0",""),"-","")))*1),0)+IF(OR(COUNTA(J31,K31,M31,N31)>0,OR(L31="X",L31="x")),IF(OR(L31="X",L31="x",AND(OR(COUNTA(J31,K31,M31,N31)>0,OR(L31="X",L31="x")),(LEN(SUBSTITUTE(SUBSTITUTE(SUBSTITUTE(J31," ",""),"0",""),"-",""))+LEN(SUBSTITUTE(SUBSTITUTE(SUBSTITUTE(K31," ",""),"0",""),"-","")))=(LEN(SUBSTITUTE(SUBSTITUTE(SUBSTITUTE(M31," ",""),"0",""),"-",""))+LEN(SUBSTITUTE(SUBSTITUTE(SUBSTITUTE(N31," ",""),"0",""),"-",""))))),0,(LEN(SUBSTITUTE(SUBSTITUTE(SUBSTITUTE(J31," ",""),"0",""),"-",""))+LEN(SUBSTITUTE(SUBSTITUTE(SUBSTITUTE(K31," ",""),"0",""),"-",""))>LEN(SUBSTITUTE(SUBSTITUTE(SUBSTITUTE(M31," ",""),"0",""),"-",""))+LEN(SUBSTITUTE(SUBSTITUTE(SUBSTITUTE(N31," ",""),"0",""),"-","")))*1),0) | K34: =IF(OR(COUNTA(J27,K27,M27,N27)>0,OR(L27="X",L27="x")),IF(OR(L27="X",L27="x",AND(OR(COUNTA(J27,K27,M27,N27)>0,OR(L27="X",L27="x")),(LEN(SUBSTITUTE(SUBSTITUTE(SUBSTITUTE(J27," ",""),"0",""),"-",""))+LEN(SUBSTITUTE(SUBSTITUTE(SUBSTITUTE(K27," ",""),"0",""),"-","")))=(LEN(SUBSTITUTE(SUBSTITUTE(SUBSTITUTE(M27," ",""),"0",""),"-",""))+LEN(SUBSTITUTE(SUBSTITUTE(SUBSTITUTE(N27," ",""),"0",""),"-",""))))),0,(LEN(SUBSTITUTE(SUBSTITUTE(SUBSTITUTE(M27," ",""),"0",""),"-",""))+LEN(SUBSTITUTE(SUBSTITUTE(SUBSTITUTE(N27," ",""),"0",""),"-",""))<LEN(SUBSTITUTE(SUBSTITUTE(SUBSTITUTE(J27," ",""),"0",""),"-",""))+LEN(SUBSTITUTE(SUBSTITUTE(SUBSTITUTE(K27," ",""),"0",""),"-","")))*1),0)+IF(OR(COUNTA(J31,K31,M31,N31)>0,OR(L31="X",L31="x")),IF(OR(L31="X",L31="x",AND(OR(COUNTA(J31,K31,M31,N31)>0,OR(L31="X",L31="x")),(LEN(SUBSTITUTE(SUBSTITUTE(SUBSTITUTE(J31," ",""),"0",""),"-",""))+LEN(SUBSTITUTE(SUBSTITUTE(SUBSTITUTE(K31," ",""),"0",""),"-","")))=(LEN(SUBSTITUTE(SUBSTITUTE(SUBSTITUTE(M31," ",""),"0",""),"-",""))+LEN(SUBSTITUTE(SUBSTITUTE(SUBSTITUTE(N31," ",""),"0",""),"-",""))))),0,(LEN(SUBSTITUTE(SUBSTITUTE(SUBSTITUTE(J31," ",""),"0",""),"-",""))+LEN(SUBSTITUTE(SUBSTITUTE(SUBSTITUTE(K31," ",""),"0",""),"-",""))<LEN(SUBSTITUTE(SUBSTITUTE(SUBSTITUTE(M31," ",""),"0",""),"-",""))+LEN(SUBSTITUTE(SUBSTITUTE(SUBSTITUTE(N31," ",""),"0",""),"-","")))*1),0) | L34: =IF(OR(COUNTA(J27,K27,M27,N27)>0,OR(L27="X",L27="x")),IF(OR(L27="X",L27="x",AND(OR(COUNTA(J27,K27,M27,N27)>0,OR(L27="X",L27="x")),(LEN(SUBSTITUTE(SUBSTITUTE(SUBSTITUTE(J27," ",""),"0",""),"-",""))+LEN(SUBSTITUTE(SUBSTITUTE(SUBSTITUTE(K27," ",""),"0",""),"-","")))=(LEN(SUBSTITUTE(SUBSTITUTE(SUBSTITUTE(M27," ",""),"0",""),"-",""))+LEN(SUBSTITUTE(SUBSTITUTE(SUBSTITUTE(N27," ",""),"0",""),"-",""))))),1,0),0)+IF(OR(COUNTA(J31,K31,M31,N31)>0,OR(L31="X",L31="x")),IF(OR(L31="X",L31="x",AND(OR(COUNTA(J31,K31,M31,N31)>0,OR(L31="X",L31="x")),(LEN(SUBSTITUTE(SUBSTITUTE(SUBSTITUTE(J31," ",""),"0",""),"-",""))+LEN(SUBSTITUTE(SUBSTITUTE(SUBSTITUTE(K31," ",""),"0",""),"-","")))=(LEN(SUBSTITUTE(SUBSTITUTE(SUBSTITUTE(M31," ",""),"0",""),"-",""))+LEN(SUBSTITUTE(SUBSTITUTE(SUBSTITUTE(N31," ",""),"0",""),"-",""))))),1,0),0) | M34: =LEN(SUBSTITUTE(SUBSTITUTE(SUBSTITUTE(M27," ",""),"0",""),"-",""))+LEN(SUBSTITUTE(SUBSTITUTE(SUBSTITUTE(N27," ",""),"0",""),"-",""))+LEN(SUBSTITUTE(SUBSTITUTE(SUBSTITUTE(J31," ",""),"0",""),"-",""))+LEN(SUBSTITUTE(SUBSTITUTE(SUBSTITUTE(K31," ",""),"0",""),"-","")) | N34: =LEN(SUBSTITUTE(SUBSTITUTE(SUBSTITUTE(J27," ",""),"0",""),"-",""))+LEN(SUBSTITUTE(SUBSTITUTE(SUBSTITUTE(K27," ",""),"0",""),"-",""))+LEN(SUBSTITUTE(SUBSTITUTE(SUBSTITUTE(M31," ",""),"0",""),"-",""))+LEN(SUBSTITUTE(SUBSTITUTE(SUBSTITUTE(N31," ",""),"0",""),"-","")) | O34: =RANK(AC34,$AC$34:$AC$38)+COUNTIF($AC$33:AC33,AC34) | U34: =(B34*1000000)-(C34*10000)+(D34*100)+(E34*1)-(F34*0.01) | AC34: =(J34*1000000)-(K34*10000)+(L34*100)+(M34*1)-(N34*0.01)
