Workbook

Sheet data
A1: Title prefix:
A2: Pool | B2: Player Name | C2: Player Dojo | D2: Display Name | E2: Player Number | F2: Metadata
A3: Pool A | B3: Oliver Walker | C3: Team Epsilon | D3: WALKER | E3: K1
A4: Pool A | B4: Fyodor Dostoevsky | C4: Team Zeta | D4: DOSTOEVSKY | E4: K2
A5: Pool A | B5: Samwise Gamgee | C5: Team Tau | D5: GAMGEE | E5: K3
A6: Pool B | B6: Michael Lewis | C6: Team Gamma | D6: LEWIS | E6: K4
A7: Pool B | B7: Bram Stoker | C7: Team Beta | D7: STOKER | E7: K5
A8: Pool B | B8: Kaden Martin | C8: Team Alpha | D8: MARTIN | E8: K6
A9: Pool C | B9: Isaac White | C9: Team Iota | D9: WHITE | E9: K7
A10: Pool C | B10: Nolan Clark | C10: Team Delta | D10: CLARK | E10: K8
A11: Pool C | B11: Petyr Baelish | C11: Team Pi | D11: BAELISH | E11: K9
A12: Pool D | B12: Gabriel Thomas | C12: Team Eta | D12: THOMAS | E12: K10
A13: Pool D | B13: Kevin Clark | C13: Team Alpha | D13: CLARK | E13: K11
A14: Pool D | B14: Tyrion Lannister | C14: Team Upsilon | D14: LANNISTER | E14: K12
... A93: Pool AE | B93: Thomas Hardy | C93: Team Upsilon | D93: HARDY | E93: K91

Sheet Time Estimator
A1: Number of pools | B1: Team size | C1: Matches per pool | D1: Time per match | E1: Total time for matches | F1: Padding time for rotation | G1: Time for breaks | H1: Total Time
A2: 31 | B2: 1 | C2: 89 | D2: 0.0020833333 | E2: =(A2*B2*C2*D2) | F2: 0.00034722222 | G2: 0.020833333 | H2: =C2*I2+J2
A3: 0 | B3: 0 | C3: 0 | D3: 0.0020833333 | E3: =(A3*B3*C3*D3) | F3: 0.00034722222 | G3: 0.020833333 | H3: =E3+(A3*C3*F3)+G3
A7: Number of Elimination Matches | B7: Team size | D7: Time per match | E7: Total time for matches | F7: Padding time for rotation | G7: Time for breaks | H7: Total Time
A8: 61 | B8: 1 | D8: 0.0027777778 | E8: =(A8*B8*D8) | F8: 0.00034722222 | G8: 0.020833333 | H8: =E8+(A8*F8)+G8
E13: Tournament Summary
A14: 2 | E14: Total Pool Time | H14: =H2
E15: Total Elimination Time | H15: =H8
E16: Grand Total (Sequential) | H16: =H14+H15
E17: Grand Total (Parallel across Courts) | H17: =H16/A14
E18: Start Time: | H18: 0.375
E19: Estimated Finish Time | H19: =H18+H17

Sheet Pool Draw
B2: =IF(data!$B$1="","Tournament Pools",data!$B$1&" - Tournament Pools")
B5: ='data'!$A$5 | D5: ='data'!$A$38 | F5: ='data'!$A$67
B6: =data!$E$3&" "&data!$B$3 | D6: =data!$E$36&" "&data!$B$36 | F6: =data!$E$65&" "&data!$B$65
B7: =data!$E$4&" "&data!$B$4 | D7: =data!$E$37&" "&data!$B$37 | F7: =data!$E$66&" "&data!$B$66
B8: =data!$E$5&" "&data!$B$5 | D8: =data!$E$38&" "&data!$B$38 | F8: =data!$E$67&" "&data!$B$67
B11: ='data'!$A$8 | D11: ='data'!$A$41 | F11: ='data'!$A$70
B12: =data!$E$6&" "&data!$B$6 | D12: =data!$E$39&" "&data!$B$39 | F12: =data!$E$68&" "&data!$B$68
B13: =data!$E$7&" "&data!$B$7 | D13: =data!$E$40&" "&data!$B$40 | F13: =data!$E$69&" "&data!$B$69
B14: =data!$E$8&" "&data!$B$8 | D14: =data!$E$41&" "&data!$B$41 | F14: =data!$E$70&" "&data!$B$70
B17: ='data'!$A$11 | D17: ='data'!$A$44 | F17: ='data'!$A$73
B18: =data!$E$9&" "&data!$B$9 | D18: =data!$E$42&" "&data!$B$42 | F18: =data!$E$71&" "&data!$B$71
B19: =data!$E$10&" "&data!$B$10 | D19: =data!$E$43&" "&data!$B$43 | F19: =data!$E$72&" "&data!$B$72
B20: =data!$E$11&" "&data!$B$11 | D20: =data!$E$44&" "&data!$B$44 | F20: =data!$E$73&" "&data!$B$73
B23: ='data'!$A$14 | D23: ='data'!$A$47 | F23: ='data'!$A$76
B24: =data!$E$12&" "&data!$B$12 | D24: =data!$E$45&" "&data!$B$45 | F24: =data!$E$74&" "&data!$B$74
B25: =data!$E$13&" "&data!$B$13 | D25: =data!$E$46&" "&data!$B$46 | F25: =data!$E$75&" "&data!$B$75
B26: =data!$E$14&" "&data!$B$14 | D26: =data!$E$47&" "&data!$B$47 | F26: =data!$E$76&" "&data!$B$76
B29: ='data'!$A$17 | D29: ='data'!$A$49 | F29: ='data'!$A$79
B30: =data!$E$15&" "&data!$B$15 | D30: =data!$E$48&" "&data!$B$48 | F30: =data!$E$77&" "&data!$B$77
B31: =data!$E$16&" "&data!$B$16 | D31: =data!$E$49&" "&data!$B$49 | F31: =data!$E$78&" "&data!$B$78
B32: =data!$E$17&" "&data!$B$17 | F32: =data!$E$79&" "&data!$B$79
D34: ='data'!$A$52
B35: ='data'!$A$20 | D35: =data!$E$50&" "&data!$B$50 | F35: ='data'!$A$82
B36: =data!$E$18&" "&data!$B$18 | D36: =data!$E$51&" "&data!$B$51 | F36: =data!$E$80&" "&data!$B$80
B37: =data!$E$19&" "&data!$B$19 | D37: =data!$E$52&" "&data!$B$52 | F37: =data!$E$81&" "&data!$B$81
B38: =data!$E$20&" "&data!$B$20 | F38: =data!$E$82&" "&data!$B$82
D40: ='data'!$A$55
B41: ='data'!$A$23 | D41: =data!$E$53&" "&data!$B$53 | F41: ='data'!$A$85
B42: =data!$E$21&" "&data!$B$21 | D42: =data!$E$54&" "&data!$B$54 | F42: =data!$E$83&" "&data!$B$83
B43: =data!$E$22&" "&data!$B$22 | D43: =data!$E$55&" "&data!$B$55 | F43: =data!$E$84&" "&data!$B$84
B44: =data!$E$23&" "&data!$B$23 | F44: =data!$E$85&" "&data!$B$85
D46: ='data'!$A$58
B47: ='data'!$A$26 | D47: =data!$E$56&" "&data!$B$56 | F47: ='data'!$A$88
B48: =data!$E$24&" "&data!$B$24 | D48: =data!$E$57&" "&data!$B$57 | F48: =data!$E$86&" "&data!$B$86
B49: =data!$E$25&" "&data!$B$25 | D49: =data!$E$58&" "&data!$B$58 | F49: =data!$E$87&" "&data!$B$87
B50: =data!$E$26&" "&data!$B$26 | F50: =data!$E$88&" "&data!$B$88
D52: ='data'!$A$61
B53: ='data'!$A$29 | D53: =data!$E$59&" "&data!$B$59 | F53: ='data'!$A$91
B54: =data!$E$27&" "&data!$B$27 | D54: =data!$E$60&" "&data!$B$60 | F54: =data!$E$89&" "&data!$B$89
B55: =data!$E$28&" "&data!$B$28 | D55: =data!$E$61&" "&data!$B$61 | F55: =data!$E$90&" "&data!$B$90
...

Sheet Pool Matches
A1: Shiaijo A | I1: Shiaijo B
A2: ='data'!$A$5 | I2: ='data'!$A$52
A3: White | D3: vs | G3: Red | I3: White | L3: vs | O3: Red
A4: =data!$E$4&" "&data!$B$4 | G4: =data!$E$3&" "&data!$B$3 | I4: =data!$E$51&" "&data!$B$51 | O4: =data!$E$50&" "&data!$B$50
A5: =data!$E$5&" "&data!$B$5 | G5: =data!$E$3&" "&data!$B$3 | I5: =data!$E$52&" "&data!$B$52 | O5: =data!$E$50&" "&data!$B$50
A6: =data!$E$5&" "&data!$B$5 | G6: =data!$E$4&" "&data!$B$4 | I6: =data!$E$52&" "&data!$B$52 | O6: =data!$E$51&" "&data!$B$51
A8: Results | B8: W | C8: L | D8: T | E8: PW | F8: PL | G8: Rank | I8: Results | J8: W | K8: L | L8: T | M8: PW | N8: PL | O8: Rank
A9: =data!$E$3&" "&data!$B$3 | B9: =IF(OR(COUNTA(B4,C4,E4,F4)>0,OR(D4="X",D4="x")),IF(OR(D4="X",D4="x",AND(OR(COUNTA(B4,C4,E4,F4)>0,OR(D4="X",D4="x")),(LEN(SUBSTITUTE(SUBSTITUTE(SUBSTITUTE(B4," ",""),"0",""),"-",""))+LEN(SUBSTITUTE(SUBSTITUTE(SUBSTITUTE(C4," ",""),"0",""),"-","")))=(LEN(SUBSTITUTE(SUBSTITUTE(SUBSTITUTE(E4," ",""),"0",""),"-",""))+LEN(SUBSTITUTE(SUBSTITUTE(SUBSTITUTE(F4," ",""),"0",""),"-",""))))),0,(LEN(SUBSTITUTE(SUBSTITUTE(SUBSTITUTE(E4," ",""),"0",""),"-",""))+LEN(SUBSTITUTE(SUBSTITUTE(SUBSTITUTE(F4," ",""),"0",""),"-",""))>LEN(SUBSTITUTE(SUBSTITUTE(SUBSTITUTE(B4," ",""),"0",""),"-",""))+LEN(SUBSTITUTE(SUBSTITUTE(SUBSTITUTE(C4," ",""),"0",""),"-","")))*1),0)+IF(OR(COUNTA(B5,C5,E5,F5)>0,OR(D5="X",D5="x")),IF(OR(D5="X",D5="x",AND(OR(COUNTA(B5,C5,E5,F5)>0,OR(D5="X",D5="x")),(LEN(SUBSTITUTE(SUBSTITUTE(SUBSTITUTE(B5," ",""),"0",""),"-",""))+LEN(SUBSTITUTE(SUBSTITUTE(SUBSTITUTE(C5," ",""),"0",""),"-","")))=(LEN(SUBSTITUTE(SUBSTITUTE(SUBSTITUTE(E5," ",""),"0",""),"-",""))+LEN(SUBSTITUTE(SUBSTITUTE(SUBSTITUTE(F5," ",""),"0",""),"-",""))))),0,(LEN(SUBSTITUTE(SUBSTITUTE(SUBSTITUTE(E5," ",""),"0",""),"-",""))+LEN(SUBSTITUTE(SUBSTITUTE(SUBSTITUTE(F5," ",""),"0",""),"-",""))>LEN(SUBSTITUTE(SUBSTITUTE(SUBSTITUTE(B5," ",""),"0",""),"-",""))+LEN(SUBSTITUTE(SUBSTITUTE(SUBSTITUTE(C5," ",""),"0",""),"-","")))*1),0) | C9: =IF(OR(COUNTA(B4,C4,E4,F4)>0,OR(D4="X",D4="x")),IF(OR(D4="X",D4="x",AND(OR(COUNTA(B4,C4,E4,F4)>0,OR(D4="X",D4="x")),(LEN(SUBSTITUTE(SUBSTITUTE(SUBSTITUTE(B4," ",""),"0",""),"-",""))+LEN(SUBSTITUTE(SUBSTITUTE(SUBSTITUTE(C4," ",""),"0",""),"-","")))=(LEN(SUBSTITUTE(SUBSTITUTE(SUBSTITUTE(E4," ",""),"0",""),"-",""))+LEN(SUBSTITUTE(SUBSTITUTE(SUBSTITUTE(F4," ",""),"0",""),"-",""))))),0,(LEN(SUBSTITUTE(SUBSTITUTE(SUBSTITUTE(E4," ",""),"0",""),"-",""))+LEN(SUBSTITUTE(SUBSTITUTE(SUBSTITUTE(F4," ",""),"0",""),"-",""))<LEN(SUBSTITUTE(SUBSTITUTE(SUBSTITUTE(B4," ",""),"0",""),"-",""))+LEN(SUBSTITUTE(SUBSTITUTE(SUBSTITUTE(C4," ",""),"0",""),"-","")))*1),0)+IF(OR(COUNTA(B5,C5,E5,F5)>0,OR(D5="X",D5="x")),IF(OR(D5="X",D5="x",AND(OR(COUNTA(B5,C5,E5,F5)>0,OR(D5="X",D5="x")),(LEN(SUBSTITUTE(SUBSTITUTE(SUBSTITUTE(B5," ",""),"0",""),"-",""))+LEN(SUBSTITUTE(SUBSTITUTE(SUBSTITUTE(C5," ",""),"0",""),"-","")))=(LEN(SUBSTITUTE(SUBSTITUTE(SUBSTITUTE(E5," ",""),"0",""),"-",""))+LEN(SUBSTITUTE(SUBSTITUTE(SUBSTITUTE(F5," ",""),"0",""),"-",""))))),0,(LEN(SUBSTITUTE(SUBSTITUTE(SUBSTITUTE(E5," ",""),"0",""),"-",""))+LEN(SUBSTITUTE(SUBSTITUTE(SUBSTITUTE(F5," ",""),"0",""),"-",""))<LEN(SUBSTITUTE(SUBSTITUTE(SUBSTITUTE(B5," ",""),"0",""),"-",""))+LEN(SUBSTITUTE(SUBSTITUTE(SUBSTITUTE(C5," ",""),"0",""),"-","")))*1),0) | D9: =IF(OR(COUNTA(B4,C4,E4,F4)>0,OR(D4="X",D4="x")),IF(OR(D4="X",D4="x",AND(OR(COUNTA(B4,C4,E4,F4)>0,OR(D4="X",D4="x")),(LEN(SUBSTITUTE(SUBSTITUTE(SUBSTITUTE(B4," ",""),"0",""),"-",""))+LEN(SUBSTITUTE(SUBSTITUTE(SUBSTITUTE(C4," ",""),"0",""),"-","")))=(LEN(SUBSTITUTE(SUBSTITUTE(SUBSTITUTE(E4," ",""),"0",""),"-",""))+LEN(SUBSTITUTE(SUBSTITUTE(SUBSTITUTE(F4," ",""),"0",""),"-",""))))),1,0),0)+IF(OR(COUNTA(B5,C5,E5,F5)>0,OR(D5="X",D5="x")),IF(OR(D5="X",D5="x",AND(OR(COUNTA(B5,C5,E5,F5)>0,OR(D5="X",D5="x")),(LEN(SUBSTITUTE(SUBSTITUTE(SUBSTITUTE(B5," ",""),"0",""),"-",""))+LEN(SUBSTITUTE(SUBSTITUTE(SUBSTITUTE(C5," ",""),"0",""),"-","")))=(LEN(SUBSTITUTE(SUBSTITUTE(SUBSTITUTE(E5," ",""),"0",""),"-",""))+LEN(SUBSTITUTE(SUBSTITUTE(SUBSTITUTE(F5," ",""),"0",""),"-",""))))),1,0),0) | E9: =LEN(SUBSTITUTE(SUBSTITUTE(SUBSTITUTE(E4," ",""),"0",""),"-",""))+LEN(SUBSTITUTE(SUBSTITUTE(SUBSTITUTE(F4," ",""),"0",""),"-",""))+LEN(SUBSTITUTE(SUBSTITUTE(SUBSTITUTE(E5," ",""),"0",""),"-",""))+LEN(SUBSTITUTE(SUBSTITUTE(SUBSTITUTE(F5," ",""),"0",""),"-","")) | F9: =LEN(SUBSTITUTE(SUBSTITUTE(SUBSTITUTE(B4," ",""),"0",""),"-",""))+LEN(SUBSTITUTE(SUBSTITUTE(SUBSTITUTE(C4," ",""),"0",""),"-",""))+LEN(SUBSTITUTE(SUBSTITUTE(SUBSTITUTE(B5," ",""),"0",""),"-",""))+LEN(SUBSTITUTE(SUBSTITUTE(SUBSTITUTE(C5," ",""),"0",""),"-","")) | G9: =RANK(U9,$U$9:$U$11)+COUNTIF($U$8:U8,U9) | I9: =data!$E$50&" "&data!$B$50 | J9: =IF(OR(COUNTA(J4,K4,M4,N4)>0,OR(L4="X",L4="x")),IF(OR(L4="X",L4="x",AND(OR(COUNTA(J4,K4,M4,N4)>0,OR(L4="X",L4="x")),(LEN(SUBSTITUTE(SUBSTITUTE(SUBSTITUTE(J4," ",""),"0",""),"-",""))+LEN(SUBSTITUTE(SUBSTITUTE(SUBSTITUTE(K4," ",""),"0",""),"-","")))=(LEN(SUBSTITUTE(SUBSTITUTE(SUBSTITUTE(M4," ",""),"0",""),"-",""))+LEN(SUBSTITUTE(SUBSTITUTE(SUBSTITUTE(N4," ",""),"0",""),"-",""))))),0,(LEN(SUBSTITUTE(SUBSTITUTE(SUBSTITUTE(M4," ",""),"0",""),"-",""))+LEN(SUBSTITUTE(SUBSTITUTE(SUBSTITUTE(N4," ",""),"0",""),"-",""))>LEN(SUBSTITUTE(SUBSTITUTE(SUBSTITUTE(J4," ",""),"0",""),"-",""))+LEN(SUBSTITUTE(SUBSTITUTE(SUBSTITUTE(K4," ",""),"0",""),"-","")))*1),0)+IF(OR(COUNTA(J5,K5,M5,N5)>0,OR(L5="X",L5="x")),IF(OR(L5="X",L5="x",AND(OR(COUNTA(J5,K5,M5,N5)>0,OR(L5="X",L5="x")),(LEN(SUBSTITUTE(SUBSTITUTE(SUBSTITUTE(J5," ",""),"0",""),"-",""))+LEN(SUBSTITUTE(SUBSTITUTE(SUBSTITUTE(K5," ",""),"0",""),"-","")))=(LEN(SUBSTITUTE(SUBSTITUTE(SUBSTITUTE(M5," ",""),"0",""),"-",""))+LEN(SUBSTITUTE(SUBSTITUTE(SUBSTITUTE(N5," ",""),"0",""),"-",""))))),0,(LEN(SUBSTITUTE(SUBSTITUTE(SUBSTITUTE(M5," ",""),"0",""),"-",""))+LEN(SUBSTITUTE(SUBSTITUTE(SUBSTITUTE(N5," ",""),"0",""),"-",""))>LEN(SUBSTITUTE(SUBSTITUTE(SUBSTITUTE(J5," ",""),"0",""),"-",""))+LEN(SUBSTITUTE(SUBSTITUTE(SUBSTITUTE(K5," ",""),"0",""),"-","")))*1),0) | K9: =IF(OR(COUNTA(J4,K4,M4,N4)>0,OR(L4="X",L4="x")),IF(OR(L4="X",L4="x",AND(OR(COUNTA(J4,K4,M4,N4)>0,OR(L4="X",L4="x")),(LEN(SUBSTITUTE(SUBSTITUTE(SUBSTITUTE(J4," ",""),"0",""),"-",""))+LEN(SUBSTITUTE(SUBSTITUTE(SUBSTITUTE(K4," ",""),"0",""),"-","")))=(LEN(SUBSTITUTE(SUBSTITUTE(SUBSTITUTE(M4," ",""),"0",""),"-",""))+LEN(SUBSTITUTE(SUBSTITUTE(SUBSTITUTE(N4," ",""),"0",""),"-",""))))),0,(LEN(SUBSTITUTE(SUBSTITUTE(SUBSTITUTE(M4," ",""),"0",""),"-",""))+LEN(SUBSTITUTE(SUBSTITUTE(SUBSTITUTE(N4," ",""),"0",""),"-",""))<LEN(SUBSTITUTE(SUBSTITUTE(SUBSTITUTE(J4," ",""),"0",""),"-",""))+LEN(SUBSTITUTE(SUBSTITUTE(SUBSTITUTE(K4," ",""),"0",""),"-","")))*1),0)+IF(OR(COUNTA(J5,K5,M5,N5)>0,OR(L5="X",L5="x")),IF(OR(L5="X",L5="x",AND(OR(COUNTA(J5,K5,M5,N5)>0,OR(L5="X",L5="x")),(LEN(SUBSTITUTE(SUBSTITUTE(SUBSTITUTE(J5," ",""),"0",""),"-",""))+LEN(SUBSTITUTE(SUBSTITUTE(SUBSTITUTE(K5," ",""),"0",""),"-","")))=(LEN(SUBSTITUTE(SUBSTITUTE(SUBSTITUTE(M5," ",""),"0",""),"-",""))+LEN(SUBSTITUTE(SUBSTITUTE(SUBSTITUTE(N5," ",""),"0",""),"-",""))))),0,(LEN(SUBSTITUTE(SUBSTITUTE(SUBSTITUTE(M5," ",""),"0",""),"-",""))+LEN(SUBSTITUTE(SUBSTITUTE(SUBSTITUTE(N5," ",""),"0",""),"-",""))<LEN(SUBSTITUTE(SUBSTITUTE(SUBSTITUTE(J5," ",""),"0",""),"-",""))+LEN(SUBSTITUTE(SUBSTITUTE(SUBSTITUTE(K5," ",""),"0",""),"-","")))*1),0) | L9: =IF(OR(COUNTA(J4,K4,M4,N4)>0,OR(L4="X",L4="x")),IF(OR(L4="X",L4="x",AND(OR(COUNTA(J4,K4,M4,N4)>0,OR(L4="X",L4="x")),(LEN(SUBSTITUTE(SUBSTITUTE(SUBSTITUTE(J4," ",""),"0",""),"-",""))+LEN(SUBSTITUTE(SUBSTITUTE(SUBSTITUTE(K4," ",""),"0",""),"-","")))=(LEN(SUBSTITUTE(SUBSTITUTE(SUBSTITUTE(M4," ",""),"0",""),"-",""))+LEN(SUBSTITUTE(SUBSTITUTE(SUBSTITUTE(N4," ",""),"0",""),"-",""))))),1,0),0)+IF(OR(COUNTA(J5,K5,M5,N5)>0,OR(L5="X",L5="x")),IF(OR(L5="X",L5="x",AND(OR(COUNTA(J5,K5,M5,N5)>0,OR(L5="X",L5="x")),(LEN(SUBSTITUTE(SUBSTITUTE(SUBSTITUTE(J5," ",""),"0",""),"-",""))+LEN(SUBSTITUTE(SUBSTITUTE(SUBSTITUTE(K5," ",""),"0",""),"-","")))=(LEN(SUBSTITUTE(SUBSTITUTE(SUBSTITUTE(M5," ",""),"0",""),"-",""))+LEN(SUBSTITUTE(SUBSTITUTE(SUBSTITUTE(N5," ",""),"0",""),"-",""))))),1,0),0) | M9: =LEN(SUBSTITUTE(SUBSTITUTE(SUBSTITUTE(M4," ",""),"0",""),"-",""))+LEN(SUBSTITUTE(SUBSTITUTE(SUBSTITUTE(N4," ",""),"0",""),"-",""))+LEN(SUBSTITUTE(SUBSTITUTE(SUBSTITUTE(M5," ",""),"0",""),"-",""))+LEN(SUBSTITUTE(SUBSTITUTE(SUBSTITUTE(N5," ",""),"0",""),"-","")) | N9: =LEN(SUBSTITUTE(SUBSTITUTE(SUBSTITUTE(J4," ",""),"0",""),"-",""))+LEN(SUBSTITUTE(SUBSTITUTE(SUBSTITUTE(K4," ",""),"0",""),"-",""))+LEN(SUBSTITUTE(SUBSTITUTE(SUBSTITUTE(J5," ",""),"0",""),"-",""))+LEN(SUBSTITUTE(SUBSTITUTE(SUBSTITUTE(K5," ",""),"0",""),"-","")) | O9: =RANK(AC9,$AC$9:$AC$11)+COUNTIF($AC$8:AC8,AC9) | U9: =(B9*1000000)-(C9*10000)+(D9*100)+(E9*1)-(F9*0.01) | AC9: =(J9*1000000)-(K9*10000)+(L9*100)+(M9*1)-(N9*0.01)
A10: =data!$E$4&" "&data!$B$4 | B10: =IF(OR(COUNTA(B4,C4,E4,F4)>0,OR(D4="X",D4="x")),IF(OR(D4="X",D4="x",AND(OR(COUNTA(B4,C4,E4,F4)>0,OR(D4="X",D4="x")),(LEN(SUBSTITUTE(SUBSTITUTE(SUBSTITUTE(B4," ",""),"0",""),"-",""))+LEN(SUBSTITUTE(SUBSTITUTE(SUBSTITUTE(C4," ",""),"0",""),"-","")))=(LEN(SUBSTITUTE(SUBSTITUTE(SUBSTITUTE(E4," ",""),"0",""),"-",""))+LEN(SUBSTITUTE(SUBSTITUTE(SUBSTITUTE(F4," ",""),"0",""),"-",""))))),0,(LEN(SUBSTITUTE(SUBSTITUTE(SUBSTITUTE(B4," ",""),"0",""),"-",""))+LEN(SUBSTITUTE(SUBSTITUTE(SUBSTITUTE(C4," ",""),"0",""),"-",""))>LEN(SUBSTITUTE(SUBSTITUTE(SUBSTITUTE(E4," ",""),"0",""),"-",""))+LEN(SUBSTITUTE(SUBSTITUTE(SUBSTITUTE(F4," ",""),"0",""),"-","")))*1),0)+IF(OR(COUNTA(B6,C6,E6,F6)>0,OR(D6="X",D6="x")),IF(OR(D6="X",D6="x",AND(OR(COUNTA(B6,C6,E6,F6)>0,OR(D6="X",D6="x")),(LEN(SUBSTITUTE(SUBSTITUTE(SUBSTITUTE(B6," ",""),"0",""),"-",""))+LEN(SUBSTITUTE(SUBSTITUTE(SUBSTITUTE(C6," ",""),"0",""),"-","")))=(LEN(SUBSTITUTE(SUBSTITUTE(SUBSTITUTE(E6," ",""),"0",""),"-",""))+LEN(SUBSTITUTE(SUBSTITUTE(SUBSTITUTE(F6," ",""),"0",""),"-",""))))),0,(LEN(SUBSTITUTE(SUBSTITUTE(SUBSTITUTE(E6," ",""),"0",""),"-",""))+LEN(SUBSTITUTE(SUBSTITUTE(SUBSTITUTE(F6," ",""),"0",""),"-",""))>LEN(SUBSTITUTE(SUBSTITUTE(SUBSTITUTE(B6," ",""),"0",""),"-",""))+LEN(SUBSTITUTE(SUBSTITUTE(SUBSTITUTE(C6," ",""),"0",""),"-","")))*1),0) | C10: =IF(OR(COUNTA(B4,C4,E4,F4)>0,OR(D4="X",D4="x")),IF(OR(D4="X",D4="x",AND(OR(COUNTA(B4,C4,E4,F4)>0,OR(D4="X",D4="x")),(LEN(SUBSTITUTE(SUBSTITUTE(SUBSTITUTE(B4," ",""),"0",""),"-",""))+LEN(SUBSTITUTE(SUBSTITUTE(SUBSTITUTE(C4," ",""),"0",""),"-","")))=(LEN(SUBSTITUTE(SUBSTITUTE(SUBSTITUTE(E4," ",""),"0",""),"-",""))+LEN(SUBSTITUTE(SUBSTITUTE(SUBSTITUTE(F4," ",""),"0",""),"-",""))))),0,(LEN(SUBSTITUTE(SUBSTITUTE(SUBSTITUTE(B4," ",""),"0",""),"-",""))+LEN(SUBSTITUTE(SUBSTITUTE(SUBSTITUTE(C4," ",""),"0",""),"-",""))<LEN(SUBSTITUTE(SUBSTITUTE(SUBSTITUTE(E4," ",""),"0",""),"-",""))+LEN(SUBSTITUTE(SUBSTITUTE(SUBSTITUTE(F4," ",""),"0",""),"-","")))*1),0)+IF(OR(COUNTA(B6,C6,E6,F6)>0,OR(D6="X",D6="x")),IF(OR(D6="X",D6="x",AND(OR(COUNTA(B6,C6,E6,F6)>0,OR(D6="X",D6="x")),(LEN(SUBSTITUTE(SUBSTITUTE(SUBSTITUTE(B6," ",""),"0",""),"-",""))+LEN(SUBSTITUTE(SUBSTITUTE(SUBSTITUTE(C6," ",""),"0",""),"-","")))=(LEN(SUBSTITUTE(SUBSTITUTE(SUBSTITUTE(E6," ",""),"0",""),"-",""))+LEN(SUBSTITUTE(SUBSTITUTE(SUBSTITUTE(F6," ",""),"0",""),"-",""))))),0,(LEN(SUBSTITUTE(SUBSTITUTE(SUBSTITUTE(E6," ",""),"0",""),"-",""))+LEN(SUBSTITUTE(SUBSTITUTE(SUBSTITUTE(F6," ",""),"0",""),"-",""))<LEN(SUBSTITUTE(SUBSTITUTE(SUBSTITUTE(B6," ",""),"0",""),"-",""))+LEN(SUBSTITUTE(SUBSTITUTE(SUBSTITUTE(C6," ",""),"0",""),"-","")))*1),0) | D10: =IF(OR(COUNTA(B4,C4,E4,F4)>0,OR(D4="X",D4="x")),IF(OR(D4="X",D4="x",AND(OR(COUNTA(B4,C4,E4,F4)>0,OR(D4="X",D4="x")),(LEN(SUBSTITUTE(SUBSTITUTE(SUBSTITUTE(B4," ",""),"0",""),"-",""))+LEN(SUBSTITUTE(SUBSTITUTE(SUBSTITUTE(C4," ",""),"0",""),"-","")))=(LEN(SUBSTITUTE(SUBSTITUTE(SUBSTITUTE(E4," ",""),"0",""),"-",""))+LEN(SUBSTITUTE(SUBSTITUTE(SUBSTITUTE(F4," ",""),"0",""),"-",""))))),1,0),0)+IF(OR(COUNTA(B6,C6,E6,F6)>0,OR(D6="X",D6="x")),IF(OR(D6="X",D6="x",AND(OR(COUNTA(B6,C6,E6,F6)>0,OR(D6="X",D6="x")),(LEN(SUBSTITUTE(SUBSTITUTE(SUBSTITUTE(B6," ",""),"0",""),"-",""))+LEN(SUBSTITUTE(SUBSTITUTE(SUBSTITUTE(C6," ",""),"0",""),"-","")))=(LEN(SUBSTITUTE(SUBSTITUTE(SUBSTITUTE(E6," ",""),"0",""),"-",""))+LEN(SUBSTITUTE(SUBSTITUTE(SUBSTITUTE(F6," ",""),"0",""),"-",""))))),1,0),0) | E10: =LEN(SUBSTITUTE(SUBSTITUTE(SUBSTITUTE(B4," ",""),"0",""),"-",""))+LEN(SUBSTITUTE(SUBSTITUTE(SUBSTITUTE(C4," ",""),"0",""),"-",""))+LEN(SUBSTITUTE(SUBSTITUTE(SUBSTITUTE(E6," ",""),"0",""),"-",""))+LEN(SUBSTITUTE(SUBSTITUTE(SUBSTITUTE(F6," ",""),"0",""),"-","")) | F10: =LEN(SUBSTITUTE(SUBSTITUTE(SUBSTITUTE(E4," ",""),"0",""),"-",""))+LEN(SUBSTITUTE(SUBSTITUTE(SUBSTITUTE(F4," ",""),"0",""),"-",""))+LEN(SUBSTITUTE(SUBSTITUTE(SUBSTITUTE(B6," ",""),"0",""),"-",""))+LEN(SUBSTITUTE(SUBSTITUTE(SUBSTITUTE(C6," ",""),"0",""),"-","")) | G10: =RANK(U10,$U$9:$U$11)+COUNTIF($U$8:U9,U10) | I10: =data!$E$51&" "&data!$B$51 | J10: =IF(OR(COUNTA(J4,K4,M4,N4)>0,OR(L4="X",L4="x")),IF(OR(L4="X",L4="x",AND(OR(COUNTA(J4,K4,M4,N4)>0,OR(L4="X",L4="x")),(LEN(SUBSTITUTE(SUBSTITUTE(SUBSTITUTE(J4," ",""),"0",""),"-",""))+LEN(SUBSTITUTE(SUBSTITUTE(SUBSTITUTE(K4," ",""),"0",""),"-","")))=(LEN(SUBSTITUTE(SUBSTITUTE(SUBSTITUTE(M4," ",""),"0",""),"-",""))+LEN(SUBSTITUTE(SUBSTITUTE(SUBSTITUTE(N4," ",""),"0",""),"-",""))))),0,(LEN(SUBSTITUTE(SUBSTITUTE(SUBSTITUTE(J4," ",""),"0",""),"-",""))+LEN(SUBSTITUTE(SUBSTITUTE(SUBSTITUTE(K4," ",""),"0",""),"-",""))>LEN(SUBSTITUTE(SUBSTITUTE(SUBSTITUTE(M4," ",""),"0",""),"-",""))+LEN(SUBSTITUTE(SUBSTITUTE(SUBSTITUTE(N4," ",""),"0",""),"-","")))*1),0)+IF(OR(COUNTA(J6,K6,M6,N6)>0,OR(L6="X",L6="x")),IF(OR(L6="X",L6="x",AND(OR(COUNTA(J6,K6,M6,N6)>0,OR(L6="X",L6="x")),(LEN(SUBSTITUTE(SUBSTITUTE(SUBSTITUTE(J6," ",""),"0",""),"-",""))+LEN(SUBSTITUTE(SUBSTITUTE(SUBSTITUTE(K6," ",""),"0",""),"-","")))=(LEN(SUBSTITUTE(SUBSTITUTE(SUBSTITUTE(M6," ",""),"0",""),"-",""))+LEN(SUBSTITUTE(SUBSTITUTE(SUBSTITUTE(N6," ",""),"0",""),"-",""))))),0,(LEN(SUBSTITUTE(SUBSTITUTE(SUBSTITUTE(M6," ",""),"0",""),"-",""))+LEN(SUBSTITUTE(SUBSTITUTE(SUBSTITUTE(N6," ",""),"0",""),"-",""))>LEN(SUBSTITUTE(SUBSTITUTE(SUBSTITUTE(J6," ",""),"0",""),"-",""))+LEN(SUBSTITUTE(SUBSTITUTE(SUBSTITUTE(K6," ",""),"0",""),"-","")))*1),0) | K10: =IF(OR(COUNTA(J4,K4,M4,N4)>0,OR(L4="X",L4="x")),IF(OR(L4="X",L4="x",AND(OR(COUNTA(J4,K4,M4,N4)>0,OR(L4="X",L4="x")),(LEN(SUBSTITUTE(SUBSTITUTE(SUBSTITUTE(J4," ",""),"0",""),"-",""))+LEN(SUBSTITUTE(SUBSTITUTE(SUBSTITUTE(K4," ",""),"0",""),"-","")))=(LEN(SUBSTITUTE(SUBSTITUTE(SUBSTITUTE(M4," ",""),"0",""),"-",""))+LEN(SUBSTITUTE(SUBSTITUTE(SUBSTITUTE(N4," ",""),"0",""),"-",""))))),0,(LEN(SUBSTITUTE(SUBSTITUTE(SUBSTITUTE(J4," ",""),"0",""),"-",""))+LEN(SUBSTITUTE(SUBSTITUTE(SUBSTITUTE(K4," ",""),"0",""),"-",""))<LEN(SUBSTITUTE(SUBSTITUTE(SUBSTITUTE(M4," ",""),"0",""),"-",""))+LEN(SUBSTITUTE(SUBSTITUTE(SUBSTITUTE(N4," ",""),"0",""),"-","")))*1),0)+IF(OR(COUNTA(J6,K6,M6,N6)>0,OR(L6="X",L6="x")),IF(OR(L6="X",L6="x",AND(OR(COUNTA(J6,K6,M6,N6)>0,OR(L6="X",L6="x")),(LEN(SUBSTITUTE(SUBSTITUTE(SUBSTITUTE(J6," ",""),"0",""),"-",""))+LEN(SUBSTITUTE(SUBSTITUTE(SUBSTITUTE(K6," ",""),"0",""),"-","")))=(LEN(SUBSTITUTE(SUBSTITUTE(SUBSTITUTE(M6," ",""),"0",""),"-",""))+LEN(SUBSTITUTE(SUBSTITUTE(SUBSTITUTE(N6," ",""),"0",""),"-",""))))),0,(LEN(SUBSTITUTE(SUBSTITUTE(SUBSTITUTE(M6," ",""),"0",""),"-",""))+LEN(SUBSTITUTE(SUBSTITUTE(SUBSTITUTE(N6," ",""),"0",""),"-",""))<LEN(SUBSTITUTE(SUBSTITUTE(SUBSTITUTE(J6," ",""),"0",""),"-",""))+LEN(SUBSTITUTE(SUBSTITUTE(SUBSTITUTE(K6," ",""),"0",""),"-","")))*1),0) | L10: =IF(OR(COUNTA(J4,K4,M4,N4)>0,OR(L4="X",L4="x")),IF(OR(L4="X",L4="x",AND(OR(COUNTA(J4,K4,M4,N4)>0,OR(L4="X",L4="x")),(LEN(SUBSTITUTE(SUBSTITUTE(SUBSTITUTE(J4," ",""),"0",""),"-",""))+LEN(SUBSTITUTE(SUBSTITUTE(SUBSTITUTE(K4," ",""),"0",""),"-","")))=(LEN(SUBSTITUTE(SUBSTITUTE(SUBSTITUTE(M4," ",""),"0",""),"-",""))+LEN(SUBSTITUTE(SUBSTITUTE(SUBSTITUTE(N4," ",""),"0",""),"-",""))))),1,0),0)+IF(OR(COUNTA(J6,K6,M6,N6)>0,OR(L6="X",L6="x")),IF(OR(L6="X",L6="x",AND(OR(COUNTA(J6,K6,M6,N6)>0,OR(L6="X",L6="x")),(LEN(SUBSTITUTE(SUBSTITUTE(SUBSTITUTE(J6," ",""),"0",""),"-",""))+LEN(SUBSTITUTE(SUBSTITUTE(SUBSTITUTE(K6," ",""),"0",""),"-","")))=(LEN(SUBSTITUTE(SUBSTITUTE(SUBSTITUTE(M6," ",""),"0",""),"-",""))+LEN(SUBSTITUTE(SUBSTITUTE(SUBSTITUTE(N6," ",""),"0",""),"-",""))))),1,0),0) | M10: =LEN(SUBSTITUTE(SUBSTITUTE(SUBSTITUTE(J4," ",""),"0",""),"-",""))+LEN(SUBSTITUTE(SUBSTITUTE(SUBSTITUTE(K4," ",""),"0",""),"-",""))+LEN(SUBSTITUTE(SUBSTITUTE(SUBSTITUTE(M6," ",""),"0",""),"-",""))+LEN(SUBSTITUTE(SUBSTITUTE(SUBSTITUTE(N6," ",""),"0",""),"-","")) | N10: =LEN(SUBSTITUTE(SUBSTITUTE(SUBSTITUTE(M4," ",""),"0",""),"-",""))+LEN(SUBSTITUTE(SUBSTITUTE(SUBSTITUTE(N4," ",""),"0",""),"-",""))+LEN(SUBSTITUTE(SUBSTITUTE(SUBSTITUTE(J6," ",""),"0",""),"-",""))+LEN(SUBSTITUTE(SUBSTITUTE(SUBSTITUTE(K6," ",""),"0",""),"-","")) | O10: =RANK(AC10,$AC$9:$AC$11)+COUNTIF($AC$8:AC9,AC10) | U10: =(B10*1000000)-(C10*10000)+(D10*100)+(E10*1)-(F10*0.01) | AC10: =(J10*1000000)-(K10*10000)+(L10*100)+(M10*1)-(N10*0.01)
A11: =data!$E$5&" "&data!$B$5 | B11: =IF(OR(COUNTA(B5,C5,E5,F5)>0,OR(D5="X",D5="x")),IF(OR(D5="X",D5="x",AND(OR(COUNTA(B5,C5,E5,F5)>0,OR(D5="X",D5="x")),(LEN(SUBSTITUTE(SUBSTITUTE(SUBSTITUTE(B5," ",""),"0",""),"-",""))+LEN(SUBSTITUTE(SUBSTITUTE(SUBSTITUTE(C5," ",""),"0",""),"-","")))=(LEN(SUBSTITUTE(SUBSTITUTE(SUBSTITUTE(E5," ",""),"0",""),"-",""))+LEN(SUBSTITUTE(SUBSTITUTE(SUBSTITUTE(F5," ",""),"0",""),"-",""))))),0,(LEN(SUBSTITUTE(SUBSTITUTE(SUBSTITUTE(B5," ",""),"0",""),"-",""))+LEN(SUBSTITUTE(SUBSTITUTE(SUBSTITUTE(C5," ",""),"0",""),"-",""))>LEN(SUBSTITUTE(SUBSTITUTE(SUBSTITUTE(E5," ",""),"0",""),"-",""))+LEN(SUBSTITUTE(SUBSTITUTE(SUBSTITUTE(F5," ",""),"0",""),"-","")))*1),0)+IF(OR(COUNTA(B6,C6,E6,F6)>0,OR(D6="X",D6="x")),IF(OR(D6="X",D6="x",AND(OR(COUNTA(B6,C6,E6,F6)>0,OR(D6="X",D6="x")),(LEN(SUBSTITUTE(SUBSTITUTE(SUBSTITUTE(B6," ",""),"0",""),"-",""))+LEN(SUBSTITUTE(SUBSTITUTE(SUBSTITUTE(C6," ",""),"0",""),"-","")))=(LEN(SUBSTITUTE(SUBSTITUTE(SUBSTITUTE(E6," ",""),"0",""),"-",""))+LEN(SUBSTITUTE(SUBSTITUTE(SUBSTITUTE(F6," ",""),"0",""),"-",""))))),0,(LEN(SUBSTITUTE(SUBSTITUTE(SUBSTITUTE(B6," ",""),"0",""),"-",""))+LEN(SUBSTITUTE(SUBSTITUTE(SUBSTITUTE(C6," ",""),"0",""),"-",""))>LEN(SUBSTITUTE(SUBSTITUTE(SUBSTITUTE(E6," ",""),"0",""),"-",""))+LEN(SUBSTITUTE(SUBSTITUTE(SUBSTITUTE(F6," ",""),"0",""),"-","")))*1),0) | C11: =IF(OR(COUNTA(B5,C5,E5,F5)>0,OR(D5="X",D5="x")),IF(OR(D5="X",D5="x",AND(OR(COUNTA(B5,C5,E5,F5)>0,OR(D5="X",D5="x")),(LEN(SUBSTITUTE(SUBSTITUTE(SUBSTITUTE(B5," ",""),"0",""),"-",""))+LEN(SUBSTITUTE(SUBSTITUTE(SUBSTITUTE(C5," ",""),"0",""),"-","")))=(LEN(SUBSTITUTE(SUBSTITUTE(SUBSTITUTE(E5," ",""),"0",""),"-",""))+LEN(SUBSTITUTE(SUBSTITUTE(SUBSTITUTE(F5," ",""),"0",""),"-",""))))),0,(LEN(SUBSTITUTE(SUBSTITUTE(SUBSTITUTE(B5," ",""),"0",""),"-",""))+LEN(SUBSTITUTE(SUBSTITUTE(SUBSTITUTE(C5," ",""),"0",""),"-",""))<LEN(SUBSTITUTE(SUBSTITUTE(SUBSTITUTE(E5," ",""),"0",""),"-",""))+LEN(SUBSTITUTE(SUBSTITUTE(SUBSTITUTE(F5," ",""),"0",""),"-","")))*1),0)+IF(OR(COUNTA(B6,C6,E6,F6)>0,OR(D6="X",D6="x")),IF(OR(D6="X",D6="x",AND(OR(COUNTA(B6,C6,E6,F6)>0,OR(D6="X",D6="x")),(LEN(SUBSTITUTE(SUBSTITUTE(SUBSTITUTE(B6," ",""),"0",""),"-",""))+LEN(SUBSTITUTE(SUBSTITUTE(SUBSTITUTE(C6," ",""),"0",""),"-","")))=(LEN(SUBSTITUTE(SUBSTITUTE(SUBSTITUTE(E6," ",""),"0",""),"-",""))+LEN(SUBSTITUTE(SUBSTITUTE(SUBSTITUTE(F6," ",""),"0",""),"-",""))))),0,(LEN(SUBSTITUTE(SUBSTITUTE(SUBSTITUTE(B6," ",""),"0",""),"-",""))+LEN(SUBSTITUTE(SUBSTITUTE(SUBSTITUTE(C6," ",""),"0",""),"-",""))<LEN(SUBSTITUTE(SUBSTITUTE(SUBSTITUTE(E6," ",""),"0",""),"-",""))+LEN(SUBSTITUTE(SUBSTITUTE(SUBSTITUTE(F6," ",""),"0",""),"-","")))*1),0) | D11: =IF(OR(COUNTA(B5,C5,E5,F5)>0,OR(D5="X",D5="x")),IF(OR(D5="X",D5="x",AND(OR(COUNTA(B5,C5,E5,F5)>0,OR(D5="X",D5="x")),(LEN(SUBSTITUTE(SUBSTITUTE(SUBSTITUTE(B5," ",""),"0",""),"-",""))+LEN(SUBSTITUTE(SUBSTITUTE(SUBSTITUTE(C5," ",""),"0",""),"-","")))=(LEN(SUBSTITUTE(SUBSTITUTE(SUBSTITUTE(E5," ",""),"0",""),"-",""))+LEN(SUBSTITUTE(SUBSTITUTE(SUBSTITUTE(F5," ",""),"0",""),"-",""))))),1,0),0)+IF(OR(COUNTA(B6,C6,E6,F6)>0,OR(D6="X",D6="x")),IF(OR(D6="X",D6="x",AND(OR(COUNTA(B6,C6,E6,F6)>0,OR(D6="X",D6="x")),(LEN(SUBSTITUTE(SUBSTITUTE(SUBSTITUTE(B6," ",""),"0",""),"-",""))+LEN(SUBSTITUTE(SUBSTITUTE(SUBSTITUTE(C6," ",""),"0",""),"-","")))=(LEN(SUBSTITUTE(SUBSTITUTE(SUBSTITUTE(E6," ",""),"0",""),"-",""))+LEN(SUBSTITUTE(SUBSTITUTE(SUBSTITUTE(F6," ",""),"0",""),"-",""))))),1,0),0) | E11: =LEN(SUBSTITUTE(SUBSTITUTE(SUBSTITUTE(B5," ",""),"0",""),"-",""))+LEN(SUBSTITUTE(SUBSTITUTE(SUBSTITUTE(C5," ",""),"0",""),"-",""))+LEN(SUBSTITUTE(SUBSTITUTE(SUBSTITUTE(B6," ",""),"0",""),"-",""))+LEN(SUBSTITUTE(SUBSTITUTE(SUBSTITUTE(C6," ",""),"0",""),"-","")) | F11: =LEN(SUBSTITUTE(SUBSTITUTE(SUBSTITUTE(E5," ",""),"0",""),"-",""))+LEN(SUBSTITUTE(SUBSTITUTE(SUBSTITUTE(F5," ",""),"0",""),"-",""))+LEN(SUBSTITUTE(SUBSTITUTE(SUBSTITUTE(E6," ",""),"0",""),"-",""))+LEN(SUBSTITUTE(SUBSTITUTE(SUBSTITUTE(F6," ",""),"0",""),"-","")) | G11: =RANK(U11,$U$9:$U$11)+COUNTIF($U$8:U10,U11) | I11: =data!$E$52&" "&data!$B$52 | J11: =IF(OR(COUNTA(J5,K5,M5,N5)>0,OR(L5="X",L5="x")),IF(OR(L5="X",L5="x",AND(OR(COUNTA(J5,K5,M5,N5)>0,OR(L5="X",L5="x")),(LEN(SUBSTITUTE(SUBSTITUTE(SUBSTITUTE(J5," ",""),"0",""),"-",""))+LEN(SUBSTITUTE(SUBSTITUTE(SUBSTITUTE(K5," ",""),"0",""),"-","")))=(LEN(SUBSTITUTE(SUBSTITUTE(SUBSTITUTE(M5," ",""),"0",""),"-",""))+LEN(SUBSTITUTE(SUBSTITUTE(SUBSTITUTE(N5," ",""),"0",""),"-",""))))),0,(LEN(SUBSTITUTE(SUBSTITUTE(SUBSTITUTE(J5," ",""),"0",""),"-",""))+LEN(SUBSTITUTE(SUBSTITUTE(SUBSTITUTE(K5," ",""),"0",""),"-",""))>LEN(SUBSTITUTE(SUBSTITUTE(SUBSTITUTE(M5," ",""),"0",""),"-",""))+LEN(SUBSTITUTE(SUBSTITUTE(SUBSTITUTE(N5," ",""),"0",""),"-","")))*1),0)+IF(OR(COUNTA(J6,K6,M6,N6)>0,OR(L6="X",L6="x")),IF(OR(L6="X",L6="x",AND(OR(COUNTA(J6,K6,M6,N6)>0,OR(L6="X",L6="x")),(LEN(SUBSTITUTE(SUBSTITUTE(SUBSTITUTE(J6," ",""),"0",""),"-",""))+LEN(SUBSTITUTE(SUBSTITUTE(SUBSTITUTE(K6," ",""),"0",""),"-","")))=(LEN(SUBSTITUTE(SUBSTITUTE(SUBSTITUTE(M6," ",""),"0",""),"-",""))+LEN(SUBSTITUTE(SUBSTITUTE(SUBSTITUTE(N6," ",""),"0",""),"-",""))))),0,(LEN(SUBSTITUTE(SUBSTITUTE(SUBSTITUTE(J6," ",""),"0",""),"-",""))+LEN(SUBSTITUTE(SUBSTITUTE(SUBSTITUTE(K6," ",""),"0",""),"-",""))>LEN(SUBSTITUTE(SUBSTITUTE(SUBSTITUTE(M6," ",""),"0",""),"-",""))+LEN(SUBSTITUTE(SUBSTITUTE(SUBSTITUTE(N6," ",""),"0",""),"-","")))*1),0) | K11: =IF(OR(COUNTA(J5,K5,M5,N5)>0,OR(L5="X",L5="x")),IF(OR(L5="X",L5="x",AND(OR(COUNTA(J5,K5,M5,N5)>0,OR(L5="X",L5="x")),(LEN(SUBSTITUTE(SUBSTITUTE(SUBSTITUTE(J5," ",""),"0",""),"-",""))+LEN(SUBSTITUTE(SUBSTITUTE(SUBSTITUTE(K5," ",""),"0",""),"-","")))=(LEN(SUBSTITUTE(SUBSTITUTE(SUBSTITUTE(M5," ",""),"0",""),"-",""))+LEN(SUBSTITUTE(SUBSTITUTE(SUBSTITUTE(N5," ",""),"0",""),"-",""))))),0,(LEN(SUBSTITUTE(SUBSTITUTE(SUBSTITUTE(J5," ",""),"0",""),"-",""))+LEN(SUBSTITUTE(SUBSTITUTE(SUBSTITUTE(K5," ",""),"0",""),"-",""))<LEN(SUBSTITUTE(SUBSTITUTE(SUBSTITUTE(M5," ",""),"0",""),"-",""))+LEN(SUBSTITUTE(SUBSTITUTE(SUBSTITUTE(N5," ",""),"0",""),"-","")))*1),0)+IF(OR(COUNTA(J6,K6,M6,N6)>0,OR(L6="X",L6="x")),IF(OR(L6="X",L6="x",AND(OR(COUNTA(J6,K6,M6,N6)>0,OR(L6="X",L6="x")),(LEN(SUBSTITUTE(SUBSTITUTE(SUBSTITUTE(J6," ",""),"0",""),"-",""))+LEN(SUBSTITUTE(SUBSTITUTE(SUBSTITUTE(K6," ",""),"0",""),"-","")))=(LEN(SUBSTITUTE(SUBSTITUTE(SUBSTITUTE(M6," ",""),"0",""),"-",""))+LEN(SUBSTITUTE(SUBSTITUTE(SUBSTITUTE(N6," ",""),"0",""),"-",""))))),0,(LEN(SUBSTITUTE(SUBSTITUTE(SUBSTITUTE(J6," ",""),"0",""),"-",""))+LEN(SUBSTITUTE(SUBSTITUTE(SUBSTITUTE(K6," ",""),"0",""),"-",""))<LEN(SUBSTITUTE(SUBSTITUTE(SUBSTITUTE(M6," ",""),"0",""),"-",""))+LEN(SUBSTITUTE(SUBSTITUTE(SUBSTITUTE(N6," ",""),"0",""),"-","")))*1),0) | L11: =IF(OR(COUNTA(J5,K5,M5,N5)>0,OR(L5="X",L5="x")),IF(OR(L5="X",L5="x",AND(OR(COUNTA(J5,K5,M5,N5)>0,OR(L5="X",L5="x")),(LEN(SUBSTITUTE(SUBSTITUTE(SUBSTITUTE(J5," ",""),"0",""),"-",""))+LEN(SUBSTITUTE(SUBSTITUTE(SUBSTITUTE(K5," ",""),"0",""),"-","")))=(LEN(SUBSTITUTE(SUBSTITUTE(SUBSTITUTE(M5," ",""),"0",""),"-",""))+LEN(SUBSTITUTE(SUBSTITUTE(SUBSTITUTE(N5," ",""),"0",""),"-",""))))),1,0),0)+IF(OR(COUNTA(J6,K6,M6,N6)>0,OR(L6="X",L6="x")),IF(OR(L6="X",L6="x",AND(OR(COUNTA(J6,K6,M6,N6)>0,OR(L6="X",L6="x")),(LEN(SUBSTITUTE(SUBSTITUTE(SUBSTITUTE(J6," ",""),"0",""),"-",""))+LEN(SUBSTITUTE(SUBSTITUTE(SUBSTITUTE(K6," ",""),"0",""),"-","")))=(LEN(SUBSTITUTE(SUBSTITUTE(SUBSTITUTE(M6," ",""),"0",""),"-",""))+LEN(SUBSTITUTE(SUBSTITUTE(SUBSTITUTE(N6," ",""),"0",""),"-",""))))),1,0),0) | M11: =LEN(SUBSTITUTE(SUBSTITUTE(SUBSTITUTE(J5," ",""),"0",""),"-",""))+LEN(SUBSTITUTE(SUBSTITUTE(SUBSTITUTE(K5," ",""),"0",""),"-",""))+LEN(SUBSTITUTE(SUBSTITUTE(SUBSTITUTE(J6," ",""),"0",""),"-",""))+LEN(SUBSTITUTE(SUBSTITUTE(SUBSTITUTE(K6," ",""),"0",""),"-","")) | N11: =LEN(SUBSTITUTE(SUBSTITUTE(SUBSTITUTE(M5," ",""),"0",""),"-",""))+LEN(SUBSTITUTE(SUBSTITUTE(SUBSTITUTE(N5," ",""),"0",""),"-",""))+LEN(SUBSTITUTE(SUBSTITUTE(SUBSTITUTE(M6," ",""),"0",""),"-",""))+LEN(SUBSTITUTE(SUBSTITUTE(SUBSTITUTE(N6," ",""),"0",""),"-","")) | O11: =RANK(AC11,$AC$9:$AC$11)+COUNTIF($AC$8:AC10,AC11) | U11: =(B11*1000000)-(C11*10000)+(D11*100)+(E11*1)-(F11*0.01) | AC11: =(J11*1000000)-(K11*10000)+(L11*100)+(M11*1)-(N11*0.01)
G14: Ranking | O14: Ranking
F15: 1. | G15: =IFERROR(INDEX($A$9:$A$11, MATCH(1, $G$9:$G$11, 0)), "-") | N15: 1. | O15: =IFERROR(INDEX($I$9:$I$11, MATCH(1, $O$9:$O$11, 0)), "-")
F16: 2. | G16: =IFERROR(INDEX($A$9:$A$11, MATCH(2, $G$9:$G$11, 0)), "-") | N16: 2. | O16: =IFERROR(INDEX($I$9:$I$11, MATCH(2, $O$9:$O$11, 0)), "-")
F17: 3. | G17: =IFERROR(INDEX($A$9:$A$11, MATCH(3, $G$9:$G$11, 0)), "-") | N17: 3. | O17: =IFERROR(INDEX($I$9:$I$11, MATCH(3, $O$9:$O$11, 0)), "-")
A19: ='data'!$A$8 | I19: ='data'!$A$55
A20: White | D20: vs | G20: Red | I20: White | L20: vs | O20: Red
A21: =data!$E$7&" "&data!$B$7 | G21: =data!$E$6&" "&data!$B$6 | I21: =data!$E$54&" "&data!$B$54 | O21: =data!$E$53&" "&data!$B$53
A22: =data!$E$8&" "&data!$B$8 | G22: =data!$E$6&" "&data!$B$6 | I22: =data!$E$55&" "&data!$B$55 | O22: =data!$E$53&" "&data!$B$53
A23: =data!$E$8&" "&data!$B$8 | G23: =data!$E$7&" "&data!$B$7 | I23: =data!$E$55&" "&data!$B$55 | O23: =data!$E$54&" "&data!$B$54
A25: Results | B25: W | C25: L | D25: T | E25: PW | F25: PL | G25: Rank | I25: Results | J25: W | K25: L | L25: T | M25: PW | N25: PL | O25: Rank
A26: =data!$E$6&" "&data!$B$6 | B26: =IF(OR(COUNTA(B21,C21,E21,F21)>0,OR(D21="X",D21="x")),IF(OR(D21="X",D21="x",AND(OR(COUNTA(B21,C21,E21,F21)>0,OR(D21="X",D21="x")),(LEN(SUBSTITUTE(SUBSTITUTE(SUBSTITUTE(B21," ",""),"0",""),"-",""))+LEN(SUBSTITUTE(SUBSTITUTE(SUBSTITUTE(C21," ",""),"0",""),"-","")))=(LEN(SUBSTITUTE(SUBSTITUTE(SUBSTITUTE(E21," ",""),"0",""),"-",""))+LEN(SUBSTITUTE(SUBSTITUTE(SUBSTITUTE(F21," ",""),"0",""),"-",""))))),0,(LEN(SUBSTITUTE(SUBSTITUTE(SUBSTITUTE(E21," ",""),"0",""),"-",""))+LEN(SUBSTITUTE(SUBSTITUTE(SUBSTITUTE(F21," ",""),"0",""),"-",""))>LEN(SUBSTITUTE(SUBSTITUTE(SUBSTITUTE(B21," ",""),"0",""),"-",""))+LEN(SUBSTITUTE(SUBSTITUTE(SUBSTITUTE(C21," ",""),"0",""),"-","")))*1),0)+IF(OR(COUNTA(B22,C22,E22,F22)>0,OR(D22="X",D22="x")),IF(OR(D22="X",D22="x",AND(OR(COUNTA(B22,C22,E22,F22)>0,OR(D22="X",D22="x")),(LEN(SUBSTITUTE(SUBSTITUTE(SUBSTITUTE(B22," ",""),"0",""),"-",""))+LEN(SUBSTITUTE(SUBSTITUTE(SUBSTITUTE(C22," ",""),"0",""),"-","")))=(LEN(SUBSTITUTE(SUBSTITUTE(SUBSTITUTE(E22," ",""),"0",""),"-",""))+LEN(SUBSTITUTE(SUBSTITUTE(SUBSTITUTE(F22," ",""),"0",""),"-",""))))),0,(LEN(SUBSTITUTE(SUBSTITUTE(SUBSTITUTE(E22," ",""),"0",""),"-",""))+LEN(SUBSTITUTE(SUBSTITUTE(SUBSTITUTE(F22," ",""),"0",""),"-",""))>LEN(SUBSTITUTE(SUBSTITUTE(SUBSTITUTE(B22," ",""),"0",""),"-",""))+LEN(SUBSTITUTE(SUBSTITUTE(SUBSTITUTE(C22," ",""),"0",""),"-","")))*1),0) | C26: =IF(OR(COUNTA(B21,C21,E21,F21)>0,OR(D21="X",D21="x")),IF(OR(D21="X",D21="x",AND(OR(COUNTA(B21,C21,E21,F21)>0,OR(D21="X",D21="x")),(LEN(SUBSTITUTE(SUBSTITUTE(SUBSTITUTE(B21," ",""),"0",""),"-",""))+LEN(SUBSTITUTE(SUBSTITUTE(SUBSTITUTE(C21," ",""),"0",""),"-","")))=(LEN(SUBSTITUTE(SUBSTITUTE(SUBSTITUTE(E21," ",""),"0",""),"-",""))+LEN(SUBSTITUTE(SUBSTITUTE(SUBSTITUTE(F21," ",""),"0",""),"-",""))))),0,(LEN(SUBSTITUTE(SUBSTITUTE(SUBSTITUTE(E21," ",""),"0",""),"-",""))+LEN(SUBSTITUTE(SUBSTITUTE(SUBSTITUTE(F21," ",""),"0",""),"-",""))<LEN(SUBSTITUTE(SUBSTITUTE(SUBSTITUTE(B21," ",""),"0",""),"-",""))+LEN(SUBSTITUTE(SUBSTITUTE(SUBSTITUTE(C21," ",""),"0",""),"-","")))*1),0)+IF(OR(COUNTA(B22,C22,E22,F22)>0,OR(D22="X",D22="x")),IF(OR(D22="X",D22="x",AND(OR(COUNTA(B22,C22,E22,F22)>0,OR(D22="X",D22="x")),(LEN(SUBSTITUTE(SUBSTITUTE(SUBSTITUTE(B22," ",""),"0",""),"-",""))+LEN(SUBSTITUTE(SUBSTITUTE(SUBSTITUTE(C22," ",""),"0",""),"-","")))=(LEN(SUBSTITUTE(SUBSTITUTE(SUBSTITUTE(E22," ",""),"0",""),"-",""))+LEN(SUBSTITUTE(SUBSTITUTE(SUBSTITUTE(F22," ",""),"0",""),"-",""))))),0,(LEN(SUBSTITUTE(SUBSTITUTE(SUBSTITUTE(E22," ",""),"0",""),"-",""))+LEN(SUBSTITUTE(SUBSTITUTE(SUBSTITUTE(F22," ",""),"0",""),"-",""))<LEN(SUBSTITUTE(SUBSTITUTE(SUBSTITUTE(B22," ",""),"0",""),"-",""))+LEN(SUBSTITUTE(SUBSTITUTE(SUBSTITUTE(C22," ",""),"0",""),"-","")))*1),0) | D26: =IF(OR(COUNTA(B21,C21,E21,F21)>0,OR(D21="X",D21="x")),IF(OR(D21="X",D21="x",AND(OR(COUNTA(B21,C21,E21,F21)>0,OR(D21="X",D21="x")),(LEN(SUBSTITUTE(SUBSTITUTE(SUBSTITUTE(B21," ",""),"0",""),"-",""))+LEN(SUBSTITUTE(SUBSTITUTE(SUBSTITUTE(C21," ",""),"0",""),"-","")))=(LEN(SUBSTITUTE(SUBSTITUTE(SUBSTITUTE(E21," ",""),"0",""),"-",""))+LEN(SUBSTITUTE(SUBSTITUTE(SUBSTITUTE(F21," ",""),"0",""),"-",""))))),1,0),0)+IF(OR(COUNTA(B22,C22,E22,F22)>0,OR(D22="X",D22="x")),IF(OR(D22="X",D22="x",AND(OR(COUNTA(B22,C22,E22,F22)>0,OR(D22="X",D22="x")),(LEN(SUBSTITUTE(SUBSTITUTE(SUBSTITUTE(B22," ",""),"0",""),"-",""))+LEN(SUBSTITUTE(SUBSTITUTE(SUBSTITUTE(C22," ",""),"0",""),"-","")))=(LEN(SUBSTITUTE(SUBSTITUTE(SUBSTITUTE(E22," ",""),"0",""),"-",""))+LEN(SUBSTITUTE(SUBSTITUTE(SUBSTITUTE(F22," ",""),"0",""),"-",""))))),1,0),0) | E26: =LEN(SUBSTITUTE(SUBSTITUTE(SUBSTITUTE(E21," ",""),"0",""),"-",""))+LEN(SUBSTITUTE(SUBSTITUTE(SUBSTITUTE(F21," ",""),"0",""),"-",""))+LEN(SUBSTITUTE(SUBSTITUTE(SUBSTITUTE(E22," ",""),"0",""),"-",""))+LEN(SUBSTITUTE(SUBSTITUTE(SUBSTITUTE(F22," ",""),"0",""),"-","")) | F26: =LEN(SUBSTITUTE(SUBSTITUTE(SUBSTITUTE(B21," ",""),"0",""),"-",""))+LEN(SUBSTITUTE(SUBSTITUTE(SUBSTITUTE(C21," ",""),"0",""),"-",""))+LEN(SUBSTITUTE(SUBSTITUTE(SUBSTITUTE(B22," ",""),"0",""),"-",""))+LEN(SUBSTITUTE(SUBSTITUTE(SUBSTITUTE(C22," ",""),"0",""),"-","")) | G26: =RANK(U26,$U$26:$U$28)+COUNTIF($U$25:U25,U26) | I26: =data!$E$53&" "&data!$B$53 | J26: =IF(OR(COUNTA(J21,K21,M21,N21)>0,OR(L21="X",L21="x")),IF(OR(L21="X",L21="x",AND(OR(COUNTA(J21,K21,M21,N21)>0,OR(L21="X",L21="x")),(LEN(SUBSTITUTE(SUBSTITUTE(SUBSTITUTE(J21," ",""),"0",""),"-",""))+LEN(SUBSTITUTE(SUBSTITUTE(SUBSTITUTE(K21," ",""),"0",""),"-","")))=(LEN(SUBSTITUTE(SUBSTITUTE(SUBSTITUTE(M21," ",""),"0",""),"-",""))+LEN(SUBSTITUTE(SUBSTITUTE(SUBSTITUTE(N21," ",""),"0",""),"-",""))))),0,(LEN(SUBSTITUTE(SUBSTITUTE(SUBSTITUTE(M21," ",""),"0",""),"-",""))+LEN(SUBSTITUTE(SUBSTITUTE(SUBSTITUTE(N21," ",""),"0",""),"-",""))>LEN(SUBSTITUTE(SUBSTITUTE(SUBSTITUTE(J21," ",""),"0",""),"-",""))+LEN(SUBSTITUTE(SUBSTITUTE(SUBSTITUTE(K21," ",""),"0",""),"-","")))*1),0)+IF(OR(COUNTA(J22,K22,M22,N22)>0,OR(L22="X",L22="x")),IF(OR(L22="X",L22="x",AND(OR(COUNTA(J22,K22,M22,N22)>0,OR(L22="X",L22="x")),(LEN(SUBSTITUTE(SUBSTITUTE(SUBSTITUTE(J22," ",""),"0",""),"-",""))+LEN(SUBSTITUTE(SUBSTITUTE(SUBSTITUTE(K22," ",""),"0",""),"-","")))=(LEN(SUBSTITUTE(SUBSTITUTE(SUBSTITUTE(M22," ",""),"0",""),"-",""))+LEN(SUBSTITUTE(SUBSTITUTE(SUBSTITUTE(N22," ",""),"0",""),"-",""))))),0,(LEN(SUBSTITUTE(SUBSTITUTE(SUBSTITUTE(M22," ",""),"0",""),"-",""))+LEN(SUBSTITUTE(SUBSTITUTE(SUBSTITUTE(N22," ",""),"0",""),"-",""))>LEN(SUBSTITUTE(SUBSTITUTE(SUBSTITUTE(J22," ",""),"0",""),"-",""))+LEN(SUBSTITUTE(SUBSTITUTE(SUBSTITUTE(K22," ",""),"0",""),"-","")))*1),0) | K26: =IF(OR(COUNTA(J21,K21,M21,N21)>0,OR(L21="X",L21="x")),IF(OR(L21="X",L21="x",AND(OR(COUNTA(J21,K21,M21,N21)>0,OR(L21="X",L21="x")),(LEN(SUBSTITUTE(SUBSTITUTE(SUBSTITUTE(J21," ",""),"0",""),"-",""))+LEN(SUBSTITUTE(SUBSTITUTE(SUBSTITUTE(K21," ",""),"0",""),"-","")))=(LEN(SUBSTITUTE(SUBSTITUTE(SUBSTITUTE(M21," ",""),"0",""),"-",""))+LEN(SUBSTITUTE(SUBSTITUTE(SUBSTITUTE(N21," ",""),"0",""),"-",""))))),0,(LEN(SUBSTITUTE(SUBSTITUTE(SUBSTITUTE(M21," ",""),"0",""),"-",""))+LEN(SUBSTITUTE(SUBSTITUTE(SUBSTITUTE(N21," ",""),"0",""),"-",""))<LEN(SUBSTITUTE(SUBSTITUTE(SUBSTITUTE(J21," ",""),"0",""),"-",""))+LEN(SUBSTITUTE(SUBSTITUTE(SUBSTITUTE(K21," ",""),"0",""),"-","")))*1),0)+IF(OR(COUNTA(J22,K22,M22,N22)>0,OR(L22="X",L22="x")),IF(OR(L22="X",L22="x",AND(OR(COUNTA(J22,K22,M22,N22)>0,OR(L22="X",L22="x")),(LEN(SUBSTITUTE(SUBSTITUTE(SUBSTITUTE(J22," ",""),"0",""),"-",""))+LEN(SUBSTITUTE(SUBSTITUTE(SUBSTITUTE(K22," ",""),"0",""),"-","")))=(LEN(SUBSTITUTE(SUBSTITUTE(SUBSTITUTE(M22," ",""),"0",""),"-",""))+LEN(SUBSTITUTE(SUBSTITUTE(SUBSTITUTE(N22," ",""),"0",""),"-",""))))),0,(LEN(SUBSTITUTE(SUBSTITUTE(SUBSTITUTE(M22," ",""),"0",""),"-",""))+LEN(SUBSTITUTE(SUBSTITUTE(SUBSTITUTE(N22," ",""),"0",""),"-",""))<LEN(SUBSTITUTE(SUBSTITUTE(SUBSTITUTE(J22," ",""),"0",""),"-",""))+LEN(SUBSTITUTE(SUBSTITUTE(SUBSTITUTE(K22," ",""),"0",""),"-","")))*1),0) | L26: =IF(OR(COUNTA(J21,K21,M21,N21)>0,OR(L21="X",L21="x")),IF(OR(L21="X",L21="x",AND(OR(COUNTA(J21,K21,M21,N21)>0,OR(L21="X",L21="x")),(LEN(SUBSTITUTE(SUBSTITUTE(SUBSTITUTE(J21," ",""),"0",""),"-",""))+LEN(SUBSTITUTE(SUBSTITUTE(SUBSTITUTE(K21," ",""),"0",""),"-","")))=(LEN(SUBSTITUTE(SUBSTITUTE(SUBSTITUTE(M21," ",""),"0",""),"-",""))+LEN(SUBSTITUTE(SUBSTITUTE(SUBSTITUTE(N21," ",""),"0",""),"-",""))))),1,0),0)+IF(OR(COUNTA(J22,K22,M22,N22)>0,OR(L22="X",L22="x")),IF(OR(L22="X",L22="x",AND(OR(COUNTA(J22,K22,M22,N22)>0,OR(L22="X",L22="x")),(LEN(SUBSTITUTE(SUBSTITUTE(SUBSTITUTE(J22," ",""),"0",""),"-",""))+LEN(SUBSTITUTE(SUBSTITUTE(SUBSTITUTE(K22," ",""),"0",""),"-","")))=(LEN(SUBSTITUTE(SUBSTITUTE(SUBSTITUTE(M22," ",""),"0",""),"-",""))+LEN(SUBSTITUTE(SUBSTITUTE(SUBSTITUTE(N22," ",""),"0",""),"-",""))))),1,0),0) | M26: =LEN(SUBSTITUTE(SUBSTITUTE(SUBSTITUTE(M21," ",""),"0",""),"-",""))+LEN(SUBSTITUTE(SUBSTITUTE(SUBSTITUTE(N21," ",""),"0",""),"-",""))+LEN(SUBSTITUTE(SUBSTITUTE(SUBSTITUTE(M22," ",""),"0",""),"-",""))+LEN(SUBSTITUTE(SUBSTITUTE(SUBSTITUTE(N22," ",""),"0",""),"-","")) | N26: =LEN(SUBSTITUTE(SUBSTITUTE(SUBSTITUTE(J21," ",""),"0",""),"-",""))+LEN(SUBSTITUTE(SUBSTITUTE(SUBSTITUTE(K21," ",""),"0",""),"-",""))+LEN(SUBSTITUTE(SUBSTITUTE(SUBSTITUTE(J22," ",""),"0",""),"-",""))+LEN(SUBSTITUTE(SUBSTITUTE(SUBSTITUTE(K22," ",""),"0",""),"-","")) | O26: =RANK(AC26,$AC$26:$AC$28)+COUNTIF($AC$25:AC25,AC26) | U26: =(B26*1000000)-(C26*10000)+(D26*100)+(E26*1)-(F26*0.01) | AC26: =(J26*1000000)-(K26*10000)+(L26*100)+(M26*1)-(N26*0.01)
A27: =data!$E$7&" "&data!$B$7 | B27: =IF(OR(COUNTA(B21,C21,E21,F21)>0,OR(D21="X",D21="x")),IF(OR(D21="X",D21="x",AND(OR(COUNTA(B21,C21,E21,F21)>0,OR(D21="X",D21="x")),(LEN(SUBSTITUTE(SUBSTITUTE(SUBSTITUTE(B21," ",""),"0",""),"-",""))+LEN(SUBSTITUTE(SUBSTITUTE(SUBSTITUTE(C21," ",""),"0",""),"-","")))=(LEN(SUBSTITUTE(SUBSTITUTE(SUBSTITUTE(E21," ",""),"0",""),"-",""))+LEN(SUBSTITUTE(SUBSTITUTE(SUBSTITUTE(F21," ",""),"0",""),"-",""))))),0,(LEN(SUBSTITUTE(SUBSTITUTE(SUBSTITUTE(B21," ",""),"0",""),"-",""))+LEN(SUBSTITUTE(SUBSTITUTE(SUBSTITUTE(C21," ",""),"0",""),"-",""))>LEN(SUBSTITUTE(SUBSTITUTE(SUBSTITUTE(E21," ",""),"0",""),"-",""))+LEN(SUBSTITUTE(SUBSTITUTE(SUBSTITUTE(F21," ",""),"0",""),"-","")))*1),0)+IF(OR(COUNTA(B23,C23,E23,F23)>0,OR(D23="X",D23="x")),IF(OR(D23="X",D23="x",AND(OR(COUNTA(B23,C23,E23,F23)>0,OR(D23="X",D23="x")),(LEN(SUBSTITUTE(SUBSTITUTE(SUBSTITUTE(B23," ",""),"0",""),"-",""))+LEN(SUBSTITUTE(SUBSTITUTE(SUBSTITUTE(C23," ",""),"0",""),"-","")))=(LEN(SUBSTITUTE(SUBSTITUTE(SUBSTITUTE(E23," ",""),"0",""),"-",""))+LEN(SUBSTITUTE(SUBSTITUTE(SUBSTITUTE(F23," ",""),"0",""),"-",""))))),0,(LEN(SUBSTITUTE(SUBSTITUTE(SUBSTITUTE(E23," ",""),"0",""),"-",""))+LEN(SUBSTITUTE(SUBSTITUTE(SUBSTITUTE(F23," ",""),"0",""),"-",""))>LEN(SUBSTITUTE(SUBSTITUTE(SUBSTITUTE(B23," ",""),"0",""),"-",""))+LEN(SUBSTITUTE(SUBSTITUTE(SUBSTITUTE(C23," ",""),"0",""),"-","")))*1),0) | C27: =IF(OR(COUNTA(B21,C21,E21,F21)>0,OR(D21="X",D21="x")),IF(OR(D21="X",D21="x",AND(OR(COUNTA(B21,C21,E21,F21)>0,OR(D21="X",D21="x")),(LEN(SUBSTITUTE(SUBSTITUTE(SUBSTITUTE(B21," ",""),"0",""),"-",""))+LEN(SUBSTITUTE(SUBSTITUTE(SUBSTITUTE(C21," ",""),"0",""),"-","")))=(LEN(SUBSTITUTE(SUBSTITUTE(SUBSTITUTE(E21," ",""),"0",""),"-",""))+LEN(SUBSTITUTE(SUBSTITUTE(SUBSTITUTE(F21," ",""),"0",""),"-",""))))),0,(LEN(SUBSTITUTE(SUBSTITUTE(SUBSTITUTE(B21," ",""),"0",""),"-",""))+LEN(SUBSTITUTE(SUBSTITUTE(SUBSTITUTE(C21," ",""),"0",""),"-",""))<LEN(SUBSTITUTE(SUBSTITUTE(SUBSTITUTE(E21," ",""),"0",""),"-",""))+LEN(SUBSTITUTE(SUBSTITUTE(SUBSTITUTE(F21," ",""),"0",""),"-","")))*1),0)+IF(OR(COUNTA(B23,C23,E23,F23)>0,OR(D23="X",D23="x")),IF(OR(D23="X",D23="x",AND(OR(COUNTA(B23,C23,E23,F23)>0,OR(D23="X",D23="x")),(LEN(SUBSTITUTE(SUBSTITUTE(SUBSTITUTE(B23," ",""),"0",""),"-",""))+LEN(SUBSTITUTE(SUBSTITUTE(SUBSTITUTE(C23," ",""),"0",""),"-","")))=(LEN(SUBSTITUTE(SUBSTITUTE(SUBSTITUTE(E23," ",""),"0",""),"-",""))+LEN(SUBSTITUTE(SUBSTITUTE(SUBSTITUTE(F23," ",""),"0",""),"-",""))))),0,(LEN(SUBSTITUTE(SUBSTITUTE(SUBSTITUTE(E23," ",""),"0",""),"-",""))+LEN(SUBSTITUTE(SUBSTITUTE(SUBSTITUTE(F23," ",""),"0",""),"-",""))<LEN(SUBSTITUTE(SUBSTITUTE(SUBSTITUTE(B23," ",""),"0",""),"-",""))+LEN(SUBSTITUTE(SUBSTITUTE(SUBSTITUTE(C23," ",""),"0",""),"-","")))*1),0) | D27: =IF(OR(COUNTA(B21,C21,E21,F21)>0,OR(D21="X",D21="x")),IF(OR(D21="X",D21="x",AND(OR(COUNTA(B21,C21,E21,F21)>0,OR(D21="X",D21="x")),(LEN(SUBSTITUTE(SUBSTITUTE(SUBSTITUTE(B21," ",""),"0",""),"-",""))+LEN(SUBSTITUTE(SUBSTITUTE(SUBSTITUTE(C21," ",""),"0",""),"-","")))=(LEN(SUBSTITUTE(SUBSTITUTE(SUBSTITUTE(E21," ",""),"0",""),"-",""))+LEN(SUBSTITUTE(SUBSTITUTE(SUBSTITUTE(F21," ",""),"0",""),"-",""))))),1,0),0)+IF(OR(COUNTA(B23,C23,E23,F23)>0,OR(D23="X",D23="x")),IF(OR(D23="X",D23="x",AND(OR(COUNTA(B23,C23,E23,F23)>0,OR(D23="X",D23="x")),(LEN(SUBSTITUTE(SUBSTITUTE(SUBSTITUTE(B23," ",""),"0",""),"-",""))+LEN(SUBSTITUTE(SUBSTITUTE(SUBSTITUTE(C23," ",""),"0",""),"-","")))=(LEN(SUBSTITUTE(SUBSTITUTE(SUBSTITUTE(E23," ",""),"0",""),"-",""))+LEN(SUBSTITUTE(SUBSTITUTE(SUBSTITUTE(F23," ",""),"0",""),"-",""))))),1,0),0) | E27: =LEN(SUBSTITUTE(SUBSTITUTE(SUBSTITUTE(B21," ",""),"0",""),"-",""))+LEN(SUBSTITUTE(SUBSTITUTE(SUBSTITUTE(C21," ",""),"0",""),"-",""))+LEN(SUBSTITUTE(SUBSTITUTE(SUBSTITUTE(E23," ",""),"0",""),"-",""))+LEN(SUBSTITUTE(SUBSTITUTE(SUBSTITUTE(F23," ",""),"0",""),"-","")) | F27: =LEN(SUBSTITUTE(SUBSTITUTE(SUBSTITUTE(E21," ",""),"0",""),"-",""))+LEN(SUBSTITUTE(SUBSTITUTE(SUBSTITUTE(F21," ",""),"0",""),"-",""))+LEN(SUBSTITUTE(SUBSTITUTE(SUBSTITUTE(B23," ",""),"0",""),"-",""))+LEN(SUBSTITUTE(SUBSTITUTE(SUBSTITUTE(C23," ",""),"0",""),"-","")) | G27: =RANK(U27,$U$26:$U$28)+COUNTIF($U$25:U26,U27) | I27: =data!$E$54&" "&data!$B$54 | J27: =IF(OR(COUNTA(J21,K21,M21,N21)>0,OR(L21="X",L21="x")),IF(OR(L21="X",L21="x",AND(OR(COUNTA(J21,K21,M21,N21)>0,OR(L21="X",L21="x")),(LEN(SUBSTITUTE(SUBSTITUTE(SUBSTITUTE(J21," ",""),"0",""),"-",""))+LEN(SUBSTITUTE(SUBSTITUTE(SUBSTITUTE(K21," ",""),"0",""),"-","")))=(LEN(SUBSTITUTE(SUBSTITUTE(SUBSTITUTE(M21," ",""),"0",""),"-",""))+LEN(SUBSTITUTE(SUBSTITUTE(SUBSTITUTE(N21," ",""),"0",""),"-",""))))),0,(LEN(SUBSTITUTE(SUBSTITUTE(SUBSTITUTE(J21," ",""),"0",""),"-",""))+LEN(SUBSTITUTE(SUBSTITUTE(SUBSTITUTE(K21," ",""),"0",""),"-",""))>LEN(SUBSTITUTE(SUBSTITUTE(SUBSTITUTE(M21," ",""),"0",""),"-",""))+LEN(SUBSTITUTE(SUBSTITUTE(SUBSTITUTE(N21," ",""),"0",""),"-","")))*1),0)+IF(OR(COUNTA(J23,K23,M23,N23)>0,OR(L23="X",L23="x")),IF(OR(L23="X",L23="x",AND(OR(COUNTA(J23,K23,M23,N23)>0,OR(L23="X",L23="x")),(LEN(SUBSTITUTE(SUBSTITUTE(SUBSTITUTE(J23," ",""),"0",""),"-",""))+LEN(SUBSTITUTE(SUBSTITUTE(SUBSTITUTE(K23," ",""),"0",""),"-","")))=(LEN(SUBSTITUTE(SUBSTITUTE(SUBSTITUTE(M23," ",""),"0",""),"-",""))+LEN(SUBSTITUTE(SUBSTITUTE(SUBSTITUTE(N23," ",""),"0",""),"-",""))))),0,(LEN(SUBSTITUTE(SUBSTITUTE(SUBSTITUTE(M23," ",""),"0",""),"-",""))+LEN(SUBSTITUTE(SUBSTITUTE(SUBSTITUTE(N23," ",""),"0",""),"-",""))>LEN(SUBSTITUTE(SUBSTITUTE(SUBSTITUTE(J23," ",""),"0",""),"-",""))+LEN(SUBSTITUTE(SUBSTITUTE(SUBSTITUTE(K23," ",""),"0",""),"-","")))*1),0) | K27: =IF(OR(COUNTA(J21,K21,M21,N21)>0,OR(L21="X",L21="x")),IF(OR(L21="X",L21="x",AND(OR(COUNTA(J21,K21,M21,N21)>0,OR(L21="X",L21="x")),(LEN(SUBSTITUTE(SUBSTITUTE(SUBSTITUTE(J21," ",""),"0",""),"-",""))+LEN(SUBSTITUTE(SUBSTITUTE(SUBSTITUTE(K21," ",""),"0",""),"-","")))=(LEN(SUBSTITUTE(SUBSTITUTE(SUBSTITUTE(M21," ",""),"0",""),"-",""))+LEN(SUBSTITUTE(SUBSTITUTE(SUBSTITUTE(N21," ",""),"0",""),"-",""))))),0,(LEN(SUBSTITUTE(SUBSTITUTE(SUBSTITUTE(J21," ",""),"0",""),"-",""))+LEN(SUBSTITUTE(SUBSTITUTE(SUBSTITUTE(K21," ",""),"0",""),"-",""))<LEN(SUBSTITUTE(SUBSTITUTE(SUBSTITUTE(M21," ",""),"0",""),"-",""))+LEN(SUBSTITUTE(SUBSTITUTE(SUBSTITUTE(N21," ",""),"0",""),"-","")))*1),0)+IF(OR(COUNTA(J23,K23,M23,N23)>0,OR(L23="X",L23="x")),IF(OR(L23="X",L23="x",AND(OR(COUNTA(J23,K23,M23,N23)>0,OR(L23="X",L23="x")),(LEN(SUBSTITUTE(SUBSTITUTE(SUBSTITUTE(J23," ",""),"0",""),"-",""))+LEN(SUBSTITUTE(SUBSTITUTE(SUBSTITUTE(K23," ",""),"0",""),"-","")))=(LEN(SUBSTITUTE(SUBSTITUTE(SUBSTITUTE(M23," ",""),"0",""),"-",""))+LEN(SUBSTITUTE(SUBSTITUTE(SUBSTITUTE(N23," ",""),"0",""),"-",""))))),0,(LEN(SUBSTITUTE(SUBSTITUTE(SUBSTITUTE(M23," ",""),"0",""),"-",""))+LEN(SUBSTITUTE(SUBSTITUTE(SUBSTITUTE(N23," ",""),"0",""),"-",""))<LEN(SUBSTITUTE(SUBSTITUTE(SUBSTITUTE(J23," ",""),"0",""),"-",""))+LEN(SUBSTITUTE(SUBSTITUTE(SUBSTITUTE(K23," ",""),"0",""),"-","")))*1),0) | L27: =IF(OR(COUNTA(J21,K21,M21,N21)>0,OR(L21="X",L21="x")),IF(OR(L21="X",L21="x",AND(OR(COUNTA(J21,K21,M21,N21)>0,OR(L21="X",L21="x")),(LEN(SUBSTITUTE(SUBSTITUTE(SUBSTITUTE(J21," ",""),"0",""),"-",""))+LEN(SUBSTITUTE(SUBSTITUTE(SUBSTITUTE(K21," ",""),"0",""),"-","")))=(LEN(SUBSTITUTE(SUBSTITUTE(SUBSTITUTE(M21," ",""),"0",""),"-",""))+LEN(SUBSTITUTE(SUBSTITUTE(SUBSTITUTE(N21," ",""),"0",""),"-",""))))),1,0),0)+IF(OR(COUNTA(J23,K23,M23,N23)>0,OR(L23="X",L23="x")),IF(OR(L23="X",L23="x",AND(OR(COUNTA(J23,K23,M23,N23)>0,OR(L23="X",L23="x")),(LEN(SUBSTITUTE(SUBSTITUTE(SUBSTITUTE(J23," ",""),"0",""),"-",""))+LEN(SUBSTITUTE(SUBSTITUTE(SUBSTITUTE(K23," ",""),"0",""),"-","")))=(LEN(SUBSTITUTE(SUBSTITUTE(SUBSTITUTE(M23," ",""),"0",""),"-",""))+LEN(SUBSTITUTE(SUBSTITUTE(SUBSTITUTE(N23," ",""),"0",""),"-",""))))),1,0),0) | M27: =LEN(SUBSTITUTE(SUBSTITUTE(SUBSTITUTE(J21," ",""),"0",""),"-",""))+LEN(SUBSTITUTE(SUBSTITUTE(SUBSTITUTE(K21," ",""),"0",""),"-",""))+LEN(SUBSTITUTE(SUBSTITUTE(SUBSTITUTE(M23," ",""),"0",""),"-",""))+LEN(SUBSTITUTE(SUBSTITUTE(SUBSTITUTE(N23," ",""),"0",""),"-","")) | N27: =LEN(SUBSTITUTE(SUBSTITUTE(SUBSTITUTE(M21," ",""),"0",""),"-",""))+LEN(SUBSTITUTE(SUBSTITUTE(SUBSTITUTE(N21," ",""),"0",""),"-",""))+LEN(SUBSTITUTE(SUBSTITUTE(SUBSTITUTE(J23," ",""),"0",""),"-",""))+LEN(SUBSTITUTE(SUBSTITUTE(SUBSTITUTE(K23," ",""),"0",""),"-","")) | O27: =RANK(AC27,$AC$26:$AC$28)+COUNTIF($AC$25:AC26,AC27) | U27: =(B27*1000000)-(C27*10000)+(D27*100)+(E27*1)-(F27*0.01) | AC27: =(J27*1000000)-(K27*10000)+(L27*100)+(M27*1)-(N27*0.01)
A28: =data!$E$8&" "&data!$B$8 | B28: =IF(OR(COUNTA(B22,C22,E22,F22)>0,OR(D22="X",D22="x")),IF(OR(D22="X",D22="x",AND(OR(COUNTA(B22,C22,E22,F22)>0,OR(D22="X",D22="x")),(LEN(SUBSTITUTE(SUBSTITUTE(SUBSTITUTE(B22," ",""),"0",""),"-",""))+LEN(SUBSTITUTE(SUBSTITUTE(SUBSTITUTE(C22," ",""),"0",""),"-","")))=(LEN(SUBSTITUTE(SUBSTITUTE(SUBSTITUTE(E22," ",""),"0",""),"-",""))+LEN(SUBSTITUTE(SUBSTITUTE(SUBSTITUTE(F22," ",""),"0",""),"-",""))))),0,(LEN(SUBSTITUTE(SUBSTITUTE(SUBSTITUTE(B22," ",""),"0",""),"-",""))+LEN(SUBSTITUTE(SUBSTITUTE(SUBSTITUTE(C22," ",""),"0",""),"-",""))>LEN(SUBSTITUTE(SUBSTITUTE(SUBSTITUTE(E22," ",""),"0",""),"-",""))+LEN(SUBSTITUTE(SUBSTITUTE(SUBSTITUTE(F22," ",""),"0",""),"-","")))*1),0)+IF(OR(COUNTA(B23,C23,E23,F23)>0,OR(D23="X",D23="x")),IF(OR(D23="X",D23="x",AND(OR(COUNTA(B23,C23,E23,F23)>0,OR(D23="X",D23="x")),(LEN(SUBSTITUTE(SUBSTITUTE(SUBSTITUTE(B23," ",""),"0",""),"-",""))+LEN(SUBSTITUTE(SUBSTITUTE(SUBSTITUTE(C23," ",""),"0",""),"-","")))=(LEN(SUBSTITUTE(SUBSTITUTE(SUBSTITUTE(E23," ",""),"0",""),"-",""))+LEN(SUBSTITUTE(SUBSTITUTE(SUBSTITUTE(F23," ",""),"0",""),"-",""))))),0,(LEN(SUBSTITUTE(SUBSTITUTE(SUBSTITUTE(B23," ",""),"0",""),"-",""))+LEN(SUBSTITUTE(SUBSTITUTE(SUBSTITUTE(C23," ",""),"0",""),"-",""))>LEN(SUBSTITUTE(SUBSTITUTE(SUBSTITUTE(E23," ",""),"0",""),"-",""))+LEN(SUBSTITUTE(SUBSTITUTE(SUBSTITUTE(F23," ",""),"0",""),"-","")))*1),0) | C28: =IF(OR(COUNTA(B22,C22,E22,F22)>0,OR(D22="X",D22="x")),IF(OR(D22="X",D22="x",AND(OR(COUNTA(B22,C22,E22,F22)>0,OR(D22="X",D22="x")),(LEN(SUBSTITUTE(SUBSTITUTE(SUBSTITUTE(B22," ",""),"0",""),"-",""))+LEN(SUBSTITUTE(SUBSTITUTE(SUBSTITUTE(C22," ",""),"0",""),"-","")))=(LEN(SUBSTITUTE(SUBSTITUTE(SUBSTITUTE(E22," ",""),"0",""),"-",""))+LEN(SUBSTITUTE(SUBSTITUTE(SUBSTITUTE(F22," ",""),"0",""),"-",""))))),0,(LEN(SUBSTITUTE(SUBSTITUTE(SUBSTITUTE(B22," ",""),"0",""),"-",""))+LEN(SUBSTITUTE(SUBSTITUTE(SUBSTITUTE(C22," ",""),"0",""),"-",""))<LEN(SUBSTITUTE(SUBSTITUTE(SUBSTITUTE(E22," ",""),"0",""),"-",""))+LEN(SUBSTITUTE(SUBSTITUTE(SUBSTITUTE(F22," ",""),"0",""),"-","")))*1),0)+IF(OR(COUNTA(B23,C23,E23,F23)>0,OR(D23="X",D23="x")),IF(OR(D23="X",D23="x",AND(OR(COUNTA(B23,C23,E23,F23)>0,OR(D23="X",D23="x")),(LEN(SUBSTITUTE(SUBSTITUTE(SUBSTITUTE(B23," ",""),"0",""),"-",""))+LEN(SUBSTITUTE(SUBSTITUTE(SUBSTITUTE(C23," ",""),"0",""),"-","")))=(LEN(SUBSTITUTE(SUBSTITUTE(SUBSTITUTE(E23," ",""),"0",""),"-",""))+LEN(SUBSTITUTE(SUBSTITUTE(SUBSTITUTE(F23," ",""),"0",""),"-",""))))),0,(LEN(SUBSTITUTE(SUBSTITUTE(SUBSTITUTE(B23," ",""),"0",""),"-",""))+LEN(SUBSTITUTE(SUBSTITUTE(SUBSTITUTE(C23," ",""),"0",""),"-",""))<LEN(SUBSTITUTE(SUBSTITUTE(SUBSTITUTE(E23," ",""),"0",""),"-",""))+LEN(SUBSTITUTE(SUBSTITUTE(SUBSTITUTE(F23," ",""),"0",""),"-","")))*1),0) | D28: =IF(OR(COUNTA(B22,C22,E22,F22)>0,OR(D22="X",D22="x")),IF(OR(D22="X",D22="x",AND(OR(COUNTA(B22,C22,E22,F22)>0,OR(D22="X",D22="x")),(LEN(SUBSTITUTE(SUBSTITUTE(SUBSTITUTE(B22," ",""),"0",""),"-",""))+LEN(SUBSTITUTE(SUBSTITUTE(SUBSTITUTE(C22," ",""),"0",""),"-","")))=(LEN(SUBSTITUTE(SUBSTITUTE(SUBSTITUTE(E22," ",""),"0",""),"-",""))+LEN(SUBSTITUTE(SUBSTITUTE(SUBSTITUTE(F22," ",""),"0",""),"-",""))))),1,0),0)+IF(OR(COUNTA(B23,C23,E23,F23)>0,OR(D23="X",D23="x")),IF(OR(D23="X",D23="x",AND(OR(COUNTA(B23,C23,E23,F23)>0,OR(D23="X",D23="x")),(LEN(SUBSTITUTE(SUBSTITUTE(SUBSTITUTE(B23," ",""),"0",""),"-",""))+LEN(SUBSTITUTE(SUBSTITUTE(SUBSTITUTE(C23," ",""),"0",""),"-","")))=(LEN(SUBSTITUTE(SUBSTITUTE(SUBSTITUTE(E23," ",""),"0",""),"-",""))+LEN(SUBSTITUTE(SUBSTITUTE(SUBSTITUTE(F23," ",""),"0",""),"-",""))))),1,0),0) | E28: =LEN(SUBSTITUTE(SUBSTITUTE(SUBSTITUTE(B22," ",""),"0",""),"-",""))+LEN(SUBSTITUTE(SUBSTITUTE(SUBSTITUTE(C22," ",""),"0",""),"-",""))+LEN(SUBSTITUTE(SUBSTITUTE(SUBSTITUTE(B23," ",""),"0",""),"-",""))+LEN(SUBSTITUTE(SUBSTITUTE(SUBSTITUTE(C23," ",""),"0",""),"-","")) | F28: =LEN(SUBSTITUTE(SUBSTITUTE(SUBSTITUTE(E22," ",""),"0",""),"-",""))+LEN(SUBSTITUTE(SUBSTITUTE(SUBSTITUTE(F22," ",""),"0",""),"-",""))+LEN(SUBSTITUTE(SUBSTITUTE(SUBSTITUTE(E23," ",""),"0",""),"-",""))+LEN(SUBSTITUTE(SUBSTITUTE(SUBSTITUTE(F23," ",""),"0",""),"-","")) | G28: =RANK(U28,$U$26:$U$28)+COUNTIF($U$25:U27,U28) | I28: =data!$E$55&" "&data!$B$55 | J28: =IF(OR(COUNTA(J22,K22,M22,N22)>0,OR(L22="X",L22="x")),IF(OR(L22="X",L22="x",AND(OR(COUNTA(J22,K22,M22,N22)>0,OR(L22="X",L22="x")),(LEN(SUBSTITUTE(SUBSTITUTE(SUBSTITUTE(J22," ",""),"0",""),"-",""))+LEN(SUBSTITUTE(SUBSTITUTE(SUBSTITUTE(K22," ",""),"0",""),"-","")))=(LEN(SUBSTITUTE(SUBSTITUTE(SUBSTITUTE(M22," ",""),"0",""),"-",""))+LEN(SUBSTITUTE(SUBSTITUTE(SUBSTITUTE(N22," ",""),"0",""),"-",""))))),0,(LEN(SUBSTITUTE(SUBSTITUTE(SUBSTITUTE(J22," ",""),"0",""),"-",""))+LEN(SUBSTITUTE(SUBSTITUTE(SUBSTITUTE(K22," ",""),"0",""),"-",""))>LEN(SUBSTITUTE(SUBSTITUTE(SUBSTITUTE(M22," ",""),"0",""),"-",""))+LEN(SUBSTITUTE(SUBSTITUTE(SUBSTITUTE(N22," ",""),"0",""),"-","")))*1),0)+IF(OR(COUNTA(J23,K23,M23,N23)>0,OR(L23="X",L23="x")),IF(OR(L23="X",L23="x",AND(OR(COUNTA(J23,K23,M23,N23)>0,OR(L23="X",L23="x")),(LEN(SUBSTITUTE(SUBSTITUTE(SUBSTITUTE(J23," ",""),"0",""),"-",""))+LEN(SUBSTITUTE(SUBSTITUTE(SUBSTITUTE(K23," ",""),"0",""),"-","")))=(LEN(SUBSTITUTE(SUBSTITUTE(SUBSTITUTE(M23," ",""),"0",""),"-",""))+LEN(SUBSTITUTE(SUBSTITUTE(SUBSTITUTE(N23," ",""),"0",""),"-",""))))),0,(LEN(SUBSTITUTE(SUBSTITUTE(SUBSTITUTE(J23," ",""),"0",""),"-",""))+LEN(SUBSTITUTE(SUBSTITUTE(SUBSTITUTE(K23," ",""),"0",""),"-",""))>LEN(SUBSTITUTE(SUBSTITUTE(SUBSTITUTE(M23," ",""),"0",""),"-",""))+LEN(SUBSTITUTE(SUBSTITUTE(SUBSTITUTE(N23," ",""),"0",""),"-","")))*1),0) | K28: =IF(OR(COUNTA(J22,K22,M22,N22)>0,OR(L22="X",L22="x")),IF(OR(L22="X",L22="x",AND(OR(COUNTA(J22,K22,M22,N22)>0,OR(L22="X",L22="x")),(LEN(SUBSTITUTE(SUBSTITUTE(SUBSTITUTE(J22," ",""),"0",""),"-",""))+LEN(SUBSTITUTE(SUBSTITUTE(SUBSTITUTE(K22," ",""),"0",""),"-","")))=(LEN(SUBSTITUTE(SUBSTITUTE(SUBSTITUTE(M22," ",""),"0",""),"-",""))+LEN(SUBSTITUTE(SUBSTITUTE(SUBSTITUTE(N22," ",""),"0",""),"-",""))))),0,(LEN(SUBSTITUTE(SUBSTITUTE(SUBSTITUTE(J22," ",""),"0",""),"-",""))+LEN(SUBSTITUTE(SUBSTITUTE(SUBSTITUTE(K22," ",""),"0",""),"-",""))<LEN(SUBSTITUTE(SUBSTITUTE(SUBSTITUTE(M22," ",""),"0",""),"-",""))+LEN(SUBSTITUTE(SUBSTITUTE(SUBSTITUTE(N22," ",""),"0",""),"-","")))*1),0)+IF(OR(COUNTA(J23,K23,M23,N23)>0,OR(L23="X",L23="x")),IF(OR(L23="X",L23="x",AND(OR(COUNTA(J23,K23,M23,N23)>0,OR(L23="X",L23="x")),(LEN(SUBSTITUTE(SUBSTITUTE(SUBSTITUTE(J23," ",""),"0",""),"-",""))+LEN(SUBSTITUTE(SUBSTITUTE(SUBSTITUTE(K23," ",""),"0",""),"-","")))=(LEN(SUBSTITUTE(SUBSTITUTE(SUBSTITUTE(M23," ",""),"0",""),"-",""))+LEN(SUBSTITUTE(SUBSTITUTE(SUBSTITUTE(N23," ",""),"0",""),"-",""))))),0,(LEN(SUBSTITUTE(SUBSTITUTE(SUBSTITUTE(J23," ",""),"0",""),"-",""))+LEN(SUBSTITUTE(SUBSTITUTE(SUBSTITUTE(K23," ",""),"0",""),"-",""))<LEN(SUBSTITUTE(SUBSTITUTE(SUBSTITUTE(M23," ",""),"0",""),"-",""))+LEN(SUBSTITUTE(SUBSTITUTE(SUBSTITUTE(N23," ",""),"0",""),"-","")))*1),0) | L28: =IF(OR(COUNTA(J22,K22,M22,N22)>0,OR(L22="X",L22="x")),IF(OR(L22="X",L22="x",AND(OR(COUNTA(J22,K22,M22,N22)>0,OR(L22="X",L22="x")),(LEN(SUBSTITUTE(SUBSTITUTE(SUBSTITUTE(J22," ",""),"0",""),"-",""))+LEN(SUBSTITUTE(SUBSTITUTE(SUBSTITUTE(K22," ",""),"0",""),"-","")))=(LEN(SUBSTITUTE(SUBSTITUTE(SUBSTITUTE(M22," ",""),"0",""),"-",""))+LEN(SUBSTITUTE(SUBSTITUTE(SUBSTITUTE(N22," ",""),"0",""),"-",""))))),1,0),0)+IF(OR(COUNTA(J23,K23,M23,N23)>0,OR(L23="X",L23="x")),IF(OR(L23="X",L23="x",AND(OR(COUNTA(J23,K23,M23,N23)>0,OR(L23="X",L23="x")),(LEN(SUBSTITUTE(SUBSTITUTE(SUBSTITUTE(J23," ",""),"0",""),"-",""))+LEN(SUBSTITUTE(SUBSTITUTE(SUBSTITUTE(K23," ",""),"0",""),"-","")))=(LEN(SUBSTITUTE(SUBSTITUTE(SUBSTITUTE(M23," ",""),"0",""),"-",""))+LEN(SUBSTITUTE(SUBSTITUTE(SUBSTITUTE(N23," ",""),"0",""),"-",""))))),1,0),0) | M28: =LEN(SUBSTITUTE(SUBSTITUTE(SUBSTITUTE(J22," ",""),"0",""),"-",""))+LEN(SUBSTITUTE(SUBSTITUTE(SUBSTITUTE(K22," ",""),"0",""),"-",""))+LEN(SUBSTITUTE(SUBSTITUTE(SUBSTITUTE(J23," ",""),"0",""),"-",""))+LEN(SUBSTITUTE(SUBSTITUTE(SUBSTITUTE(K23," ",""),"0",""),"-","")) | N28: =LEN(SUBSTITUTE(SUBSTITUTE(SUBSTITUTE(M22," ",""),"0",""),"-",""))+LEN(SUBSTITUTE(SUBSTITUTE(SUBSTITUTE(N22," ",""),"0",""),"-",""))+LEN(SUBSTITUTE(SUBSTITUTE(SUBSTITUTE(M23," ",""),"0",""),"-",""))+LEN(SUBSTITUTE(SUBSTITUTE(SUBSTITUTE(N23," ",""),"0",""),"-","")) | O28: =RANK(AC28,$AC$26:$AC$28)+COUNTIF($AC$25:AC27,AC28) | U28: =(B28*1000000)-(C28*10000)+(D28*100)+(E28*1)-(F28*0.01) | AC28: =(J28*1000000)-(K28*10000)+(L28*100)+(M28*1)-(N28*0.01)
G31: Ranking | O31: Ranking
F32: 1. | G32: =IFERROR(INDEX($A$26:$A$28, MATCH(1, $G$26:$G$28, 0)), "-") | N32: 1. | O32: =IFERROR(INDEX($I$26:$I$28, MATCH(1, $O$26:$O$28, 0)), "-")
F33: 2. | G33: =IFERROR(INDEX($A$26:$A$28, MATCH(2, $G$26:$G$28, 0)), "-") | N33: 2. | O33: =IFERROR(INDEX($I$26:$I$28, MATCH(2, $O$26:$O$28, 0)), "-")
F34: 3. | G34: =IFERROR(INDEX($A$26:$A$28, MATCH(3, $G$26:$G$28, 0)), "-") | N34: 3. | O34: =IFERROR(INDEX($I$26:$I$28, MATCH(3, $O$26:$O$28, 0)), "-")
A36: ='data'!$A$11 | I36: ='data'!$A$58
A37: White | D37: vs | G37: Red | I37: White | L37: vs | O37: Red
A38: =data!$E$10&" "&data!$B$10 | G38: =data!$E$9&" "&data!$B$9 | I38: =data!$E$57&" "&data!$B$57 | O38: =data!$E$56&" "&data!$B$56
A39: =data!$E$11&" "&data!$B$11 | G39: =data!$E$9&" "&data!$B$9 | I39: =data!$E$58&" "&data!$B$58 | O39: =data!$E$56&" "&data!$B$56
A40: =data!$E$11&" "&data!$B$11 | G40: =data!$E$10&" "&data!$B$10 | I40: =data!$E$58&" "&data!$B$58 | O40: =data!$E$57&" "&data!$B$57
A42: Results | B42: W | C42: L | D42: T | E42: PW | F42: PL | G42: Rank | I42: Results | J42: W | K42: L | L42: T | M42: PW | N42: PL | O42: Rank
