Workbook

Sheet data
A1: Title prefix:
A2: Pool | B2: Player Name | C2: Player Dojo | D2: Player Number | E2: Metadata
A3: Pool A | B3: Kevin Clark | C3: Team Alpha | D3: K1
A4: Pool A | B4: Nathan Lee | C4: Team Delta | D4: K2
A5: Pool A | B5: Quentin Allen | C5: Team Beta | D5: K3
A6: Pool A | B6: Robert Young | C6: Team Gamma | D6: K4
A7: Pool B | B7: Michael Lewis | C7: Team Gamma | D7: K5
A8: Pool B | B8: Steven Hernandez | C8: Team Delta | D8: K6
A9: Pool B | B9: Thomas King | C9: Team Epsilon | D9: K7
A10: Pool C | B10: Luke Rodriguez | C10: Team Beta | D10: K8
A11: Pool C | B11: Oliver Walker | C11: Team Epsilon | D11: K9
A12: Pool C | B12: Paul Hall | C12: Team Alpha | D12: K10

Sheet Time Estimator
A1: Number of pools | B1: Team size | C1: Matches per pool | D1: Time per match | E1: Total time for matches | F1: Padding time for rotation | G1: Time for breaks | H1: Total Time
A2: 3 | B2: 5 | C2: 12 | D2: 0.0020833333 | E2: =(A2*B2*C2*D2) | F2: 0.00034722222 | G2: 0.020833333 | H2: =C2*I2+J2
A3: 0 | B3: 0 | C3: 0 | D3: 0.0020833333 | E3: =(A3*B3*C3*D3) | F3: 0.00034722222 | G3: 0.020833333 | H3: =E3+(A3*C3*F3)+G3
A7: Number of Elimination Matches | B7: Team size | D7: Time per match | E7: Total time for matches | F7: Padding time for rotation | G7: Time for breaks | H7: Total Time
A8: 5 | B8: 5 | D8: 0.0027777778 | E8: =(A8*B8*D8) | F8: 0.00034722222 | G8: 0.020833333 | H8: =E8+(A8*F8)+G8
E13: Tournament Summary
A14: 2 | E14: Total Pool Time | H14: =H2
E15: Total Elimination Time | H15: =H8
E16: Grand Total (Sequential) | H16: =H14+H15
E17: Grand Total (Parallel across Courts) | H17: =H16/A14
E18: Start Time: | H18: 0.375
E19: Estimated Finish Time | H19: =H18+H17

Sheet Pool Draw
B2: =IF(data!$B$1="","Tournament Pools",data!$B$1&" - Tournament Pools")
B5: ='data'!$A$6 | D5: ='data'!$A$9 | F5: ='data'!$A$12
B6: =data!$D$3&" "&data!$B$3 | D6: =data!$D$7&" "&data!$B$7 | F6: =data!$D$10&" "&data!$B$10
B7: =data!$D$4&" "&data!$B$4 | D7: =data!$D$8&" "&data!$B$8 | F7: =data!$D$11&" "&data!$B$11
B8: =data!$D$5&" "&data!$B$5 | D8: =data!$D$9&" "&data!$B$9 | F8: =data!$D$12&" "&data!$B$12
B9: =data!$D$6&" "&data!$B$6

Sheet Pool Matches
A1: Shiaijo A | I1: Shiaijo B
A2: ='data'!$A$6 | I2: ='data'!$A$12
A3: White | D3: vs | G3: Red | I3: White | L3: vs | O3: Red
A4: =data!$D$4&" "&data!$B$4 | B4: =IF(UPPER(D5)="X",0,IF((LEN(SUBSTITUTE(SUBSTITUTE(SUBSTITUTE(B5," ",""),"0",""),"-",""))+LEN(SUBSTITUTE(SUBSTITUTE(SUBSTITUTE(C5," ",""),"0",""),"-","")))>(LEN(SUBSTITUTE(SUBSTITUTE(SUBSTITUTE(E5," ",""),"0",""),"-",""))+LEN(SUBSTITUTE(SUBSTITUTE(SUBSTITUTE(F5," ",""),"0",""),"-",""))),1,0))+IF(UPPER(D6)="X",0,IF((LEN(SUBSTITUTE(SUBSTITUTE(SUBSTITUTE(B6," ",""),"0",""),"-",""))+LEN(SUBSTITUTE(SUBSTITUTE(SUBSTITUTE(C6," ",""),"0",""),"-","")))>(LEN(SUBSTITUTE(SUBSTITUTE(SUBSTITUTE(E6," ",""),"0",""),"-",""))+LEN(SUBSTITUTE(SUBSTITUTE(SUBSTITUTE(F6," ",""),"0",""),"-",""))),1,0))+IF(UPPER(D7)="X",0,IF((LEN(SUBSTITUTE(SUBSTITUTE(SUBSTITUTE(B7," ",""),"0",""),"-",""))+LEN(SUBSTITUTE(SUBSTITUTE(SUBSTITUTE(C7," ",""),"0",""),"-","")))>(LEN(SUBSTITUTE(SUBSTITUTE(SUBSTITUTE(E7," ",""),"0",""),"-",""))+LEN(SUBSTITUTE(SUBSTITUTE(SUBSTITUTE(F7," ",""),"0",""),"-",""))),1,0))+IF(UPPER(D8)="X",0,IF((LEN(SUBSTITUTE(SUBSTITUTE(SUBSTITUTE(B8," ",""),"0",""),"-",""))+LEN(SUBSTITUTE(SUBSTITUTE(SUBSTITUTE(C8," ",""),"0",""),"-","")))>(LEN(SUBSTITUTE(SUBSTITUTE(SUBSTITUTE(E8," ",""),"0",""),"-",""))+LEN(SUBSTITUTE(SUBSTITUTE(SUBSTITUTE(F8," ",""),"0",""),"-",""))),1,0))+IF(UPPER(D9)="X",0,IF((LEN(SUBSTITUTE(SUBSTITUTE(SUBSTITUTE(B9," ",""),"0",""),"-",""))+LEN(SUBSTITUTE(SUBSTITUTE(SUBSTITUTE(C9," ",""),"0",""),"-","")))>(LEN(SUBSTITUTE(SUBSTITUTE(SUBSTITUTE(E9," ",""),"0",""),"-",""))+LEN(SUBSTITUTE(SUBSTITUTE(SUBSTITUTE(F9," ",""),"0",""),"-",""))),1,0)) | C4: =LEN(SUBSTITUTE(SUBSTITUTE(SUBSTITUTE(B5," ",""),"0",""),"-",""))+LEN(SUBSTITUTE(SUBSTITUTE(SUBSTITUTE(C5," ",""),"0",""),"-",""))+LEN(SUBSTITUTE(SUBSTITUTE(SUBSTITUTE(B6," ",""),"0",""),"-",""))+LEN(SUBSTITUTE(SUBSTITUTE(SUBSTITUTE(C6," ",""),"0",""),"-",""))+LEN(SUBSTITUTE(SUBSTITUTE(SUBSTITUTE(B7," ",""),"0",""),"-",""))+LEN(SUBSTITUTE(SUBSTITUTE(SUBSTITUTE(C7," ",""),"0",""),"-",""))+LEN(SUBSTITUTE(SUBSTITUTE(SUBSTITUTE(B8," ",""),"0",""),"-",""))+LEN(SUBSTITUTE(SUBSTITUTE(SUBSTITUTE(C8," ",""),"0",""),"-",""))+LEN(SUBSTITUTE(SUBSTITUTE(SUBSTITUTE(B9," ",""),"0",""),"-",""))+LEN(SUBSTITUTE(SUBSTITUTE(SUBSTITUTE(C9," ",""),"0",""),"-","")) | E4: =LEN(SUBSTITUTE(SUBSTITUTE(SUBSTITUTE(E5," ",""),"0",""),"-",""))+LEN(SUBSTITUTE(SUBSTITUTE(SUBSTITUTE(F5," ",""),"0",""),"-",""))+LEN(SUBSTITUTE(SUBSTITUTE(SUBSTITUTE(E6," ",""),"0",""),"-",""))+LEN(SUBSTITUTE(SUBSTITUTE(SUBSTITUTE(F6," ",""),"0",""),"-",""))+LEN(SUBSTITUTE(SUBSTITUTE(SUBSTITUTE(E7," ",""),"0",""),"-",""))+LEN(SUBSTITUTE(SUBSTITUTE(SUBSTITUTE(F7," ",""),"0",""),"-",""))+LEN(SUBSTITUTE(SUBSTITUTE(SUBSTITUTE(E8," ",""),"0",""),"-",""))+LEN(SUBSTITUTE(SUBSTITUTE(SUBSTITUTE(F8," ",""),"0",""),"-",""))+LEN(SUBSTITUTE(SUBSTITUTE(SUBSTITUTE(E9," ",""),"0",""),"-",""))+LEN(SUBSTITUTE(SUBSTITUTE(SUBSTITUTE(F9," ",""),"0",""),"-","")) | F4: =IF(UPPER(D5)="X",0,IF((LEN(SUBSTITUTE(SUBSTITUTE(SUBSTITUTE(E5," ",""),"0",""),"-",""))+LEN(SUBSTITUTE(SUBSTITUTE(SUBSTITUTE(F5," ",""),"0",""),"-","")))>(LEN(SUBSTITUTE(SUBSTITUTE(SUBSTITUTE(B5," ",""),"0",""),"-",""))+LEN(SUBSTITUTE(SUBSTITUTE(SUBSTITUTE(C5," ",""),"0",""),"-",""))),1,0))+IF(UPPER(D6)="X",0,IF((LEN(SUBSTITUTE(SUBSTITUTE(SUBSTITUTE(E6," ",""),"0",""),"-",""))+LEN(SUBSTITUTE(SUBSTITUTE(SUBSTITUTE(F6," ",""),"0",""),"-","")))>(LEN(SUBSTITUTE(SUBSTITUTE(SUBSTITUTE(B6," ",""),"0",""),"-",""))+LEN(SUBSTITUTE(SUBSTITUTE(SUBSTITUTE(C6," ",""),"0",""),"-",""))),1,0))+IF(UPPER(D7)="X",0,IF((LEN(SUBSTITUTE(SUBSTITUTE(SUBSTITUTE(E7," ",""),"0",""),"-",""))+LEN(SUBSTITUTE(SUBSTITUTE(SUBSTITUTE(F7," ",""),"0",""),"-","")))>(LEN(SUBSTITUTE(SUBSTITUTE(SUBSTITUTE(B7," ",""),"0",""),"-",""))+LEN(SUBSTITUTE(SUBSTITUTE(SUBSTITUTE(C7," ",""),"0",""),"-",""))),1,0))+IF(UPPER(D8)="X",0,IF((LEN(SUBSTITUTE(SUBSTITUTE(SUBSTITUTE(E8," ",""),"0",""),"-",""))+LEN(SUBSTITUTE(SUBSTITUTE(SUBSTITUTE(F8," ",""),"0",""),"-","")))>(LEN(SUBSTITUTE(SUBSTITUTE(SUBSTITUTE(B8," ",""),"0",""),"-",""))+LEN(SUBSTITUTE(SUBSTITUTE(SUBSTITUTE(C8," ",""),"0",""),"-",""))),1,0))+IF(UPPER(D9)="X",0,IF((LEN(SUBSTITUTE(SUBSTITUTE(SUBSTITUTE(E9," ",""),"0",""),"-",""))+LEN(SUBSTITUTE(SUBSTITUTE(SUBSTITUTE(F9," ",""),"0",""),"-","")))>(LEN(SUBSTITUTE(SUBSTITUTE(SUBSTITUTE(B9," ",""),"0",""),"-",""))+LEN(SUBSTITUTE(SUBSTITUTE(SUBSTITUTE(C9," ",""),"0",""),"-",""))),1,0)) | G4: =data!$D$3&" "&data!$B$3 | I4: =data!$D$11&" "&data!$B$11 | J4: =IF(UPPER(L5)="X",0,IF((LEN(SUBSTITUTE(SUBSTITUTE(SUBSTITUTE(J5," ",""),"0",""),"-",""))+LEN(SUBSTITUTE(SUBSTITUTE(SUBSTITUTE(K5," ",""),"0",""),"-","")))>(LEN(SUBSTITUTE(SUBSTITUTE(SUBSTITUTE(M5," ",""),"0",""),"-",""))+LEN(SUBSTITUTE(SUBSTITUTE(SUBSTITUTE(N5," ",""),"0",""),"-",""))),1,0))+IF(UPPER(L6)="X",0,IF((LEN(SUBSTITUTE(SUBSTITUTE(SUBSTITUTE(J6," ",""),"0",""),"-",""))+LEN(SUBSTITUTE(SUBSTITUTE(SUBSTITUTE(K6," ",""),"0",""),"-","")))>(LEN(SUBSTITUTE(SUBSTITUTE(SUBSTITUTE(M6," ",""),"0",""),"-",""))+LEN(SUBSTITUTE(SUBSTITUTE(SUBSTITUTE(N6," ",""),"0",""),"-",""))),1,0))+IF(UPPER(L7)="X",0,IF((LEN(SUBSTITUTE(SUBSTITUTE(SUBSTITUTE(J7," ",""),"0",""),"-",""))+LEN(SUBSTITUTE(SUBSTITUTE(SUBSTITUTE(K7," ",""),"0",""),"-","")))>(LEN(SUBSTITUTE(SUBSTITUTE(SUBSTITUTE(M7," ",""),"0",""),"-",""))+LEN(SUBSTITUTE(SUBSTITUTE(SUBSTITUTE(N7," ",""),"0",""),"-",""))),1,0))+IF(UPPER(L8)="X",0,IF((LEN(SUBSTITUTE(SUBSTITUTE(SUBSTITUTE(J8," ",""),"0",""),"-",""))+LEN(SUBSTITUTE(SUBSTITUTE(SUBSTITUTE(K8," ",""),"0",""),"-","")))>(LEN(SUBSTITUTE(SUBSTITUTE(SUBSTITUTE(M8," ",""),"0",""),"-",""))+LEN(SUBSTITUTE(SUBSTITUTE(SUBSTITUTE(N8," ",""),"0",""),"-",""))),1,0))+IF(UPPER(L9)="X",0,IF((LEN(SUBSTITUTE(SUBSTITUTE(SUBSTITUTE(J9," ",""),"0",""),"-",""))+LEN(SUBSTITUTE(SUBSTITUTE(SUBSTITUTE(K9," ",""),"0",""),"-","")))>(LEN(SUBSTITUTE(SUBSTITUTE(SUBSTITUTE(M9," ",""),"0",""),"-",""))+LEN(SUBSTITUTE(SUBSTITUTE(SUBSTITUTE(N9," ",""),"0",""),"-",""))),1,0)) | K4: =LEN(SUBSTITUTE(SUBSTITUTE(SUBSTITUTE(J5," ",""),"0",""),"-",""))+LEN(SUBSTITUTE(SUBSTITUTE(SUBSTITUTE(K5," ",""),"0",""),"-",""))+LEN(SUBSTITUTE(SUBSTITUTE(SUBSTITUTE(J6," ",""),"0",""),"-",""))+LEN(SUBSTITUTE(SUBSTITUTE(SUBSTITUTE(K6," ",""),"0",""),"-",""))+LEN(SUBSTITUTE(SUBSTITUTE(SUBSTITUTE(J7," ",""),"0",""),"-",""))+LEN(SUBSTITUTE(SUBSTITUTE(SUBSTITUTE(K7," ",""),"0",""),"-",""))+LEN(SUBSTITUTE(SUBSTITUTE(SUBSTITUTE(J8," ",""),"0",""),"-",""))+LEN(SUBSTITUTE(SUBSTITUTE(SUBSTITUTE(K8," ",""),"0",""),"-",""))+LEN(SUBSTITUTE(SUBSTITUTE(SUBSTITUTE(J9," ",""),"0",""),"-",""))+LEN(SUBSTITUTE(SUBSTITUTE(SUBSTITUTE(K9," ",""),"0",""),"-","")) | M4: =LEN(SUBSTITUTE(SUBSTITUTE(SUBSTITUTE(M5," ",""),"0",""),"-",""))+LEN(SUBSTITUTE(SUBSTITUTE(SUBSTITUTE(N5," ",""),"0",""),"-",""))+LEN(SUBSTITUTE(SUBSTITUTE(SUBSTITUTE(M6," ",""),"0",""),"-",""))+LEN(SUBSTITUTE(SUBSTITUTE(SUBSTITUTE(N6," ",""),"0",""),"-",""))+LEN(SUBSTITUTE(SUBSTITUTE(SUBSTITUTE(M7," ",""),"0",""),"-",""))+LEN(SUBSTITUTE(SUBSTITUTE(SUBSTITUTE(N7," ",""),"0",""),"-",""))+LEN(SUBSTITUTE(SUBSTITUTE(SUBSTITUTE(M8," ",""),"0",""),"-",""))+LEN(SUBSTITUTE(SUBSTITUTE(SUBSTITUTE(N8," ",""),"0",""),"-",""))+LEN(SUBSTITUTE(SUBSTITUTE(SUBSTITUTE(M9," ",""),"0",""),"-",""))+LEN(SUBSTITUTE(SUBSTITUTE(SUBSTITUTE(N9," ",""),"0",""),"-","")) | N4: =IF(UPPER(L5)="X",0,IF((LEN(SUBSTITUTE(SUBSTITUTE(SUBSTITUTE(M5," ",""),"0",""),"-",""))+LEN(SUBSTITUTE(SUBSTITUTE(SUBSTITUTE(N5," ",""),"0",""),"-","")))>(LEN(SUBSTITUTE(SUBSTITUTE(SUBSTITUTE(J5," ",""),"0",""),"-",""))+LEN(SUBSTITUTE(SUBSTITUTE(SUBSTITUTE(K5," ",""),"0",""),"-",""))),1,0))+IF(UPPER(L6)="X",0,IF((LEN(SUBSTITUTE(SUBSTITUTE(SUBSTITUTE(M6," ",""),"0",""),"-",""))+LEN(SUBSTITUTE(SUBSTITUTE(SUBSTITUTE(N6," ",""),"0",""),"-","")))>(LEN(SUBSTITUTE(SUBSTITUTE(SUBSTITUTE(J6," ",""),"0",""),"-",""))+LEN(SUBSTITUTE(SUBSTITUTE(SUBSTITUTE(K6," ",""),"0",""),"-",""))),1,0))+IF(UPPER(L7)="X",0,IF((LEN(SUBSTITUTE(SUBSTITUTE(SUBSTITUTE(M7," ",""),"0",""),"-",""))+LEN(SUBSTITUTE(SUBSTITUTE(SUBSTITUTE(N7," ",""),"0",""),"-","")))>(LEN(SUBSTITUTE(SUBSTITUTE(SUBSTITUTE(J7," ",""),"0",""),"-",""))+LEN(SUBSTITUTE(SUBSTITUTE(SUBSTITUTE(K7," ",""),"0",""),"-",""))),1,0))+IF(UPPER(L8)="X",0,IF((LEN(SUBSTITUTE(SUBSTITUTE(SUBSTITUTE(M8," ",""),"0",""),"-",""))+LEN(SUBSTITUTE(SUBSTITUTE(SUBSTITUTE(N8," ",""),"0",""),"-","")))>(LEN(SUBSTITUTE(SUBSTITUTE(SUBSTITUTE(J8," ",""),"0",""),"-",""))+LEN(SUBSTITUTE(SUBSTITUTE(SUBSTITUTE(K8," ",""),"0",""),"-",""))),1,0))+IF(UPPER(L9)="X",0,IF((LEN(SUBSTITUTE(SUBSTITUTE(SUBSTITUTE(M9," ",""),"0",""),"-",""))+LEN(SUBSTITUTE(SUBSTITUTE(SUBSTITUTE(N9," ",""),"0",""),"-","")))>(LEN(SUBSTITUTE(SUBSTITUTE(SUBSTITUTE(J9," ",""),"0",""),"-",""))+LEN(SUBSTITUTE(SUBSTITUTE(SUBSTITUTE(K9," ",""),"0",""),"-",""))),1,0)) | O4: =data!$D$10&" "&data!$B$10
A5: 1 | G5: 1 | I5: 1 | O5: 1
A6: 2 | G6: 2 | I6: 2 | O6: 2
A7: 3 | G7: 3 | I7: 3 | O7: 3
A8: 4 | G8: 4 | I8: 4 | O8: 4
A9: 5 | G9: 5 | I9: 5 | O9: 5
A11: White | D11: vs | G11: Red | I11: White | L11: vs | O11: Red
A12: =data!$D$4&" "&data!$B$4 | B12: =IF(UPPER(D13)="X",0,IF((LEN(SUBSTITUTE(SUBSTITUTE(SUBSTITUTE(B13," ",""),"0",""),"-",""))+LEN(SUBSTITUTE(SUBSTITUTE(SUBSTITUTE(C13," ",""),"0",""),"-","")))>(LEN(SUBSTITUTE(SUBSTITUTE(SUBSTITUTE(E13," ",""),"0",""),"-",""))+LEN(SUBSTITUTE(SUBSTITUTE(SUBSTITUTE(F13," ",""),"0",""),"-",""))),1,0))+IF(UPPER(D14)="X",0,IF((LEN(SUBSTITUTE(SUBSTITUTE(SUBSTITUTE(B14," ",""),"0",""),"-",""))+LEN(SUBSTITUTE(SUBSTITUTE(SUBSTITUTE(C14," ",""),"0",""),"-","")))>(LEN(SUBSTITUTE(SUBSTITUTE(SUBSTITUTE(E14," ",""),"0",""),"-",""))+LEN(SUBSTITUTE(SUBSTITUTE(SUBSTITUTE(F14," ",""),"0",""),"-",""))),1,0))+IF(UPPER(D15)="X",0,IF((LEN(SUBSTITUTE(SUBSTITUTE(SUBSTITUTE(B15," ",""),"0",""),"-",""))+LEN(SUBSTITUTE(SUBSTITUTE(SUBSTITUTE(C15," ",""),"0",""),"-","")))>(LEN(SUBSTITUTE(SUBSTITUTE(SUBSTITUTE(E15," ",""),"0",""),"-",""))+LEN(SUBSTITUTE(SUBSTITUTE(SUBSTITUTE(F15," ",""),"0",""),"-",""))),1,0))+IF(UPPER(D16)="X",0,IF((LEN(SUBSTITUTE(SUBSTITUTE(SUBSTITUTE(B16," ",""),"0",""),"-",""))+LEN(SUBSTITUTE(SUBSTITUTE(SUBSTITUTE(C16," ",""),"0",""),"-","")))>(LEN(SUBSTITUTE(SUBSTITUTE(SUBSTITUTE(E16," ",""),"0",""),"-",""))+LEN(SUBSTITUTE(SUBSTITUTE(SUBSTITUTE(F16," ",""),"0",""),"-",""))),1,0))+IF(UPPER(D17)="X",0,IF((LEN(SUBSTITUTE(SUBSTITUTE(SUBSTITUTE(B17," ",""),"0",""),"-",""))+LEN(SUBSTITUTE(SUBSTITUTE(SUBSTITUTE(C17," ",""),"0",""),"-","")))>(LEN(SUBSTITUTE(SUBSTITUTE(SUBSTITUTE(E17," ",""),"0",""),"-",""))+LEN(SUBSTITUTE(SUBSTITUTE(SUBSTITUTE(F17," ",""),"0",""),"-",""))),1,0)) | C12: =LEN(SUBSTITUTE(SUBSTITUTE(SUBSTITUTE(B13," ",""),"0",""),"-",""))+LEN(SUBSTITUTE(SUBSTITUTE(SUBSTITUTE(C13," ",""),"0",""),"-",""))+LEN(SUBSTITUTE(SUBSTITUTE(SUBSTITUTE(B14," ",""),"0",""),"-",""))+LEN(SUBSTITUTE(SUBSTITUTE(SUBSTITUTE(C14," ",""),"0",""),"-",""))+LEN(SUBSTITUTE(SUBSTITUTE(SUBSTITUTE(B15," ",""),"0",""),"-",""))+LEN(SUBSTITUTE(SUBSTITUTE(SUBSTITUTE(C15," ",""),"0",""),"-",""))+LEN(SUBSTITUTE(SUBSTITUTE(SUBSTITUTE(B16," ",""),"0",""),"-",""))+LEN(SUBSTITUTE(SUBSTITUTE(SUBSTITUTE(C16," ",""),"0",""),"-",""))+LEN(SUBSTITUTE(SUBSTITUTE(SUBSTITUTE(B17," ",""),"0",""),"-",""))+LEN(SUBSTITUTE(SUBSTITUTE(SUBSTITUTE(C17," ",""),"0",""),"-","")) | E12: =LEN(SUBSTITUTE(SUBSTITUTE(SUBSTITUTE(E13," ",""),"0",""),"-",""))+LEN(SUBSTITUTE(SUBSTITUTE(SUBSTITUTE(F13," ",""),"0",""),"-",""))+LEN(SUBSTITUTE(SUBSTITUTE(SUBSTITUTE(E14," ",""),"0",""),"-",""))+LEN(SUBSTITUTE(SUBSTITUTE(SUBSTITUTE(F14," ",""),"0",""),"-",""))+LEN(SUBSTITUTE(SUBSTITUTE(SUBSTITUTE(E15," ",""),"0",""),"-",""))+LEN(SUBSTITUTE(SUBSTITUTE(SUBSTITUTE(F15," ",""),"0",""),"-",""))+LEN(SUBSTITUTE(SUBSTITUTE(SUBSTITUTE(E16," ",""),"0",""),"-",""))+LEN(SUBSTITUTE(SUBSTITUTE(SUBSTITUTE(F16," ",""),"0",""),"-",""))+LEN(SUBSTITUTE(SUBSTITUTE(SUBSTITUTE(E17," ",""),"0",""),"-",""))+LEN(SUBSTITUTE(SUBSTITUTE(SUBSTITUTE(F17," ",""),"0",""),"-","")) | F12: =IF(UPPER(D13)="X",0,IF((LEN(SUBSTITUTE(SUBSTITUTE(SUBSTITUTE(E13," ",""),"0",""),"-",""))+LEN(SUBSTITUTE(SUBSTITUTE(SUBSTITUTE(F13," ",""),"0",""),"-","")))>(LEN(SUBSTITUTE(SUBSTITUTE(SUBSTITUTE(B13," ",""),"0",""),"-",""))+LEN(SUBSTITUTE(SUBSTITUTE(SUBSTITUTE(C13," ",""),"0",""),"-",""))),1,0))+IF(UPPER(D14)="X",0,IF((LEN(SUBSTITUTE(SUBSTITUTE(SUBSTITUTE(E14," ",""),"0",""),"-",""))+LEN(SUBSTITUTE(SUBSTITUTE(SUBSTITUTE(F14," ",""),"0",""),"-","")))>(LEN(SUBSTITUTE(SUBSTITUTE(SUBSTITUTE(B14," ",""),"0",""),"-",""))+LEN(SUBSTITUTE(SUBSTITUTE(SUBSTITUTE(C14," ",""),"0",""),"-",""))),1,0))+IF(UPPER(D15)="X",0,IF((LEN(SUBSTITUTE(SUBSTITUTE(SUBSTITUTE(E15," ",""),"0",""),"-",""))+LEN(SUBSTITUTE(SUBSTITUTE(SUBSTITUTE(F15," ",""),"0",""),"-","")))>(LEN(SUBSTITUTE(SUBSTITUTE(SUBSTITUTE(B15," ",""),"0",""),"-",""))+LEN(SUBSTITUTE(SUBSTITUTE(SUBSTITUTE(C15," ",""),"0",""),"-",""))),1,0))+IF(UPPER(D16)="X",0,IF((LEN(SUBSTITUTE(SUBSTITUTE(SUBSTITUTE(E16," ",""),"0",""),"-",""))+LEN(SUBSTITUTE(SUBSTITUTE(SUBSTITUTE(F16," ",""),"0",""),"-","")))>(LEN(SUBSTITUTE(SUBSTITUTE(SUBSTITUTE(B16," ",""),"0",""),"-",""))+LEN(SUBSTITUTE(SUBSTITUTE(SUBSTITUTE(C16," ",""),"0",""),"-",""))),1,0))+IF(UPPER(D17)="X",0,IF((LEN(SUBSTITUTE(SUBSTITUTE(SUBSTITUTE(E17," ",""),"0",""),"-",""))+LEN(SUBSTITUTE(SUBSTITUTE(SUBSTITUTE(F17," ",""),"0",""),"-","")))>(LEN(SUBSTITUTE(SUBSTITUTE(SUBSTITUTE(B17," ",""),"0",""),"-",""))+LEN(SUBSTITUTE(SUBSTITUTE(SUBSTITUTE(C17," ",""),"0",""),"-",""))),1,0)) | G12: =data!$D$5&" "&data!$B$5 | I12: =data!$D$12&" "&data!$B$12 | J12: =IF(UPPER(L13)="X",0,IF((LEN(SUBSTITUTE(SUBSTITUTE(SUBSTITUTE(J13," ",""),"0",""),"-",""))+LEN(SUBSTITUTE(SUBSTITUTE(SUBSTITUTE(K13," ",""),"0",""),"-","")))>(LEN(SUBSTITUTE(SUBSTITUTE(SUBSTITUTE(M13," ",""),"0",""),"-",""))+LEN(SUBSTITUTE(SUBSTITUTE(SUBSTITUTE(N13," ",""),"0",""),"-",""))),1,0))+IF(UPPER(L14)="X",0,IF((LEN(SUBSTITUTE(SUBSTITUTE(SUBSTITUTE(J14," ",""),"0",""),"-",""))+LEN(SUBSTITUTE(SUBSTITUTE(SUBSTITUTE(K14," ",""),"0",""),"-","")))>(LEN(SUBSTITUTE(SUBSTITUTE(SUBSTITUTE(M14," ",""),"0",""),"-",""))+LEN(SUBSTITUTE(SUBSTITUTE(SUBSTITUTE(N14," ",""),"0",""),"-",""))),1,0))+IF(UPPER(L15)="X",0,IF((LEN(SUBSTITUTE(SUBSTITUTE(SUBSTITUTE(J15," ",""),"0",""),"-",""))+LEN(SUBSTITUTE(SUBSTITUTE(SUBSTITUTE(K15," ",""),"0",""),"-","")))>(LEN(SUBSTITUTE(SUBSTITUTE(SUBSTITUTE(M15," ",""),"0",""),"-",""))+LEN(SUBSTITUTE(SUBSTITUTE(SUBSTITUTE(N15," ",""),"0",""),"-",""))),1,0))+IF(UPPER(L16)="X",0,IF((LEN(SUBSTITUTE(SUBSTITUTE(SUBSTITUTE(J16," ",""),"0",""),"-",""))+LEN(SUBSTITUTE(SUBSTITUTE(SUBSTITUTE(K16," ",""),"0",""),"-","")))>(LEN(SUBSTITUTE(SUBSTITUTE(SUBSTITUTE(M16," ",""),"0",""),"-",""))+LEN(SUBSTITUTE(SUBSTITUTE(SUBSTITUTE(N16," ",""),"0",""),"-",""))),1,0))+IF(UPPER(L17)="X",0,IF((LEN(SUBSTITUTE(SUBSTITUTE(SUBSTITUTE(J17," ",""),"0",""),"-",""))+LEN(SUBSTITUTE(SUBSTITUTE(SUBSTITUTE(K17," ",""),"0",""),"-","")))>(LEN(SUBSTITUTE(SUBSTITUTE(SUBSTITUTE(M17," ",""),"0",""),"-",""))+LEN(SUBSTITUTE(SUBSTITUTE(SUBSTITUTE(N17," ",""),"0",""),"-",""))),1,0)) | K12: =LEN(SUBSTITUTE(SUBSTITUTE(SUBSTITUTE(J13," ",""),"0",""),"-",""))+LEN(SUBSTITUTE(SUBSTITUTE(SUBSTITUTE(K13," ",""),"0",""),"-",""))+LEN(SUBSTITUTE(SUBSTITUTE(SUBSTITUTE(J14," ",""),"0",""),"-",""))+LEN(SUBSTITUTE(SUBSTITUTE(SUBSTITUTE(K14," ",""),"0",""),"-",""))+LEN(SUBSTITUTE(SUBSTITUTE(SUBSTITUTE(J15," ",""),"0",""),"-",""))+LEN(SUBSTITUTE(SUBSTITUTE(SUBSTITUTE(K15," ",""),"0",""),"-",""))+LEN(SUBSTITUTE(SUBSTITUTE(SUBSTITUTE(J16," ",""),"0",""),"-",""))+LEN(SUBSTITUTE(SUBSTITUTE(SUBSTITUTE(K16," ",""),"0",""),"-",""))+LEN(SUBSTITUTE(SUBSTITUTE(SUBSTITUTE(J17," ",""),"0",""),"-",""))+LEN(SUBSTITUTE(SUBSTITUTE(SUBSTITUTE(K17," ",""),"0",""),"-","")) | M12: =LEN(SUBSTITUTE(SUBSTITUTE(SUBSTITUTE(M13," ",""),"0",""),"-",""))+LEN(SUBSTITUTE(SUBSTITUTE(SUBSTITUTE(N13," ",""),"0",""),"-",""))+LEN(SUBSTITUTE(SUBSTITUTE(SUBSTITUTE(M14," ",""),"0",""),"-",""))+LEN(SUBSTITUTE(SUBSTITUTE(SUBSTITUTE(N14," ",""),"0",""),"-",""))+LEN(SUBSTITUTE(SUBSTITUTE(SUBSTITUTE(M15," ",""),"0",""),"-",""))+LEN(SUBSTITUTE(SUBSTITUTE(SUBSTITUTE(N15," ",""),"0",""),"-",""))+LEN(SUBSTITUTE(SUBSTITUTE(SUBSTITUTE(M16," ",""),"0",""),"-",""))+LEN(SUBSTITUTE(SUBSTITUTE(SUBSTITUTE(N16," ",""),"0",""),"-",""))+LEN(SUBSTITUTE(SUBSTITUTE(SUBSTITUTE(M17," ",""),"0",""),"-",""))+LEN(SUBSTITUTE(SUBSTITUTE(SUBSTITUTE(N17," ",""),"0",""),"-","")) | N12: =IF(UPPER(L13)="X",0,IF((LEN(SUBSTITUTE(SUBSTITUTE(SUBSTITUTE(M13," ",""),"0",""),"-",""))+LEN(SUBSTITUTE(SUBSTITUTE(SUBSTITUTE(N13," ",""),"0",""),"-","")))>(LEN(SUBSTITUTE(SUBSTITUTE(SUBSTITUTE(J13," ",""),"0",""),"-",""))+LEN(SUBSTITUTE(SUBSTITUTE(SUBSTITUTE(K13," ",""),"0",""),"-",""))),1,0))+IF(UPPER(L14)="X",0,IF((LEN(SUBSTITUTE(SUBSTITUTE(SUBSTITUTE(M14," ",""),"0",""),"-",""))+LEN(SUBSTITUTE(SUBSTITUTE(SUBSTITUTE(N14," ",""),"0",""),"-","")))>(LEN(SUBSTITUTE(SUBSTITUTE(SUBSTITUTE(J14," ",""),"0",""),"-",""))+LEN(SUBSTITUTE(SUBSTITUTE(SUBSTITUTE(K14," ",""),"0",""),"-",""))),1,0))+IF(UPPER(L15)="X",0,IF((LEN(SUBSTITUTE(SUBSTITUTE(SUBSTITUTE(M15," ",""),"0",""),"-",""))+LEN(SUBSTITUTE(SUBSTITUTE(SUBSTITUTE(N15," ",""),"0",""),"-","")))>(LEN(SUBSTITUTE(SUBSTITUTE(SUBSTITUTE(J15," ",""),"0",""),"-",""))+LEN(SUBSTITUTE(SUBSTITUTE(SUBSTITUTE(K15," ",""),"0",""),"-",""))),1,0))+IF(UPPER(L16)="X",0,IF((LEN(SUBSTITUTE(SUBSTITUTE(SUBSTITUTE(M16," ",""),"0",""),"-",""))+LEN(SUBSTITUTE(SUBSTITUTE(SUBSTITUTE(N16," ",""),"0",""),"-","")))>(LEN(SUBSTITUTE(SUBSTITUTE(SUBSTITUTE(J16," ",""),"0",""),"-",""))+LEN(SUBSTITUTE(SUBSTITUTE(SUBSTITUTE(K16," ",""),"0",""),"-",""))),1,0))+IF(UPPER(L17)="X",0,IF((LEN(SUBSTITUTE(SUBSTITUTE(SUBSTITUTE(M17," ",""),"0",""),"-",""))+LEN(SUBSTITUTE(SUBSTITUTE(SUBSTITUTE(N17," ",""),"0",""),"-","")))>(LEN(SUBSTITUTE(SUBSTITUTE(SUBSTITUTE(J17," ",""),"0",""),"-",""))+LEN(SUBSTITUTE(SUBSTITUTE(SUBSTITUTE(K17," ",""),"0",""),"-",""))),1,0)) | O12: =data!$D$10&" "&data!$B$10
A13: 1 | G13: 1 | I13: 1 | O13: 1
A14: 2 | G14: 2 | I14: 2 | O14: 2
A15: 3 | G15: 3 | I15: 3 | O15: 3
A16: 4 | G16: 4 | I16: 4 | O16: 4
A17: 5 | G17: 5 | I17: 5 | O17: 5
A19: White | D19: vs | G19: Red | I19: White | L19: vs | O19: Red
A20: =data!$D$6&" "&data!$B$6 | B20: =IF(UPPER(D21)="X",0,IF((LEN(SUBSTITUTE(SUBSTITUTE(SUBSTITUTE(B21," ",""),"0",""),"-",""))+LEN(SUBSTITUTE(SUBSTITUTE(SUBSTITUTE(C21," ",""),"0",""),"-","")))>(LEN(SUBSTITUTE(SUBSTITUTE(SUBSTITUTE(E21," ",""),"0",""),"-",""))+LEN(SUBSTITUTE(SUBSTITUTE(SUBSTITUTE(F21," ",""),"0",""),"-",""))),1,0))+IF(UPPER(D22)="X",0,IF((LEN(SUBSTITUTE(SUBSTITUTE(SUBSTITUTE(B22," ",""),"0",""),"-",""))+LEN(SUBSTITUTE(SUBSTITUTE(SUBSTITUTE(C22," ",""),"0",""),"-","")))>(LEN(SUBSTITUTE(SUBSTITUTE(SUBSTITUTE(E22," ",""),"0",""),"-",""))+LEN(SUBSTITUTE(SUBSTITUTE(SUBSTITUTE(F22," ",""),"0",""),"-",""))),1,0))+IF(UPPER(D23)="X",0,IF((LEN(SUBSTITUTE(SUBSTITUTE(SUBSTITUTE(B23," ",""),"0",""),"-",""))+LEN(SUBSTITUTE(SUBSTITUTE(SUBSTITUTE(C23," ",""),"0",""),"-","")))>(LEN(SUBSTITUTE(SUBSTITUTE(SUBSTITUTE(E23," ",""),"0",""),"-",""))+LEN(SUBSTITUTE(SUBSTITUTE(SUBSTITUTE(F23," ",""),"0",""),"-",""))),1,0))+IF(UPPER(D24)="X",0,IF((LEN(SUBSTITUTE(SUBSTITUTE(SUBSTITUTE(B24," ",""),"0",""),"-",""))+LEN(SUBSTITUTE(SUBSTITUTE(SUBSTITUTE(C24," ",""),"0",""),"-","")))>(LEN(SUBSTITUTE(SUBSTITUTE(SUBSTITUTE(E24," ",""),"0",""),"-",""))+LEN(SUBSTITUTE(SUBSTITUTE(SUBSTITUTE(F24," ",""),"0",""),"-",""))),1,0))+IF(UPPER(D25)="X",0,IF((LEN(SUBSTITUTE(SUBSTITUTE(SUBSTITUTE(B25," ",""),"0",""),"-",""))+LEN(SUBSTITUTE(SUBSTITUTE(SUBSTITUTE(C25," ",""),"0",""),"-","")))>(LEN(SUBSTITUTE(SUBSTITUTE(SUBSTITUTE(E25," ",""),"0",""),"-",""))+LEN(SUBSTITUTE(SUBSTITUTE(SUBSTITUTE(F25," ",""),"0",""),"-",""))),1,0)) | C20: =LEN(SUBSTITUTE(SUBSTITUTE(SUBSTITUTE(B21," ",""),"0",""),"-",""))+LEN(SUBSTITUTE(SUBSTITUTE(SUBSTITUTE(C21," ",""),"0",""),"-",""))+LEN(SUBSTITUTE(SUBSTITUTE(SUBSTITUTE(B22," ",""),"0",""),"-",""))+LEN(SUBSTITUTE(SUBSTITUTE(SUBSTITUTE(C22," ",""),"0",""),"-",""))+LEN(SUBSTITUTE(SUBSTITUTE(SUBSTITUTE(B23," ",""),"0",""),"-",""))+LEN(SUBSTITUTE(SUBSTITUTE(SUBSTITUTE(C23," ",""),"0",""),"-",""))+LEN(SUBSTITUTE(SUBSTITUTE(SUBSTITUTE(B24," ",""),"0",""),"-",""))+LEN(SUBSTITUTE(SUBSTITUTE(SUBSTITUTE(C24," ",""),"0",""),"-",""))+LEN(SUBSTITUTE(SUBSTITUTE(SUBSTITUTE(B25," ",""),"0",""),"-",""))+LEN(SUBSTITUTE(SUBSTITUTE(SUBSTITUTE(C25," ",""),"0",""),"-","")) | E20: =LEN(SUBSTITUTE(SUBSTITUTE(SUBSTITUTE(E21," ",""),"0",""),"-",""))+LEN(SUBSTITUTE(SUBSTITUTE(SUBSTITUTE(F21," ",""),"0",""),"-",""))+LEN(SUBSTITUTE(SUBSTITUTE(SUBSTITUTE(E22," ",""),"0",""),"-",""))+LEN(SUBSTITUTE(SUBSTITUTE(SUBSTITUTE(F22," ",""),"0",""),"-",""))+LEN(SUBSTITUTE(SUBSTITUTE(SUBSTITUTE(E23," ",""),"0",""),"-",""))+LEN(SUBSTITUTE(SUBSTITUTE(SUBSTITUTE(F23," ",""),"0",""),"-",""))+LEN(SUBSTITUTE(SUBSTITUTE(SUBSTITUTE(E24," ",""),"0",""),"-",""))+LEN(SUBSTITUTE(SUBSTITUTE(SUBSTITUTE(F24," ",""),"0",""),"-",""))+LEN(SUBSTITUTE(SUBSTITUTE(SUBSTITUTE(E25," ",""),"0",""),"-",""))+LEN(SUBSTITUTE(SUBSTITUTE(SUBSTITUTE(F25," ",""),"0",""),"-","")) | F20: =IF(UPPER(D21)="X",0,IF((LEN(SUBSTITUTE(SUBSTITUTE(SUBSTITUTE(E21," ",""),"0",""),"-",""))+LEN(SUBSTITUTE(SUBSTITUTE(SUBSTITUTE(F21," ",""),"0",""),"-","")))>(LEN(SUBSTITUTE(SUBSTITUTE(SUBSTITUTE(B21," ",""),"0",""),"-",""))+LEN(SUBSTITUTE(SUBSTITUTE(SUBSTITUTE(C21," ",""),"0",""),"-",""))),1,0))+IF(UPPER(D22)="X",0,IF((LEN(SUBSTITUTE(SUBSTITUTE(SUBSTITUTE(E22," ",""),"0",""),"-",""))+LEN(SUBSTITUTE(SUBSTITUTE(SUBSTITUTE(F22," ",""),"0",""),"-","")))>(LEN(SUBSTITUTE(SUBSTITUTE(SUBSTITUTE(B22," ",""),"0",""),"-",""))+LEN(SUBSTITUTE(SUBSTITUTE(SUBSTITUTE(C22," ",""),"0",""),"-",""))),1,0))+IF(UPPER(D23)="X",0,IF((LEN(SUBSTITUTE(SUBSTITUTE(SUBSTITUTE(E23," ",""),"0",""),"-",""))+LEN(SUBSTITUTE(SUBSTITUTE(SUBSTITUTE(F23," ",""),"0",""),"-","")))>(LEN(SUBSTITUTE(SUBSTITUTE(SUBSTITUTE(B23," ",""),"0",""),"-",""))+LEN(SUBSTITUTE(SUBSTITUTE(SUBSTITUTE(C23," ",""),"0",""),"-",""))),1,0))+IF(UPPER(D24)="X",0,IF((LEN(SUBSTITUTE(SUBSTITUTE(SUBSTITUTE(E24," ",""),"0",""),"-",""))+LEN(SUBSTITUTE(SUBSTITUTE(SUBSTITUTE(F24," ",""),"0",""),"-","")))>(LEN(SUBSTITUTE(SUBSTITUTE(SUBSTITUTE(B24," ",""),"0",""),"-",""))+LEN(SUBSTITUTE(SUBSTITUTE(SUBSTITUTE(C24," ",""),"0",""),"-",""))),1,0))+IF(UPPER(D25)="X",0,IF((LEN(SUBSTITUTE(SUBSTITUTE(SUBSTITUTE(E25," ",""),"0",""),"-",""))+LEN(SUBSTITUTE(SUBSTITUTE(SUBSTITUTE(F25," ",""),"0",""),"-","")))>(LEN(SUBSTITUTE(SUBSTITUTE(SUBSTITUTE(B25," ",""),"0",""),"-",""))+LEN(SUBSTITUTE(SUBSTITUTE(SUBSTITUTE(C25," ",""),"0",""),"-",""))),1,0)) | G20: =data!$D$5&" "&data!$B$5 | I20: =data!$D$12&" "&data!$B$12 | J20: =IF(UPPER(L21)="X",0,IF((LEN(SUBSTITUTE(SUBSTITUTE(SUBSTITUTE(J21," ",""),"0",""),"-",""))+LEN(SUBSTITUTE(SUBSTITUTE(SUBSTITUTE(K21," ",""),"0",""),"-","")))>(LEN(SUBSTITUTE(SUBSTITUTE(SUBSTITUTE(M21," ",""),"0",""),"-",""))+LEN(SUBSTITUTE(SUBSTITUTE(SUBSTITUTE(N21," ",""),"0",""),"-",""))),1,0))+IF(UPPER(L22)="X",0,IF((LEN(SUBSTITUTE(SUBSTITUTE(SUBSTITUTE(J22," ",""),"0",""),"-",""))+LEN(SUBSTITUTE(SUBSTITUTE(SUBSTITUTE(K22," ",""),"0",""),"-","")))>(LEN(SUBSTITUTE(SUBSTITUTE(SUBSTITUTE(M22," ",""),"0",""),"-",""))+LEN(SUBSTITUTE(SUBSTITUTE(SUBSTITUTE(N22," ",""),"0",""),"-",""))),1,0))+IF(UPPER(L23)="X",0,IF((LEN(SUBSTITUTE(SUBSTITUTE(SUBSTITUTE(J23," ",""),"0",""),"-",""))+LEN(SUBSTITUTE(SUBSTITUTE(SUBSTITUTE(K23," ",""),"0",""),"-","")))>(LEN(SUBSTITUTE(SUBSTITUTE(SUBSTITUTE(M23," ",""),"0",""),"-",""))+LEN(SUBSTITUTE(SUBSTITUTE(SUBSTITUTE(N23," ",""),"0",""),"-",""))),1,0))+IF(UPPER(L24)="X",0,IF((LEN(SUBSTITUTE(SUBSTITUTE(SUBSTITUTE(J24," ",""),"0",""),"-",""))+LEN(SUBSTITUTE(SUBSTITUTE(SUBSTITUTE(K24," ",""),"0",""),"-","")))>(LEN(SUBSTITUTE(SUBSTITUTE(SUBSTITUTE(M24," ",""),"0",""),"-",""))+LEN(SUBSTITUTE(SUBSTITUTE(SUBSTITUTE(N24," ",""),"0",""),"-",""))),1,0))+IF(UPPER(L25)="X",0,IF((LEN(SUBSTITUTE(SUBSTITUTE(SUBSTITUTE(J25," ",""),"0",""),"-",""))+LEN(SUBSTITUTE(SUBSTITUTE(SUBSTITUTE(K25," ",""),"0",""),"-","")))>(LEN(SUBSTITUTE(SUBSTITUTE(SUBSTITUTE(M25," ",""),"0",""),"-",""))+LEN(SUBSTITUTE(SUBSTITUTE(SUBSTITUTE(N25," ",""),"0",""),"-",""))),1,0)) | K20: =LEN(SUBSTITUTE(SUBSTITUTE(SUBSTITUTE(J21," ",""),"0",""),"-",""))+LEN(SUBSTITUTE(SUBSTITUTE(SUBSTITUTE(K21," ",""),"0",""),"-",""))+LEN(SUBSTITUTE(SUBSTITUTE(SUBSTITUTE(J22," ",""),"0",""),"-",""))+LEN(SUBSTITUTE(SUBSTITUTE(SUBSTITUTE(K22," ",""),"0",""),"-",""))+LEN(SUBSTITUTE(SUBSTITUTE(SUBSTITUTE(J23," ",""),"0",""),"-",""))+LEN(SUBSTITUTE(SUBSTITUTE(SUBSTITUTE(K23," ",""),"0",""),"-",""))+LEN(SUBSTITUTE(SUBSTITUTE(SUBSTITUTE(J24," ",""),"0",""),"-",""))+LEN(SUBSTITUTE(SUBSTITUTE(SUBSTITUTE(K24," ",""),"0",""),"-",""))+LEN(SUBSTITUTE(SUBSTITUTE(SUBSTITUTE(J25," ",""),"0",""),"-",""))+LEN(SUBSTITUTE(SUBSTITUTE(SUBSTITUTE(K25," ",""),"0",""),"-","")) | M20: =LEN(SUBSTITUTE(SUBSTITUTE(SUBSTITUTE(M21," ",""),"0",""),"-",""))+LEN(SUBSTITUTE(SUBSTITUTE(SUBSTITUTE(N21," ",""),"0",""),"-",""))+LEN(SUBSTITUTE(SUBSTITUTE(SUBSTITUTE(M22," ",""),"0",""),"-",""))+LEN(SUBSTITUTE(SUBSTITUTE(SUBSTITUTE(N22," ",""),"0",""),"-",""))+LEN(SUBSTITUTE(SUBSTITUTE(SUBSTITUTE(M23," ",""),"0",""),"-",""))+LEN(SUBSTITUTE(SUBSTITUTE(SUBSTITUTE(N23," ",""),"0",""),"-",""))+LEN(SUBSTITUTE(SUBSTITUTE(SUBSTITUTE(M24," ",""),"0",""),"-",""))+LEN(SUBSTITUTE(SUBSTITUTE(SUBSTITUTE(N24," ",""),"0",""),"-",""))+LEN(SUBSTITUTE(SUBSTITUTE(SUBSTITUTE(M25," ",""),"0",""),"-",""))+LEN(SUBSTITUTE(SUBSTITUTE(SUBSTITUTE(N25," ",""),"0",""),"-","")) | N20: =IF(UPPER(L21)="X",0,IF((LEN(SUBSTITUTE(SUBSTITUTE(SUBSTITUTE(M21," ",""),"0",""),"-",""))+LEN(SUBSTITUTE(SUBSTITUTE(SUBSTITUTE(N21," ",""),"0",""),"-","")))>(LEN(SUBSTITUTE(SUBSTITUTE(SUBSTITUTE(J21," ",""),"0",""),"-",""))+LEN(SUBSTITUTE(SUBSTITUTE(SUBSTITUTE(K21," ",""),"0",""),"-",""))),1,0))+IF(UPPER(L22)="X",0,IF((LEN(SUBSTITUTE(SUBSTITUTE(SUBSTITUTE(M22," ",""),"0",""),"-",""))+LEN(SUBSTITUTE(SUBSTITUTE(SUBSTITUTE(N22," ",""),"0",""),"-","")))>(LEN(SUBSTITUTE(SUBSTITUTE(SUBSTITUTE(J22," ",""),"0",""),"-",""))+LEN(SUBSTITUTE(SUBSTITUTE(SUBSTITUTE(K22," ",""),"0",""),"-",""))),1,0))+IF(UPPER(L23)="X",0,IF((LEN(SUBSTITUTE(SUBSTITUTE(SUBSTITUTE(M23," ",""),"0",""),"-",""))+LEN(SUBSTITUTE(SUBSTITUTE(SUBSTITUTE(N23," ",""),"0",""),"-","")))>(LEN(SUBSTITUTE(SUBSTITUTE(SUBSTITUTE(J23," ",""),"0",""),"-",""))+LEN(SUBSTITUTE(SUBSTITUTE(SUBSTITUTE(K23," ",""),"0",""),"-",""))),1,0))+IF(UPPER(L24)="X",0,IF((LEN(SUBSTITUTE(SUBSTITUTE(SUBSTITUTE(M24," ",""),"0",""),"-",""))+LEN(SUBSTITUTE(SUBSTITUTE(SUBSTITUTE(N24," ",""),"0",""),"-","")))>(LEN(SUBSTITUTE(SUBSTITUTE(SUBSTITUTE(J24," ",""),"0",""),"-",""))+LEN(SUBSTITUTE(SUBSTITUTE(SUBSTITUTE(K24," ",""),"0",""),"-",""))),1,0))+IF(UPPER(L25)="X",0,IF((LEN(SUBSTITUTE(SUBSTITUTE(SUBSTITUTE(M25," ",""),"0",""),"-",""))+LEN(SUBSTITUTE(SUBSTITUTE(SUBSTITUTE(N25," ",""),"0",""),"-","")))>(LEN(SUBSTITUTE(SUBSTITUTE(SUBSTITUTE(J25," ",""),"0",""),"-",""))+LEN(SUBSTITUTE(SUBSTITUTE(SUBSTITUTE(K25," ",""),"0",""),"-",""))),1,0)) | O20: =data!$D$11&" "&data!$B$11
A21: 1 | G21: 1 | I21: 1 | O21: 1
A22: 2 | G22: 2 | I22: 2 | O22: 2
A23: 3 | G23: 3 | I23: 3 | O23: 3
A24: 4 | G24: 4 | I24: 4 | O24: 4
A25: 5 | G25: 5 | I25: 5 | O25: 5
A27: White | D27: vs | G27: Red
A28: =data!$D$6&" "&data!$B$6 | B28: =IF(UPPER(D29)="X",0,IF((LEN(SUBSTITUTE(SUBSTITUTE(SUBSTITUTE(B29," ",""),"0",""),"-",""))+LEN(SUBSTITUTE(SUBSTITUTE(SUBSTITUTE(C29," ",""),"0",""),"-","")))>(LEN(SUBSTITUTE(SUBSTITUTE(SUBSTITUTE(E29," ",""),"0",""),"-",""))+LEN(SUBSTITUTE(SUBSTITUTE(SUBSTITUTE(F29," ",""),"0",""),"-",""))),1,0))+IF(UPPER(D30)="X",0,IF((LEN(SUBSTITUTE(SUBSTITUTE(SUBSTITUTE(B30," ",""),"0",""),"-",""))+LEN(SUBSTITUTE(SUBSTITUTE(SUBSTITUTE(C30," ",""),"0",""),"-","")))>(LEN(SUBSTITUTE(SUBSTITUTE(SUBSTITUTE(E30," ",""),"0",""),"-",""))+LEN(SUBSTITUTE(SUBSTITUTE(SUBSTITUTE(F30," ",""),"0",""),"-",""))),1,0))+IF(UPPER(D31)="X",0,IF((LEN(SUBSTITUTE(SUBSTITUTE(SUBSTITUTE(B31," ",""),"0",""),"-",""))+LEN(SUBSTITUTE(SUBSTITUTE(SUBSTITUTE(C31," ",""),"0",""),"-","")))>(LEN(SUBSTITUTE(SUBSTITUTE(SUBSTITUTE(E31," ",""),"0",""),"-",""))+LEN(SUBSTITUTE(SUBSTITUTE(SUBSTITUTE(F31," ",""),"0",""),"-",""))),1,0))+IF(UPPER(D32)="X",0,IF((LEN(SUBSTITUTE(SUBSTITUTE(SUBSTITUTE(B32," ",""),"0",""),"-",""))+LEN(SUBSTITUTE(SUBSTITUTE(SUBSTITUTE(C32," ",""),"0",""),"-","")))>(LEN(SUBSTITUTE(SUBSTITUTE(SUBSTITUTE(E32," ",""),"0",""),"-",""))+LEN(SUBSTITUTE(SUBSTITUTE(SUBSTITUTE(F32," ",""),"0",""),"-",""))),1,0))+IF(UPPER(D33)="X",0,IF((LEN(SUBSTITUTE(SUBSTITUTE(SUBSTITUTE(B33," ",""),"0",""),"-",""))+LEN(SUBSTITUTE(SUBSTITUTE(SUBSTITUTE(C33," ",""),"0",""),"-","")))>(LEN(SUBSTITUTE(SUBSTITUTE(SUBSTITUTE(E33," ",""),"0",""),"-",""))+LEN(SUBSTITUTE(SUBSTITUTE(SUBSTITUTE(F33," ",""),"0",""),"-",""))),1,0)) | C28: =LEN(SUBSTITUTE(SUBSTITUTE(SUBSTITUTE(B29," ",""),"0",""),"-",""))+LEN(SUBSTITUTE(SUBSTITUTE(SUBSTITUTE(C29," ",""),"0",""),"-",""))+LEN(SUBSTITUTE(SUBSTITUTE(SUBSTITUTE(B30," ",""),"0",""),"-",""))+LEN(SUBSTITUTE(SUBSTITUTE(SUBSTITUTE(C30," ",""),"0",""),"-",""))+LEN(SUBSTITUTE(SUBSTITUTE(SUBSTITUTE(B31," ",""),"0",""),"-",""))+LEN(SUBSTITUTE(SUBSTITUTE(SUBSTITUTE(C31," ",""),"0",""),"-",""))+LEN(SUBSTITUTE(SUBSTITUTE(SUBSTITUTE(B32," ",""),"0",""),"-",""))+LEN(SUBSTITUTE(SUBSTITUTE(SUBSTITUTE(C32," ",""),"0",""),"-",""))+LEN(SUBSTITUTE(SUBSTITUTE(SUBSTITUTE(B33," ",""),"0",""),"-",""))+LEN(SUBSTITUTE(SUBSTITUTE(SUBSTITUTE(C33," ",""),"0",""),"-","")) | E28: =LEN(SUBSTITUTE(SUBSTITUTE(SUBSTITUTE(E29," ",""),"0",""),"-",""))+LEN(SUBSTITUTE(SUBSTITUTE(SUBSTITUTE(F29," ",""),"0",""),"-",""))+LEN(SUBSTITUTE(SUBSTITUTE(SUBSTITUTE(E30," ",""),"0",""),"-",""))+LEN(SUBSTITUTE(SUBSTITUTE(SUBSTITUTE(F30," ",""),"0",""),"-",""))+LEN(SUBSTITUTE(SUBSTITUTE(SUBSTITUTE(E31," ",""),"0",""),"-",""))+LEN(SUBSTITUTE(SUBSTITUTE(SUBSTITUTE(F31," ",""),"0",""),"-",""))+LEN(SUBSTITUTE(SUBSTITUTE(SUBSTITUTE(E32," ",""),"0",""),"-",""))+LEN(SUBSTITUTE(SUBSTITUTE(SUBSTITUTE(F32," ",""),"0",""),"-",""))+LEN(SUBSTITUTE(SUBSTITUTE(SUBSTITUTE(E33," ",""),"0",""),"-",""))+LEN(SUBSTITUTE(SUBSTITUTE(SUBSTITUTE(F33," ",""),"0",""),"-","")) | F28: =IF(UPPER(D29)="X",0,IF((LEN(SUBSTITUTE(SUBSTITUTE(SUBSTITUTE(E29," ",""),"0",""),"-",""))+LEN(SUBSTITUTE(SUBSTITUTE(SUBSTITUTE(F29," ",""),"0",""),"-","")))>(LEN(SUBSTITUTE(SUBSTITUTE(SUBSTITUTE(B29," ",""),"0",""),"-",""))+LEN(SUBSTITUTE(SUBSTITUTE(SUBSTITUTE(C29," ",""),"0",""),"-",""))),1,0))+IF(UPPER(D30)="X",0,IF((LEN(SUBSTITUTE(SUBSTITUTE(SUBSTITUTE(E30," ",""),"0",""),"-",""))+LEN(SUBSTITUTE(SUBSTITUTE(SUBSTITUTE(F30," ",""),"0",""),"-","")))>(LEN(SUBSTITUTE(SUBSTITUTE(SUBSTITUTE(B30," ",""),"0",""),"-",""))+LEN(SUBSTITUTE(SUBSTITUTE(SUBSTITUTE(C30," ",""),"0",""),"-",""))),1,0))+IF(UPPER(D31)="X",0,IF((LEN(SUBSTITUTE(SUBSTITUTE(SUBSTITUTE(E31," ",""),"0",""),"-",""))+LEN(SUBSTITUTE(SUBSTITUTE(SUBSTITUTE(F31," ",""),"0",""),"-","")))>(LEN(SUBSTITUTE(SUBSTITUTE(SUBSTITUTE(B31," ",""),"0",""),"-",""))+LEN(SUBSTITUTE(SUBSTITUTE(SUBSTITUTE(C31," ",""),"0",""),"-",""))),1,0))+IF(UPPER(D32)="X",0,IF((LEN(SUBSTITUTE(SUBSTITUTE(SUBSTITUTE(E32," ",""),"0",""),"-",""))+LEN(SUBSTITUTE(SUBSTITUTE(SUBSTITUTE(F32," ",""),"0",""),"-","")))>(LEN(SUBSTITUTE(SUBSTITUTE(SUBSTITUTE(B32," ",""),"0",""),"-",""))+LEN(SUBSTITUTE(SUBSTITUTE(SUBSTITUTE(C32," ",""),"0",""),"-",""))),1,0))+IF(UPPER(D33)="X",0,IF((LEN(SUBSTITUTE(SUBSTITUTE(SUBSTITUTE(E33," ",""),"0",""),"-",""))+LEN(SUBSTITUTE(SUBSTITUTE(SUBSTITUTE(F33," ",""),"0",""),"-","")))>(LEN(SUBSTITUTE(SUBSTITUTE(SUBSTITUTE(B33," ",""),"0",""),"-",""))+LEN(SUBSTITUTE(SUBSTITUTE(SUBSTITUTE(C33," ",""),"0",""),"-",""))),1,0)) | G28: =data!$D$3&" "&data!$B$3
A29: 1 | G29: 1
A30: 2 | G30: 2
A31: 3 | G31: 3
A32: 4 | G32: 4
A33: 5 | G33: 5
A35: White | D35: vs | G35: Red
A36: =data!$D$5&" "&data!$B$5 | B36: =IF(UPPER(D37)="X",0,IF((LEN(SUBSTITUTE(SUBSTITUTE(SUBSTITUTE(B37," ",""),"0",""),"-",""))+LEN(SUBSTITUTE(SUBSTITUTE(SUBSTITUTE(C37," ",""),"0",""),"-","")))>(LEN(SUBSTITUTE(SUBSTITUTE(SUBSTITUTE(E37," ",""),"0",""),"-",""))+LEN(SUBSTITUTE(SUBSTITUTE(SUBSTITUTE(F37," ",""),"0",""),"-",""))),1,0))+IF(UPPER(D38)="X",0,IF((LEN(SUBSTITUTE(SUBSTITUTE(SUBSTITUTE(B38," ",""),"0",""),"-",""))+LEN(SUBSTITUTE(SUBSTITUTE(SUBSTITUTE(C38," ",""),"0",""),"-","")))>(LEN(SUBSTITUTE(SUBSTITUTE(SUBSTITUTE(E38," ",""),"0",""),"-",""))+LEN(SUBSTITUTE(SUBSTITUTE(SUBSTITUTE(F38," ",""),"0",""),"-",""))),1,0))+IF(UPPER(D39)="X",0,IF((LEN(SUBSTITUTE(SUBSTITUTE(SUBSTITUTE(B39," ",""),"0",""),"-",""))+LEN(SUBSTITUTE(SUBSTITUTE(SUBSTITUTE(C39," ",""),"0",""),"-","")))>(LEN(SUBSTITUTE(SUBSTITUTE(SUBSTITUTE(E39," ",""),"0",""),"-",""))+LEN(SUBSTITUTE(SUBSTITUTE(SUBSTITUTE(F39," ",""),"0",""),"-",""))),1,0))+IF(UPPER(D40)="X",0,IF((LEN(SUBSTITUTE(SUBSTITUTE(SUBSTITUTE(B40," ",""),"0",""),"-",""))+LEN(SUBSTITUTE(SUBSTITUTE(SUBSTITUTE(C40," ",""),"0",""),"-","")))>(LEN(SUBSTITUTE(SUBSTITUTE(SUBSTITUTE(E40," ",""),"0",""),"-",""))+LEN(SUBSTITUTE(SUBSTITUTE(SUBSTITUTE(F40," ",""),"0",""),"-",""))),1,0))+IF(UPPER(D41)="X",0,IF((LEN(SUBSTITUTE(SUBSTITUTE(SUBSTITUTE(B41," ",""),"0",""),"-",""))+LEN(SUBSTITUTE(SUBSTITUTE(SUBSTITUTE(C41," ",""),"0",""),"-","")))>(LEN(SUBSTITUTE(SUBSTITUTE(SUBSTITUTE(E41," ",""),"0",""),"-",""))+LEN(SUBSTITUTE(SUBSTITUTE(SUBSTITUTE(F41," ",""),"0",""),"-",""))),1,0)) | C36: =LEN(SUBSTITUTE(SUBSTITUTE(SUBSTITUTE(B37," ",""),"0",""),"-",""))+LEN(SUBSTITUTE(SUBSTITUTE(SUBSTITUTE(C37," ",""),"0",""),"-",""))+LEN(SUBSTITUTE(SUBSTITUTE(SUBSTITUTE(B38," ",""),"0",""),"-",""))+LEN(SUBSTITUTE(SUBSTITUTE(SUBSTITUTE(C38," ",""),"0",""),"-",""))+LEN(SUBSTITUTE(SUBSTITUTE(SUBSTITUTE(B39," ",""),"0",""),"-",""))+LEN(SUBSTITUTE(SUBSTITUTE(SUBSTITUTE(C39," ",""),"0",""),"-",""))+LEN(SUBSTITUTE(SUBSTITUTE(SUBSTITUTE(B40," ",""),"0",""),"-",""))+LEN(SUBSTITUTE(SUBSTITUTE(SUBSTITUTE(C40," ",""),"0",""),"-",""))+LEN(SUBSTITUTE(SUBSTITUTE(SUBSTITUTE(B41," ",""),"0",""),"-",""))+LEN(SUBSTITUTE(SUBSTITUTE(SUBSTITUTE(C41," ",""),"0",""),"-","")) | E36: =LEN(SUBSTITUTE(SUBSTITUTE(SUBSTITUTE(E37," ",""),"0",""),"-",""))+LEN(SUBSTITUTE(SUBSTITUTE(SUBSTITUTE(F37," ",""),"0",""),"-",""))+LEN(SUBSTITUTE(SUBSTITUTE(SUBSTITUTE(E38," ",""),"0",""),"-",""))+LEN(SUBSTITUTE(SUBSTITUTE(SUBSTITUTE(F38," ",""),"0",""),"-",""))+LEN(SUBSTITUTE(SUBSTITUTE(SUBSTITUTE(E39," ",""),"0",""),"-",""))+LEN(SUBSTITUTE(SUBSTITUTE(SUBSTITUTE(F39," ",""),"0",""),"-",""))+LEN(SUBSTITUTE(SUBSTITUTE(SUBSTITUTE(E40," ",""),"0",""),"-",""))+LEN(SUBSTITUTE(SUBSTITUTE(SUBSTITUTE(F40," ",""),"0",""),"-",""))+LEN(SUBSTITUTE(SUBSTITUTE(SUBSTITUTE(E41," ",""),"0",""),"-",""))+LEN(SUBSTITUTE(SUBSTITUTE(SUBSTITUTE(F41," ",""),"0",""),"-","")) | F36: =IF(UPPER(D37)="X",0,IF((LEN(SUBSTITUTE(SUBSTITUTE(SUBSTITUTE(E37," ",""),"0",""),"-",""))+LEN(SUBSTITUTE(SUBSTITUTE(SUBSTITUTE(F37," ",""),"0",""),"-","")))>(LEN(SUBSTITUTE(SUBSTITUTE(SUBSTITUTE(B37," ",""),"0",""),"-",""))+LEN(SUBSTITUTE(SUBSTITUTE(SUBSTITUTE(C37," ",""),"0",""),"-",""))),1,0))+IF(UPPER(D38)="X",0,IF((LEN(SUBSTITUTE(SUBSTITUTE(SUBSTITUTE(E38," ",""),"0",""),"-",""))+LEN(SUBSTITUTE(SUBSTITUTE(SUBSTITUTE(F38," ",""),"0",""),"-","")))>(LEN(SUBSTITUTE(SUBSTITUTE(SUBSTITUTE(B38," ",""),"0",""),"-",""))+LEN(SUBSTITUTE(SUBSTITUTE(SUBSTITUTE(C38," ",""),"0",""),"-",""))),1,0))+IF(UPPER(D39)="X",0,IF((LEN(SUBSTITUTE(SUBSTITUTE(SUBSTITUTE(E39," ",""),"0",""),"-",""))+LEN(SUBSTITUTE(SUBSTITUTE(SUBSTITUTE(F39," ",""),"0",""),"-","")))>(LEN(SUBSTITUTE(SUBSTITUTE(SUBSTITUTE(B39," ",""),"0",""),"-",""))+LEN(SUBSTITUTE(SUBSTITUTE(SUBSTITUTE(C39," ",""),"0",""),"-",""))),1,0))+IF(UPPER(D40)="X",0,IF((LEN(SUBSTITUTE(SUBSTITUTE(SUBSTITUTE(E40," ",""),"0",""),"-",""))+LEN(SUBSTITUTE(SUBSTITUTE(SUBSTITUTE(F40," ",""),"0",""),"-","")))>(LEN(SUBSTITUTE(SUBSTITUTE(SUBSTITUTE(B40," ",""),"0",""),"-",""))+LEN(SUBSTITUTE(SUBSTITUTE(SUBSTITUTE(C40," ",""),"0",""),"-",""))),1,0))+IF(UPPER(D41)="X",0,IF((LEN(SUBSTITUTE(SUBSTITUTE(SUBSTITUTE(E41," ",""),"0",""),"-",""))+LEN(SUBSTITUTE(SUBSTITUTE(SUBSTITUTE(F41," ",""),"0",""),"-","")))>(LEN(SUBSTITUTE(SUBSTITUTE(SUBSTITUTE(B41," ",""),"0",""),"-",""))+LEN(SUBSTITUTE(SUBSTITUTE(SUBSTITUTE(C41," ",""),"0",""),"-",""))),1,0)) | G36: =data!$D$3&" "&data!$B$3
A37: 1 | G37: 1
A38: 2 | G38: 2
A39: 3 | G39: 3
A40: 4 | G40: 4
A41: 5 | G41: 5
A43: White | D43: vs | G43: Red
A44: =data!$D$6&" "&data!$B$6 | B44: =IF(UPPER(D45)="X",0,IF((LEN(SUBSTITUTE(SUBSTITUTE(SUBSTITUTE(B45," ",""),"0",""),"-",""))+LEN(SUBSTITUTE(SUBSTITUTE(SUBSTITUTE(C45," ",""),"0",""),"-","")))>(LEN(SUBSTITUTE(SUBSTITUTE(SUBSTITUTE(E45," ",""),"0",""),"-",""))+LEN(SUBSTITUTE(SUBSTITUTE(SUBSTITUTE(F45," ",""),"0",""),"-",""))),1,0))+IF(UPPER(D46)="X",0,IF((LEN(SUBSTITUTE(SUBSTITUTE(SUBSTITUTE(B46," ",""),"0",""),"-",""))+LEN(SUBSTITUTE(SUBSTITUTE(SUBSTITUTE(C46," ",""),"0",""),"-","")))>(LEN(SUBSTITUTE(SUBSTITUTE(SUBSTITUTE(E46," ",""),"0",""),"-",""))+LEN(SUBSTITUTE(SUBSTITUTE(SUBSTITUTE(F46," ",""),"0",""),"-",""))),1,0))+IF(UPPER(D47)="X",0,IF((LEN(SUBSTITUTE(SUBSTITUTE(SUBSTITUTE(B47," ",""),"0",""),"-",""))+LEN(SUBSTITUTE(SUBSTITUTE(SUBSTITUTE(C47," ",""),"0",""),"-","")))>(LEN(SUBSTITUTE(SUBSTITUTE(SUBSTITUTE(E47," ",""),"0",""),"-",""))+LEN(SUBSTITUTE(SUBSTITUTE(SUBSTITUTE(F47," ",""),"0",""),"-",""))),1,0))+IF(UPPER(D48)="X",0,IF((LEN(SUBSTITUTE(SUBSTITUTE(SUBSTITUTE(B48," ",""),"0",""),"-",""))+LEN(SUBSTITUTE(SUBSTITUTE(SUBSTITUTE(C48," ",""),"0",""),"-","")))>(LEN(SUBSTITUTE(SUBSTITUTE(SUBSTITUTE(E48," ",""),"0",""),"-",""))+LEN(SUBSTITUTE(SUBSTITUTE(SUBSTITUTE(F48," ",""),"0",""),"-",""))),1,0))+IF(UPPER(D49)="X",0,IF((LEN(SUBSTITUTE(SUBSTITUTE(SUBSTITUTE(B49," ",""),"0",""),"-",""))+LEN(SUBSTITUTE(SUBSTITUTE(SUBSTITUTE(C49," ",""),"0",""),"-","")))>(LEN(SUBSTITUTE(SUBSTITUTE(SUBSTITUTE(E49," ",""),"0",""),"-",""))+LEN(SUBSTITUTE(SUBSTITUTE(SUBSTITUTE(F49," ",""),"0",""),"-",""))),1,0)) | C44: =LEN(SUBSTITUTE(SUBSTITUTE(SUBSTITUTE(B45," ",""),"0",""),"-",""))+LEN(SUBSTITUTE(SUBSTITUTE(SUBSTITUTE(C45," ",""),"0",""),"-",""))+LEN(SUBSTITUTE(SUBSTITUTE(SUBSTITUTE(B46," ",""),"0",""),"-",""))+LEN(SUBSTITUTE(SUBSTITUTE(SUBSTITUTE(C46," ",""),"0",""),"-",""))+LEN(SUBSTITUTE(SUBSTITUTE(SUBSTITUTE(B47," ",""),"0",""),"-",""))+LEN(SUBSTITUTE(SUBSTITUTE(SUBSTITUTE(C47," ",""),"0",""),"-",""))+LEN(SUBSTITUTE(SUBSTITUTE(SUBSTITUTE(B48," ",""),"0",""),"-",""))+LEN(SUBSTITUTE(SUBSTITUTE(SUBSTITUTE(C48," ",""),"0",""),"-",""))+LEN(SUBSTITUTE(SUBSTITUTE(SUBSTITUTE(B49," ",""),"0",""),"-",""))+LEN(SUBSTITUTE(SUBSTITUTE(SUBSTITUTE(C49," ",""),"0",""),"-","")) | E44: =LEN(SUBSTITUTE(SUBSTITUTE(SUBSTITUTE(E45," ",""),"0",""),"-",""))+LEN(SUBSTITUTE(SUBSTITUTE(SUBSTITUTE(F45," ",""),"0",""),"-",""))+LEN(SUBSTITUTE(SUBSTITUTE(SUBSTITUTE(E46," ",""),"0",""),"-",""))+LEN(SUBSTITUTE(SUBSTITUTE(SUBSTITUTE(F46," ",""),"0",""),"-",""))+LEN(SUBSTITUTE(SUBSTITUTE(SUBSTITUTE(E47," ",""),"0",""),"-",""))+LEN(SUBSTITUTE(SUBSTITUTE(SUBSTITUTE(F47," ",""),"0",""),"-",""))+LEN(SUBSTITUTE(SUBSTITUTE(SUBSTITUTE(E48," ",""),"0",""),"-",""))+LEN(SUBSTITUTE(SUBSTITUTE(SUBSTITUTE(F48," ",""),"0",""),"-",""))+LEN(SUBSTITUTE(SUBSTITUTE(SUBSTITUTE(E49," ",""),"0",""),"-",""))+LEN(SUBSTITUTE(SUBSTITUTE(SUBSTITUTE(F49," ",""),"0",""),"-","")) | F44: =IF(UPPER(D45)="X",0,IF((LEN(SUBSTITUTE(SUBSTITUTE(SUBSTITUTE(E45," ",""),"0",""),"-",""))+LEN(SUBSTITUTE(SUBSTITUTE(SUBSTITUTE(F45," ",""),"0",""),"-","")))>(LEN(SUBSTITUTE(SUBSTITUTE(SUBSTITUTE(B45," ",""),"0",""),"-",""))+LEN(SUBSTITUTE(SUBSTITUTE(SUBSTITUTE(C45," ",""),"0",""),"-",""))),1,0))+IF(UPPER(D46)="X",0,IF((LEN(SUBSTITUTE(SUBSTITUTE(SUBSTITUTE(E46," ",""),"0",""),"-",""))+LEN(SUBSTITUTE(SUBSTITUTE(SUBSTITUTE(F46," ",""),"0",""),"-","")))>(LEN(SUBSTITUTE(SUBSTITUTE(SUBSTITUTE(B46," ",""),"0",""),"-",""))+LEN(SUBSTITUTE(SUBSTITUTE(SUBSTITUTE(C46," ",""),"0",""),"-",""))),1,0))+IF(UPPER(D47)="X",0,IF((LEN(SUBSTITUTE(SUBSTITUTE(SUBSTITUTE(E47," ",""),"0",""),"-",""))+LEN(SUBSTITUTE(SUBSTITUTE(SUBSTITUTE(F47," ",""),"0",""),"-","")))>(LEN(SUBSTITUTE(SUBSTITUTE(SUBSTITUTE(B47," ",""),"0",""),"-",""))+LEN(SUBSTITUTE(SUBSTITUTE(SUBSTITUTE(C47," ",""),"0",""),"-",""))),1,0))+IF(UPPER(D48)="X",0,IF((LEN(SUBSTITUTE(SUBSTITUTE(SUBSTITUTE(E48," ",""),"0",""),"-",""))+LEN(SUBSTITUTE(SUBSTITUTE(SUBSTITUTE(F48," ",""),"0",""),"-","")))>(LEN(SUBSTITUTE(SUBSTITUTE(SUBSTITUTE(B48," ",""),"0",""),"-",""))+LEN(SUBSTITUTE(SUBSTITUTE(SUBSTITUTE(C48," ",""),"0",""),"-",""))),1,0))+IF(UPPER(D49)="X",0,IF((LEN(SUBSTITUTE(SUBSTITUTE(SUBSTITUTE(E49," ",""),"0",""),"-",""))+LEN(SUBSTITUTE(SUBSTITUTE(SUBSTITUTE(F49," ",""),"0",""),"-","")))>(LEN(SUBSTITUTE(SUBSTITUTE(SUBSTITUTE(B49," ",""),"0",""),"-",""))+LEN(SUBSTITUTE(SUBSTITUTE(SUBSTITUTE(C49," ",""),"0",""),"-",""))),1,0)) | G44: =data!$D$4&" "&data!$B$4
A45: 1 | G45: 1
...

Sheet Elimination Matches
A1: Shiaijo A | I1: Shiaijo B
A2: Round 1 - Match 1 | I2: Round 1 - Match 2
A3: White | D3: vs | G3: Red | I3: White | L3: vs | O3: Red
A4: =CONCATENATE("Pool C-2nd ",'Pool Matches'!O65) | G4: =CONCATENATE("Pool B-1st ",'Pool Matches'!G109) | I4: =CONCATENATE("Pool B-2nd ",'Pool Matches'!G110) | O4: =CONCATENATE("Pool A-2nd ",'Pool Matches'!G67)
A5: 1 | G5: 1 | I5: 1 | O5: 1
A6: 2 | G6: 2 | I6: 2 | O6: 2
A7: 3 | G7: 3 | I7: 3 | O7: 3
A8: 4 | G8: 4 | I8: 4 | O8: 4
A9: 5 | G9: 5 | I9: 5 | O9: 5
A11: =CONCATENATE("Pool C-2nd ",'Pool Matches'!O65) | B11: IV | C11: PW | E11: PW | F11: IV | G11: =CONCATENATE("Pool B-1st ",'Pool Matches'!G109) | I11: =CONCATENATE("Pool B-2nd ",'Pool Matches'!G110) | J11: IV | K11: PW | M11: PW | N11: IV | O11: =CONCATENATE("Pool A-2nd ",'Pool Matches'!G67)
A12: Victories / Points | B12: =IF(UPPER(D5)="X",0,IF((LEN(SUBSTITUTE(SUBSTITUTE(SUBSTITUTE(B5," ",""),"0",""),"-",""))+LEN(SUBSTITUTE(SUBSTITUTE(SUBSTITUTE(C5," ",""),"0",""),"-","")))>(LEN(SUBSTITUTE(SUBSTITUTE(SUBSTITUTE(E5," ",""),"0",""),"-",""))+LEN(SUBSTITUTE(SUBSTITUTE(SUBSTITUTE(F5," ",""),"0",""),"-",""))),1,0))+IF(UPPER(D6)="X",0,IF((LEN(SUBSTITUTE(SUBSTITUTE(SUBSTITUTE(B6," ",""),"0",""),"-",""))+LEN(SUBSTITUTE(SUBSTITUTE(SUBSTITUTE(C6," ",""),"0",""),"-","")))>(LEN(SUBSTITUTE(SUBSTITUTE(SUBSTITUTE(E6," ",""),"0",""),"-",""))+LEN(SUBSTITUTE(SUBSTITUTE(SUBSTITUTE(F6," ",""),"0",""),"-",""))),1,0))+IF(UPPER(D7)="X",0,IF((LEN(SUBSTITUTE(SUBSTITUTE(SUBSTITUTE(B7," ",""),"0",""),"-",""))+LEN(SUBSTITUTE(SUBSTITUTE(SUBSTITUTE(C7," ",""),"0",""),"-","")))>(LEN(SUBSTITUTE(SUBSTITUTE(SUBSTITUTE(E7," ",""),"0",""),"-",""))+LEN(SUBSTITUTE(SUBSTITUTE(SUBSTITUTE(F7," ",""),"0",""),"-",""))),1,0))+IF(UPPER(D8)="X",0,IF((LEN(SUBSTITUTE(SUBSTITUTE(SUBSTITUTE(B8," ",""),"0",""),"-",""))+LEN(SUBSTITUTE(SUBSTITUTE(SUBSTITUTE(C8," ",""),"0",""),"-","")))>(LEN(SUBSTITUTE(SUBSTITUTE(SUBSTITUTE(E8," ",""),"0",""),"-",""))+LEN(SUBSTITUTE(SUBSTITUTE(SUBSTITUTE(F8," ",""),"0",""),"-",""))),1,0))+IF(UPPER(D9)="X",0,IF((LEN(SUBSTITUTE(SUBSTITUTE(SUBSTITUTE(B9," ",""),"0",""),"-",""))+LEN(SUBSTITUTE(SUBSTITUTE(SUBSTITUTE(C9," ",""),"0",""),"-","")))>(LEN(SUBSTITUTE(SUBSTITUTE(SUBSTITUTE(E9," ",""),"0",""),"-",""))+LEN(SUBSTITUTE(SUBSTITUTE(SUBSTITUTE(F9," ",""),"0",""),"-",""))),1,0)) | C12: =LEN(SUBSTITUTE(SUBSTITUTE(SUBSTITUTE(B5," ",""),"0",""),"-",""))+LEN(SUBSTITUTE(SUBSTITUTE(SUBSTITUTE(C5," ",""),"0",""),"-",""))+LEN(SUBSTITUTE(SUBSTITUTE(SUBSTITUTE(B6," ",""),"0",""),"-",""))+LEN(SUBSTITUTE(SUBSTITUTE(SUBSTITUTE(C6," ",""),"0",""),"-",""))+LEN(SUBSTITUTE(SUBSTITUTE(SUBSTITUTE(B7," ",""),"0",""),"-",""))+LEN(SUBSTITUTE(SUBSTITUTE(SUBSTITUTE(C7," ",""),"0",""),"-",""))+LEN(SUBSTITUTE(SUBSTITUTE(SUBSTITUTE(B8," ",""),"0",""),"-",""))+LEN(SUBSTITUTE(SUBSTITUTE(SUBSTITUTE(C8," ",""),"0",""),"-",""))+LEN(SUBSTITUTE(SUBSTITUTE(SUBSTITUTE(B9," ",""),"0",""),"-",""))+LEN(SUBSTITUTE(SUBSTITUTE(SUBSTITUTE(C9," ",""),"0",""),"-","")) | E12: =LEN(SUBSTITUTE(SUBSTITUTE(SUBSTITUTE(E5," ",""),"0",""),"-",""))+LEN(SUBSTITUTE(SUBSTITUTE(SUBSTITUTE(F5," ",""),"0",""),"-",""))+LEN(SUBSTITUTE(SUBSTITUTE(SUBSTITUTE(E6," ",""),"0",""),"-",""))+LEN(SUBSTITUTE(SUBSTITUTE(SUBSTITUTE(F6," ",""),"0",""),"-",""))+LEN(SUBSTITUTE(SUBSTITUTE(SUBSTITUTE(E7," ",""),"0",""),"-",""))+LEN(SUBSTITUTE(SUBSTITUTE(SUBSTITUTE(F7," ",""),"0",""),"-",""))+LEN(SUBSTITUTE(SUBSTITUTE(SUBSTITUTE(E8," ",""),"0",""),"-",""))+LEN(SUBSTITUTE(SUBSTITUTE(SUBSTITUTE(F8," ",""),"0",""),"-",""))+LEN(SUBSTITUTE(SUBSTITUTE(SUBSTITUTE(E9," ",""),"0",""),"-",""))+LEN(SUBSTITUTE(SUBSTITUTE(SUBSTITUTE(F9," ",""),"0",""),"-","")) | F12: =IF(UPPER(D5)="X",0,IF((LEN(SUBSTITUTE(SUBSTITUTE(SUBSTITUTE(E5," ",""),"0",""),"-",""))+LEN(SUBSTITUTE(SUBSTITUTE(SUBSTITUTE(F5," ",""),"0",""),"-","")))>(LEN(SUBSTITUTE(SUBSTITUTE(SUBSTITUTE(B5," ",""),"0",""),"-",""))+LEN(SUBSTITUTE(SUBSTITUTE(SUBSTITUTE(C5," ",""),"0",""),"-",""))),1,0))+IF(UPPER(D6)="X",0,IF((LEN(SUBSTITUTE(SUBSTITUTE(SUBSTITUTE(E6," ",""),"0",""),"-",""))+LEN(SUBSTITUTE(SUBSTITUTE(SUBSTITUTE(F6," ",""),"0",""),"-","")))>(LEN(SUBSTITUTE(SUBSTITUTE(SUBSTITUTE(B6," ",""),"0",""),"-",""))+LEN(SUBSTITUTE(SUBSTITUTE(SUBSTITUTE(C6," ",""),"0",""),"-",""))),1,0))+IF(UPPER(D7)="X",0,IF((LEN(SUBSTITUTE(SUBSTITUTE(SUBSTITUTE(E7," ",""),"0",""),"-",""))+LEN(SUBSTITUTE(SUBSTITUTE(SUBSTITUTE(F7," ",""),"0",""),"-","")))>(LEN(SUBSTITUTE(SUBSTITUTE(SUBSTITUTE(B7," ",""),"0",""),"-",""))+LEN(SUBSTITUTE(SUBSTITUTE(SUBSTITUTE(C7," ",""),"0",""),"-",""))),1,0))+IF(UPPER(D8)="X",0,IF((LEN(SUBSTITUTE(SUBSTITUTE(SUBSTITUTE(E8," ",""),"0",""),"-",""))+LEN(SUBSTITUTE(SUBSTITUTE(SUBSTITUTE(F8," ",""),"0",""),"-","")))>(LEN(SUBSTITUTE(SUBSTITUTE(SUBSTITUTE(B8," ",""),"0",""),"-",""))+LEN(SUBSTITUTE(SUBSTITUTE(SUBSTITUTE(C8," ",""),"0",""),"-",""))),1,0))+IF(UPPER(D9)="X",0,IF((LEN(SUBSTITUTE(SUBSTITUTE(SUBSTITUTE(E9," ",""),"0",""),"-",""))+LEN(SUBSTITUTE(SUBSTITUTE(SUBSTITUTE(F9," ",""),"0",""),"-","")))>(LEN(SUBSTITUTE(SUBSTITUTE(SUBSTITUTE(B9," ",""),"0",""),"-",""))+LEN(SUBSTITUTE(SUBSTITUTE(SUBSTITUTE(C9," ",""),"0",""),"-",""))),1,0)) | G12: Victories / Points | I12: Victories / Points | J12: =IF(UPPER(L5)="X",0,IF((LEN(SUBSTITUTE(SUBSTITUTE(SUBSTITUTE(J5," ",""),"0",""),"-",""))+LEN(SUBSTITUTE(SUBSTITUTE(SUBSTITUTE(K5," ",""),"0",""),"-","")))>(LEN(SUBSTITUTE(SUBSTITUTE(SUBSTITUTE(M5," ",""),"0",""),"-",""))+LEN(SUBSTITUTE(SUBSTITUTE(SUBSTITUTE(N5," ",""),"0",""),"-",""))),1,0))+IF(UPPER(L6)="X",0,IF((LEN(SUBSTITUTE(SUBSTITUTE(SUBSTITUTE(J6," ",""),"0",""),"-",""))+LEN(SUBSTITUTE(SUBSTITUTE(SUBSTITUTE(K6," ",""),"0",""),"-","")))>(LEN(SUBSTITUTE(SUBSTITUTE(SUBSTITUTE(M6," ",""),"0",""),"-",""))+LEN(SUBSTITUTE(SUBSTITUTE(SUBSTITUTE(N6," ",""),"0",""),"-",""))),1,0))+IF(UPPER(L7)="X",0,IF((LEN(SUBSTITUTE(SUBSTITUTE(SUBSTITUTE(J7," ",""),"0",""),"-",""))+LEN(SUBSTITUTE(SUBSTITUTE(SUBSTITUTE(K7," ",""),"0",""),"-","")))>(LEN(SUBSTITUTE(SUBSTITUTE(SUBSTITUTE(M7," ",""),"0",""),"-",""))+LEN(SUBSTITUTE(SUBSTITUTE(SUBSTITUTE(N7," ",""),"0",""),"-",""))),1,0))+IF(UPPER(L8)="X",0,IF((LEN(SUBSTITUTE(SUBSTITUTE(SUBSTITUTE(J8," ",""),"0",""),"-",""))+LEN(SUBSTITUTE(SUBSTITUTE(SUBSTITUTE(K8," ",""),"0",""),"-","")))>(LEN(SUBSTITUTE(SUBSTITUTE(SUBSTITUTE(M8," ",""),"0",""),"-",""))+LEN(SUBSTITUTE(SUBSTITUTE(SUBSTITUTE(N8," ",""),"0",""),"-",""))),1,0))+IF(UPPER(L9)="X",0,IF((LEN(SUBSTITUTE(SUBSTITUTE(SUBSTITUTE(J9," ",""),"0",""),"-",""))+LEN(SUBSTITUTE(SUBSTITUTE(SUBSTITUTE(K9," ",""),"0",""),"-","")))>(LEN(SUBSTITUTE(SUBSTITUTE(SUBSTITUTE(M9," ",""),"0",""),"-",""))+LEN(SUBSTITUTE(SUBSTITUTE(SUBSTITUTE(N9," ",""),"0",""),"-",""))),1,0)) | K12: =LEN(SUBSTITUTE(SUBSTITUTE(SUBSTITUTE(J5," ",""),"0",""),"-",""))+LEN(SUBSTITUTE(SUBSTITUTE(SUBSTITUTE(K5," ",""),"0",""),"-",""))+LEN(SUBSTITUTE(SUBSTITUTE(SUBSTITUTE(J6," ",""),"0",""),"-",""))+LEN(SUBSTITUTE(SUBSTITUTE(SUBSTITUTE(K6," ",""),"0",""),"-",""))+LEN(SUBSTITUTE(SUBSTITUTE(SUBSTITUTE(J7," ",""),"0",""),"-",""))+LEN(SUBSTITUTE(SUBSTITUTE(SUBSTITUTE(K7," ",""),"0",""),"-",""))+LEN(SUBSTITUTE(SUBSTITUTE(SUBSTITUTE(J8," ",""),"0",""),"-",""))+LEN(SUBSTITUTE(SUBSTITUTE(SUBSTITUTE(K8," ",""),"0",""),"-",""))+LEN(SUBSTITUTE(SUBSTITUTE(SUBSTITUTE(J9," ",""),"0",""),"-",""))+LEN(SUBSTITUTE(SUBSTITUTE(SUBSTITUTE(K9," ",""),"0",""),"-","")) | M12: =LEN(SUBSTITUTE(SUBSTITUTE(SUBSTITUTE(M5," ",""),"0",""),"-",""))+LEN(SUBSTITUTE(SUBSTITUTE(SUBSTITUTE(N5," ",""),"0",""),"-",""))+LEN(SUBSTITUTE(SUBSTITUTE(SUBSTITUTE(M6," ",""),"0",""),"-",""))+LEN(SUBSTITUTE(SUBSTITUTE(SUBSTITUTE(N6," ",""),"0",""),"-",""))+LEN(SUBSTITUTE(SUBSTITUTE(SUBSTITUTE(M7," ",""),"0",""),"-",""))+LEN(SUBSTITUTE(SUBSTITUTE(SUBSTITUTE(N7," ",""),"0",""),"-",""))+LEN(SUBSTITUTE(SUBSTITUTE(SUBSTITUTE(M8," ",""),"0",""),"-",""))+LEN(SUBSTITUTE(SUBSTITUTE(SUBSTITUTE(N8," ",""),"0",""),"-",""))+LEN(SUBSTITUTE(SUBSTITUTE(SUBSTITUTE(M9," ",""),"0",""),"-",""))+LEN(SUBSTITUTE(SUBSTITUTE(SUBSTITUTE(N9," ",""),"0",""),"-","")) | N12: =IF(UPPER(L5)="X",0,IF((LEN(SUBSTITUTE(SUBSTITUTE(SUBSTITUTE(M5," ",""),"0",""),"-",""))+LEN(SUBSTITUTE(SUBSTITUTE(SUBSTITUTE(N5," ",""),"0",""),"-","")))>(LEN(SUBSTITUTE(SUBSTITUTE(SUBSTITUTE(J5," ",""),"0",""),"-",""))+LEN(SUBSTITUTE(SUBSTITUTE(SUBSTITUTE(K5," ",""),"0",""),"-",""))),1,0))+IF(UPPER(L6)="X",0,IF((LEN(SUBSTITUTE(SUBSTITUTE(SUBSTITUTE(M6," ",""),"0",""),"-",""))+LEN(SUBSTITUTE(SUBSTITUTE(SUBSTITUTE(N6," ",""),"0",""),"-","")))>(LEN(SUBSTITUTE(SUBSTITUTE(SUBSTITUTE(J6," ",""),"0",""),"-",""))+LEN(SUBSTITUTE(SUBSTITUTE(SUBSTITUTE(K6," ",""),"0",""),"-",""))),1,0))+IF(UPPER(L7)="X",0,IF((LEN(SUBSTITUTE(SUBSTITUTE(SUBSTITUTE(M7," ",""),"0",""),"-",""))+LEN(SUBSTITUTE(SUBSTITUTE(SUBSTITUTE(N7," ",""),"0",""),"-","")))>(LEN(SUBSTITUTE(SUBSTITUTE(SUBSTITUTE(J7," ",""),"0",""),"-",""))+LEN(SUBSTITUTE(SUBSTITUTE(SUBSTITUTE(K7," ",""),"0",""),"-",""))),1,0))+IF(UPPER(L8)="X",0,IF((LEN(SUBSTITUTE(SUBSTITUTE(SUBSTITUTE(M8," ",""),"0",""),"-",""))+LEN(SUBSTITUTE(SUBSTITUTE(SUBSTITUTE(N8," ",""),"0",""),"-","")))>(LEN(SUBSTITUTE(SUBSTITUTE(SUBSTITUTE(J8," ",""),"0",""),"-",""))+LEN(SUBSTITUTE(SUBSTITUTE(SUBSTITUTE(K8," ",""),"0",""),"-",""))),1,0))+IF(UPPER(L9)="X",0,IF((LEN(SUBSTITUTE(SUBSTITUTE(SUBSTITUTE(M9," ",""),"0",""),"-",""))+LEN(SUBSTITUTE(SUBSTITUTE(SUBSTITUTE(N9," ",""),"0",""),"-","")))>(LEN(SUBSTITUTE(SUBSTITUTE(SUBSTITUTE(J9," ",""),"0",""),"-",""))+LEN(SUBSTITUTE(SUBSTITUTE(SUBSTITUTE(K9," ",""),"0",""),"-",""))),1,0)) | O12: Victories / Points
F15: 1. | N15: 1.
F16: 2. | N16: 2.
A23: Round 2 - Match 3 | I23: Round 2 - Match 4
A24: White | D24: vs | G24: Red | I24: White | L24: vs | O24: Red
A25: =CONCATENATE("M 1 ",G15) | G25: =CONCATENATE("Pool A-1st ",'Pool Matches'!G66) | I25: =CONCATENATE("M 2 ",O15) | O25: =CONCATENATE("Pool C-1st ",'Pool Matches'!O64)
A26: 1 | G26: 1 | I26: 1 | O26: 1
A27: 2 | G27: 2 | I27: 2 | O27: 2
A28: 3 | G28: 3 | I28: 3 | O28: 3
A29: 4 | G29: 4 | I29: 4 | O29: 4
A30: 5 | G30: 5 | I30: 5 | O30: 5
A32: =CONCATENATE("M 1 ",G15) | B32: IV | C32: PW | E32: PW | F32: IV | G32: =CONCATENATE("Pool A-1st ",'Pool Matches'!G66) | I32: =CONCATENATE("M 2 ",O15) | J32: IV | K32: PW | M32: PW | N32: IV | O32: =CONCATENATE("Pool C-1st ",'Pool Matches'!O64)
