Workbook

Sheet data
A1: Title prefix: | B1: MY TOURNAMENT
A2: Number | B2: Player Name | C2: Player Dojo | E2: Metadata
A3: 0 | B3: Kevin Clark | C3: Team Alpha
A4: 1 | B4: Luke Rodriguez | C4: Team Beta
A5: 2 | B5: Michael Lewis | C5: Team Gamma
A6: 3 | B6: Nathan Lee | C6: Team Delta
A7: 4 | B7: Oliver Walker | C7: Team Epsilon
A8: 5 | B8: Paul Hall | C8: Team Alpha
A9: 6 | B9: Quentin Allen | C9: Team Beta
A10: 7 | B10: Robert Young | C10: Team Gamma
A11: 8 | B11: Steven Hernandez | C11: Team Delta
A12: 9 | B12: Thomas King | C12: Team Epsilon

Sheet Time Estimator
A1: Number of pools | B1: Team size | C1: Matches per pool | D1: Time per match | E1: Total time for matches | F1: Padding time for rotation | G1: Time for breaks | H1: Total Time
A2: 0 | B2: 1 | C2: 0 | D2: 0.0020833333 | E2: =(A2*B2*C2*D2) | F2: 0.00034722222 | G2: 0.020833333 | H2: =C2*I2+J2
A3: 0 | B3: 0 | C3: 0 | D3: 0.0020833333 | E3: =(A3*B3*C3*D3) | F3: 0.00034722222 | G3: 0.020833333 | H3: =E3+(A3*C3*F3)+G3
A7: Number of Elimination Matches | B7: Team size | D7: Time per match | E7: Total time for matches | F7: Padding time for rotation | G7: Time for breaks | H7: Total Time
A8: 9 | B8: 1 | D8: 0.0027777778 | E8: =(A8*B8*D8) | F8: 0.00034722222 | G8: 0.020833333 | H8: =E8+(A8*F8)+G8
E13: Tournament Summary
A14: 1 | E14: Total Pool Time | H14: =H2
E15: Total Elimination Time | H15: =H8
E16: Grand Total (Sequential) | H16: =H14+H15
E17: Grand Total (Parallel across Courts) | H17: =H16/A14
E18: Start Time: | H18: 0.375
E19: Estimated Finish Time | H19: =H18+H17

Sheet Elimination Matches
A1: Shiaijo A
A2: Round 1 - Match 1
A3: White | D3: vs | G3: Red
A4: ='data'!$B$7 | G4: ='data'!$B$6
F6: 1.
F7: 2.
A10: Round 1 - Match 2
A11: White | D11: vs | G11: Red
A12: ='data'!$B$12 | G12: ='data'!$B$11
F14: 1.
F15: 2.
A23: Round 2 - Match 3
A24: White | D24: vs | G24: Red
A25: ='data'!$B$4 | G25: ='data'!$B$3
F27: 1.
F28: 2.
A31: Round 2 - Match 4
A32: White | D32: vs | G32: Red
A33: =CONCATENATE("M 1 ",G6) | G33: ='data'!$B$5
F35: 1.
F36: 2.
A39: Round 2 - Match 5
A40: White | D40: vs | G40: Red
A41: ='data'!$B$9 | G41: ='data'!$B$8
F43: 1.
F44: 2.
A47: Round 2 - Match 6
A48: White | D48: vs | G48: Red
A49: =CONCATENATE("M 2 ",G14) | G49: ='data'!$B$10
F51: 1.
F52: 2.
A60: Round 3 - Match 7
A61: White | D61: vs | G61: Red
A62: =CONCATENATE("M 4 ",G35) | G62: =CONCATENATE("M 3 ",G27)
F64: 1.
F65: 2.
A68: Round 3 - Match 8
A69: White | D69: vs | G69: Red
A70: =CONCATENATE("M 6 ",G51) | G70: =CONCATENATE("M 5 ",G43)
F72: 1.
...

Sheet Names to Print
A1: 0 | B1: =data!$B$3
A2: 1 | B2: =data!$B$4
A3: 2 | B3: =data!$B$5
A4: 3 | B4: =data!$B$6
A5: 4 | B5: =data!$B$7
A6: 5 | B6: =data!$B$8
A7: 6 | B7: =data!$B$9
A8: 7 | B8: =data!$B$10
A9: 8 | B9: =data!$B$11
A10: 9 | B10: =data!$B$12

Sheet Tree 1
A1: =IF(data!$B$1="","Shiaijo A",data!$B$1&" - Shiaijo A")
E6: Kevin Clark
G8: 3
E10: Luke Rodriguez
I12: 7
E14: Michael Lewis
G16: 4
C17: Nathan Lee
E18: 1
C19: Oliver Walker
K20: 9
E22: Paul Hall
G24: 5
E26: Quentin Allen
I28: 8
E30: Robert Young
G32: 6
C33: Steven Hernandez
E34: 2
C35: Thomas King
